Workbook

Sheet 使用说明
A1: 股票复盘训练模板
A2: 使用流程 | B2: 先在“板块观察”记录大盘和3个候选强板块；再在“每日复盘”填写个股，并用板块记录ID联动板块评分和阶段；到期后补“事后验证”；触发模拟买卖时补“模拟交易”。
A3: 核心原则 | B3: 模板不替你判断强弱和趋势，只帮你把大盘、板块、个股串起来，并自动计算完整度、板块综合分、验证日期和交易收益。
A4: 建议频率 | B4: 每天 3 个板块，每个板块 1-2 只股票；先坚持低负担记录，再逐步提高判断质量。
A5: 板块评分 | B5: 相对大盘、近3/5日持续、内部扩散、领涨股、回调抗跌各填0-2分；7分以上重点观察，5-6分候选，4分以下降级观察。
A7: 最小闭环标识 | B7: 绿色列为每天最低必填项。只要完成“板块观察”绿色列 + “每日复盘”绿色列，就算当天最低训练完成。
A8: 到期验证规则 | B8: 3日/5日/10日验证到期时，再补“事后验证”绿色列；没有到期记录时当天不用补。
A9: 建议负荷 | B9: 前2周每天填3个板块、1只重点股票；先保证闭环，不追求数量。

Sheet 板块观察
A1: 记录ID | B1: 日期 | C1: 大盘状态 | D1: 大盘涨跌% | E1: 市场量能 | F1: 板块名称 | G1: 板块类型 | H1: 板块今日涨跌% | I1: 相对大盘评分 | J1: 近3/5日持续评分 | K1: 内部扩散评分 | L1: 领涨股评分 | M1: 回调抗跌评分 | N1: 综合分 | O1: 板块阶段 | P1: 领涨股 | Q1: 健康回调股 | R1: 补涨股 | S1: 观察结论 | T1: 完整度 | U1: 备注
N2: =IF(A2="","",SUM(I2:M2)) | T2: =IF(A2="","",(COUNTA(A2:M2)+COUNTA(O2:S2))/18)
N3: =IF(A3="","",SUM(I3:M3)) | T3: =IF(A3="","",(COUNTA(A3:M3)+COUNTA(O3:S3))/18)
N4: =IF(A4="","",SUM(I4:M4)) | T4: =IF(A4="","",(COUNTA(A4:M4)+COUNTA(O4:S4))/18)
N5: =IF(A5="","",SUM(I5:M5)) | T5: =IF(A5="","",(COUNTA(A5:M5)+COUNTA(O5:S5))/18)
N6: =IF(A6="","",SUM(I6:M6)) | T6: =IF(A6="","",(COUNTA(A6:M6)+COUNTA(O6:S6))/18)
N7: =IF(A7="","",SUM(I7:M7)) | T7: =IF(A7="","",(COUNTA(A7:M7)+COUNTA(O7:S7))/18)
N8: =IF(A8="","",SUM(I8:M8)) | T8: =IF(A8="","",(COUNTA(A8:M8)+COUNTA(O8:S8))/18)
N9: =IF(A9="","",SUM(I9:M9)) | T9: =IF(A9="","",(COUNTA(A9:M9)+COUNTA(O9:S9))/18)
N10: =IF(A10="","",SUM(I10:M10)) | T10: =IF(A10="","",(COUNTA(A10:M10)+COUNTA(O10:S10))/18)
N11: =IF(A11="","",SUM(I11:M11)) | T11: =IF(A11="","",(COUNTA(A11:M11)+COUNTA(O11:S11))/18)
N12: =IF(A12="","",SUM(I12:M12)) | T12: =IF(A12="","",(COUNTA(A12:M12)+COUNTA(O12:S12))/18)
N13: =IF(A13="","",SUM(I13:M13)) | T13: =IF(A13="","",(COUNTA(A13:M13)+COUNTA(O13:S13))/18)
... N501: =IF(A501="","",SUM(I501:M501)) | T501: =IF(A501="","",(COUNTA(A501:M501)+COUNTA(O501:S501))/18)

Sheet 每日复盘
A1: 记录ID | B1: 日期 | C1: 大盘状态 | D1: 大盘涨跌% | E1: 股票 | F1: 板块 | G1: 板块记录ID | H1: 板块综合分 | I1: 板块阶段 | J1: 个股类型 | K1: 个股相对板块 | L1: 当前价 | M1: 今日涨跌% | N1: 个股结构 | O1: 5/20日线 | P1: MACD | Q1: 成交量 | R1: 支撑位 | S1: 压力位 | T1: 强走势 | U1: 中性走势 | V1: 弱走势 | W1: 失效条件 | X1: 模拟动作 | Y1: 状态色 | Z1: 完整度 | AA1: 3日验证日 | AB1: 5日验证日 | AC1: 10日验证日 | AD1: 备注
H2: =IF(G2="","",IFERROR(VLOOKUP(G2,板块观察!A:U,14,FALSE),"")) | I2: =IF(G2="","",IFERROR(VLOOKUP(G2,板块观察!A:U,15,FALSE),"")) | Z2: =IF(A2="","",(COUNTA(A2:G2)+COUNTA(J2:Y2))/23) | AA2: =IF(B2="","",WORKDAY(B2,3)) | AB2: =IF(B2="","",WORKDAY(B2,5)) | AC2: =IF(B2="","",WORKDAY(B2,10))
H3: =IF(G3="","",IFERROR(VLOOKUP(G3,板块观察!A:U,14,FALSE),"")) | I3: =IF(G3="","",IFERROR(VLOOKUP(G3,板块观察!A:U,15,FALSE),"")) | Z3: =IF(A3="","",(COUNTA(A3:G3)+COUNTA(J3:Y3))/23) | AA3: =IF(B3="","",WORKDAY(B3,3)) | AB3: =IF(B3="","",WORKDAY(B3,5)) | AC3: =IF(B3="","",WORKDAY(B3,10))
H4: =IF(G4="","",IFERROR(VLOOKUP(G4,板块观察!A:U,14,FALSE),"")) | I4: =IF(G4="","",IFERROR(VLOOKUP(G4,板块观察!A:U,15,FALSE),"")) | Z4: =IF(A4="","",(COUNTA(A4:G4)+COUNTA(J4:Y4))/23) | AA4: =IF(B4="","",WORKDAY(B4,3)) | AB4: =IF(B4="","",WORKDAY(B4,5)) | AC4: =IF(B4="","",WORKDAY(B4,10))
H5: =IF(G5="","",IFERROR(VLOOKUP(G5,板块观察!A:U,14,FALSE),"")) | I5: =IF(G5="","",IFERROR(VLOOKUP(G5,板块观察!A:U,15,FALSE),"")) | Z5: =IF(A5="","",(COUNTA(A5:G5)+COUNTA(J5:Y5))/23) | AA5: =IF(B5="","",WORKDAY(B5,3)) | AB5: =IF(B5="","",WORKDAY(B5,5)) | AC5: =IF(B5="","",WORKDAY(B5,10))
H6: =IF(G6="","",IFERROR(VLOOKUP(G6,板块观察!A:U,14,FALSE),"")) | I6: =IF(G6="","",IFERROR(VLOOKUP(G6,板块观察!A:U,15,FALSE),"")) | Z6: =IF(A6="","",(COUNTA(A6:G6)+COUNTA(J6:Y6))/23) | AA6: =IF(B6="","",WORKDAY(B6,3)) | AB6: =IF(B6="","",WORKDAY(B6,5)) | AC6: =IF(B6="","",WORKDAY(B6,10))
H7: =IF(G7="","",IFERROR(VLOOKUP(G7,板块观察!A:U,14,FALSE),"")) | I7: =IF(G7="","",IFERROR(VLOOKUP(G7,板块观察!A:U,15,FALSE),"")) | Z7: =IF(A7="","",(COUNTA(A7:G7)+COUNTA(J7:Y7))/23) | AA7: =IF(B7="","",WORKDAY(B7,3)) | AB7: =IF(B7="","",WORKDAY(B7,5)) | AC7: =IF(B7="","",WORKDAY(B7,10))
H8: =IF(G8="","",IFERROR(VLOOKUP(G8,板块观察!A:U,14,FALSE),"")) | I8: =IF(G8="","",IFERROR(VLOOKUP(G8,板块观察!A:U,15,FALSE),"")) | Z8: =IF(A8="","",(COUNTA(A8:G8)+COUNTA(J8:Y8))/23) | AA8: =IF(B8="","",WORKDAY(B8,3)) | AB8: =IF(B8="","",WORKDAY(B8,5)) | AC8: =IF(B8="","",WORKDAY(B8,10))
H9: =IF(G9="","",IFERROR(VLOOKUP(G9,板块观察!A:U,14,FALSE),"")) | I9: =IF(G9="","",IFERROR(VLOOKUP(G9,板块观察!A:U,15,FALSE),"")) | Z9: =IF(A9="","",(COUNTA(A9:G9)+COUNTA(J9:Y9))/23) | AA9: =IF(B9="","",WORKDAY(B9,3)) | AB9: =IF(B9="","",WORKDAY(B9,5)) | AC9: =IF(B9="","",WORKDAY(B9,10))
H10: =IF(G10="","",IFERROR(VLOOKUP(G10,板块观察!A:U,14,FALSE),"")) | I10: =IF(G10="","",IFERROR(VLOOKUP(G10,板块观察!A:U,15,FALSE),"")) | Z10: =IF(A10="","",(COUNTA(A10:G10)+COUNTA(J10:Y10))/23) | AA10: =IF(B10="","",WORKDAY(B10,3)) | AB10: =IF(B10="","",WORKDAY(B10,5)) | AC10: =IF(B10="","",WORKDAY(B10,10))
H11: =IF(G11="","",IFERROR(VLOOKUP(G11,板块观察!A:U,14,FALSE),"")) | I11: =IF(G11="","",IFERROR(VLOOKUP(G11,板块观察!A:U,15,FALSE),"")) | Z11: =IF(A11="","",(COUNTA(A11:G11)+COUNTA(J11:Y11))/23) | AA11: =IF(B11="","",WORKDAY(B11,3)) | AB11: =IF(B11="","",WORKDAY(B11,5)) | AC11: =IF(B11="","",WORKDAY(B11,10))
H12: =IF(G12="","",IFERROR(VLOOKUP(G12,板块观察!A:U,14,FALSE),"")) | I12: =IF(G12="","",IFERROR(VLOOKUP(G12,板块观察!A:U,15,FALSE),"")) | Z12: =IF(A12="","",(COUNTA(A12:G12)+COUNTA(J12:Y12))/23) | AA12: =IF(B12="","",WORKDAY(B12,3)) | AB12: =IF(B12="","",WORKDAY(B12,5)) | AC12: =IF(B12="","",WORKDAY(B12,10))
H13: =IF(G13="","",IFERROR(VLOOKUP(G13,板块观察!A:U,14,FALSE),"")) | I13: =IF(G13="","",IFERROR(VLOOKUP(G13,板块观察!A:U,15,FALSE),"")) | Z13: =IF(A13="","",(COUNTA(A13:G13)+COUNTA(J13:Y13))/23) | AA13: =IF(B13="","",WORKDAY(B13,3)) | AB13: =IF(B13="","",WORKDAY(B13,5)) | AC13: =IF(B13="","",WORKDAY(B13,10))
... H501: =IF(G501="","",IFERROR(VLOOKUP(G501,板块观察!A:U,14,FALSE),"")) | I501: =IF(G501="","",IFERROR(VLOOKUP(G501,板块观察!A:U,15,FALSE),"")) | Z501: =IF(A501="","",(COUNTA(A501:G501)+COUNTA(J501:Y501))/23) | AA501: =IF(B501="","",WORKDAY(B501,3)) | AB501: =IF(B501="","",WORKDAY(B501,5)) | AC501: =IF(B501="","",WORKDAY(B501,10))

Sheet 事后验证
A1: 验证ID | B1: 来源记录ID | C1: 股票 | D1: 原复盘日期 | E1: 原个股结构 | F1: 验证节点 | G1: 验证日期 | H1: 验证价格 | I1: 实际走势归类 | J1: 是否触发失效 | K1: 判断结果 | L1: 错误归因 | M1: 修正建议 | N1: 到期状态
N2: =IF(G2="","",IF(TODAY()>=G2,"到期","未到期"))
N3: =IF(G3="","",IF(TODAY()>=G3,"到期","未到期"))
N4: =IF(G4="","",IF(TODAY()>=G4,"到期","未到期"))
N5: =IF(G5="","",IF(TODAY()>=G5,"到期","未到期"))
N6: =IF(G6="","",IF(TODAY()>=G6,"到期","未到期"))
N7: =IF(G7="","",IF(TODAY()>=G7,"到期","未到期"))
N8: =IF(G8="","",IF(TODAY()>=G8,"到期","未到期"))
N9: =IF(G9="","",IF(TODAY()>=G9,"到期","未到期"))
N10: =IF(G10="","",IF(TODAY()>=G10,"到期","未到期"))
N11: =IF(G11="","",IF(TODAY()>=G11,"到期","未到期"))
N12: =IF(G12="","",IF(TODAY()>=G12,"到期","未到期"))
N13: =IF(G13="","",IF(TODAY()>=G13,"到期","未到期"))
... N501: =IF(G501="","",IF(TODAY()>=G501,"到期","未到期"))

Sheet 模拟交易
A1: 交易ID | B1: 来源记录ID | C1: 股票 | D1: 买入日期 | E1: 买入理由 | F1: 买入价 | G1: 止损价 | H1: 目标价 | I1: 仓位类型 | J1: 卖出日期 | K1: 卖出价 | L1: 收益率 | M1: 止损距离 | N1: 风险收益比 | O1: 结果 | P1: 主要问题 | Q1: 备注
L2: =IF(OR(F2="",K2=""),"",(K2-F2)/F2) | M2: =IF(OR(F2="",G2=""),"",(G2-F2)/F2) | N2: =IF(OR(F2="",G2="",H2=""),"",(H2-F2)/(F2-G2))
L3: =IF(OR(F3="",K3=""),"",(K3-F3)/F3) | M3: =IF(OR(F3="",G3=""),"",(G3-F3)/F3) | N3: =IF(OR(F3="",G3="",H3=""),"",(H3-F3)/(F3-G3))
L4: =IF(OR(F4="",K4=""),"",(K4-F4)/F4) | M4: =IF(OR(F4="",G4=""),"",(G4-F4)/F4) | N4: =IF(OR(F4="",G4="",H4=""),"",(H4-F4)/(F4-G4))
L5: =IF(OR(F5="",K5=""),"",(K5-F5)/F5) | M5: =IF(OR(F5="",G5=""),"",(G5-F5)/F5) | N5: =IF(OR(F5="",G5="",H5=""),"",(H5-F5)/(F5-G5))
L6: =IF(OR(F6="",K6=""),"",(K6-F6)/F6) | M6: =IF(OR(F6="",G6=""),"",(G6-F6)/F6) | N6: =IF(OR(F6="",G6="",H6=""),"",(H6-F6)/(F6-G6))
L7: =IF(OR(F7="",K7=""),"",(K7-F7)/F7) | M7: =IF(OR(F7="",G7=""),"",(G7-F7)/F7) | N7: =IF(OR(F7="",G7="",H7=""),"",(H7-F7)/(F7-G7))
L8: =IF(OR(F8="",K8=""),"",(K8-F8)/F8) | M8: =IF(OR(F8="",G8=""),"",(G8-F8)/F8) | N8: =IF(OR(F8="",G8="",H8=""),"",(H8-F8)/(F8-G8))
L9: =IF(OR(F9="",K9=""),"",(K9-F9)/F9) | M9: =IF(OR(F9="",G9=""),"",(G9-F9)/F9) | N9: =IF(OR(F9="",G9="",H9=""),"",(H9-F9)/(F9-G9))
L10: =IF(OR(F10="",K10=""),"",(K10-F10)/F10) | M10: =IF(OR(F10="",G10=""),"",(G10-F10)/F10) | N10: =IF(OR(F10="",G10="",H10=""),"",(H10-F10)/(F10-G10))
L11: =IF(OR(F11="",K11=""),"",(K11-F11)/F11) | M11: =IF(OR(F11="",G11=""),"",(G11-F11)/F11) | N11: =IF(OR(F11="",G11="",H11=""),"",(H11-F11)/(F11-G11))
L12: =IF(OR(F12="",K12=""),"",(K12-F12)/F12) | M12: =IF(OR(F12="",G12=""),"",(G12-F12)/F12) | N12: =IF(OR(F12="",G12="",H12=""),"",(H12-F12)/(F12-G12))
L13: =IF(OR(F13="",K13=""),"",(K13-F13)/F13) | M13: =IF(OR(F13="",G13=""),"",(G13-F13)/F13) | N13: =IF(OR(F13="",G13="",H13=""),"",(H13-F13)/(F13-G13))
... L501: =IF(OR(F501="",K501=""),"",(K501-F501)/F501) | M501: =IF(OR(F501="",G501=""),"",(G501-F501)/F501) | N501: =IF(OR(F501="",G501="",H501=""),"",(H501-F501)/(F501-G501))

Sheet 汇总看板
A1: 指标 | B1: 当前统计
A2: 板块观察记录数 | B2: =COUNTA(板块观察!A2:A501)
A3: 平均板块分 | B3: =IFERROR(AVERAGEIF(板块观察!N2:N501,">0"),"")
A4: 强板块数量(>=7分) | B4: =COUNTIF(板块观察!N2:N501,">=7")
A5: 复盘记录数 | B5: =COUNTA(每日复盘!A2:A501)
A6: 平均复盘完整度 | B6: =IFERROR(AVERAGEIF(每日复盘!Z2:Z501,">0"),"")
A7: 验证记录数 | B7: =COUNTA(事后验证!A2:A501)
A8: 判断正确 | B8: =COUNTIF(事后验证!K2:K501,"正确")
A9: 部分正确 | B9: =COUNTIF(事后验证!K2:K501,"部分正确")
A10: 判断错误 | B10: =COUNTIF(事后验证!K2:K501,"错误")
A11: 模拟交易笔数 | B11: =COUNTA(模拟交易!A2:A501)
A12: 已平仓成功 | B12: =COUNTIF(模拟交易!O2:O501,"成功")
A13: 已平仓失败 | B13: =COUNTIF(模拟交易!O2:O501,"失败")
A14: 模拟胜率 | B14: =IFERROR(B12/(B12+B13),"")
A15: 平均收益率 | B15: =IFERROR(AVERAGEIF(模拟交易!L2:L501,"<>"),"")
A16: 最大亏损 | B16: =IFERROR(MIN(模拟交易!L2:L501),"")
A18: 错误类型 | B18: 次数
A19: 假突破误判 | B19: =COUNTIF(事后验证!L2:L501,"假突破误判")+COUNTIF(模拟交易!P2:P501,"假突破误判")
A20: 低位突破确认不足 | B20: =COUNTIF(事后验证!L2:L501,"低位突破确认不足")+COUNTIF(模拟交易!P2:P501,"低位突破确认不足")
A21: 支撑误判 | B21: =COUNTIF(事后验证!L2:L501,"支撑误判")+COUNTIF(模拟交易!P2:P501,"支撑误判")
A22: 买入过早 | B22: =COUNTIF(事后验证!L2:L501,"买入过早")+COUNTIF(模拟交易!P2:P501,"买入过早")
A23: 放量滞涨后退出慢 | B23: =COUNTIF(事后验证!L2:L501,"放量滞涨后退出慢")+COUNTIF(模拟交易!P2:P501,"放量滞涨后退出慢")
A24: 板块强弱误判 | B24: =COUNTIF(事后验证!L2:L501,"板块强弱误判")+COUNTIF(模拟交易!P2:P501,"板块强弱误判")
A25: 成交量理解错误 | B25: =COUNTIF(事后验证!L2:L501,"成交量理解错误")+COUNTIF(模拟交易!P2:P501,"成交量理解错误")
A26: 减仓偏早 | B26: =COUNTIF(事后验证!L2:L501,"减仓偏早")+COUNTIF(模拟交易!P2:P501,"减仓偏早")
A28: 板块阶段统计
A29: 板块阶段 | B29: 样本数 | C29: 平均板块分
A30: 新启动 | B30: =COUNTIF(板块观察!O2:O501,"新启动") | C30: =IFERROR(AVERAGEIF(板块观察!O2:O501,"新启动",板块观察!N2:N501),"")
A31: 主升初期 | B31: =COUNTIF(板块观察!O2:O501,"主升初期") | C31: =IFERROR(AVERAGEIF(板块观察!O2:O501,"主升初期",板块观察!N2:N501),"")
A32: 主升中段 | B32: =COUNTIF(板块观察!O2:O501,"主升中段") | C32: =IFERROR(AVERAGEIF(板块观察!O2:O501,"主升中段",板块观察!N2:N501),"")
A33: 高潮加速 | B33: =COUNTIF(板块观察!O2:O501,"高潮加速") | C33: =IFERROR(AVERAGEIF(板块观察!O2:O501,"高潮加速",板块观察!N2:N501),"")
A34: 高位震荡 | B34: =COUNTIF(板块观察!O2:O501,"高位震荡") | C34: =IFERROR(AVERAGEIF(板块观察!O2:O501,"高位震荡",板块观察!N2:N501),"")
A35: 退潮 | B35: =COUNTIF(板块观察!O2:O501,"退潮") | C35: =IFERROR(AVERAGEIF(板块观察!O2:O501,"退潮",板块观察!N2:N501),"")
A36: 待观察 | B36: =COUNTIF(板块观察!O2:O501,"待观察") | C36: =IFERROR(AVERAGEIF(板块观察!O2:O501,"待观察",板块观察!N2:N501),"")
A38: 个股类型统计
A39: 个股类型 | B39: 复盘样本 | C39: 强于板块 | D39: 同步板块 | E39: 弱于板块
A40: 领涨股 | B40: =COUNTIF(每日复盘!J2:J501,"领涨股") | C40: =COUNTIFS(每日复盘!J2:J501,"领涨股",每日复盘!K2:K501,"强于板块") | D40: =COUNTIFS(每日复盘!J2:J501,"领涨股",每日复盘!K2:K501,"同步板块") | E40: =COUNTIFS(每日复盘!J2:J501,"领涨股",每日复盘!K2:K501,"弱于板块")
A41: 健康回调股 | B41: =COUNTIF(每日复盘!J2:J501,"健康回调股") | C41: =COUNTIFS(每日复盘!J2:J501,"健康回调股",每日复盘!K2:K501,"强于板块") | D41: =COUNTIFS(每日复盘!J2:J501,"健康回调股",每日复盘!K2:K501,"同步板块") | E41: =COUNTIFS(每日复盘!J2:J501,"健康回调股",每日复盘!K2:K501,"弱于板块")
A42: 补涨股 | B42: =COUNTIF(每日复盘!J2:J501,"补涨股") | C42: =COUNTIFS(每日复盘!J2:J501,"补涨股",每日复盘!K2:K501,"强于板块") | D42: =COUNTIFS(每日复盘!J2:J501,"补涨股",每日复盘!K2:K501,"同步板块") | E42: =COUNTIFS(每日复盘!J2:J501,"补涨股",每日复盘!K2:K501,"弱于板块")
A43: 跟风股 | B43: =COUNTIF(每日复盘!J2:J501,"跟风股") | C43: =COUNTIFS(每日复盘!J2:J501,"跟风股",每日复盘!K2:K501,"强于板块") | D43: =COUNTIFS(每日复盘!J2:J501,"跟风股",每日复盘!K2:K501,"同步板块") | E43: =COUNTIFS(每日复盘!J2:J501,"跟风股",每日复盘!K2:K501,"弱于板块")
...

Sheet 选项
A1: 大盘状态 | B1: 上升 | C1: 震荡偏强 | D1: 震荡 | E1: 震荡偏弱 | F1: 下降
A2: 市场量能 | B2: 放量 | C2: 平量 | D2: 缩量 | E2: 不明确
A3: 板块类型 | B3: 行业 | C3: 概念
A4: 板块阶段 | B4: 新启动 | C4: 主升初期 | D4: 主升中段 | E4: 高潮加速 | F4: 高位震荡 | G4: 退潮 | H4: 待观察
A5: 板块状态 | B5: 强 | C5: 一般 | D5: 弱
A6: 个股类型 | B6: 领涨股 | C6: 健康回调股 | D6: 补涨股 | E6: 跟风股 | F6: 弱反弹股 | G6: 未分类
A7: 相对强弱 | B7: 强于板块 | C7: 同步板块 | D7: 弱于板块 | E7: 不明确
A8: 个股结构 | B8: 上升趋势 | C8: 下降趋势 | D8: 震荡 | E8: 下降逆转 | F8: 箱体突破初期 | G8: 突破后回踩 | H8: 假突破 | I8: 高位整理 | J8: 未分类
A9: 均线 | B9: 5日>20日 | C9: 5日接近20日 | D9: 5日<20日
A10: MACD | B10: 金叉向上 | C10: 金叉初现 | D10: 红柱扩大 | E10: 红柱缩短 | F10: 绿柱缩短 | G10: 绿柱扩大 | H10: 死叉 | I10: 不明确
A11: 成交量 | B11: 放量上涨 | C11: 缩量上涨 | D11: 放量下跌 | E11: 缩量回调 | F11: 放量滞涨 | G11: 平量 | H11: 不明确
A12: 模拟动作 | B12: 仅观察 | C12: 试错买入 | D12: 等回踩 | E12: 加仓 | F12: 减仓 | G12: 退出 | H12: 持有模拟
A13: 状态色 | B13: 绿-确认 | C13: 黄-待确认 | D13: 红-失效 | E13: 灰-观察
A14: 验证节点 | B14: 3日 | C14: 5日 | D14: 10日
A15: 实际走势归类 | B15: 强走势 | C15: 中性走势 | D15: 弱走势 | E15: 未触发
A16: 判断结果 | B16: 正确 | C16: 部分正确 | D16: 错误 | E16: 待验证
A17: 错误归因 | B17: 无 | C17: 假突破误判 | D17: 低位突破确认不足 | E17: 支撑误判 | F17: 买入过早 | G17: 放量滞涨后退出慢 | H17: 板块强弱误判 | I17: 成交量理解错误 | J17: 减仓偏早
A18: 仓位类型 | B18: 观察仓 | C18: 试错仓 | D18: 确认仓 | E18: 加仓
A19: 交易结果 | B19: 成功 | C19: 部分成功 | D19: 失败 | E19: 持有中
