Workbook

Sheet 单次交易
A1: 交易编号 | B1: 股票代码 | C1: 买入时账户金额 | D1: 本次允许亏损比例 | E1: 第一批买入价 | F1: 买入建议股数 | G1: 开仓风险告警 | H1: 第一批买入股数 | I1: 首次买入日期 | J1: 期望卖出价 | K1: 实际卖出价（填写） | L1: 最终卖出股数（自动） | M1: 卖出日期（填写） | N1: 止损价 | O1: 买入总费用 | P1: 卖出费用（填写） | Q1: 买入价的由来 | R1: 止损价的由来 | S1: 期望卖出价的由来 | T1: 实际卖出价的由来 | U1: 期望盈利比例 | V1: 期望止损比例 | W1: 盈亏比 | X1: 加权后实际盈亏 | Y1: 单笔仓位收益率 | Z1: 账户收益率与平均盈利率差值 | AA1: 持有天数 | AB1: 复利容许平均亏损上限 | AC1: 复利风险判断 | AD1: 交易打分评价 | AE1: 实际账户收益率 | AF1: 列1 | AG1: 交易预期类型 | AH1: 预期持有周期 | AI1: 预期选择理由 | AJ1: 周期匹配检查 | AK1: 已执行加仓次数 | AL1: 加仓总股数 | AM1: 最近加仓价 | AN1: 最新加仓止损价 | AO1: 实际加权买入价 | AP1: 最终持仓股数 | AQ1: 当前净止损风险 | AR1: 加仓规则检查
F2: =IF(OR(C2="",D2="",E2="",N2="",C2<=0,D2<=0,E2<=N2),"",ROUNDDOWN((C2*D2)/(E2-N2)/100,0)*100) | G2: =IF(A2="","",IF(H2<>"","已开仓",IF(账户数据!$B$23="已锁仓","禁止开仓：连续亏损达到上限",IF(账户数据!$B$23="解锁信息不完整","禁止开仓：请完整填写解锁信息",IF(OR(F2="",E2="",N2="",E2<=N2,账户数据!$B$7=""),"",IF(OR(AG2="",AH2="",AI2=""),"禁止开仓：交易预期未填写完整",IF(账户数据!$B$9+F2*(E2-N2)>=账户数据!$B$7,"禁止开仓：风险额度不足",IF(AJ2="周期与交易预期不匹配，请重新确认",IF(账户数据!$B$23="接近锁仓","允许开仓（接近锁仓；周期需复核）","允许开仓（周期需复核）"),IF(账户数据!$B$23="接近锁仓","允许开仓（接近锁仓）","允许开仓"))))))))) | L2: =IF(AP2="","",AP2) | U2: =IF(OR(AO2="",J2="",AO2<=0),"",(J2-AO2)/AO2) | V2: =IF(OR(AO2="",N2="",AO2<=0),"",(AO2-N2)/AO2) | W2: =IF(OR(U2="",V2="",V2<=0),"",U2/V2) | X2: =IF(OR(K2="",L2="",AO2="",AP2=""),"",(K2-AO2)*L2-IF(O2="",0,O2)-IF(P2="",0,P2)) | Y2: =IF(OR(X2="",AO2="",L2=""),"",IF(AO2*L2+IF(O2="",0,O2)<=0,"",X2/(AO2*L2+IF(O2="",0,O2)))) | Z2: =IF(OR(AE2="",多次统计数据!$B$8=""),"",AE2-多次统计数据!$B$8) | AA2: =IF(OR(I2="",M2="",M2<I2),"",M2-I2) | AB2: =IF(OR(A2="",多次统计数据!$B$8="",多次统计数据!$B$6<=0,多次统计数据!$B$6>=1),"",1-POWER(1+多次统计数据!$B$8,-多次统计数据!$B$6/(1-多次统计数据!$B$6))) | AC2: =IF(OR(AB2="",多次统计数据!$B$9=""),"",IF(多次统计数据!$B$9<AB2,"低于上限","达到或超过上限")) | AE2: =IF(OR(X2="",C2="",C2<=0),"",X2/C2) | AJ2: =IF(OR(AG2="",AH2=""),"",IF(OR(AND(AG2="短期博反弹",OR(AH2="1～3个交易日",AH2="4～10个交易日")),AND(AG2="突破冲新高",OR(AH2="4～10个交易日",AH2="11～20个交易日")),AND(AG2="趋势波段",OR(AH2="11～20个交易日",AH2="21～60个交易日",AH2="60个交易日以上"))),"匹配","周期与交易预期不匹配，请重新确认")) | AK2: =IF(A2="","",COUNTIFS(加仓管理!$A$2:$A$1001,A2,加仓管理!$G$2:$G$1001,">0")) | AL2: =IF(A2="","",SUMIFS(加仓管理!$G$2:$G$1001,加仓管理!$A$2:$A$1001,A2)) | AM2: =IF(AK2=0,"",IFERROR(LOOKUP(2,1/((加仓管理!$A$2:$A$1001=A2)*(加仓管理!$G$2:$G$1001>0)),加仓管理!$D$2:$D$1001),"")) | AN2: =IF(AK2=0,"",IFERROR(LOOKUP(2,1/((加仓管理!$A$2:$A$1001=A2)*(加仓管理!$G$2:$G$1001>0)),加仓管理!$E$2:$E$1001),"")) | AO2: =IF(OR(A2="",H2="",H2<=0),"",(E2*H2+SUMIFS(加仓管理!$H$2:$H$1001,加仓管理!$A$2:$A$1001,A2))/AP2) | AP2: =IF(OR(A2="",H2="",H2<=0),"",H2+AL2) | AQ2: =IF(A2="","",IF(M2<>"",0,IF(OR(H2="",N2=""),"",MAX((E2*H2+SUMIFS(加仓管理!$H$2:$H$1001,加仓管理!$A$2:$A$1001,A2))-MAX(N2,AN2)*AP2,0)))) | AR2: =IF(A2="","",IF(OR(E2="",H2=""),"违规：首次买入价格或股数缺失",IF(COUNTIFS(加仓管理!$A$2:$A$1001,A2,加仓管理!$R$2:$R$1001,"违规*")>0,"违规：请检查加仓管理表",IF(SUM($AQ$2:$AQ$201)>账户数据!$B$7,"预警：超过账户风险上限",IF(COUNTIFS(加仓管理!$A$2:$A$1001,A2,加仓管理!$N$2:$N$1001,">0",加仓管理!$G$2:$G$1001,"")>0,"提示：存在待执行加仓计划","通过")))))
C3: =IF(C2="","",C2+SUM(单次交易!Y2:Y201)) | F3: =IF(OR(C3="",D3="",E3="",N3="",C3<=0,D3<=0,E3<=N3),"",ROUNDDOWN((C3*D3)/(E3-N3)/100,0)*100) | G3: =IF(A3="","",IF(H3<>"","已开仓",IF(账户数据!$B$23="已锁仓","禁止开仓：连续亏损达到上限",IF(账户数据!$B$23="解锁信息不完整","禁止开仓：请完整填写解锁信息",IF(OR(F3="",E3="",N3="",E3<=N3,账户数据!$B$7=""),"",IF(OR(AG3="",AH3="",AI3=""),"禁止开仓：交易预期未填写完整",IF(账户数据!$B$9+F3*(E3-N3)>=账户数据!$B$7,"禁止开仓：风险额度不足",IF(AJ3="周期与交易预期不匹配，请重新确认",IF(账户数据!$B$23="接近锁仓","允许开仓（接近锁仓；周期需复核）","允许开仓（周期需复核）"),IF(账户数据!$B$23="接近锁仓","允许开仓（接近锁仓）","允许开仓"))))))))) | L3: =IF(AP3="","",AP3) | U3: =IF(OR(AO3="",J3="",AO3<=0),"",(J3-AO3)/AO3) | V3: =IF(OR(AO3="",N3="",AO3<=0),"",(AO3-N3)/AO3) | W3: =IF(OR(U3="",V3="",V3<=0),"",U3/V3) | X3: =IF(OR(K3="",L3="",AO3="",AP3=""),"",(K3-AO3)*L3-IF(O3="",0,O3)-IF(P3="",0,P3)) | Y3: =IF(OR(X3="",AO3="",L3=""),"",IF(AO3*L3+IF(O3="",0,O3)<=0,"",X3/(AO3*L3+IF(O3="",0,O3)))) | Z3: =IF(OR(AE3="",多次统计数据!$B$8=""),"",AE3-多次统计数据!$B$8) | AA3: =IF(OR(I3="",M3="",M3<I3),"",M3-I3) | AB3: =IF(OR(A3="",多次统计数据!$B$8="",多次统计数据!$B$6<=0,多次统计数据!$B$6>=1),"",1-POWER(1+多次统计数据!$B$8,-多次统计数据!$B$6/(1-多次统计数据!$B$6))) | AC3: =IF(OR(AB3="",多次统计数据!$B$9=""),"",IF(多次统计数据!$B$9<AB3,"低于上限","达到或超过上限")) | AE3: =IF(OR(X3="",C3="",C3<=0),"",X3/C3) | AJ3: =IF(OR(AG3="",AH3=""),"",IF(OR(AND(AG3="短期博反弹",OR(AH3="1～3个交易日",AH3="4～10个交易日")),AND(AG3="突破冲新高",OR(AH3="4～10个交易日",AH3="11～20个交易日")),AND(AG3="趋势波段",OR(AH3="11～20个交易日",AH3="21～60个交易日",AH3="60个交易日以上"))),"匹配","周期与交易预期不匹配，请重新确认")) | AK3: =IF(A3="","",COUNTIFS(加仓管理!$A$2:$A$1001,A3,加仓管理!$G$2:$G$1001,">0")) | AL3: =IF(A3="","",SUMIFS(加仓管理!$G$2:$G$1001,加仓管理!$A$2:$A$1001,A3)) | AM3: =IF(AK3=0,"",IFERROR(LOOKUP(2,1/((加仓管理!$A$2:$A$1001=A3)*(加仓管理!$G$2:$G$1001>0)),加仓管理!$D$2:$D$1001),"")) | AN3: =IF(AK3=0,"",IFERROR(LOOKUP(2,1/((加仓管理!$A$2:$A$1001=A3)*(加仓管理!$G$2:$G$1001>0)),加仓管理!$E$2:$E$1001),"")) | AO3: =IF(OR(A3="",H3="",H3<=0),"",(E3*H3+SUMIFS(加仓管理!$H$2:$H$1001,加仓管理!$A$2:$A$1001,A3))/AP3) | AP3: =IF(OR(A3="",H3="",H3<=0),"",H3+AL3) | AQ3: =IF(A3="","",IF(M3<>"",0,IF(OR(H3="",N3=""),"",MAX((E3*H3+SUMIFS(加仓管理!$H$2:$H$1001,加仓管理!$A$2:$A$1001,A3))-MAX(N3,AN3)*AP3,0)))) | AR3: =IF(A3="","",IF(OR(E3="",H3=""),"违规：首次买入价格或股数缺失",IF(COUNTIFS(加仓管理!$A$2:$A$1001,A3,加仓管理!$R$2:$R$1001,"违规*")>0,"违规：请检查加仓管理表",IF(SUM($AQ$2:$AQ$201)>账户数据!$B$7,"预警：超过账户风险上限",IF(COUNTIFS(加仓管理!$A$2:$A$1001,A3,加仓管理!$N$2:$N$1001,">0",加仓管理!$G$2:$G$1001,"")>0,"提示：存在待执行加仓计划","通过")))))
F4: =IF(OR(C4="",D4="",E4="",N4="",C4<=0,D4<=0,E4<=N4),"",ROUNDDOWN((C4*D4)/(E4-N4)/100,0)*100) | G4: =IF(A4="","",IF(H4<>"","已开仓",IF(账户数据!$B$23="已锁仓","禁止开仓：连续亏损达到上限",IF(账户数据!$B$23="解锁信息不完整","禁止开仓：请完整填写解锁信息",IF(OR(F4="",E4="",N4="",E4<=N4,账户数据!$B$7=""),"",IF(OR(AG4="",AH4="",AI4=""),"禁止开仓：交易预期未填写完整",IF(账户数据!$B$9+F4*(E4-N4)>=账户数据!$B$7,"禁止开仓：风险额度不足",IF(AJ4="周期与交易预期不匹配，请重新确认",IF(账户数据!$B$23="接近锁仓","允许开仓（接近锁仓；周期需复核）","允许开仓（周期需复核）"),IF(账户数据!$B$23="接近锁仓","允许开仓（接近锁仓）","允许开仓"))))))))) | L4: =IF(AP4="","",AP4) | U4: =IF(OR(AO4="",J4="",AO4<=0),"",(J4-AO4)/AO4) | V4: =IF(OR(AO4="",N4="",AO4<=0),"",(AO4-N4)/AO4) | W4: =IF(OR(U4="",V4="",V4<=0),"",U4/V4) | X4: =IF(OR(K4="",L4="",AO4="",AP4=""),"",(K4-AO4)*L4-IF(O4="",0,O4)-IF(P4="",0,P4)) | Y4: =IF(OR(X4="",AO4="",L4=""),"",IF(AO4*L4+IF(O4="",0,O4)<=0,"",X4/(AO4*L4+IF(O4="",0,O4)))) | Z4: =IF(OR(AE4="",多次统计数据!$B$8=""),"",AE4-多次统计数据!$B$8) | AA4: =IF(OR(I4="",M4="",M4<I4),"",M4-I4) | AB4: =IF(OR(A4="",多次统计数据!$B$8="",多次统计数据!$B$6<=0,多次统计数据!$B$6>=1),"",1-POWER(1+多次统计数据!$B$8,-多次统计数据!$B$6/(1-多次统计数据!$B$6))) | AC4: =IF(OR(AB4="",多次统计数据!$B$9=""),"",IF(多次统计数据!$B$9<AB4,"低于上限","达到或超过上限")) | AE4: =IF(OR(X4="",C4="",C4<=0),"",X4/C4) | AJ4: =IF(OR(AG4="",AH4=""),"",IF(OR(AND(AG4="短期博反弹",OR(AH4="1～3个交易日",AH4="4～10个交易日")),AND(AG4="突破冲新高",OR(AH4="4～10个交易日",AH4="11～20个交易日")),AND(AG4="趋势波段",OR(AH4="11～20个交易日",AH4="21～60个交易日",AH4="60个交易日以上"))),"匹配","周期与交易预期不匹配，请重新确认")) | AK4: =IF(A4="","",COUNTIFS(加仓管理!$A$2:$A$1001,A4,加仓管理!$G$2:$G$1001,">0")) | AL4: =IF(A4="","",SUMIFS(加仓管理!$G$2:$G$1001,加仓管理!$A$2:$A$1001,A4)) | AM4: =IF(AK4=0,"",IFERROR(LOOKUP(2,1/((加仓管理!$A$2:$A$1001=A4)*(加仓管理!$G$2:$G$1001>0)),加仓管理!$D$2:$D$1001),"")) | AN4: =IF(AK4=0,"",IFERROR(LOOKUP(2,1/((加仓管理!$A$2:$A$1001=A4)*(加仓管理!$G$2:$G$1001>0)),加仓管理!$E$2:$E$1001),"")) | AO4: =IF(OR(A4="",H4="",H4<=0),"",(E4*H4+SUMIFS(加仓管理!$H$2:$H$1001,加仓管理!$A$2:$A$1001,A4))/AP4) | AP4: =IF(OR(A4="",H4="",H4<=0),"",H4+AL4) | AQ4: =IF(A4="","",IF(M4<>"",0,IF(OR(H4="",N4=""),"",MAX((E4*H4+SUMIFS(加仓管理!$H$2:$H$1001,加仓管理!$A$2:$A$1001,A4))-MAX(N4,AN4)*AP4,0)))) | AR4: =IF(A4="","",IF(OR(E4="",H4=""),"违规：首次买入价格或股数缺失",IF(COUNTIFS(加仓管理!$A$2:$A$1001,A4,加仓管理!$R$2:$R$1001,"违规*")>0,"违规：请检查加仓管理表",IF(SUM($AQ$2:$AQ$201)>账户数据!$B$7,"预警：超过账户风险上限",IF(COUNTIFS(加仓管理!$A$2:$A$1001,A4,加仓管理!$N$2:$N$1001,">0",加仓管理!$G$2:$G$1001,"")>0,"提示：存在待执行加仓计划","通过")))))
F5: =IF(OR(C5="",D5="",E5="",N5="",C5<=0,D5<=0,E5<=N5),"",ROUNDDOWN((C5*D5)/(E5-N5)/100,0)*100) | G5: =IF(A5="","",IF(H5<>"","已开仓",IF(账户数据!$B$23="已锁仓","禁止开仓：连续亏损达到上限",IF(账户数据!$B$23="解锁信息不完整","禁止开仓：请完整填写解锁信息",IF(OR(F5="",E5="",N5="",E5<=N5,账户数据!$B$7=""),"",IF(OR(AG5="",AH5="",AI5=""),"禁止开仓：交易预期未填写完整",IF(账户数据!$B$9+F5*(E5-N5)>=账户数据!$B$7,"禁止开仓：风险额度不足",IF(AJ5="周期与交易预期不匹配，请重新确认",IF(账户数据!$B$23="接近锁仓","允许开仓（接近锁仓；周期需复核）","允许开仓（周期需复核）"),IF(账户数据!$B$23="接近锁仓","允许开仓（接近锁仓）","允许开仓"))))))))) | L5: =IF(AP5="","",AP5) | U5: =IF(OR(AO5="",J5="",AO5<=0),"",(J5-AO5)/AO5) | V5: =IF(OR(AO5="",N5="",AO5<=0),"",(AO5-N5)/AO5) | W5: =IF(OR(U5="",V5="",V5<=0),"",U5/V5) | X5: =IF(OR(K5="",L5="",AO5="",AP5=""),"",(K5-AO5)*L5-IF(O5="",0,O5)-IF(P5="",0,P5)) | Y5: =IF(OR(X5="",AO5="",L5=""),"",IF(AO5*L5+IF(O5="",0,O5)<=0,"",X5/(AO5*L5+IF(O5="",0,O5)))) | Z5: =IF(OR(AE5="",多次统计数据!$B$8=""),"",AE5-多次统计数据!$B$8) | AA5: =IF(OR(I5="",M5="",M5<I5),"",M5-I5) | AB5: =IF(OR(A5="",多次统计数据!$B$8="",多次统计数据!$B$6<=0,多次统计数据!$B$6>=1),"",1-POWER(1+多次统计数据!$B$8,-多次统计数据!$B$6/(1-多次统计数据!$B$6))) | AC5: =IF(OR(AB5="",多次统计数据!$B$9=""),"",IF(多次统计数据!$B$9<AB5,"低于上限","达到或超过上限")) | AE5: =IF(OR(X5="",C5="",C5<=0),"",X5/C5) | AJ5: =IF(OR(AG5="",AH5=""),"",IF(OR(AND(AG5="短期博反弹",OR(AH5="1～3个交易日",AH5="4～10个交易日")),AND(AG5="突破冲新高",OR(AH5="4～10个交易日",AH5="11～20个交易日")),AND(AG5="趋势波段",OR(AH5="11～20个交易日",AH5="21～60个交易日",AH5="60个交易日以上"))),"匹配","周期与交易预期不匹配，请重新确认")) | AK5: =IF(A5="","",COUNTIFS(加仓管理!$A$2:$A$1001,A5,加仓管理!$G$2:$G$1001,">0")) | AL5: =IF(A5="","",SUMIFS(加仓管理!$G$2:$G$1001,加仓管理!$A$2:$A$1001,A5)) | AM5: =IF(AK5=0,"",IFERROR(LOOKUP(2,1/((加仓管理!$A$2:$A$1001=A5)*(加仓管理!$G$2:$G$1001>0)),加仓管理!$D$2:$D$1001),"")) | AN5: =IF(AK5=0,"",IFERROR(LOOKUP(2,1/((加仓管理!$A$2:$A$1001=A5)*(加仓管理!$G$2:$G$1001>0)),加仓管理!$E$2:$E$1001),"")) | AO5: =IF(OR(A5="",H5="",H5<=0),"",(E5*H5+SUMIFS(加仓管理!$H$2:$H$1001,加仓管理!$A$2:$A$1001,A5))/AP5) | AP5: =IF(OR(A5="",H5="",H5<=0),"",H5+AL5) | AQ5: =IF(A5="","",IF(M5<>"",0,IF(OR(H5="",N5=""),"",MAX((E5*H5+SUMIFS(加仓管理!$H$2:$H$1001,加仓管理!$A$2:$A$1001,A5))-MAX(N5,AN5)*AP5,0)))) | AR5: =IF(A5="","",IF(OR(E5="",H5=""),"违规：首次买入价格或股数缺失",IF(COUNTIFS(加仓管理!$A$2:$A$1001,A5,加仓管理!$R$2:$R$1001,"违规*")>0,"违规：请检查加仓管理表",IF(SUM($AQ$2:$AQ$201)>账户数据!$B$7,"预警：超过账户风险上限",IF(COUNTIFS(加仓管理!$A$2:$A$1001,A5,加仓管理!$N$2:$N$1001,">0",加仓管理!$G$2:$G$1001,"")>0,"提示：存在待执行加仓计划","通过")))))
F6: =IF(OR(C6="",D6="",E6="",N6="",C6<=0,D6<=0,E6<=N6),"",ROUNDDOWN((C6*D6)/(E6-N6)/100,0)*100) | G6: =IF(A6="","",IF(H6<>"","已开仓",IF(账户数据!$B$23="已锁仓","禁止开仓：连续亏损达到上限",IF(账户数据!$B$23="解锁信息不完整","禁止开仓：请完整填写解锁信息",IF(OR(F6="",E6="",N6="",E6<=N6,账户数据!$B$7=""),"",IF(OR(AG6="",AH6="",AI6=""),"禁止开仓：交易预期未填写完整",IF(账户数据!$B$9+F6*(E6-N6)>=账户数据!$B$7,"禁止开仓：风险额度不足",IF(AJ6="周期与交易预期不匹配，请重新确认",IF(账户数据!$B$23="接近锁仓","允许开仓（接近锁仓；周期需复核）","允许开仓（周期需复核）"),IF(账户数据!$B$23="接近锁仓","允许开仓（接近锁仓）","允许开仓"))))))))) | L6: =IF(AP6="","",AP6) | U6: =IF(OR(AO6="",J6="",AO6<=0),"",(J6-AO6)/AO6) | V6: =IF(OR(AO6="",N6="",AO6<=0),"",(AO6-N6)/AO6) | W6: =IF(OR(U6="",V6="",V6<=0),"",U6/V6) | X6: =IF(OR(K6="",L6="",AO6="",AP6=""),"",(K6-AO6)*L6-IF(O6="",0,O6)-IF(P6="",0,P6)) | Y6: =IF(OR(X6="",AO6="",L6=""),"",IF(AO6*L6+IF(O6="",0,O6)<=0,"",X6/(AO6*L6+IF(O6="",0,O6)))) | Z6: =IF(OR(AE6="",多次统计数据!$B$8=""),"",AE6-多次统计数据!$B$8) | AA6: =IF(OR(I6="",M6="",M6<I6),"",M6-I6) | AB6: =IF(OR(A6="",多次统计数据!$B$8="",多次统计数据!$B$6<=0,多次统计数据!$B$6>=1),"",1-POWER(1+多次统计数据!$B$8,-多次统计数据!$B$6/(1-多次统计数据!$B$6))) | AC6: =IF(OR(AB6="",多次统计数据!$B$9=""),"",IF(多次统计数据!$B$9<AB6,"低于上限","达到或超过上限")) | AE6: =IF(OR(X6="",C6="",C6<=0),"",X6/C6) | AJ6: =IF(OR(AG6="",AH6=""),"",IF(OR(AND(AG6="短期博反弹",OR(AH6="1～3个交易日",AH6="4～10个交易日")),AND(AG6="突破冲新高",OR(AH6="4～10个交易日",AH6="11～20个交易日")),AND(AG6="趋势波段",OR(AH6="11～20个交易日",AH6="21～60个交易日",AH6="60个交易日以上"))),"匹配","周期与交易预期不匹配，请重新确认")) | AK6: =IF(A6="","",COUNTIFS(加仓管理!$A$2:$A$1001,A6,加仓管理!$G$2:$G$1001,">0")) | AL6: =IF(A6="","",SUMIFS(加仓管理!$G$2:$G$1001,加仓管理!$A$2:$A$1001,A6)) | AM6: =IF(AK6=0,"",IFERROR(LOOKUP(2,1/((加仓管理!$A$2:$A$1001=A6)*(加仓管理!$G$2:$G$1001>0)),加仓管理!$D$2:$D$1001),"")) | AN6: =IF(AK6=0,"",IFERROR(LOOKUP(2,1/((加仓管理!$A$2:$A$1001=A6)*(加仓管理!$G$2:$G$1001>0)),加仓管理!$E$2:$E$1001),"")) | AO6: =IF(OR(A6="",H6="",H6<=0),"",(E6*H6+SUMIFS(加仓管理!$H$2:$H$1001,加仓管理!$A$2:$A$1001,A6))/AP6) | AP6: =IF(OR(A6="",H6="",H6<=0),"",H6+AL6) | AQ6: =IF(A6="","",IF(M6<>"",0,IF(OR(H6="",N6=""),"",MAX((E6*H6+SUMIFS(加仓管理!$H$2:$H$1001,加仓管理!$A$2:$A$1001,A6))-MAX(N6,AN6)*AP6,0)))) | AR6: =IF(A6="","",IF(OR(E6="",H6=""),"违规：首次买入价格或股数缺失",IF(COUNTIFS(加仓管理!$A$2:$A$1001,A6,加仓管理!$R$2:$R$1001,"违规*")>0,"违规：请检查加仓管理表",IF(SUM($AQ$2:$AQ$201)>账户数据!$B$7,"预警：超过账户风险上限",IF(COUNTIFS(加仓管理!$A$2:$A$1001,A6,加仓管理!$N$2:$N$1001,">0",加仓管理!$G$2:$G$1001,"")>0,"提示：存在待执行加仓计划","通过")))))
F7: =IF(OR(C7="",D7="",E7="",N7="",C7<=0,D7<=0,E7<=N7),"",ROUNDDOWN((C7*D7)/(E7-N7)/100,0)*100) | G7: =IF(A7="","",IF(H7<>"","已开仓",IF(账户数据!$B$23="已锁仓","禁止开仓：连续亏损达到上限",IF(账户数据!$B$23="解锁信息不完整","禁止开仓：请完整填写解锁信息",IF(OR(F7="",E7="",N7="",E7<=N7,账户数据!$B$7=""),"",IF(OR(AG7="",AH7="",AI7=""),"禁止开仓：交易预期未填写完整",IF(账户数据!$B$9+F7*(E7-N7)>=账户数据!$B$7,"禁止开仓：风险额度不足",IF(AJ7="周期与交易预期不匹配，请重新确认",IF(账户数据!$B$23="接近锁仓","允许开仓（接近锁仓；周期需复核）","允许开仓（周期需复核）"),IF(账户数据!$B$23="接近锁仓","允许开仓（接近锁仓）","允许开仓"))))))))) | L7: =IF(AP7="","",AP7) | U7: =IF(OR(AO7="",J7="",AO7<=0),"",(J7-AO7)/AO7) | V7: =IF(OR(AO7="",N7="",AO7<=0),"",(AO7-N7)/AO7) | W7: =IF(OR(U7="",V7="",V7<=0),"",U7/V7) | X7: =IF(OR(K7="",L7="",AO7="",AP7=""),"",(K7-AO7)*L7-IF(O7="",0,O7)-IF(P7="",0,P7)) | Y7: =IF(OR(X7="",AO7="",L7=""),"",IF(AO7*L7+IF(O7="",0,O7)<=0,"",X7/(AO7*L7+IF(O7="",0,O7)))) | Z7: =IF(OR(AE7="",多次统计数据!$B$8=""),"",AE7-多次统计数据!$B$8) | AA7: =IF(OR(I7="",M7="",M7<I7),"",M7-I7) | AB7: =IF(OR(A7="",多次统计数据!$B$8="",多次统计数据!$B$6<=0,多次统计数据!$B$6>=1),"",1-POWER(1+多次统计数据!$B$8,-多次统计数据!$B$6/(1-多次统计数据!$B$6))) | AC7: =IF(OR(AB7="",多次统计数据!$B$9=""),"",IF(多次统计数据!$B$9<AB7,"低于上限","达到或超过上限")) | AE7: =IF(OR(X7="",C7="",C7<=0),"",X7/C7) | AJ7: =IF(OR(AG7="",AH7=""),"",IF(OR(AND(AG7="短期博反弹",OR(AH7="1～3个交易日",AH7="4～10个交易日")),AND(AG7="突破冲新高",OR(AH7="4～10个交易日",AH7="11～20个交易日")),AND(AG7="趋势波段",OR(AH7="11～20个交易日",AH7="21～60个交易日",AH7="60个交易日以上"))),"匹配","周期与交易预期不匹配，请重新确认")) | AK7: =IF(A7="","",COUNTIFS(加仓管理!$A$2:$A$1001,A7,加仓管理!$G$2:$G$1001,">0")) | AL7: =IF(A7="","",SUMIFS(加仓管理!$G$2:$G$1001,加仓管理!$A$2:$A$1001,A7)) | AM7: =IF(AK7=0,"",IFERROR(LOOKUP(2,1/((加仓管理!$A$2:$A$1001=A7)*(加仓管理!$G$2:$G$1001>0)),加仓管理!$D$2:$D$1001),"")) | AN7: =IF(AK7=0,"",IFERROR(LOOKUP(2,1/((加仓管理!$A$2:$A$1001=A7)*(加仓管理!$G$2:$G$1001>0)),加仓管理!$E$2:$E$1001),"")) | AO7: =IF(OR(A7="",H7="",H7<=0),"",(E7*H7+SUMIFS(加仓管理!$H$2:$H$1001,加仓管理!$A$2:$A$1001,A7))/AP7) | AP7: =IF(OR(A7="",H7="",H7<=0),"",H7+AL7) | AQ7: =IF(A7="","",IF(M7<>"",0,IF(OR(H7="",N7=""),"",MAX((E7*H7+SUMIFS(加仓管理!$H$2:$H$1001,加仓管理!$A$2:$A$1001,A7))-MAX(N7,AN7)*AP7,0)))) | AR7: =IF(A7="","",IF(OR(E7="",H7=""),"违规：首次买入价格或股数缺失",IF(COUNTIFS(加仓管理!$A$2:$A$1001,A7,加仓管理!$R$2:$R$1001,"违规*")>0,"违规：请检查加仓管理表",IF(SUM($AQ$2:$AQ$201)>账户数据!$B$7,"预警：超过账户风险上限",IF(COUNTIFS(加仓管理!$A$2:$A$1001,A7,加仓管理!$N$2:$N$1001,">0",加仓管理!$G$2:$G$1001,"")>0,"提示：存在待执行加仓计划","通过")))))
F8: =IF(OR(C8="",D8="",E8="",N8="",C8<=0,D8<=0,E8<=N8),"",ROUNDDOWN((C8*D8)/(E8-N8)/100,0)*100) | G8: =IF(A8="","",IF(H8<>"","已开仓",IF(账户数据!$B$23="已锁仓","禁止开仓：连续亏损达到上限",IF(账户数据!$B$23="解锁信息不完整","禁止开仓：请完整填写解锁信息",IF(OR(F8="",E8="",N8="",E8<=N8,账户数据!$B$7=""),"",IF(OR(AG8="",AH8="",AI8=""),"禁止开仓：交易预期未填写完整",IF(账户数据!$B$9+F8*(E8-N8)>=账户数据!$B$7,"禁止开仓：风险额度不足",IF(AJ8="周期与交易预期不匹配，请重新确认",IF(账户数据!$B$23="接近锁仓","允许开仓（接近锁仓；周期需复核）","允许开仓（周期需复核）"),IF(账户数据!$B$23="接近锁仓","允许开仓（接近锁仓）","允许开仓"))))))))) | L8: =IF(AP8="","",AP8) | U8: =IF(OR(AO8="",J8="",AO8<=0),"",(J8-AO8)/AO8) | V8: =IF(OR(AO8="",N8="",AO8<=0),"",(AO8-N8)/AO8) | W8: =IF(OR(U8="",V8="",V8<=0),"",U8/V8) | X8: =IF(OR(K8="",L8="",AO8="",AP8=""),"",(K8-AO8)*L8-IF(O8="",0,O8)-IF(P8="",0,P8)) | Y8: =IF(OR(X8="",AO8="",L8=""),"",IF(AO8*L8+IF(O8="",0,O8)<=0,"",X8/(AO8*L8+IF(O8="",0,O8)))) | Z8: =IF(OR(AE8="",多次统计数据!$B$8=""),"",AE8-多次统计数据!$B$8) | AA8: =IF(OR(I8="",M8="",M8<I8),"",M8-I8) | AB8: =IF(OR(A8="",多次统计数据!$B$8="",多次统计数据!$B$6<=0,多次统计数据!$B$6>=1),"",1-POWER(1+多次统计数据!$B$8,-多次统计数据!$B$6/(1-多次统计数据!$B$6))) | AC8: =IF(OR(AB8="",多次统计数据!$B$9=""),"",IF(多次统计数据!$B$9<AB8,"低于上限","达到或超过上限")) | AE8: =IF(OR(X8="",C8="",C8<=0),"",X8/C8) | AJ8: =IF(OR(AG8="",AH8=""),"",IF(OR(AND(AG8="短期博反弹",OR(AH8="1～3个交易日",AH8="4～10个交易日")),AND(AG8="突破冲新高",OR(AH8="4～10个交易日",AH8="11～20个交易日")),AND(AG8="趋势波段",OR(AH8="11～20个交易日",AH8="21～60个交易日",AH8="60个交易日以上"))),"匹配","周期与交易预期不匹配，请重新确认")) | AK8: =IF(A8="","",COUNTIFS(加仓管理!$A$2:$A$1001,A8,加仓管理!$G$2:$G$1001,">0")) | AL8: =IF(A8="","",SUMIFS(加仓管理!$G$2:$G$1001,加仓管理!$A$2:$A$1001,A8)) | AM8: =IF(AK8=0,"",IFERROR(LOOKUP(2,1/((加仓管理!$A$2:$A$1001=A8)*(加仓管理!$G$2:$G$1001>0)),加仓管理!$D$2:$D$1001),"")) | AN8: =IF(AK8=0,"",IFERROR(LOOKUP(2,1/((加仓管理!$A$2:$A$1001=A8)*(加仓管理!$G$2:$G$1001>0)),加仓管理!$E$2:$E$1001),"")) | AO8: =IF(OR(A8="",H8="",H8<=0),"",(E8*H8+SUMIFS(加仓管理!$H$2:$H$1001,加仓管理!$A$2:$A$1001,A8))/AP8) | AP8: =IF(OR(A8="",H8="",H8<=0),"",H8+AL8) | AQ8: =IF(A8="","",IF(M8<>"",0,IF(OR(H8="",N8=""),"",MAX((E8*H8+SUMIFS(加仓管理!$H$2:$H$1001,加仓管理!$A$2:$A$1001,A8))-MAX(N8,AN8)*AP8,0)))) | AR8: =IF(A8="","",IF(OR(E8="",H8=""),"违规：首次买入价格或股数缺失",IF(COUNTIFS(加仓管理!$A$2:$A$1001,A8,加仓管理!$R$2:$R$1001,"违规*")>0,"违规：请检查加仓管理表",IF(SUM($AQ$2:$AQ$201)>账户数据!$B$7,"预警：超过账户风险上限",IF(COUNTIFS(加仓管理!$A$2:$A$1001,A8,加仓管理!$N$2:$N$1001,">0",加仓管理!$G$2:$G$1001,"")>0,"提示：存在待执行加仓计划","通过")))))
F9: =IF(OR(C9="",D9="",E9="",N9="",C9<=0,D9<=0,E9<=N9),"",ROUNDDOWN((C9*D9)/(E9-N9)/100,0)*100) | G9: =IF(A9="","",IF(H9<>"","已开仓",IF(账户数据!$B$23="已锁仓","禁止开仓：连续亏损达到上限",IF(账户数据!$B$23="解锁信息不完整","禁止开仓：请完整填写解锁信息",IF(OR(F9="",E9="",N9="",E9<=N9,账户数据!$B$7=""),"",IF(OR(AG9="",AH9="",AI9=""),"禁止开仓：交易预期未填写完整",IF(账户数据!$B$9+F9*(E9-N9)>=账户数据!$B$7,"禁止开仓：风险额度不足",IF(AJ9="周期与交易预期不匹配，请重新确认",IF(账户数据!$B$23="接近锁仓","允许开仓（接近锁仓；周期需复核）","允许开仓（周期需复核）"),IF(账户数据!$B$23="接近锁仓","允许开仓（接近锁仓）","允许开仓"))))))))) | L9: =IF(AP9="","",AP9) | U9: =IF(OR(AO9="",J9="",AO9<=0),"",(J9-AO9)/AO9) | V9: =IF(OR(AO9="",N9="",AO9<=0),"",(AO9-N9)/AO9) | W9: =IF(OR(U9="",V9="",V9<=0),"",U9/V9) | X9: =IF(OR(K9="",L9="",AO9="",AP9=""),"",(K9-AO9)*L9-IF(O9="",0,O9)-IF(P9="",0,P9)) | Y9: =IF(OR(X9="",AO9="",L9=""),"",IF(AO9*L9+IF(O9="",0,O9)<=0,"",X9/(AO9*L9+IF(O9="",0,O9)))) | Z9: =IF(OR(AE9="",多次统计数据!$B$8=""),"",AE9-多次统计数据!$B$8) | AA9: =IF(OR(I9="",M9="",M9<I9),"",M9-I9) | AB9: =IF(OR(A9="",多次统计数据!$B$8="",多次统计数据!$B$6<=0,多次统计数据!$B$6>=1),"",1-POWER(1+多次统计数据!$B$8,-多次统计数据!$B$6/(1-多次统计数据!$B$6))) | AC9: =IF(OR(AB9="",多次统计数据!$B$9=""),"",IF(多次统计数据!$B$9<AB9,"低于上限","达到或超过上限")) | AE9: =IF(OR(X9="",C9="",C9<=0),"",X9/C9) | AJ9: =IF(OR(AG9="",AH9=""),"",IF(OR(AND(AG9="短期博反弹",OR(AH9="1～3个交易日",AH9="4～10个交易日")),AND(AG9="突破冲新高",OR(AH9="4～10个交易日",AH9="11～20个交易日")),AND(AG9="趋势波段",OR(AH9="11～20个交易日",AH9="21～60个交易日",AH9="60个交易日以上"))),"匹配","周期与交易预期不匹配，请重新确认")) | AK9: =IF(A9="","",COUNTIFS(加仓管理!$A$2:$A$1001,A9,加仓管理!$G$2:$G$1001,">0")) | AL9: =IF(A9="","",SUMIFS(加仓管理!$G$2:$G$1001,加仓管理!$A$2:$A$1001,A9)) | AM9: =IF(AK9=0,"",IFERROR(LOOKUP(2,1/((加仓管理!$A$2:$A$1001=A9)*(加仓管理!$G$2:$G$1001>0)),加仓管理!$D$2:$D$1001),"")) | AN9: =IF(AK9=0,"",IFERROR(LOOKUP(2,1/((加仓管理!$A$2:$A$1001=A9)*(加仓管理!$G$2:$G$1001>0)),加仓管理!$E$2:$E$1001),"")) | AO9: =IF(OR(A9="",H9="",H9<=0),"",(E9*H9+SUMIFS(加仓管理!$H$2:$H$1001,加仓管理!$A$2:$A$1001,A9))/AP9) | AP9: =IF(OR(A9="",H9="",H9<=0),"",H9+AL9) | AQ9: =IF(A9="","",IF(M9<>"",0,IF(OR(H9="",N9=""),"",MAX((E9*H9+SUMIFS(加仓管理!$H$2:$H$1001,加仓管理!$A$2:$A$1001,A9))-MAX(N9,AN9)*AP9,0)))) | AR9: =IF(A9="","",IF(OR(E9="",H9=""),"违规：首次买入价格或股数缺失",IF(COUNTIFS(加仓管理!$A$2:$A$1001,A9,加仓管理!$R$2:$R$1001,"违规*")>0,"违规：请检查加仓管理表",IF(SUM($AQ$2:$AQ$201)>账户数据!$B$7,"预警：超过账户风险上限",IF(COUNTIFS(加仓管理!$A$2:$A$1001,A9,加仓管理!$N$2:$N$1001,">0",加仓管理!$G$2:$G$1001,"")>0,"提示：存在待执行加仓计划","通过")))))
F10: =IF(OR(C10="",D10="",E10="",N10="",C10<=0,D10<=0,E10<=N10),"",ROUNDDOWN((C10*D10)/(E10-N10)/100,0)*100) | G10: =IF(A10="","",IF(H10<>"","已开仓",IF(账户数据!$B$23="已锁仓","禁止开仓：连续亏损达到上限",IF(账户数据!$B$23="解锁信息不完整","禁止开仓：请完整填写解锁信息",IF(OR(F10="",E10="",N10="",E10<=N10,账户数据!$B$7=""),"",IF(OR(AG10="",AH10="",AI10=""),"禁止开仓：交易预期未填写完整",IF(账户数据!$B$9+F10*(E10-N10)>=账户数据!$B$7,"禁止开仓：风险额度不足",IF(AJ10="周期与交易预期不匹配，请重新确认",IF(账户数据!$B$23="接近锁仓","允许开仓（接近锁仓；周期需复核）","允许开仓（周期需复核）"),IF(账户数据!$B$23="接近锁仓","允许开仓（接近锁仓）","允许开仓"))))))))) | L10: =IF(AP10="","",AP10) | U10: =IF(OR(AO10="",J10="",AO10<=0),"",(J10-AO10)/AO10) | V10: =IF(OR(AO10="",N10="",AO10<=0),"",(AO10-N10)/AO10) | W10: =IF(OR(U10="",V10="",V10<=0),"",U10/V10) | X10: =IF(OR(K10="",L10="",AO10="",AP10=""),"",(K10-AO10)*L10-IF(O10="",0,O10)-IF(P10="",0,P10)) | Y10: =IF(OR(X10="",AO10="",L10=""),"",IF(AO10*L10+IF(O10="",0,O10)<=0,"",X10/(AO10*L10+IF(O10="",0,O10)))) | Z10: =IF(OR(AE10="",多次统计数据!$B$8=""),"",AE10-多次统计数据!$B$8) | AA10: =IF(OR(I10="",M10="",M10<I10),"",M10-I10) | AB10: =IF(OR(A10="",多次统计数据!$B$8="",多次统计数据!$B$6<=0,多次统计数据!$B$6>=1),"",1-POWER(1+多次统计数据!$B$8,-多次统计数据!$B$6/(1-多次统计数据!$B$6))) | AC10: =IF(OR(AB10="",多次统计数据!$B$9=""),"",IF(多次统计数据!$B$9<AB10,"低于上限","达到或超过上限")) | AE10: =IF(OR(X10="",C10="",C10<=0),"",X10/C10) | AJ10: =IF(OR(AG10="",AH10=""),"",IF(OR(AND(AG10="短期博反弹",OR(AH10="1～3个交易日",AH10="4～10个交易日")),AND(AG10="突破冲新高",OR(AH10="4～10个交易日",AH10="11～20个交易日")),AND(AG10="趋势波段",OR(AH10="11～20个交易日",AH10="21～60个交易日",AH10="60个交易日以上"))),"匹配","周期与交易预期不匹配，请重新确认")) | AK10: =IF(A10="","",COUNTIFS(加仓管理!$A$2:$A$1001,A10,加仓管理!$G$2:$G$1001,">0")) | AL10: =IF(A10="","",SUMIFS(加仓管理!$G$2:$G$1001,加仓管理!$A$2:$A$1001,A10)) | AM10: =IF(AK10=0,"",IFERROR(LOOKUP(2,1/((加仓管理!$A$2:$A$1001=A10)*(加仓管理!$G$2:$G$1001>0)),加仓管理!$D$2:$D$1001),"")) | AN10: =IF(AK10=0,"",IFERROR(LOOKUP(2,1/((加仓管理!$A$2:$A$1001=A10)*(加仓管理!$G$2:$G$1001>0)),加仓管理!$E$2:$E$1001),"")) | AO10: =IF(OR(A10="",H10="",H10<=0),"",(E10*H10+SUMIFS(加仓管理!$H$2:$H$1001,加仓管理!$A$2:$A$1001,A10))/AP10) | AP10: =IF(OR(A10="",H10="",H10<=0),"",H10+AL10) | AQ10: =IF(A10="","",IF(M10<>"",0,IF(OR(H10="",N10=""),"",MAX((E10*H10+SUMIFS(加仓管理!$H$2:$H$1001,加仓管理!$A$2:$A$1001,A10))-MAX(N10,AN10)*AP10,0)))) | AR10: =IF(A10="","",IF(OR(E10="",H10=""),"违规：首次买入价格或股数缺失",IF(COUNTIFS(加仓管理!$A$2:$A$1001,A10,加仓管理!$R$2:$R$1001,"违规*")>0,"违规：请检查加仓管理表",IF(SUM($AQ$2:$AQ$201)>账户数据!$B$7,"预警：超过账户风险上限",IF(COUNTIFS(加仓管理!$A$2:$A$1001,A10,加仓管理!$N$2:$N$1001,">0",加仓管理!$G$2:$G$1001,"")>0,"提示：存在待执行加仓计划","通过")))))
F11: =IF(OR(C11="",D11="",E11="",N11="",C11<=0,D11<=0,E11<=N11),"",ROUNDDOWN((C11*D11)/(E11-N11)/100,0)*100) | G11: =IF(A11="","",IF(H11<>"","已开仓",IF(账户数据!$B$23="已锁仓","禁止开仓：连续亏损达到上限",IF(账户数据!$B$23="解锁信息不完整","禁止开仓：请完整填写解锁信息",IF(OR(F11="",E11="",N11="",E11<=N11,账户数据!$B$7=""),"",IF(OR(AG11="",AH11="",AI11=""),"禁止开仓：交易预期未填写完整",IF(账户数据!$B$9+F11*(E11-N11)>=账户数据!$B$7,"禁止开仓：风险额度不足",IF(AJ11="周期与交易预期不匹配，请重新确认",IF(账户数据!$B$23="接近锁仓","允许开仓（接近锁仓；周期需复核）","允许开仓（周期需复核）"),IF(账户数据!$B$23="接近锁仓","允许开仓（接近锁仓）","允许开仓"))))))))) | L11: =IF(AP11="","",AP11) | U11: =IF(OR(AO11="",J11="",AO11<=0),"",(J11-AO11)/AO11) | V11: =IF(OR(AO11="",N11="",AO11<=0),"",(AO11-N11)/AO11) | W11: =IF(OR(U11="",V11="",V11<=0),"",U11/V11) | X11: =IF(OR(K11="",L11="",AO11="",AP11=""),"",(K11-AO11)*L11-IF(O11="",0,O11)-IF(P11="",0,P11)) | Y11: =IF(OR(X11="",AO11="",L11=""),"",IF(AO11*L11+IF(O11="",0,O11)<=0,"",X11/(AO11*L11+IF(O11="",0,O11)))) | Z11: =IF(OR(AE11="",多次统计数据!$B$8=""),"",AE11-多次统计数据!$B$8) | AA11: =IF(OR(I11="",M11="",M11<I11),"",M11-I11) | AB11: =IF(OR(A11="",多次统计数据!$B$8="",多次统计数据!$B$6<=0,多次统计数据!$B$6>=1),"",1-POWER(1+多次统计数据!$B$8,-多次统计数据!$B$6/(1-多次统计数据!$B$6))) | AC11: =IF(OR(AB11="",多次统计数据!$B$9=""),"",IF(多次统计数据!$B$9<AB11,"低于上限","达到或超过上限")) | AE11: =IF(OR(X11="",C11="",C11<=0),"",X11/C11) | AJ11: =IF(OR(AG11="",AH11=""),"",IF(OR(AND(AG11="短期博反弹",OR(AH11="1～3个交易日",AH11="4～10个交易日")),AND(AG11="突破冲新高",OR(AH11="4～10个交易日",AH11="11～20个交易日")),AND(AG11="趋势波段",OR(AH11="11～20个交易日",AH11="21～60个交易日",AH11="60个交易日以上"))),"匹配","周期与交易预期不匹配，请重新确认")) | AK11: =IF(A11="","",COUNTIFS(加仓管理!$A$2:$A$1001,A11,加仓管理!$G$2:$G$1001,">0")) | AL11: =IF(A11="","",SUMIFS(加仓管理!$G$2:$G$1001,加仓管理!$A$2:$A$1001,A11)) | AM11: =IF(AK11=0,"",IFERROR(LOOKUP(2,1/((加仓管理!$A$2:$A$1001=A11)*(加仓管理!$G$2:$G$1001>0)),加仓管理!$D$2:$D$1001),"")) | AN11: =IF(AK11=0,"",IFERROR(LOOKUP(2,1/((加仓管理!$A$2:$A$1001=A11)*(加仓管理!$G$2:$G$1001>0)),加仓管理!$E$2:$E$1001),"")) | AO11: =IF(OR(A11="",H11="",H11<=0),"",(E11*H11+SUMIFS(加仓管理!$H$2:$H$1001,加仓管理!$A$2:$A$1001,A11))/AP11) | AP11: =IF(OR(A11="",H11="",H11<=0),"",H11+AL11) | AQ11: =IF(A11="","",IF(M11<>"",0,IF(OR(H11="",N11=""),"",MAX((E11*H11+SUMIFS(加仓管理!$H$2:$H$1001,加仓管理!$A$2:$A$1001,A11))-MAX(N11,AN11)*AP11,0)))) | AR11: =IF(A11="","",IF(OR(E11="",H11=""),"违规：首次买入价格或股数缺失",IF(COUNTIFS(加仓管理!$A$2:$A$1001,A11,加仓管理!$R$2:$R$1001,"违规*")>0,"违规：请检查加仓管理表",IF(SUM($AQ$2:$AQ$201)>账户数据!$B$7,"预警：超过账户风险上限",IF(COUNTIFS(加仓管理!$A$2:$A$1001,A11,加仓管理!$N$2:$N$1001,">0",加仓管理!$G$2:$G$1001,"")>0,"提示：存在待执行加仓计划","通过")))))
F12: =IF(OR(C12="",D12="",E12="",N12="",C12<=0,D12<=0,E12<=N12),"",ROUNDDOWN((C12*D12)/(E12-N12)/100,0)*100) | G12: =IF(A12="","",IF(H12<>"","已开仓",IF(账户数据!$B$23="已锁仓","禁止开仓：连续亏损达到上限",IF(账户数据!$B$23="解锁信息不完整","禁止开仓：请完整填写解锁信息",IF(OR(F12="",E12="",N12="",E12<=N12,账户数据!$B$7=""),"",IF(OR(AG12="",AH12="",AI12=""),"禁止开仓：交易预期未填写完整",IF(账户数据!$B$9+F12*(E12-N12)>=账户数据!$B$7,"禁止开仓：风险额度不足",IF(AJ12="周期与交易预期不匹配，请重新确认",IF(账户数据!$B$23="接近锁仓","允许开仓（接近锁仓；周期需复核）","允许开仓（周期需复核）"),IF(账户数据!$B$23="接近锁仓","允许开仓（接近锁仓）","允许开仓"))))))))) | L12: =IF(AP12="","",AP12) | U12: =IF(OR(AO12="",J12="",AO12<=0),"",(J12-AO12)/AO12) | V12: =IF(OR(AO12="",N12="",AO12<=0),"",(AO12-N12)/AO12) | W12: =IF(OR(U12="",V12="",V12<=0),"",U12/V12) | X12: =IF(OR(K12="",L12="",AO12="",AP12=""),"",(K12-AO12)*L12-IF(O12="",0,O12)-IF(P12="",0,P12)) | Y12: =IF(OR(X12="",AO12="",L12=""),"",IF(AO12*L12+IF(O12="",0,O12)<=0,"",X12/(AO12*L12+IF(O12="",0,O12)))) | Z12: =IF(OR(AE12="",多次统计数据!$B$8=""),"",AE12-多次统计数据!$B$8) | AA12: =IF(OR(I12="",M12="",M12<I12),"",M12-I12) | AB12: =IF(OR(A12="",多次统计数据!$B$8="",多次统计数据!$B$6<=0,多次统计数据!$B$6>=1),"",1-POWER(1+多次统计数据!$B$8,-多次统计数据!$B$6/(1-多次统计数据!$B$6))) | AC12: =IF(OR(AB12="",多次统计数据!$B$9=""),"",IF(多次统计数据!$B$9<AB12,"低于上限","达到或超过上限")) | AE12: =IF(OR(X12="",C12="",C12<=0),"",X12/C12) | AJ12: =IF(OR(AG12="",AH12=""),"",IF(OR(AND(AG12="短期博反弹",OR(AH12="1～3个交易日",AH12="4～10个交易日")),AND(AG12="突破冲新高",OR(AH12="4～10个交易日",AH12="11～20个交易日")),AND(AG12="趋势波段",OR(AH12="11～20个交易日",AH12="21～60个交易日",AH12="60个交易日以上"))),"匹配","周期与交易预期不匹配，请重新确认")) | AK12: =IF(A12="","",COUNTIFS(加仓管理!$A$2:$A$1001,A12,加仓管理!$G$2:$G$1001,">0")) | AL12: =IF(A12="","",SUMIFS(加仓管理!$G$2:$G$1001,加仓管理!$A$2:$A$1001,A12)) | AM12: =IF(AK12=0,"",IFERROR(LOOKUP(2,1/((加仓管理!$A$2:$A$1001=A12)*(加仓管理!$G$2:$G$1001>0)),加仓管理!$D$2:$D$1001),"")) | AN12: =IF(AK12=0,"",IFERROR(LOOKUP(2,1/((加仓管理!$A$2:$A$1001=A12)*(加仓管理!$G$2:$G$1001>0)),加仓管理!$E$2:$E$1001),"")) | AO12: =IF(OR(A12="",H12="",H12<=0),"",(E12*H12+SUMIFS(加仓管理!$H$2:$H$1001,加仓管理!$A$2:$A$1001,A12))/AP12) | AP12: =IF(OR(A12="",H12="",H12<=0),"",H12+AL12) | AQ12: =IF(A12="","",IF(M12<>"",0,IF(OR(H12="",N12=""),"",MAX((E12*H12+SUMIFS(加仓管理!$H$2:$H$1001,加仓管理!$A$2:$A$1001,A12))-MAX(N12,AN12)*AP12,0)))) | AR12: =IF(A12="","",IF(OR(E12="",H12=""),"违规：首次买入价格或股数缺失",IF(COUNTIFS(加仓管理!$A$2:$A$1001,A12,加仓管理!$R$2:$R$1001,"违规*")>0,"违规：请检查加仓管理表",IF(SUM($AQ$2:$AQ$201)>账户数据!$B$7,"预警：超过账户风险上限",IF(COUNTIFS(加仓管理!$A$2:$A$1001,A12,加仓管理!$N$2:$N$1001,">0",加仓管理!$G$2:$G$1001,"")>0,"提示：存在待执行加仓计划","通过")))))
F13: =IF(OR(C13="",D13="",E13="",N13="",C13<=0,D13<=0,E13<=N13),"",ROUNDDOWN((C13*D13)/(E13-N13)/100,0)*100) | G13: =IF(A13="","",IF(H13<>"","已开仓",IF(账户数据!$B$23="已锁仓","禁止开仓：连续亏损达到上限",IF(账户数据!$B$23="解锁信息不完整","禁止开仓：请完整填写解锁信息",IF(OR(F13="",E13="",N13="",E13<=N13,账户数据!$B$7=""),"",IF(OR(AG13="",AH13="",AI13=""),"禁止开仓：交易预期未填写完整",IF(账户数据!$B$9+F13*(E13-N13)>=账户数据!$B$7,"禁止开仓：风险额度不足",IF(AJ13="周期与交易预期不匹配，请重新确认",IF(账户数据!$B$23="接近锁仓","允许开仓（接近锁仓；周期需复核）","允许开仓（周期需复核）"),IF(账户数据!$B$23="接近锁仓","允许开仓（接近锁仓）","允许开仓"))))))))) | L13: =IF(AP13="","",AP13) | U13: =IF(OR(AO13="",J13="",AO13<=0),"",(J13-AO13)/AO13) | V13: =IF(OR(AO13="",N13="",AO13<=0),"",(AO13-N13)/AO13) | W13: =IF(OR(U13="",V13="",V13<=0),"",U13/V13) | X13: =IF(OR(K13="",L13="",AO13="",AP13=""),"",(K13-AO13)*L13-IF(O13="",0,O13)-IF(P13="",0,P13)) | Y13: =IF(OR(X13="",AO13="",L13=""),"",IF(AO13*L13+IF(O13="",0,O13)<=0,"",X13/(AO13*L13+IF(O13="",0,O13)))) | Z13: =IF(OR(AE13="",多次统计数据!$B$8=""),"",AE13-多次统计数据!$B$8) | AA13: =IF(OR(I13="",M13="",M13<I13),"",M13-I13) | AB13: =IF(OR(A13="",多次统计数据!$B$8="",多次统计数据!$B$6<=0,多次统计数据!$B$6>=1),"",1-POWER(1+多次统计数据!$B$8,-多次统计数据!$B$6/(1-多次统计数据!$B$6))) | AC13: =IF(OR(AB13="",多次统计数据!$B$9=""),"",IF(多次统计数据!$B$9<AB13,"低于上限","达到或超过上限")) | AE13: =IF(OR(X13="",C13="",C13<=0),"",X13/C13) | AJ13: =IF(OR(AG13="",AH13=""),"",IF(OR(AND(AG13="短期博反弹",OR(AH13="1～3个交易日",AH13="4～10个交易日")),AND(AG13="突破冲新高",OR(AH13="4～10个交易日",AH13="11～20个交易日")),AND(AG13="趋势波段",OR(AH13="11～20个交易日",AH13="21～60个交易日",AH13="60个交易日以上"))),"匹配","周期与交易预期不匹配，请重新确认")) | AK13: =IF(A13="","",COUNTIFS(加仓管理!$A$2:$A$1001,A13,加仓管理!$G$2:$G$1001,">0")) | AL13: =IF(A13="","",SUMIFS(加仓管理!$G$2:$G$1001,加仓管理!$A$2:$A$1001,A13)) | AM13: =IF(AK13=0,"",IFERROR(LOOKUP(2,1/((加仓管理!$A$2:$A$1001=A13)*(加仓管理!$G$2:$G$1001>0)),加仓管理!$D$2:$D$1001),"")) | AN13: =IF(AK13=0,"",IFERROR(LOOKUP(2,1/((加仓管理!$A$2:$A$1001=A13)*(加仓管理!$G$2:$G$1001>0)),加仓管理!$E$2:$E$1001),"")) | AO13: =IF(OR(A13="",H13="",H13<=0),"",(E13*H13+SUMIFS(加仓管理!$H$2:$H$1001,加仓管理!$A$2:$A$1001,A13))/AP13) | AP13: =IF(OR(A13="",H13="",H13<=0),"",H13+AL13) | AQ13: =IF(A13="","",IF(M13<>"",0,IF(OR(H13="",N13=""),"",MAX((E13*H13+SUMIFS(加仓管理!$H$2:$H$1001,加仓管理!$A$2:$A$1001,A13))-MAX(N13,AN13)*AP13,0)))) | AR13: =IF(A13="","",IF(OR(E13="",H13=""),"违规：首次买入价格或股数缺失",IF(COUNTIFS(加仓管理!$A$2:$A$1001,A13,加仓管理!$R$2:$R$1001,"违规*")>0,"违规：请检查加仓管理表",IF(SUM($AQ$2:$AQ$201)>账户数据!$B$7,"预警：超过账户风险上限",IF(COUNTIFS(加仓管理!$A$2:$A$1001,A13,加仓管理!$N$2:$N$1001,">0",加仓管理!$G$2:$G$1001,"")>0,"提示：存在待执行加仓计划","通过")))))
F14: =IF(OR(C14="",D14="",E14="",N14="",C14<=0,D14<=0,E14<=N14),"",ROUNDDOWN((C14*D14)/(E14-N14)/100,0)*100) | G14: =IF(A14="","",IF(H14<>"","已开仓",IF(账户数据!$B$23="已锁仓","禁止开仓：连续亏损达到上限",IF(账户数据!$B$23="解锁信息不完整","禁止开仓：请完整填写解锁信息",IF(OR(F14="",E14="",N14="",E14<=N14,账户数据!$B$7=""),"",IF(OR(AG14="",AH14="",AI14=""),"禁止开仓：交易预期未填写完整",IF(账户数据!$B$9+F14*(E14-N14)>=账户数据!$B$7,"禁止开仓：风险额度不足",IF(AJ14="周期与交易预期不匹配，请重新确认",IF(账户数据!$B$23="接近锁仓","允许开仓（接近锁仓；周期需复核）","允许开仓（周期需复核）"),IF(账户数据!$B$23="接近锁仓","允许开仓（接近锁仓）","允许开仓"))))))))) | L14: =IF(AP14="","",AP14) | U14: =IF(OR(AO14="",J14="",AO14<=0),"",(J14-AO14)/AO14) | V14: =IF(OR(AO14="",N14="",AO14<=0),"",(AO14-N14)/AO14) | W14: =IF(OR(U14="",V14="",V14<=0),"",U14/V14) | X14: =IF(OR(K14="",L14="",AO14="",AP14=""),"",(K14-AO14)*L14-IF(O14="",0,O14)-IF(P14="",0,P14)) | Y14: =IF(OR(X14="",AO14="",L14=""),"",IF(AO14*L14+IF(O14="",0,O14)<=0,"",X14/(AO14*L14+IF(O14="",0,O14)))) | Z14: =IF(OR(AE14="",多次统计数据!$B$8=""),"",AE14-多次统计数据!$B$8) | AA14: =IF(OR(I14="",M14="",M14<I14),"",M14-I14) | AB14: =IF(OR(A14="",多次统计数据!$B$8="",多次统计数据!$B$6<=0,多次统计数据!$B$6>=1),"",1-POWER(1+多次统计数据!$B$8,-多次统计数据!$B$6/(1-多次统计数据!$B$6))) | AC14: =IF(OR(AB14="",多次统计数据!$B$9=""),"",IF(多次统计数据!$B$9<AB14,"低于上限","达到或超过上限")) | AE14: =IF(OR(X14="",C14="",C14<=0),"",X14/C14) | AJ14: =IF(OR(AG14="",AH14=""),"",IF(OR(AND(AG14="短期博反弹",OR(AH14="1～3个交易日",AH14="4～10个交易日")),AND(AG14="突破冲新高",OR(AH14="4～10个交易日",AH14="11～20个交易日")),AND(AG14="趋势波段",OR(AH14="11～20个交易日",AH14="21～60个交易日",AH14="60个交易日以上"))),"匹配","周期与交易预期不匹配，请重新确认")) | AK14: =IF(A14="","",COUNTIFS(加仓管理!$A$2:$A$1001,A14,加仓管理!$G$2:$G$1001,">0")) | AL14: =IF(A14="","",SUMIFS(加仓管理!$G$2:$G$1001,加仓管理!$A$2:$A$1001,A14)) | AM14: =IF(AK14=0,"",IFERROR(LOOKUP(2,1/((加仓管理!$A$2:$A$1001=A14)*(加仓管理!$G$2:$G$1001>0)),加仓管理!$D$2:$D$1001),"")) | AN14: =IF(AK14=0,"",IFERROR(LOOKUP(2,1/((加仓管理!$A$2:$A$1001=A14)*(加仓管理!$G$2:$G$1001>0)),加仓管理!$E$2:$E$1001),"")) | AO14: =IF(OR(A14="",H14="",H14<=0),"",(E14*H14+SUMIFS(加仓管理!$H$2:$H$1001,加仓管理!$A$2:$A$1001,A14))/AP14) | AP14: =IF(OR(A14="",H14="",H14<=0),"",H14+AL14) | AQ14: =IF(A14="","",IF(M14<>"",0,IF(OR(H14="",N14=""),"",MAX((E14*H14+SUMIFS(加仓管理!$H$2:$H$1001,加仓管理!$A$2:$A$1001,A14))-MAX(N14,AN14)*AP14,0)))) | AR14: =IF(A14="","",IF(OR(E14="",H14=""),"违规：首次买入价格或股数缺失",IF(COUNTIFS(加仓管理!$A$2:$A$1001,A14,加仓管理!$R$2:$R$1001,"违规*")>0,"违规：请检查加仓管理表",IF(SUM($AQ$2:$AQ$201)>账户数据!$B$7,"预警：超过账户风险上限",IF(COUNTIFS(加仓管理!$A$2:$A$1001,A14,加仓管理!$N$2:$N$1001,">0",加仓管理!$G$2:$G$1001,"")>0,"提示：存在待执行加仓计划","通过")))))
F15: =IF(OR(C15="",D15="",E15="",N15="",C15<=0,D15<=0,E15<=N15),"",ROUNDDOWN((C15*D15)/(E15-N15)/100,0)*100) | G15: =IF(A15="","",IF(H15<>"","已开仓",IF(账户数据!$B$23="已锁仓","禁止开仓：连续亏损达到上限",IF(账户数据!$B$23="解锁信息不完整","禁止开仓：请完整填写解锁信息",IF(OR(F15="",E15="",N15="",E15<=N15,账户数据!$B$7=""),"",IF(OR(AG15="",AH15="",AI15=""),"禁止开仓：交易预期未填写完整",IF(账户数据!$B$9+F15*(E15-N15)>=账户数据!$B$7,"禁止开仓：风险额度不足",IF(AJ15="周期与交易预期不匹配，请重新确认",IF(账户数据!$B$23="接近锁仓","允许开仓（接近锁仓；周期需复核）","允许开仓（周期需复核）"),IF(账户数据!$B$23="接近锁仓","允许开仓（接近锁仓）","允许开仓"))))))))) | L15: =IF(AP15="","",AP15) | U15: =IF(OR(AO15="",J15="",AO15<=0),"",(J15-AO15)/AO15) | V15: =IF(OR(AO15="",N15="",AO15<=0),"",(AO15-N15)/AO15) | W15: =IF(OR(U15="",V15="",V15<=0),"",U15/V15) | X15: =IF(OR(K15="",L15="",AO15="",AP15=""),"",(K15-AO15)*L15-IF(O15="",0,O15)-IF(P15="",0,P15)) | Y15: =IF(OR(X15="",AO15="",L15=""),"",IF(AO15*L15+IF(O15="",0,O15)<=0,"",X15/(AO15*L15+IF(O15="",0,O15)))) | Z15: =IF(OR(AE15="",多次统计数据!$B$8=""),"",AE15-多次统计数据!$B$8) | AA15: =IF(OR(I15="",M15="",M15<I15),"",M15-I15) | AB15: =IF(OR(A15="",多次统计数据!$B$8="",多次统计数据!$B$6<=0,多次统计数据!$B$6>=1),"",1-POWER(1+多次统计数据!$B$8,-多次统计数据!$B$6/(1-多次统计数据!$B$6))) | AC15: =IF(OR(AB15="",多次统计数据!$B$9=""),"",IF(多次统计数据!$B$9<AB15,"低于上限","达到或超过上限")) | AE15: =IF(OR(X15="",C15="",C15<=0),"",X15/C15) | AJ15: =IF(OR(AG15="",AH15=""),"",IF(OR(AND(AG15="短期博反弹",OR(AH15="1～3个交易日",AH15="4～10个交易日")),AND(AG15="突破冲新高",OR(AH15="4～10个交易日",AH15="11～20个交易日")),AND(AG15="趋势波段",OR(AH15="11～20个交易日",AH15="21～60个交易日",AH15="60个交易日以上"))),"匹配","周期与交易预期不匹配，请重新确认")) | AK15: =IF(A15="","",COUNTIFS(加仓管理!$A$2:$A$1001,A15,加仓管理!$G$2:$G$1001,">0")) | AL15: =IF(A15="","",SUMIFS(加仓管理!$G$2:$G$1001,加仓管理!$A$2:$A$1001,A15)) | AM15: =IF(AK15=0,"",IFERROR(LOOKUP(2,1/((加仓管理!$A$2:$A$1001=A15)*(加仓管理!$G$2:$G$1001>0)),加仓管理!$D$2:$D$1001),"")) | AN15: =IF(AK15=0,"",IFERROR(LOOKUP(2,1/((加仓管理!$A$2:$A$1001=A15)*(加仓管理!$G$2:$G$1001>0)),加仓管理!$E$2:$E$1001),"")) | AO15: =IF(OR(A15="",H15="",H15<=0),"",(E15*H15+SUMIFS(加仓管理!$H$2:$H$1001,加仓管理!$A$2:$A$1001,A15))/AP15) | AP15: =IF(OR(A15="",H15="",H15<=0),"",H15+AL15) | AQ15: =IF(A15="","",IF(M15<>"",0,IF(OR(H15="",N15=""),"",MAX((E15*H15+SUMIFS(加仓管理!$H$2:$H$1001,加仓管理!$A$2:$A$1001,A15))-MAX(N15,AN15)*AP15,0)))) | AR15: =IF(A15="","",IF(OR(E15="",H15=""),"违规：首次买入价格或股数缺失",IF(COUNTIFS(加仓管理!$A$2:$A$1001,A15,加仓管理!$R$2:$R$1001,"违规*")>0,"违规：请检查加仓管理表",IF(SUM($AQ$2:$AQ$201)>账户数据!$B$7,"预警：超过账户风险上限",IF(COUNTIFS(加仓管理!$A$2:$A$1001,A15,加仓管理!$N$2:$N$1001,">0",加仓管理!$G$2:$G$1001,"")>0,"提示：存在待执行加仓计划","通过")))))
... F201: =IF(OR(C201="",D201="",E201="",N201="",C201<=0,D201<=0,E201<=N201),"",ROUNDDOWN((C201*D201)/(E201-N201)/100,0)*100) | G201: =IF(A201="","",IF(H201<>"","已开仓",IF(账户数据!$B$23="已锁仓","禁止开仓：连续亏损达到上限",IF(账户数据!$B$23="解锁信息不完整","禁止开仓：请完整填写解锁信息",IF(OR(F201="",E201="",N201="",E201<=N201,账户数据!$B$7=""),"",IF(OR(AG201="",AH201="",AI201=""),"禁止开仓：交易预期未填写完整",IF(账户数据!$B$9+F201*(E201-N201)>=账户数据!$B$7,"禁止开仓：风险额度不足",IF(AJ201="周期与交易预期不匹配，请重新确认",IF(账户数据!$B$23="接近锁仓","允许开仓（接近锁仓；周期需复核）","允许开仓（周期需复核）"),IF(账户数据!$B$23="接近锁仓","允许开仓（接近锁仓）","允许开仓"))))))))) | L201: =IF(AP201="","",AP201) | U201: =IF(OR(AO201="",J201="",AO201<=0),"",(J201-AO201)/AO201) | V201: =IF(OR(AO201="",N201="",AO201<=0),"",(AO201-N201)/AO201) | W201: =IF(OR(U201="",V201="",V201<=0),"",U201/V201) | X201: =IF(OR(K201="",L201="",AO201="",AP201=""),"",(K201-AO201)*L201-IF(O201="",0,O201)-IF(P201="",0,P201)) | Y201: =IF(OR(X201="",AO201="",L201=""),"",IF(AO201*L201+IF(O201="",0,O201)<=0,"",X201/(AO201*L201+IF(O201="",0,O201)))) | Z201: =IF(OR(AE201="",多次统计数据!$B$8=""),"",AE201-多次统计数据!$B$8) | AA201: =IF(OR(I201="",M201="",M201<I201),"",M201-I201) | AB201: =IF(OR(A201="",多次统计数据!$B$8="",多次统计数据!$B$6<=0,多次统计数据!$B$6>=1),"",1-POWER(1+多次统计数据!$B$8,-多次统计数据!$B$6/(1-多次统计数据!$B$6))) | AC201: =IF(OR(AB201="",多次统计数据!$B$9=""),"",IF(多次统计数据!$B$9<AB201,"低于上限","达到或超过上限")) | AE201: =IF(OR(X201="",C201="",C201<=0),"",X201/C201) | AJ201: =IF(OR(AG201="",AH201=""),"",IF(OR(AND(AG201="短期博反弹",OR(AH201="1～3个交易日",AH201="4～10个交易日")),AND(AG201="突破冲新高",OR(AH201="4～10个交易日",AH201="11～20个交易日")),AND(AG201="趋势波段",OR(AH201="11～20个交易日",AH201="21～60个交易日",AH201="60个交易日以上"))),"匹配","周期与交易预期不匹配，请重新确认")) | AK201: =IF(A201="","",COUNTIFS(加仓管理!$A$2:$A$1001,A201,加仓管理!$G$2:$G$1001,">0")) | AL201: =IF(A201="","",SUMIFS(加仓管理!$G$2:$G$1001,加仓管理!$A$2:$A$1001,A201)) | AM201: =IF(AK201=0,"",IFERROR(LOOKUP(2,1/((加仓管理!$A$2:$A$1001=A201)*(加仓管理!$G$2:$G$1001>0)),加仓管理!$D$2:$D$1001),"")) | AN201: =IF(AK201=0,"",IFERROR(LOOKUP(2,1/((加仓管理!$A$2:$A$1001=A201)*(加仓管理!$G$2:$G$1001>0)),加仓管理!$E$2:$E$1001),"")) | AO201: =IF(OR(A201="",H201="",H201<=0),"",(E201*H201+SUMIFS(加仓管理!$H$2:$H$1001,加仓管理!$A$2:$A$1001,A201))/AP201) | AP201: =IF(OR(A201="",H201="",H201<=0),"",H201+AL201) | AQ201: =IF(A201="","",IF(M201<>"",0,IF(OR(H201="",N201=""),"",MAX((E201*H201+SUMIFS(加仓管理!$H$2:$H$1001,加仓管理!$A$2:$A$1001,A201))-MAX(N201,AN201)*AP201,0)))) | AR201: =IF(A201="","",IF(OR(E201="",H201=""),"违规：首次买入价格或股数缺失",IF(COUNTIFS(加仓管理!$A$2:$A$1001,A201,加仓管理!$R$2:$R$1001,"违规*")>0,"违规：请检查加仓管理表",IF(SUM($AQ$2:$AQ$201)>账户数据!$B$7,"预警：超过账户风险上限",IF(COUNTIFS(加仓管理!$A$2:$A$1001,A201,加仓管理!$N$2:$N$1001,">0",加仓管理!$G$2:$G$1001,"")>0,"提示：存在待执行加仓计划","通过")))))

Sheet 加仓管理
A1: 交易编号 | B1: 加仓序号(1-5) | C1: 加仓日期 | D1: 加仓价 | E1: 新止损价 | F1: 本次风险预算金额 | G1: 实际加仓股数 | H1: 本次买入金额 | I1: 加仓前持仓股数 | J1: 加仓前持仓成本 | K1: 新止损下底仓锁定利润 | L1: 风险允许股数 | M1: 金字塔上限股数 | N1: 建议加仓股数 | O1: 加仓后累计股数 | P1: 加仓后加权成本 | Q1: 加仓后止损风险 | R1: 规则检查
H2: =IF(OR(A2="",D2="",G2=""),"",D2*G2) | I2: =IF(OR(A2="",B2=""),"",IFERROR(LOOKUP(2,1/(单次交易!$A$2:$A$201=A2),单次交易!$H$2:$H$201),0)+SUMIFS($G$2:$G$1001,$A$2:$A$1001,A2,$B$2:$B$1001,"<"&B2)) | J2: =IF(OR(A2="",B2=""),"",IFERROR(LOOKUP(2,1/(单次交易!$A$2:$A$201=A2),单次交易!$E$2:$E$201)*LOOKUP(2,1/(单次交易!$A$2:$A$201=A2),单次交易!$H$2:$H$201),0)+SUMIFS($H$2:$H$1001,$A$2:$A$1001,A2,$B$2:$B$1001,"<"&B2)) | K2: =IF(OR(E2="",I2="",J2=""),"",MAX(E2*I2-J2,0)) | L2: =IF(OR(D2="",E2="",F2="",D2<=E2),"",FLOOR((F2+K2)/(D2-E2),100)) | M2: =IF(OR(A2="",B2="",L2=""),"",IF(B2=1,L2,IFERROR(SUMIFS($G$2:$G$1001,$A$2:$A$1001,A2,$B$2:$B$1001,B2-1),0))) | N2: =IF(OR(L2="",M2=""),"",MIN(L2,M2)) | O2: =IF(OR(I2="",G2=""),"",I2+G2) | P2: =IF(OR(O2="",O2=0),"",(J2+H2)/O2) | Q2: =IF(OR(O2="",E2=""),"",MAX(J2+H2-E2*O2,0)) | R2: =IF(A2="","",IF(COUNTIF(_TradeIds,A2)=0,"违规：交易编号不存在",IF(OR(B2="",B2<1,B2>5,B2<>INT(B2)),"违规：加仓序号须为1到5的整数",IF(COUNTIFS($A$2:$A$1001,A2,$B$2:$B$1001,B2)>1,"违规：同一交易的加仓序号重复",IF(OR(D2="",E2="",F2=""),"计划不完整：请填写加仓价、新止损价和风险预算",IF(OR(D2<=0,E2<=0,F2<=0,D2<=E2),"违规：加仓价必须高于新止损价，金额须大于0",IF(AND(B2>1,COUNTIFS($A$2:$A$1001,A2,$B$2:$B$1001,B2-1,$G$2:$G$1001,">0")=0),"违规：须先完成上一次加仓",IF(AND(B2>1,E2<SUMIFS($E$2:$E$1001,$A$2:$A$1001,A2,$B$2:$B$1001,B2-1)),"违规：新止损价不得低于上一次",IF(AND(B2>1,F2>SUMIFS($F$2:$F$1001,$A$2:$A$1001,A2,$B$2:$B$1001,B2-1)),"违规：风险预算须逐次不增加",IF(OR(_LockStatus="已锁仓",_LockStatus="解锁信息不完整"),"违规：锁仓期间禁止加仓",IF(G2="","计划可执行：建议股数见N列",IF(OR(G2<=0,G2<>INT(G2),MOD(G2,100)<>0),"违规：实际股数须为100股整数倍",IF(G2>N2,"违规：实际股数超过风险或金字塔上限",IF(AND(B2>1,G2>SUMIFS($G$2:$G$1001,$A$2:$A$1001,A2,$B$2:$B$1001,B2-1)),"违规：加仓股数须逐次不增加",IF(Q2>F2,"违规：止损风险超过本次预算","通过")))))))))))))))
H3: =IF(OR(A3="",D3="",G3=""),"",D3*G3) | I3: =IF(OR(A3="",B3=""),"",IFERROR(LOOKUP(2,1/(单次交易!$A$2:$A$201=A3),单次交易!$H$2:$H$201),0)+SUMIFS($G$2:$G$1001,$A$2:$A$1001,A3,$B$2:$B$1001,"<"&B3)) | J3: =IF(OR(A3="",B3=""),"",IFERROR(LOOKUP(2,1/(单次交易!$A$2:$A$201=A3),单次交易!$E$2:$E$201)*LOOKUP(2,1/(单次交易!$A$2:$A$201=A3),单次交易!$H$2:$H$201),0)+SUMIFS($H$2:$H$1001,$A$2:$A$1001,A3,$B$2:$B$1001,"<"&B3)) | K3: =IF(OR(E3="",I3="",J3=""),"",MAX(E3*I3-J3,0)) | L3: =IF(OR(D3="",E3="",F3="",D3<=E3),"",FLOOR((F3+K3)/(D3-E3),100)) | M3: =IF(OR(A3="",B3="",L3=""),"",IF(B3=1,L3,IFERROR(SUMIFS($G$2:$G$1001,$A$2:$A$1001,A3,$B$2:$B$1001,B3-1),0))) | N3: =IF(OR(L3="",M3=""),"",MIN(L3,M3)) | O3: =IF(OR(I3="",G3=""),"",I3+G3) | P3: =IF(OR(O3="",O3=0),"",(J3+H3)/O3) | Q3: =IF(OR(O3="",E3=""),"",MAX(J3+H3-E3*O3,0)) | R3: =IF(A3="","",IF(COUNTIF(_TradeIds,A3)=0,"违规：交易编号不存在",IF(OR(B3="",B3<1,B3>5,B3<>INT(B3)),"违规：加仓序号须为1到5的整数",IF(COUNTIFS($A$2:$A$1001,A3,$B$2:$B$1001,B3)>1,"违规：同一交易的加仓序号重复",IF(OR(D3="",E3="",F3=""),"计划不完整：请填写加仓价、新止损价和风险预算",IF(OR(D3<=0,E3<=0,F3<=0,D3<=E3),"违规：加仓价必须高于新止损价，金额须大于0",IF(AND(B3>1,COUNTIFS($A$2:$A$1001,A3,$B$2:$B$1001,B3-1,$G$2:$G$1001,">0")=0),"违规：须先完成上一次加仓",IF(AND(B3>1,E3<SUMIFS($E$2:$E$1001,$A$2:$A$1001,A3,$B$2:$B$1001,B3-1)),"违规：新止损价不得低于上一次",IF(AND(B3>1,F3>SUMIFS($F$2:$F$1001,$A$2:$A$1001,A3,$B$2:$B$1001,B3-1)),"违规：风险预算须逐次不增加",IF(OR(_LockStatus="已锁仓",_LockStatus="解锁信息不完整"),"违规：锁仓期间禁止加仓",IF(G3="","计划可执行：建议股数见N列",IF(OR(G3<=0,G3<>INT(G3),MOD(G3,100)<>0),"违规：实际股数须为100股整数倍",IF(G3>N3,"违规：实际股数超过风险或金字塔上限",IF(AND(B3>1,G3>SUMIFS($G$2:$G$1001,$A$2:$A$1001,A3,$B$2:$B$1001,B3-1)),"违规：加仓股数须逐次不增加",IF(Q3>F3,"违规：止损风险超过本次预算","通过")))))))))))))))
H4: =IF(OR(A4="",D4="",G4=""),"",D4*G4) | I4: =IF(OR(A4="",B4=""),"",IFERROR(LOOKUP(2,1/(单次交易!$A$2:$A$201=A4),单次交易!$H$2:$H$201),0)+SUMIFS($G$2:$G$1001,$A$2:$A$1001,A4,$B$2:$B$1001,"<"&B4)) | J4: =IF(OR(A4="",B4=""),"",IFERROR(LOOKUP(2,1/(单次交易!$A$2:$A$201=A4),单次交易!$E$2:$E$201)*LOOKUP(2,1/(单次交易!$A$2:$A$201=A4),单次交易!$H$2:$H$201),0)+SUMIFS($H$2:$H$1001,$A$2:$A$1001,A4,$B$2:$B$1001,"<"&B4)) | K4: =IF(OR(E4="",I4="",J4=""),"",MAX(E4*I4-J4,0)) | L4: =IF(OR(D4="",E4="",F4="",D4<=E4),"",FLOOR((F4+K4)/(D4-E4),100)) | M4: =IF(OR(A4="",B4="",L4=""),"",IF(B4=1,L4,IFERROR(SUMIFS($G$2:$G$1001,$A$2:$A$1001,A4,$B$2:$B$1001,B4-1),0))) | N4: =IF(OR(L4="",M4=""),"",MIN(L4,M4)) | O4: =IF(OR(I4="",G4=""),"",I4+G4) | P4: =IF(OR(O4="",O4=0),"",(J4+H4)/O4) | Q4: =IF(OR(O4="",E4=""),"",MAX(J4+H4-E4*O4,0)) | R4: =IF(A4="","",IF(COUNTIF(_TradeIds,A4)=0,"违规：交易编号不存在",IF(OR(B4="",B4<1,B4>5,B4<>INT(B4)),"违规：加仓序号须为1到5的整数",IF(COUNTIFS($A$2:$A$1001,A4,$B$2:$B$1001,B4)>1,"违规：同一交易的加仓序号重复",IF(OR(D4="",E4="",F4=""),"计划不完整：请填写加仓价、新止损价和风险预算",IF(OR(D4<=0,E4<=0,F4<=0,D4<=E4),"违规：加仓价必须高于新止损价，金额须大于0",IF(AND(B4>1,COUNTIFS($A$2:$A$1001,A4,$B$2:$B$1001,B4-1,$G$2:$G$1001,">0")=0),"违规：须先完成上一次加仓",IF(AND(B4>1,E4<SUMIFS($E$2:$E$1001,$A$2:$A$1001,A4,$B$2:$B$1001,B4-1)),"违规：新止损价不得低于上一次",IF(AND(B4>1,F4>SUMIFS($F$2:$F$1001,$A$2:$A$1001,A4,$B$2:$B$1001,B4-1)),"违规：风险预算须逐次不增加",IF(OR(_LockStatus="已锁仓",_LockStatus="解锁信息不完整"),"违规：锁仓期间禁止加仓",IF(G4="","计划可执行：建议股数见N列",IF(OR(G4<=0,G4<>INT(G4),MOD(G4,100)<>0),"违规：实际股数须为100股整数倍",IF(G4>N4,"违规：实际股数超过风险或金字塔上限",IF(AND(B4>1,G4>SUMIFS($G$2:$G$1001,$A$2:$A$1001,A4,$B$2:$B$1001,B4-1)),"违规：加仓股数须逐次不增加",IF(Q4>F4,"违规：止损风险超过本次预算","通过")))))))))))))))
H5: =IF(OR(A5="",D5="",G5=""),"",D5*G5) | I5: =IF(OR(A5="",B5=""),"",IFERROR(LOOKUP(2,1/(单次交易!$A$2:$A$201=A5),单次交易!$H$2:$H$201),0)+SUMIFS($G$2:$G$1001,$A$2:$A$1001,A5,$B$2:$B$1001,"<"&B5)) | J5: =IF(OR(A5="",B5=""),"",IFERROR(LOOKUP(2,1/(单次交易!$A$2:$A$201=A5),单次交易!$E$2:$E$201)*LOOKUP(2,1/(单次交易!$A$2:$A$201=A5),单次交易!$H$2:$H$201),0)+SUMIFS($H$2:$H$1001,$A$2:$A$1001,A5,$B$2:$B$1001,"<"&B5)) | K5: =IF(OR(E5="",I5="",J5=""),"",MAX(E5*I5-J5,0)) | L5: =IF(OR(D5="",E5="",F5="",D5<=E5),"",FLOOR((F5+K5)/(D5-E5),100)) | M5: =IF(OR(A5="",B5="",L5=""),"",IF(B5=1,L5,IFERROR(SUMIFS($G$2:$G$1001,$A$2:$A$1001,A5,$B$2:$B$1001,B5-1),0))) | N5: =IF(OR(L5="",M5=""),"",MIN(L5,M5)) | O5: =IF(OR(I5="",G5=""),"",I5+G5) | P5: =IF(OR(O5="",O5=0),"",(J5+H5)/O5) | Q5: =IF(OR(O5="",E5=""),"",MAX(J5+H5-E5*O5,0)) | R5: =IF(A5="","",IF(COUNTIF(_TradeIds,A5)=0,"违规：交易编号不存在",IF(OR(B5="",B5<1,B5>5,B5<>INT(B5)),"违规：加仓序号须为1到5的整数",IF(COUNTIFS($A$2:$A$1001,A5,$B$2:$B$1001,B5)>1,"违规：同一交易的加仓序号重复",IF(OR(D5="",E5="",F5=""),"计划不完整：请填写加仓价、新止损价和风险预算",IF(OR(D5<=0,E5<=0,F5<=0,D5<=E5),"违规：加仓价必须高于新止损价，金额须大于0",IF(AND(B5>1,COUNTIFS($A$2:$A$1001,A5,$B$2:$B$1001,B5-1,$G$2:$G$1001,">0")=0),"违规：须先完成上一次加仓",IF(AND(B5>1,E5<SUMIFS($E$2:$E$1001,$A$2:$A$1001,A5,$B$2:$B$1001,B5-1)),"违规：新止损价不得低于上一次",IF(AND(B5>1,F5>SUMIFS($F$2:$F$1001,$A$2:$A$1001,A5,$B$2:$B$1001,B5-1)),"违规：风险预算须逐次不增加",IF(OR(_LockStatus="已锁仓",_LockStatus="解锁信息不完整"),"违规：锁仓期间禁止加仓",IF(G5="","计划可执行：建议股数见N列",IF(OR(G5<=0,G5<>INT(G5),MOD(G5,100)<>0),"违规：实际股数须为100股整数倍",IF(G5>N5,"违规：实际股数超过风险或金字塔上限",IF(AND(B5>1,G5>SUMIFS($G$2:$G$1001,$A$2:$A$1001,A5,$B$2:$B$1001,B5-1)),"违规：加仓股数须逐次不增加",IF(Q5>F5,"违规：止损风险超过本次预算","通过")))))))))))))))
H6: =IF(OR(A6="",D6="",G6=""),"",D6*G6) | I6: =IF(OR(A6="",B6=""),"",IFERROR(LOOKUP(2,1/(单次交易!$A$2:$A$201=A6),单次交易!$H$2:$H$201),0)+SUMIFS($G$2:$G$1001,$A$2:$A$1001,A6,$B$2:$B$1001,"<"&B6)) | J6: =IF(OR(A6="",B6=""),"",IFERROR(LOOKUP(2,1/(单次交易!$A$2:$A$201=A6),单次交易!$E$2:$E$201)*LOOKUP(2,1/(单次交易!$A$2:$A$201=A6),单次交易!$H$2:$H$201),0)+SUMIFS($H$2:$H$1001,$A$2:$A$1001,A6,$B$2:$B$1001,"<"&B6)) | K6: =IF(OR(E6="",I6="",J6=""),"",MAX(E6*I6-J6,0)) | L6: =IF(OR(D6="",E6="",F6="",D6<=E6),"",FLOOR((F6+K6)/(D6-E6),100)) | M6: =IF(OR(A6="",B6="",L6=""),"",IF(B6=1,L6,IFERROR(SUMIFS($G$2:$G$1001,$A$2:$A$1001,A6,$B$2:$B$1001,B6-1),0))) | N6: =IF(OR(L6="",M6=""),"",MIN(L6,M6)) | O6: =IF(OR(I6="",G6=""),"",I6+G6) | P6: =IF(OR(O6="",O6=0),"",(J6+H6)/O6) | Q6: =IF(OR(O6="",E6=""),"",MAX(J6+H6-E6*O6,0)) | R6: =IF(A6="","",IF(COUNTIF(_TradeIds,A6)=0,"违规：交易编号不存在",IF(OR(B6="",B6<1,B6>5,B6<>INT(B6)),"违规：加仓序号须为1到5的整数",IF(COUNTIFS($A$2:$A$1001,A6,$B$2:$B$1001,B6)>1,"违规：同一交易的加仓序号重复",IF(OR(D6="",E6="",F6=""),"计划不完整：请填写加仓价、新止损价和风险预算",IF(OR(D6<=0,E6<=0,F6<=0,D6<=E6),"违规：加仓价必须高于新止损价，金额须大于0",IF(AND(B6>1,COUNTIFS($A$2:$A$1001,A6,$B$2:$B$1001,B6-1,$G$2:$G$1001,">0")=0),"违规：须先完成上一次加仓",IF(AND(B6>1,E6<SUMIFS($E$2:$E$1001,$A$2:$A$1001,A6,$B$2:$B$1001,B6-1)),"违规：新止损价不得低于上一次",IF(AND(B6>1,F6>SUMIFS($F$2:$F$1001,$A$2:$A$1001,A6,$B$2:$B$1001,B6-1)),"违规：风险预算须逐次不增加",IF(OR(_LockStatus="已锁仓",_LockStatus="解锁信息不完整"),"违规：锁仓期间禁止加仓",IF(G6="","计划可执行：建议股数见N列",IF(OR(G6<=0,G6<>INT(G6),MOD(G6,100)<>0),"违规：实际股数须为100股整数倍",IF(G6>N6,"违规：实际股数超过风险或金字塔上限",IF(AND(B6>1,G6>SUMIFS($G$2:$G$1001,$A$2:$A$1001,A6,$B$2:$B$1001,B6-1)),"违规：加仓股数须逐次不增加",IF(Q6>F6,"违规：止损风险超过本次预算","通过")))))))))))))))
H7: =IF(OR(A7="",D7="",G7=""),"",D7*G7) | I7: =IF(OR(A7="",B7=""),"",IFERROR(LOOKUP(2,1/(单次交易!$A$2:$A$201=A7),单次交易!$H$2:$H$201),0)+SUMIFS($G$2:$G$1001,$A$2:$A$1001,A7,$B$2:$B$1001,"<"&B7)) | J7: =IF(OR(A7="",B7=""),"",IFERROR(LOOKUP(2,1/(单次交易!$A$2:$A$201=A7),单次交易!$E$2:$E$201)*LOOKUP(2,1/(单次交易!$A$2:$A$201=A7),单次交易!$H$2:$H$201),0)+SUMIFS($H$2:$H$1001,$A$2:$A$1001,A7,$B$2:$B$1001,"<"&B7)) | K7: =IF(OR(E7="",I7="",J7=""),"",MAX(E7*I7-J7,0)) | L7: =IF(OR(D7="",E7="",F7="",D7<=E7),"",FLOOR((F7+K7)/(D7-E7),100)) | M7: =IF(OR(A7="",B7="",L7=""),"",IF(B7=1,L7,IFERROR(SUMIFS($G$2:$G$1001,$A$2:$A$1001,A7,$B$2:$B$1001,B7-1),0))) | N7: =IF(OR(L7="",M7=""),"",MIN(L7,M7)) | O7: =IF(OR(I7="",G7=""),"",I7+G7) | P7: =IF(OR(O7="",O7=0),"",(J7+H7)/O7) | Q7: =IF(OR(O7="",E7=""),"",MAX(J7+H7-E7*O7,0)) | R7: =IF(A7="","",IF(COUNTIF(_TradeIds,A7)=0,"违规：交易编号不存在",IF(OR(B7="",B7<1,B7>5,B7<>INT(B7)),"违规：加仓序号须为1到5的整数",IF(COUNTIFS($A$2:$A$1001,A7,$B$2:$B$1001,B7)>1,"违规：同一交易的加仓序号重复",IF(OR(D7="",E7="",F7=""),"计划不完整：请填写加仓价、新止损价和风险预算",IF(OR(D7<=0,E7<=0,F7<=0,D7<=E7),"违规：加仓价必须高于新止损价，金额须大于0",IF(AND(B7>1,COUNTIFS($A$2:$A$1001,A7,$B$2:$B$1001,B7-1,$G$2:$G$1001,">0")=0),"违规：须先完成上一次加仓",IF(AND(B7>1,E7<SUMIFS($E$2:$E$1001,$A$2:$A$1001,A7,$B$2:$B$1001,B7-1)),"违规：新止损价不得低于上一次",IF(AND(B7>1,F7>SUMIFS($F$2:$F$1001,$A$2:$A$1001,A7,$B$2:$B$1001,B7-1)),"违规：风险预算须逐次不增加",IF(OR(_LockStatus="已锁仓",_LockStatus="解锁信息不完整"),"违规：锁仓期间禁止加仓",IF(G7="","计划可执行：建议股数见N列",IF(OR(G7<=0,G7<>INT(G7),MOD(G7,100)<>0),"违规：实际股数须为100股整数倍",IF(G7>N7,"违规：实际股数超过风险或金字塔上限",IF(AND(B7>1,G7>SUMIFS($G$2:$G$1001,$A$2:$A$1001,A7,$B$2:$B$1001,B7-1)),"违规：加仓股数须逐次不增加",IF(Q7>F7,"违规：止损风险超过本次预算","通过")))))))))))))))
H8: =IF(OR(A8="",D8="",G8=""),"",D8*G8) | I8: =IF(OR(A8="",B8=""),"",IFERROR(LOOKUP(2,1/(单次交易!$A$2:$A$201=A8),单次交易!$H$2:$H$201),0)+SUMIFS($G$2:$G$1001,$A$2:$A$1001,A8,$B$2:$B$1001,"<"&B8)) | J8: =IF(OR(A8="",B8=""),"",IFERROR(LOOKUP(2,1/(单次交易!$A$2:$A$201=A8),单次交易!$E$2:$E$201)*LOOKUP(2,1/(单次交易!$A$2:$A$201=A8),单次交易!$H$2:$H$201),0)+SUMIFS($H$2:$H$1001,$A$2:$A$1001,A8,$B$2:$B$1001,"<"&B8)) | K8: =IF(OR(E8="",I8="",J8=""),"",MAX(E8*I8-J8,0)) | L8: =IF(OR(D8="",E8="",F8="",D8<=E8),"",FLOOR((F8+K8)/(D8-E8),100)) | M8: =IF(OR(A8="",B8="",L8=""),"",IF(B8=1,L8,IFERROR(SUMIFS($G$2:$G$1001,$A$2:$A$1001,A8,$B$2:$B$1001,B8-1),0))) | N8: =IF(OR(L8="",M8=""),"",MIN(L8,M8)) | O8: =IF(OR(I8="",G8=""),"",I8+G8) | P8: =IF(OR(O8="",O8=0),"",(J8+H8)/O8) | Q8: =IF(OR(O8="",E8=""),"",MAX(J8+H8-E8*O8,0)) | R8: =IF(A8="","",IF(COUNTIF(_TradeIds,A8)=0,"违规：交易编号不存在",IF(OR(B8="",B8<1,B8>5,B8<>INT(B8)),"违规：加仓序号须为1到5的整数",IF(COUNTIFS($A$2:$A$1001,A8,$B$2:$B$1001,B8)>1,"违规：同一交易的加仓序号重复",IF(OR(D8="",E8="",F8=""),"计划不完整：请填写加仓价、新止损价和风险预算",IF(OR(D8<=0,E8<=0,F8<=0,D8<=E8),"违规：加仓价必须高于新止损价，金额须大于0",IF(AND(B8>1,COUNTIFS($A$2:$A$1001,A8,$B$2:$B$1001,B8-1,$G$2:$G$1001,">0")=0),"违规：须先完成上一次加仓",IF(AND(B8>1,E8<SUMIFS($E$2:$E$1001,$A$2:$A$1001,A8,$B$2:$B$1001,B8-1)),"违规：新止损价不得低于上一次",IF(AND(B8>1,F8>SUMIFS($F$2:$F$1001,$A$2:$A$1001,A8,$B$2:$B$1001,B8-1)),"违规：风险预算须逐次不增加",IF(OR(_LockStatus="已锁仓",_LockStatus="解锁信息不完整"),"违规：锁仓期间禁止加仓",IF(G8="","计划可执行：建议股数见N列",IF(OR(G8<=0,G8<>INT(G8),MOD(G8,100)<>0),"违规：实际股数须为100股整数倍",IF(G8>N8,"违规：实际股数超过风险或金字塔上限",IF(AND(B8>1,G8>SUMIFS($G$2:$G$1001,$A$2:$A$1001,A8,$B$2:$B$1001,B8-1)),"违规：加仓股数须逐次不增加",IF(Q8>F8,"违规：止损风险超过本次预算","通过")))))))))))))))
H9: =IF(OR(A9="",D9="",G9=""),"",D9*G9) | I9: =IF(OR(A9="",B9=""),"",IFERROR(LOOKUP(2,1/(单次交易!$A$2:$A$201=A9),单次交易!$H$2:$H$201),0)+SUMIFS($G$2:$G$1001,$A$2:$A$1001,A9,$B$2:$B$1001,"<"&B9)) | J9: =IF(OR(A9="",B9=""),"",IFERROR(LOOKUP(2,1/(单次交易!$A$2:$A$201=A9),单次交易!$E$2:$E$201)*LOOKUP(2,1/(单次交易!$A$2:$A$201=A9),单次交易!$H$2:$H$201),0)+SUMIFS($H$2:$H$1001,$A$2:$A$1001,A9,$B$2:$B$1001,"<"&B9)) | K9: =IF(OR(E9="",I9="",J9=""),"",MAX(E9*I9-J9,0)) | L9: =IF(OR(D9="",E9="",F9="",D9<=E9),"",FLOOR((F9+K9)/(D9-E9),100)) | M9: =IF(OR(A9="",B9="",L9=""),"",IF(B9=1,L9,IFERROR(SUMIFS($G$2:$G$1001,$A$2:$A$1001,A9,$B$2:$B$1001,B9-1),0))) | N9: =IF(OR(L9="",M9=""),"",MIN(L9,M9)) | O9: =IF(OR(I9="",G9=""),"",I9+G9) | P9: =IF(OR(O9="",O9=0),"",(J9+H9)/O9) | Q9: =IF(OR(O9="",E9=""),"",MAX(J9+H9-E9*O9,0)) | R9: =IF(A9="","",IF(COUNTIF(_TradeIds,A9)=0,"违规：交易编号不存在",IF(OR(B9="",B9<1,B9>5,B9<>INT(B9)),"违规：加仓序号须为1到5的整数",IF(COUNTIFS($A$2:$A$1001,A9,$B$2:$B$1001,B9)>1,"违规：同一交易的加仓序号重复",IF(OR(D9="",E9="",F9=""),"计划不完整：请填写加仓价、新止损价和风险预算",IF(OR(D9<=0,E9<=0,F9<=0,D9<=E9),"违规：加仓价必须高于新止损价，金额须大于0",IF(AND(B9>1,COUNTIFS($A$2:$A$1001,A9,$B$2:$B$1001,B9-1,$G$2:$G$1001,">0")=0),"违规：须先完成上一次加仓",IF(AND(B9>1,E9<SUMIFS($E$2:$E$1001,$A$2:$A$1001,A9,$B$2:$B$1001,B9-1)),"违规：新止损价不得低于上一次",IF(AND(B9>1,F9>SUMIFS($F$2:$F$1001,$A$2:$A$1001,A9,$B$2:$B$1001,B9-1)),"违规：风险预算须逐次不增加",IF(OR(_LockStatus="已锁仓",_LockStatus="解锁信息不完整"),"违规：锁仓期间禁止加仓",IF(G9="","计划可执行：建议股数见N列",IF(OR(G9<=0,G9<>INT(G9),MOD(G9,100)<>0),"违规：实际股数须为100股整数倍",IF(G9>N9,"违规：实际股数超过风险或金字塔上限",IF(AND(B9>1,G9>SUMIFS($G$2:$G$1001,$A$2:$A$1001,A9,$B$2:$B$1001,B9-1)),"违规：加仓股数须逐次不增加",IF(Q9>F9,"违规：止损风险超过本次预算","通过")))))))))))))))
H10: =IF(OR(A10="",D10="",G10=""),"",D10*G10) | I10: =IF(OR(A10="",B10=""),"",IFERROR(LOOKUP(2,1/(单次交易!$A$2:$A$201=A10),单次交易!$H$2:$H$201),0)+SUMIFS($G$2:$G$1001,$A$2:$A$1001,A10,$B$2:$B$1001,"<"&B10)) | J10: =IF(OR(A10="",B10=""),"",IFERROR(LOOKUP(2,1/(单次交易!$A$2:$A$201=A10),单次交易!$E$2:$E$201)*LOOKUP(2,1/(单次交易!$A$2:$A$201=A10),单次交易!$H$2:$H$201),0)+SUMIFS($H$2:$H$1001,$A$2:$A$1001,A10,$B$2:$B$1001,"<"&B10)) | K10: =IF(OR(E10="",I10="",J10=""),"",MAX(E10*I10-J10,0)) | L10: =IF(OR(D10="",E10="",F10="",D10<=E10),"",FLOOR((F10+K10)/(D10-E10),100)) | M10: =IF(OR(A10="",B10="",L10=""),"",IF(B10=1,L10,IFERROR(SUMIFS($G$2:$G$1001,$A$2:$A$1001,A10,$B$2:$B$1001,B10-1),0))) | N10: =IF(OR(L10="",M10=""),"",MIN(L10,M10)) | O10: =IF(OR(I10="",G10=""),"",I10+G10) | P10: =IF(OR(O10="",O10=0),"",(J10+H10)/O10) | Q10: =IF(OR(O10="",E10=""),"",MAX(J10+H10-E10*O10,0)) | R10: =IF(A10="","",IF(COUNTIF(_TradeIds,A10)=0,"违规：交易编号不存在",IF(OR(B10="",B10<1,B10>5,B10<>INT(B10)),"违规：加仓序号须为1到5的整数",IF(COUNTIFS($A$2:$A$1001,A10,$B$2:$B$1001,B10)>1,"违规：同一交易的加仓序号重复",IF(OR(D10="",E10="",F10=""),"计划不完整：请填写加仓价、新止损价和风险预算",IF(OR(D10<=0,E10<=0,F10<=0,D10<=E10),"违规：加仓价必须高于新止损价，金额须大于0",IF(AND(B10>1,COUNTIFS($A$2:$A$1001,A10,$B$2:$B$1001,B10-1,$G$2:$G$1001,">0")=0),"违规：须先完成上一次加仓",IF(AND(B10>1,E10<SUMIFS($E$2:$E$1001,$A$2:$A$1001,A10,$B$2:$B$1001,B10-1)),"违规：新止损价不得低于上一次",IF(AND(B10>1,F10>SUMIFS($F$2:$F$1001,$A$2:$A$1001,A10,$B$2:$B$1001,B10-1)),"违规：风险预算须逐次不增加",IF(OR(_LockStatus="已锁仓",_LockStatus="解锁信息不完整"),"违规：锁仓期间禁止加仓",IF(G10="","计划可执行：建议股数见N列",IF(OR(G10<=0,G10<>INT(G10),MOD(G10,100)<>0),"违规：实际股数须为100股整数倍",IF(G10>N10,"违规：实际股数超过风险或金字塔上限",IF(AND(B10>1,G10>SUMIFS($G$2:$G$1001,$A$2:$A$1001,A10,$B$2:$B$1001,B10-1)),"违规：加仓股数须逐次不增加",IF(Q10>F10,"违规：止损风险超过本次预算","通过")))))))))))))))
H11: =IF(OR(A11="",D11="",G11=""),"",D11*G11) | I11: =IF(OR(A11="",B11=""),"",IFERROR(LOOKUP(2,1/(单次交易!$A$2:$A$201=A11),单次交易!$H$2:$H$201),0)+SUMIFS($G$2:$G$1001,$A$2:$A$1001,A11,$B$2:$B$1001,"<"&B11)) | J11: =IF(OR(A11="",B11=""),"",IFERROR(LOOKUP(2,1/(单次交易!$A$2:$A$201=A11),单次交易!$E$2:$E$201)*LOOKUP(2,1/(单次交易!$A$2:$A$201=A11),单次交易!$H$2:$H$201),0)+SUMIFS($H$2:$H$1001,$A$2:$A$1001,A11,$B$2:$B$1001,"<"&B11)) | K11: =IF(OR(E11="",I11="",J11=""),"",MAX(E11*I11-J11,0)) | L11: =IF(OR(D11="",E11="",F11="",D11<=E11),"",FLOOR((F11+K11)/(D11-E11),100)) | M11: =IF(OR(A11="",B11="",L11=""),"",IF(B11=1,L11,IFERROR(SUMIFS($G$2:$G$1001,$A$2:$A$1001,A11,$B$2:$B$1001,B11-1),0))) | N11: =IF(OR(L11="",M11=""),"",MIN(L11,M11)) | O11: =IF(OR(I11="",G11=""),"",I11+G11) | P11: =IF(OR(O11="",O11=0),"",(J11+H11)/O11) | Q11: =IF(OR(O11="",E11=""),"",MAX(J11+H11-E11*O11,0)) | R11: =IF(A11="","",IF(COUNTIF(_TradeIds,A11)=0,"违规：交易编号不存在",IF(OR(B11="",B11<1,B11>5,B11<>INT(B11)),"违规：加仓序号须为1到5的整数",IF(COUNTIFS($A$2:$A$1001,A11,$B$2:$B$1001,B11)>1,"违规：同一交易的加仓序号重复",IF(OR(D11="",E11="",F11=""),"计划不完整：请填写加仓价、新止损价和风险预算",IF(OR(D11<=0,E11<=0,F11<=0,D11<=E11),"违规：加仓价必须高于新止损价，金额须大于0",IF(AND(B11>1,COUNTIFS($A$2:$A$1001,A11,$B$2:$B$1001,B11-1,$G$2:$G$1001,">0")=0),"违规：须先完成上一次加仓",IF(AND(B11>1,E11<SUMIFS($E$2:$E$1001,$A$2:$A$1001,A11,$B$2:$B$1001,B11-1)),"违规：新止损价不得低于上一次",IF(AND(B11>1,F11>SUMIFS($F$2:$F$1001,$A$2:$A$1001,A11,$B$2:$B$1001,B11-1)),"违规：风险预算须逐次不增加",IF(OR(_LockStatus="已锁仓",_LockStatus="解锁信息不完整"),"违规：锁仓期间禁止加仓",IF(G11="","计划可执行：建议股数见N列",IF(OR(G11<=0,G11<>INT(G11),MOD(G11,100)<>0),"违规：实际股数须为100股整数倍",IF(G11>N11,"违规：实际股数超过风险或金字塔上限",IF(AND(B11>1,G11>SUMIFS($G$2:$G$1001,$A$2:$A$1001,A11,$B$2:$B$1001,B11-1)),"违规：加仓股数须逐次不增加",IF(Q11>F11,"违规：止损风险超过本次预算","通过")))))))))))))))
H12: =IF(OR(A12="",D12="",G12=""),"",D12*G12) | I12: =IF(OR(A12="",B12=""),"",IFERROR(LOOKUP(2,1/(单次交易!$A$2:$A$201=A12),单次交易!$H$2:$H$201),0)+SUMIFS($G$2:$G$1001,$A$2:$A$1001,A12,$B$2:$B$1001,"<"&B12)) | J12: =IF(OR(A12="",B12=""),"",IFERROR(LOOKUP(2,1/(单次交易!$A$2:$A$201=A12),单次交易!$E$2:$E$201)*LOOKUP(2,1/(单次交易!$A$2:$A$201=A12),单次交易!$H$2:$H$201),0)+SUMIFS($H$2:$H$1001,$A$2:$A$1001,A12,$B$2:$B$1001,"<"&B12)) | K12: =IF(OR(E12="",I12="",J12=""),"",MAX(E12*I12-J12,0)) | L12: =IF(OR(D12="",E12="",F12="",D12<=E12),"",FLOOR((F12+K12)/(D12-E12),100)) | M12: =IF(OR(A12="",B12="",L12=""),"",IF(B12=1,L12,IFERROR(SUMIFS($G$2:$G$1001,$A$2:$A$1001,A12,$B$2:$B$1001,B12-1),0))) | N12: =IF(OR(L12="",M12=""),"",MIN(L12,M12)) | O12: =IF(OR(I12="",G12=""),"",I12+G12) | P12: =IF(OR(O12="",O12=0),"",(J12+H12)/O12) | Q12: =IF(OR(O12="",E12=""),"",MAX(J12+H12-E12*O12,0)) | R12: =IF(A12="","",IF(COUNTIF(_TradeIds,A12)=0,"违规：交易编号不存在",IF(OR(B12="",B12<1,B12>5,B12<>INT(B12)),"违规：加仓序号须为1到5的整数",IF(COUNTIFS($A$2:$A$1001,A12,$B$2:$B$1001,B12)>1,"违规：同一交易的加仓序号重复",IF(OR(D12="",E12="",F12=""),"计划不完整：请填写加仓价、新止损价和风险预算",IF(OR(D12<=0,E12<=0,F12<=0,D12<=E12),"违规：加仓价必须高于新止损价，金额须大于0",IF(AND(B12>1,COUNTIFS($A$2:$A$1001,A12,$B$2:$B$1001,B12-1,$G$2:$G$1001,">0")=0),"违规：须先完成上一次加仓",IF(AND(B12>1,E12<SUMIFS($E$2:$E$1001,$A$2:$A$1001,A12,$B$2:$B$1001,B12-1)),"违规：新止损价不得低于上一次",IF(AND(B12>1,F12>SUMIFS($F$2:$F$1001,$A$2:$A$1001,A12,$B$2:$B$1001,B12-1)),"违规：风险预算须逐次不增加",IF(OR(_LockStatus="已锁仓",_LockStatus="解锁信息不完整"),"违规：锁仓期间禁止加仓",IF(G12="","计划可执行：建议股数见N列",IF(OR(G12<=0,G12<>INT(G12),MOD(G12,100)<>0),"违规：实际股数须为100股整数倍",IF(G12>N12,"违规：实际股数超过风险或金字塔上限",IF(AND(B12>1,G12>SUMIFS($G$2:$G$1001,$A$2:$A$1001,A12,$B$2:$B$1001,B12-1)),"违规：加仓股数须逐次不增加",IF(Q12>F12,"违规：止损风险超过本次预算","通过")))))))))))))))
H13: =IF(OR(A13="",D13="",G13=""),"",D13*G13) | I13: =IF(OR(A13="",B13=""),"",IFERROR(LOOKUP(2,1/(单次交易!$A$2:$A$201=A13),单次交易!$H$2:$H$201),0)+SUMIFS($G$2:$G$1001,$A$2:$A$1001,A13,$B$2:$B$1001,"<"&B13)) | J13: =IF(OR(A13="",B13=""),"",IFERROR(LOOKUP(2,1/(单次交易!$A$2:$A$201=A13),单次交易!$E$2:$E$201)*LOOKUP(2,1/(单次交易!$A$2:$A$201=A13),单次交易!$H$2:$H$201),0)+SUMIFS($H$2:$H$1001,$A$2:$A$1001,A13,$B$2:$B$1001,"<"&B13)) | K13: =IF(OR(E13="",I13="",J13=""),"",MAX(E13*I13-J13,0)) | L13: =IF(OR(D13="",E13="",F13="",D13<=E13),"",FLOOR((F13+K13)/(D13-E13),100)) | M13: =IF(OR(A13="",B13="",L13=""),"",IF(B13=1,L13,IFERROR(SUMIFS($G$2:$G$1001,$A$2:$A$1001,A13,$B$2:$B$1001,B13-1),0))) | N13: =IF(OR(L13="",M13=""),"",MIN(L13,M13)) | O13: =IF(OR(I13="",G13=""),"",I13+G13) | P13: =IF(OR(O13="",O13=0),"",(J13+H13)/O13) | Q13: =IF(OR(O13="",E13=""),"",MAX(J13+H13-E13*O13,0)) | R13: =IF(A13="","",IF(COUNTIF(_TradeIds,A13)=0,"违规：交易编号不存在",IF(OR(B13="",B13<1,B13>5,B13<>INT(B13)),"违规：加仓序号须为1到5的整数",IF(COUNTIFS($A$2:$A$1001,A13,$B$2:$B$1001,B13)>1,"违规：同一交易的加仓序号重复",IF(OR(D13="",E13="",F13=""),"计划不完整：请填写加仓价、新止损价和风险预算",IF(OR(D13<=0,E13<=0,F13<=0,D13<=E13),"违规：加仓价必须高于新止损价，金额须大于0",IF(AND(B13>1,COUNTIFS($A$2:$A$1001,A13,$B$2:$B$1001,B13-1,$G$2:$G$1001,">0")=0),"违规：须先完成上一次加仓",IF(AND(B13>1,E13<SUMIFS($E$2:$E$1001,$A$2:$A$1001,A13,$B$2:$B$1001,B13-1)),"违规：新止损价不得低于上一次",IF(AND(B13>1,F13>SUMIFS($F$2:$F$1001,$A$2:$A$1001,A13,$B$2:$B$1001,B13-1)),"违规：风险预算须逐次不增加",IF(OR(_LockStatus="已锁仓",_LockStatus="解锁信息不完整"),"违规：锁仓期间禁止加仓",IF(G13="","计划可执行：建议股数见N列",IF(OR(G13<=0,G13<>INT(G13),MOD(G13,100)<>0),"违规：实际股数须为100股整数倍",IF(G13>N13,"违规：实际股数超过风险或金字塔上限",IF(AND(B13>1,G13>SUMIFS($G$2:$G$1001,$A$2:$A$1001,A13,$B$2:$B$1001,B13-1)),"违规：加仓股数须逐次不增加",IF(Q13>F13,"违规：止损风险超过本次预算","通过")))))))))))))))
... H1001: =IF(OR(A1001="",D1001="",G1001=""),"",D1001*G1001) | I1001: =IF(OR(A1001="",B1001=""),"",IFERROR(LOOKUP(2,1/(单次交易!$A$2:$A$201=A1001),单次交易!$H$2:$H$201),0)+SUMIFS($G$2:$G$1001,$A$2:$A$1001,A1001,$B$2:$B$1001,"<"&B1001)) | J1001: =IF(OR(A1001="",B1001=""),"",IFERROR(LOOKUP(2,1/(单次交易!$A$2:$A$201=A1001),单次交易!$E$2:$E$201)*LOOKUP(2,1/(单次交易!$A$2:$A$201=A1001),单次交易!$H$2:$H$201),0)+SUMIFS($H$2:$H$1001,$A$2:$A$1001,A1001,$B$2:$B$1001,"<"&B1001)) | K1001: =IF(OR(E1001="",I1001="",J1001=""),"",MAX(E1001*I1001-J1001,0)) | L1001: =IF(OR(D1001="",E1001="",F1001="",D1001<=E1001),"",FLOOR((F1001+K1001)/(D1001-E1001),100)) | M1001: =IF(OR(A1001="",B1001="",L1001=""),"",IF(B1001=1,L1001,IFERROR(SUMIFS($G$2:$G$1001,$A$2:$A$1001,A1001,$B$2:$B$1001,B1001-1),0))) | N1001: =IF(OR(L1001="",M1001=""),"",MIN(L1001,M1001)) | O1001: =IF(OR(I1001="",G1001=""),"",I1001+G1001) | P1001: =IF(OR(O1001="",O1001=0),"",(J1001+H1001)/O1001) | Q1001: =IF(OR(O1001="",E1001=""),"",MAX(J1001+H1001-E1001*O1001,0)) | R1001: =IF(A1001="","",IF(COUNTIF(_TradeIds,A1001)=0,"违规：交易编号不存在",IF(OR(B1001="",B1001<1,B1001>5,B1001<>INT(B1001)),"违规：加仓序号须为1到5的整数",IF(COUNTIFS($A$2:$A$1001,A1001,$B$2:$B$1001,B1001)>1,"违规：同一交易的加仓序号重复",IF(OR(D1001="",E1001="",F1001=""),"计划不完整：请填写加仓价、新止损价和风险预算",IF(OR(D1001<=0,E1001<=0,F1001<=0,D1001<=E1001),"违规：加仓价必须高于新止损价，金额须大于0",IF(AND(B1001>1,COUNTIFS($A$2:$A$1001,A1001,$B$2:$B$1001,B1001-1,$G$2:$G$1001,">0")=0),"违规：须先完成上一次加仓",IF(AND(B1001>1,E1001<SUMIFS($E$2:$E$1001,$A$2:$A$1001,A1001,$B$2:$B$1001,B1001-1)),"违规：新止损价不得低于上一次",IF(AND(B1001>1,F1001>SUMIFS($F$2:$F$1001,$A$2:$A$1001,A1001,$B$2:$B$1001,B1001-1)),"违规：风险预算须逐次不增加",IF(OR(_LockStatus="已锁仓",_LockStatus="解锁信息不完整"),"违规：锁仓期间禁止加仓",IF(G1001="","计划可执行：建议股数见N列",IF(OR(G1001<=0,G1001<>INT(G1001),MOD(G1001,100)<>0),"违规：实际股数须为100股整数倍",IF(G1001>N1001,"违规：实际股数超过风险或金字塔上限",IF(AND(B1001>1,G1001>SUMIFS($G$2:$G$1001,$A$2:$A$1001,A1001,$B$2:$B$1001,B1001-1)),"违规：加仓股数须逐次不增加",IF(Q1001>F1001,"违规：止损风险超过本次预算","通过")))))))))))))))

Sheet 多次统计数据
A1: 指标 | B1: 当前统计 | C1: 口径说明
A2: 已完成交易数 | B2: =COUNT(单次交易!M2:M201) -> 0 | C2: 存在卖出日期的交易
A3: 盈利交易数 | B3: =COUNTIF(单次交易!X2:X201,">0") -> 0 | C3: 实际盈亏金额大于0
A4: 亏损交易数 | B4: =COUNTIF(单次交易!X2:X201,"<0") -> 0 | C4: 实际盈亏金额小于0
A5: 持平交易数 | B5: =COUNTIFS(单次交易!M2:M201,"<>",单次交易!X2:X201,"=0") -> 0 | C5: 已卖出且实际盈亏为0；不进入胜负样本
A6: 盈利概率 | B6: =IFERROR(B3/(B3+B4),"") | C6: 盈利数÷胜负交易数
A7: 亏损概率 | B7: =IFERROR(B4/(B3+B4),"") | C7: 亏损数÷胜负交易数
A8: 平均盈利百分比 | B8: =IFERROR(AVERAGEIF(单次交易!X2:X201,">0",单次交易!AE2:AE201),"") | C8: 盈利交易实际账户收益率的平均值
A9: 平均亏损百分比 | B9: =IFERROR(-AVERAGEIF(单次交易!X2:X201,"<0",单次交易!AE2:AE201),"") | C9: 亏损交易实际账户收益率绝对值的平均值
A10: 盈利的持有总天数 | B10: =SUMIF(单次交易!X2:X201,">0",单次交易!AA2:AA201) -> 0 | C10: 自然日
