Workbook
Name _LockStatus: 账户数据!$B$23
Name _AccountRiskLimit: 账户数据!$B$7
Name _TrackRule: 持仓跟踪!$AC$2:$AC$497
Name _TrackTradeId: 持仓跟踪!$B$2:$B$497
Name _TrackType: 持仓跟踪!$A$2:$A$497
Name _TradeIds: 单次交易!$A$2:$A$201
Name 技术指标列表: 技术指标!$A$2:$A$201

Sheet 单次交易
A1: 交易编号 | B1: 股票代码 | C1: 买入时账户金额 | D1: 本次允许亏损比例 | E1: 第一批买入价 | F1: 买入建议股数 | G1: 开仓风险告警 | H1: 第一批买入股数 | I1: 首次买入日期 | J1: 期望卖出价 | K1: 实际卖出价 | L1: 卖出股数 | M1: 卖出日期 | N1: 止损价 | O1: 买入总费用 | P1: 卖出费用 | Q1: 买入价的由来 | R1: 止损价的由来 | S1: 期望卖出价的由来 | T1: 实际卖出价的由来 | U1: 期望盈利比例 | V1: 期望止损比例 | W1: 盈亏比 | X1: 实际盈亏金额 | Y1: 单笔仓位收益率 | Z1: 账户收益率与平均盈利率差值 | AA1: 持有天数 | AB1: 复利容许平均亏损上限 | AC1: 复利风险判断 | AD1: 交易打分评价 | AE1: 实际账户收益率 | AF1: 列1 | AG1: 交易预期类型 | AH1: 预期持有周期 | AI1: 预期选择理由 | AJ1: 周期匹配检查 | AK1: 第二批买入价 | AL1: 第二批买入股数 | AM1: 第三批买入价 | AN1: 第三批买入股数 | AO1: 实际加权买入价 | AP1: 累计买入股数 | AQ1: 当前持仓风险 | AR1: 分仓规则检查
F2: =IF(OR(C2="",D2="",E2="",N2="",C2<=0,D2<=0,E2<=N2),"",ROUNDDOWN((C2*D2)/(E2-N2)/100,0)*100) | G2: =IF(A2="","",IF(H2<>"","已开仓",IF(账户数据!$B$23="已锁仓","禁止开仓：连续亏损达到上限",IF(账户数据!$B$23="解锁信息不完整","禁止开仓：请完整填写解锁信息",IF(OR(F2="",E2="",N2="",E2<=N2,账户数据!$B$7=""),"",IF(OR(AG2="",AH2="",AI2=""),"禁止开仓：交易预期未填写完整",IF(COUNTIFS(持仓跟踪!$A$2:$A$497,"止损计划",持仓跟踪!$B$2:$B$497,A2,持仓跟踪!$AC$2:$AC$497,"计划有效")=0,"禁止开仓：请先填写止损计划",IF(账户数据!$B$9+F2*(E2-N2)>=账户数据!$B$7,"禁止开仓：风险额度不足",IF(AJ2="周期与交易预期不匹配，请重新确认",IF(账户数据!$B$23="接近锁仓","允许开仓（接近锁仓；周期需复核）","允许开仓（周期需复核）"),IF(账户数据!$B$23="接近锁仓","允许开仓（接近锁仓）","允许开仓")))))))))) | L2: =IF(K2="","",H2) | U2: =IF(OR(AO2="",J2="",AO2<=0),"",(J2-AO2)/AO2) | V2: =IF(OR(AO2="",N2="",AO2<=0),"",(AO2-N2)/AO2) | W2: =IF(OR(U2="",V2="",V2<=0),"",U2/V2) | X2: =IF(OR(K2="",L2="",AP2=""),"",K2*L2-(E2*H2+IF(AND(AK2<>"",AL2<>""),AK2*AL2,0)+IF(AND(AM2<>"",AN2<>""),AM2*AN2,0))-IF(O2="",0,O2)-IF(P2="",0,P2)) | Y2: =IF(OR(X2="",AP2=""),"",IF((E2*H2+IF(AND(AK2<>"",AL2<>""),AK2*AL2,0)+IF(AND(AM2<>"",AN2<>""),AM2*AN2,0))+IF(O2="",0,O2)<=0,"",X2/((E2*H2+IF(AND(AK2<>"",AL2<>""),AK2*AL2,0)+IF(AND(AM2<>"",AN2<>""),AM2*AN2,0))+IF(O2="",0,O2)))) | Z2: =IF(OR(AE2="",多次统计数据!$B$8=""),"",AE2-多次统计数据!$B$8) | AA2: =IF(OR(I2="",M2="",M2<I2),"",M2-I2) | AB2: =IF(OR(A2="",多次统计数据!$B$8="",多次统计数据!$B$6<=0,多次统计数据!$B$6>=1),"",1-POWER(1+多次统计数据!$B$8,-多次统计数据!$B$6/(1-多次统计数据!$B$6))) | AC2: =IF(OR(AB2="",多次统计数据!$B$9=""),"",IF(多次统计数据!$B$9<AB2,"低于上限","达到或超过上限")) | AE2: =IF(OR(X2="",C2="",C2<=0),"",X2/C2) | AJ2: =IF(OR(AG2="",AH2=""),"",IF(OR(AND(AG2="短期博反弹",OR(AH2="1～3个交易日",AH2="4～10个交易日")),AND(AG2="突破冲新高",OR(AH2="4～10个交易日",AH2="11～20个交易日")),AND(AG2="趋势波段",OR(AH2="11～20个交易日",AH2="21～60个交易日",AH2="60个交易日以上"))),"匹配","周期与交易预期不匹配，请重新确认")) | AO2: =IF(OR(A2="",H2="",H2<=0),"",(E2*H2+IF(AND(AK2<>"",AL2<>""),AK2*AL2,0)+IF(AND(AM2<>"",AN2<>""),AM2*AN2,0))/AP2) | AP2: =IF(OR(A2="",H2="",H2<=0),"",H2+IF(AL2="",0,AL2)+IF(AN2="",0,AN2)) | AQ2: =IF(A2="","",IF(M2<>"",0,IF(OR(H2="",N2=""),"",MAX(E2-MAX(N2,IFERROR(SUMPRODUCT(MAX(((持仓跟踪!$A$2:$A$497="每日跟踪")*(持仓跟踪!$B$2:$B$497=A2))*持仓跟踪!$S$2:$S$497)),0)),0)*H2+IF(OR(AK2="",AL2=""),0,MAX(AK2-MAX(N2,IFERROR(SUMPRODUCT(MAX(((持仓跟踪!$A$2:$A$497="每日跟踪")*(持仓跟踪!$B$2:$B$497=A2))*持仓跟踪!$S$2:$S$497)),0)),0)*AL2)+IF(OR(AM2="",AN2=""),0,MAX(AM2-MAX(N2,IFERROR(SUMPRODUCT(MAX(((持仓跟踪!$A$2:$A$497="每日跟踪")*(持仓跟踪!$B$2:$B$497=A2))*持仓跟踪!$S$2:$S$497)),0)),0)*AN2)))) | AR2: =IF(A2="","",IF(OR(E2="",H2=""),"违规：第一批价格或股数缺失",IF(OR(AND(AK2="",AL2<>""),AND(AK2<>"",AL2="")),"违规：第二批价格与股数须成对填写",IF(OR(AND(AM2="",AN2<>""),AND(AM2<>"",AN2="")),"违规：第三批价格与股数须成对填写",IF(AND(OR(AM2<>"",AN2<>""),OR(AK2="",AL2="")),"违规：必须先完成第二批",IF(OR(H2<=0,H2<>INT(H2),MOD(H2,100)<>0,AND(AL2<>"",OR(AL2<=0,AL2<>INT(AL2),MOD(AL2,100)<>0)),AND(AN2<>"",OR(AN2<=0,AN2<>INT(AN2),MOD(AN2,100)<>0))),"违规：股数须为100股整数倍",IF(AND(OR(AL2<>"",AN2<>""),OR(_LockStatus="已锁仓",_LockStatus="解锁信息不完整")),"违规：锁仓期间禁止加仓",IF(AQ2>C2*D2,"违规：超过单笔风险上限",IF(SUM($AQ$2:$AQ$201)>账户数据!$B$7,"违规：超过账户风险上限","通过")))))))))
C3: =IF(C2="","",C2+SUM(单次交易!Y2:Y201)) | F3: =IF(OR(C3="",D3="",E3="",N3="",C3<=0,D3<=0,E3<=N3),"",ROUNDDOWN((C3*D3)/(E3-N3)/100,0)*100) | G3: =IF(A3="","",IF(H3<>"","已开仓",IF(账户数据!$B$23="已锁仓","禁止开仓：连续亏损达到上限",IF(账户数据!$B$23="解锁信息不完整","禁止开仓：请完整填写解锁信息",IF(OR(F3="",E3="",N3="",E3<=N3,账户数据!$B$7=""),"",IF(OR(AG3="",AH3="",AI3=""),"禁止开仓：交易预期未填写完整",IF(COUNTIFS(持仓跟踪!$A$2:$A$497,"止损计划",持仓跟踪!$B$2:$B$497,A3,持仓跟踪!$AC$2:$AC$497,"计划有效")=0,"禁止开仓：请先填写止损计划",IF(账户数据!$B$9+F3*(E3-N3)>=账户数据!$B$7,"禁止开仓：风险额度不足",IF(AJ3="周期与交易预期不匹配，请重新确认",IF(账户数据!$B$23="接近锁仓","允许开仓（接近锁仓；周期需复核）","允许开仓（周期需复核）"),IF(账户数据!$B$23="接近锁仓","允许开仓（接近锁仓）","允许开仓")))))))))) | L3: =IF(K3="","",H3) | U3: =IF(OR(AO3="",J3="",AO3<=0),"",(J3-AO3)/AO3) | V3: =IF(OR(AO3="",N3="",AO3<=0),"",(AO3-N3)/AO3) | W3: =IF(OR(U3="",V3="",V3<=0),"",U3/V3) | X3: =IF(OR(K3="",L3="",AP3=""),"",K3*L3-(E3*H3+IF(AND(AK3<>"",AL3<>""),AK3*AL3,0)+IF(AND(AM3<>"",AN3<>""),AM3*AN3,0))-IF(O3="",0,O3)-IF(P3="",0,P3)) | Y3: =IF(OR(X3="",AP3=""),"",IF((E3*H3+IF(AND(AK3<>"",AL3<>""),AK3*AL3,0)+IF(AND(AM3<>"",AN3<>""),AM3*AN3,0))+IF(O3="",0,O3)<=0,"",X3/((E3*H3+IF(AND(AK3<>"",AL3<>""),AK3*AL3,0)+IF(AND(AM3<>"",AN3<>""),AM3*AN3,0))+IF(O3="",0,O3)))) | Z3: =IF(OR(AE3="",多次统计数据!$B$8=""),"",AE3-多次统计数据!$B$8) | AA3: =IF(OR(I3="",M3="",M3<I3),"",M3-I3) | AB3: =IF(OR(A3="",多次统计数据!$B$8="",多次统计数据!$B$6<=0,多次统计数据!$B$6>=1),"",1-POWER(1+多次统计数据!$B$8,-多次统计数据!$B$6/(1-多次统计数据!$B$6))) | AC3: =IF(OR(AB3="",多次统计数据!$B$9=""),"",IF(多次统计数据!$B$9<AB3,"低于上限","达到或超过上限")) | AE3: =IF(OR(X3="",C3="",C3<=0),"",X3/C3) | AJ3: =IF(OR(AG3="",AH3=""),"",IF(OR(AND(AG3="短期博反弹",OR(AH3="1～3个交易日",AH3="4～10个交易日")),AND(AG3="突破冲新高",OR(AH3="4～10个交易日",AH3="11～20个交易日")),AND(AG3="趋势波段",OR(AH3="11～20个交易日",AH3="21～60个交易日",AH3="60个交易日以上"))),"匹配","周期与交易预期不匹配，请重新确认")) | AO3: =IF(OR(A3="",H3="",H3<=0),"",(E3*H3+IF(AND(AK3<>"",AL3<>""),AK3*AL3,0)+IF(AND(AM3<>"",AN3<>""),AM3*AN3,0))/AP3) | AP3: =IF(OR(A3="",H3="",H3<=0),"",H3+IF(AL3="",0,AL3)+IF(AN3="",0,AN3)) | AQ3: =IF(A3="","",IF(M3<>"",0,IF(OR(H3="",N3=""),"",MAX(E3-MAX(N3,IFERROR(SUMPRODUCT(MAX(((持仓跟踪!$A$2:$A$497="每日跟踪")*(持仓跟踪!$B$2:$B$497=A3))*持仓跟踪!$S$2:$S$497)),0)),0)*H3+IF(OR(AK3="",AL3=""),0,MAX(AK3-MAX(N3,IFERROR(SUMPRODUCT(MAX(((持仓跟踪!$A$2:$A$497="每日跟踪")*(持仓跟踪!$B$2:$B$497=A3))*持仓跟踪!$S$2:$S$497)),0)),0)*AL3)+IF(OR(AM3="",AN3=""),0,MAX(AM3-MAX(N3,IFERROR(SUMPRODUCT(MAX(((持仓跟踪!$A$2:$A$497="每日跟踪")*(持仓跟踪!$B$2:$B$497=A3))*持仓跟踪!$S$2:$S$497)),0)),0)*AN3)))) | AR3: =IF(A3="","",IF(OR(E3="",H3=""),"违规：第一批价格或股数缺失",IF(OR(AND(AK3="",AL3<>""),AND(AK3<>"",AL3="")),"违规：第二批价格与股数须成对填写",IF(OR(AND(AM3="",AN3<>""),AND(AM3<>"",AN3="")),"违规：第三批价格与股数须成对填写",IF(AND(OR(AM3<>"",AN3<>""),OR(AK3="",AL3="")),"违规：必须先完成第二批",IF(OR(H3<=0,H3<>INT(H3),MOD(H3,100)<>0,AND(AL3<>"",OR(AL3<=0,AL3<>INT(AL3),MOD(AL3,100)<>0)),AND(AN3<>"",OR(AN3<=0,AN3<>INT(AN3),MOD(AN3,100)<>0))),"违规：股数须为100股整数倍",IF(AND(OR(AL3<>"",AN3<>""),OR(_LockStatus="已锁仓",_LockStatus="解锁信息不完整")),"违规：锁仓期间禁止加仓",IF(AQ3>C3*D3,"违规：超过单笔风险上限",IF(SUM($AQ$2:$AQ$201)>账户数据!$B$7,"违规：超过账户风险上限","通过")))))))))
F4: =IF(OR(C4="",D4="",E4="",N4="",C4<=0,D4<=0,E4<=N4),"",ROUNDDOWN((C4*D4)/(E4-N4)/100,0)*100) | G4: =IF(A4="","",IF(H4<>"","已开仓",IF(账户数据!$B$23="已锁仓","禁止开仓：连续亏损达到上限",IF(账户数据!$B$23="解锁信息不完整","禁止开仓：请完整填写解锁信息",IF(OR(F4="",E4="",N4="",E4<=N4,账户数据!$B$7=""),"",IF(OR(AG4="",AH4="",AI4=""),"禁止开仓：交易预期未填写完整",IF(COUNTIFS(持仓跟踪!$A$2:$A$497,"止损计划",持仓跟踪!$B$2:$B$497,A4,持仓跟踪!$AC$2:$AC$497,"计划有效")=0,"禁止开仓：请先填写止损计划",IF(账户数据!$B$9+F4*(E4-N4)>=账户数据!$B$7,"禁止开仓：风险额度不足",IF(AJ4="周期与交易预期不匹配，请重新确认",IF(账户数据!$B$23="接近锁仓","允许开仓（接近锁仓；周期需复核）","允许开仓（周期需复核）"),IF(账户数据!$B$23="接近锁仓","允许开仓（接近锁仓）","允许开仓")))))))))) | L4: =IF(K4="","",H4) | U4: =IF(OR(AO4="",J4="",AO4<=0),"",(J4-AO4)/AO4) | V4: =IF(OR(AO4="",N4="",AO4<=0),"",(AO4-N4)/AO4) | W4: =IF(OR(U4="",V4="",V4<=0),"",U4/V4) | X4: =IF(OR(K4="",L4="",AP4=""),"",K4*L4-(E4*H4+IF(AND(AK4<>"",AL4<>""),AK4*AL4,0)+IF(AND(AM4<>"",AN4<>""),AM4*AN4,0))-IF(O4="",0,O4)-IF(P4="",0,P4)) | Y4: =IF(OR(X4="",AP4=""),"",IF((E4*H4+IF(AND(AK4<>"",AL4<>""),AK4*AL4,0)+IF(AND(AM4<>"",AN4<>""),AM4*AN4,0))+IF(O4="",0,O4)<=0,"",X4/((E4*H4+IF(AND(AK4<>"",AL4<>""),AK4*AL4,0)+IF(AND(AM4<>"",AN4<>""),AM4*AN4,0))+IF(O4="",0,O4)))) | Z4: =IF(OR(AE4="",多次统计数据!$B$8=""),"",AE4-多次统计数据!$B$8) | AA4: =IF(OR(I4="",M4="",M4<I4),"",M4-I4) | AB4: =IF(OR(A4="",多次统计数据!$B$8="",多次统计数据!$B$6<=0,多次统计数据!$B$6>=1),"",1-POWER(1+多次统计数据!$B$8,-多次统计数据!$B$6/(1-多次统计数据!$B$6))) | AC4: =IF(OR(AB4="",多次统计数据!$B$9=""),"",IF(多次统计数据!$B$9<AB4,"低于上限","达到或超过上限")) | AE4: =IF(OR(X4="",C4="",C4<=0),"",X4/C4) | AJ4: =IF(OR(AG4="",AH4=""),"",IF(OR(AND(AG4="短期博反弹",OR(AH4="1～3个交易日",AH4="4～10个交易日")),AND(AG4="突破冲新高",OR(AH4="4～10个交易日",AH4="11～20个交易日")),AND(AG4="趋势波段",OR(AH4="11～20个交易日",AH4="21～60个交易日",AH4="60个交易日以上"))),"匹配","周期与交易预期不匹配，请重新确认")) | AO4: =IF(OR(A4="",H4="",H4<=0),"",(E4*H4+IF(AND(AK4<>"",AL4<>""),AK4*AL4,0)+IF(AND(AM4<>"",AN4<>""),AM4*AN4,0))/AP4) | AP4: =IF(OR(A4="",H4="",H4<=0),"",H4+IF(AL4="",0,AL4)+IF(AN4="",0,AN4)) | AQ4: =IF(A4="","",IF(M4<>"",0,IF(OR(H4="",N4=""),"",MAX(E4-MAX(N4,IFERROR(SUMPRODUCT(MAX(((持仓跟踪!$A$2:$A$497="每日跟踪")*(持仓跟踪!$B$2:$B$497=A4))*持仓跟踪!$S$2:$S$497)),0)),0)*H4+IF(OR(AK4="",AL4=""),0,MAX(AK4-MAX(N4,IFERROR(SUMPRODUCT(MAX(((持仓跟踪!$A$2:$A$497="每日跟踪")*(持仓跟踪!$B$2:$B$497=A4))*持仓跟踪!$S$2:$S$497)),0)),0)*AL4)+IF(OR(AM4="",AN4=""),0,MAX(AM4-MAX(N4,IFERROR(SUMPRODUCT(MAX(((持仓跟踪!$A$2:$A$497="每日跟踪")*(持仓跟踪!$B$2:$B$497=A4))*持仓跟踪!$S$2:$S$497)),0)),0)*AN4)))) | AR4: =IF(A4="","",IF(OR(E4="",H4=""),"违规：第一批价格或股数缺失",IF(OR(AND(AK4="",AL4<>""),AND(AK4<>"",AL4="")),"违规：第二批价格与股数须成对填写",IF(OR(AND(AM4="",AN4<>""),AND(AM4<>"",AN4="")),"违规：第三批价格与股数须成对填写",IF(AND(OR(AM4<>"",AN4<>""),OR(AK4="",AL4="")),"违规：必须先完成第二批",IF(OR(H4<=0,H4<>INT(H4),MOD(H4,100)<>0,AND(AL4<>"",OR(AL4<=0,AL4<>INT(AL4),MOD(AL4,100)<>0)),AND(AN4<>"",OR(AN4<=0,AN4<>INT(AN4),MOD(AN4,100)<>0))),"违规：股数须为100股整数倍",IF(AND(OR(AL4<>"",AN4<>""),OR(_LockStatus="已锁仓",_LockStatus="解锁信息不完整")),"违规：锁仓期间禁止加仓",IF(AQ4>C4*D4,"违规：超过单笔风险上限",IF(SUM($AQ$2:$AQ$201)>账户数据!$B$7,"违规：超过账户风险上限","通过")))))))))
F5: =IF(OR(C5="",D5="",E5="",N5="",C5<=0,D5<=0,E5<=N5),"",ROUNDDOWN((C5*D5)/(E5-N5)/100,0)*100) | G5: =IF(A5="","",IF(H5<>"","已开仓",IF(账户数据!$B$23="已锁仓","禁止开仓：连续亏损达到上限",IF(账户数据!$B$23="解锁信息不完整","禁止开仓：请完整填写解锁信息",IF(OR(F5="",E5="",N5="",E5<=N5,账户数据!$B$7=""),"",IF(OR(AG5="",AH5="",AI5=""),"禁止开仓：交易预期未填写完整",IF(COUNTIFS(持仓跟踪!$A$2:$A$497,"止损计划",持仓跟踪!$B$2:$B$497,A5,持仓跟踪!$AC$2:$AC$497,"计划有效")=0,"禁止开仓：请先填写止损计划",IF(账户数据!$B$9+F5*(E5-N5)>=账户数据!$B$7,"禁止开仓：风险额度不足",IF(AJ5="周期与交易预期不匹配，请重新确认",IF(账户数据!$B$23="接近锁仓","允许开仓（接近锁仓；周期需复核）","允许开仓（周期需复核）"),IF(账户数据!$B$23="接近锁仓","允许开仓（接近锁仓）","允许开仓")))))))))) | L5: =IF(K5="","",H5) | U5: =IF(OR(AO5="",J5="",AO5<=0),"",(J5-AO5)/AO5) | V5: =IF(OR(AO5="",N5="",AO5<=0),"",(AO5-N5)/AO5) | W5: =IF(OR(U5="",V5="",V5<=0),"",U5/V5) | X5: =IF(OR(K5="",L5="",AP5=""),"",K5*L5-(E5*H5+IF(AND(AK5<>"",AL5<>""),AK5*AL5,0)+IF(AND(AM5<>"",AN5<>""),AM5*AN5,0))-IF(O5="",0,O5)-IF(P5="",0,P5)) | Y5: =IF(OR(X5="",AP5=""),"",IF((E5*H5+IF(AND(AK5<>"",AL5<>""),AK5*AL5,0)+IF(AND(AM5<>"",AN5<>""),AM5*AN5,0))+IF(O5="",0,O5)<=0,"",X5/((E5*H5+IF(AND(AK5<>"",AL5<>""),AK5*AL5,0)+IF(AND(AM5<>"",AN5<>""),AM5*AN5,0))+IF(O5="",0,O5)))) | Z5: =IF(OR(AE5="",多次统计数据!$B$8=""),"",AE5-多次统计数据!$B$8) | AA5: =IF(OR(I5="",M5="",M5<I5),"",M5-I5) | AB5: =IF(OR(A5="",多次统计数据!$B$8="",多次统计数据!$B$6<=0,多次统计数据!$B$6>=1),"",1-POWER(1+多次统计数据!$B$8,-多次统计数据!$B$6/(1-多次统计数据!$B$6))) | AC5: =IF(OR(AB5="",多次统计数据!$B$9=""),"",IF(多次统计数据!$B$9<AB5,"低于上限","达到或超过上限")) | AE5: =IF(OR(X5="",C5="",C5<=0),"",X5/C5) | AJ5: =IF(OR(AG5="",AH5=""),"",IF(OR(AND(AG5="短期博反弹",OR(AH5="1～3个交易日",AH5="4～10个交易日")),AND(AG5="突破冲新高",OR(AH5="4～10个交易日",AH5="11～20个交易日")),AND(AG5="趋势波段",OR(AH5="11～20个交易日",AH5="21～60个交易日",AH5="60个交易日以上"))),"匹配","周期与交易预期不匹配，请重新确认")) | AO5: =IF(OR(A5="",H5="",H5<=0),"",(E5*H5+IF(AND(AK5<>"",AL5<>""),AK5*AL5,0)+IF(AND(AM5<>"",AN5<>""),AM5*AN5,0))/AP5) | AP5: =IF(OR(A5="",H5="",H5<=0),"",H5+IF(AL5="",0,AL5)+IF(AN5="",0,AN5)) | AQ5: =IF(A5="","",IF(M5<>"",0,IF(OR(H5="",N5=""),"",MAX(E5-MAX(N5,IFERROR(SUMPRODUCT(MAX(((持仓跟踪!$A$2:$A$497="每日跟踪")*(持仓跟踪!$B$2:$B$497=A5))*持仓跟踪!$S$2:$S$497)),0)),0)*H5+IF(OR(AK5="",AL5=""),0,MAX(AK5-MAX(N5,IFERROR(SUMPRODUCT(MAX(((持仓跟踪!$A$2:$A$497="每日跟踪")*(持仓跟踪!$B$2:$B$497=A5))*持仓跟踪!$S$2:$S$497)),0)),0)*AL5)+IF(OR(AM5="",AN5=""),0,MAX(AM5-MAX(N5,IFERROR(SUMPRODUCT(MAX(((持仓跟踪!$A$2:$A$497="每日跟踪")*(持仓跟踪!$B$2:$B$497=A5))*持仓跟踪!$S$2:$S$497)),0)),0)*AN5)))) | AR5: =IF(A5="","",IF(OR(E5="",H5=""),"违规：第一批价格或股数缺失",IF(OR(AND(AK5="",AL5<>""),AND(AK5<>"",AL5="")),"违规：第二批价格与股数须成对填写",IF(OR(AND(AM5="",AN5<>""),AND(AM5<>"",AN5="")),"违规：第三批价格与股数须成对填写",IF(AND(OR(AM5<>"",AN5<>""),OR(AK5="",AL5="")),"违规：必须先完成第二批",IF(OR(H5<=0,H5<>INT(H5),MOD(H5,100)<>0,AND(AL5<>"",OR(AL5<=0,AL5<>INT(AL5),MOD(AL5,100)<>0)),AND(AN5<>"",OR(AN5<=0,AN5<>INT(AN5),MOD(AN5,100)<>0))),"违规：股数须为100股整数倍",IF(AND(OR(AL5<>"",AN5<>""),OR(_LockStatus="已锁仓",_LockStatus="解锁信息不完整")),"违规：锁仓期间禁止加仓",IF(AQ5>C5*D5,"违规：超过单笔风险上限",IF(SUM($AQ$2:$AQ$201)>账户数据!$B$7,"违规：超过账户风险上限","通过")))))))))
F6: =IF(OR(C6="",D6="",E6="",N6="",C6<=0,D6<=0,E6<=N6),"",ROUNDDOWN((C6*D6)/(E6-N6)/100,0)*100) | G6: =IF(A6="","",IF(H6<>"","已开仓",IF(账户数据!$B$23="已锁仓","禁止开仓：连续亏损达到上限",IF(账户数据!$B$23="解锁信息不完整","禁止开仓：请完整填写解锁信息",IF(OR(F6="",E6="",N6="",E6<=N6,账户数据!$B$7=""),"",IF(OR(AG6="",AH6="",AI6=""),"禁止开仓：交易预期未填写完整",IF(COUNTIFS(持仓跟踪!$A$2:$A$497,"止损计划",持仓跟踪!$B$2:$B$497,A6,持仓跟踪!$AC$2:$AC$497,"计划有效")=0,"禁止开仓：请先填写止损计划",IF(账户数据!$B$9+F6*(E6-N6)>=账户数据!$B$7,"禁止开仓：风险额度不足",IF(AJ6="周期与交易预期不匹配，请重新确认",IF(账户数据!$B$23="接近锁仓","允许开仓（接近锁仓；周期需复核）","允许开仓（周期需复核）"),IF(账户数据!$B$23="接近锁仓","允许开仓（接近锁仓）","允许开仓")))))))))) | L6: =IF(K6="","",H6) | U6: =IF(OR(AO6="",J6="",AO6<=0),"",(J6-AO6)/AO6) | V6: =IF(OR(AO6="",N6="",AO6<=0),"",(AO6-N6)/AO6) | W6: =IF(OR(U6="",V6="",V6<=0),"",U6/V6) | X6: =IF(OR(K6="",L6="",AP6=""),"",K6*L6-(E6*H6+IF(AND(AK6<>"",AL6<>""),AK6*AL6,0)+IF(AND(AM6<>"",AN6<>""),AM6*AN6,0))-IF(O6="",0,O6)-IF(P6="",0,P6)) | Y6: =IF(OR(X6="",AP6=""),"",IF((E6*H6+IF(AND(AK6<>"",AL6<>""),AK6*AL6,0)+IF(AND(AM6<>"",AN6<>""),AM6*AN6,0))+IF(O6="",0,O6)<=0,"",X6/((E6*H6+IF(AND(AK6<>"",AL6<>""),AK6*AL6,0)+IF(AND(AM6<>"",AN6<>""),AM6*AN6,0))+IF(O6="",0,O6)))) | Z6: =IF(OR(AE6="",多次统计数据!$B$8=""),"",AE6-多次统计数据!$B$8) | AA6: =IF(OR(I6="",M6="",M6<I6),"",M6-I6) | AB6: =IF(OR(A6="",多次统计数据!$B$8="",多次统计数据!$B$6<=0,多次统计数据!$B$6>=1),"",1-POWER(1+多次统计数据!$B$8,-多次统计数据!$B$6/(1-多次统计数据!$B$6))) | AC6: =IF(OR(AB6="",多次统计数据!$B$9=""),"",IF(多次统计数据!$B$9<AB6,"低于上限","达到或超过上限")) | AE6: =IF(OR(X6="",C6="",C6<=0),"",X6/C6) | AJ6: =IF(OR(AG6="",AH6=""),"",IF(OR(AND(AG6="短期博反弹",OR(AH6="1～3个交易日",AH6="4～10个交易日")),AND(AG6="突破冲新高",OR(AH6="4～10个交易日",AH6="11～20个交易日")),AND(AG6="趋势波段",OR(AH6="11～20个交易日",AH6="21～60个交易日",AH6="60个交易日以上"))),"匹配","周期与交易预期不匹配，请重新确认")) | AO6: =IF(OR(A6="",H6="",H6<=0),"",(E6*H6+IF(AND(AK6<>"",AL6<>""),AK6*AL6,0)+IF(AND(AM6<>"",AN6<>""),AM6*AN6,0))/AP6) | AP6: =IF(OR(A6="",H6="",H6<=0),"",H6+IF(AL6="",0,AL6)+IF(AN6="",0,AN6)) | AQ6: =IF(A6="","",IF(M6<>"",0,IF(OR(H6="",N6=""),"",MAX(E6-MAX(N6,IFERROR(SUMPRODUCT(MAX(((持仓跟踪!$A$2:$A$497="每日跟踪")*(持仓跟踪!$B$2:$B$497=A6))*持仓跟踪!$S$2:$S$497)),0)),0)*H6+IF(OR(AK6="",AL6=""),0,MAX(AK6-MAX(N6,IFERROR(SUMPRODUCT(MAX(((持仓跟踪!$A$2:$A$497="每日跟踪")*(持仓跟踪!$B$2:$B$497=A6))*持仓跟踪!$S$2:$S$497)),0)),0)*AL6)+IF(OR(AM6="",AN6=""),0,MAX(AM6-MAX(N6,IFERROR(SUMPRODUCT(MAX(((持仓跟踪!$A$2:$A$497="每日跟踪")*(持仓跟踪!$B$2:$B$497=A6))*持仓跟踪!$S$2:$S$497)),0)),0)*AN6)))) | AR6: =IF(A6="","",IF(OR(E6="",H6=""),"违规：第一批价格或股数缺失",IF(OR(AND(AK6="",AL6<>""),AND(AK6<>"",AL6="")),"违规：第二批价格与股数须成对填写",IF(OR(AND(AM6="",AN6<>""),AND(AM6<>"",AN6="")),"违规：第三批价格与股数须成对填写",IF(AND(OR(AM6<>"",AN6<>""),OR(AK6="",AL6="")),"违规：必须先完成第二批",IF(OR(H6<=0,H6<>INT(H6),MOD(H6,100)<>0,AND(AL6<>"",OR(AL6<=0,AL6<>INT(AL6),MOD(AL6,100)<>0)),AND(AN6<>"",OR(AN6<=0,AN6<>INT(AN6),MOD(AN6,100)<>0))),"违规：股数须为100股整数倍",IF(AND(OR(AL6<>"",AN6<>""),OR(_LockStatus="已锁仓",_LockStatus="解锁信息不完整")),"违规：锁仓期间禁止加仓",IF(AQ6>C6*D6,"违规：超过单笔风险上限",IF(SUM($AQ$2:$AQ$201)>账户数据!$B$7,"违规：超过账户风险上限","通过")))))))))
F7: =IF(OR(C7="",D7="",E7="",N7="",C7<=0,D7<=0,E7<=N7),"",ROUNDDOWN((C7*D7)/(E7-N7)/100,0)*100) | G7: =IF(A7="","",IF(H7<>"","已开仓",IF(账户数据!$B$23="已锁仓","禁止开仓：连续亏损达到上限",IF(账户数据!$B$23="解锁信息不完整","禁止开仓：请完整填写解锁信息",IF(OR(F7="",E7="",N7="",E7<=N7,账户数据!$B$7=""),"",IF(OR(AG7="",AH7="",AI7=""),"禁止开仓：交易预期未填写完整",IF(COUNTIFS(持仓跟踪!$A$2:$A$497,"止损计划",持仓跟踪!$B$2:$B$497,A7,持仓跟踪!$AC$2:$AC$497,"计划有效")=0,"禁止开仓：请先填写止损计划",IF(账户数据!$B$9+F7*(E7-N7)>=账户数据!$B$7,"禁止开仓：风险额度不足",IF(AJ7="周期与交易预期不匹配，请重新确认",IF(账户数据!$B$23="接近锁仓","允许开仓（接近锁仓；周期需复核）","允许开仓（周期需复核）"),IF(账户数据!$B$23="接近锁仓","允许开仓（接近锁仓）","允许开仓")))))))))) | L7: =IF(K7="","",H7) | U7: =IF(OR(AO7="",J7="",AO7<=0),"",(J7-AO7)/AO7) | V7: =IF(OR(AO7="",N7="",AO7<=0),"",(AO7-N7)/AO7) | W7: =IF(OR(U7="",V7="",V7<=0),"",U7/V7) | X7: =IF(OR(K7="",L7="",AP7=""),"",K7*L7-(E7*H7+IF(AND(AK7<>"",AL7<>""),AK7*AL7,0)+IF(AND(AM7<>"",AN7<>""),AM7*AN7,0))-IF(O7="",0,O7)-IF(P7="",0,P7)) | Y7: =IF(OR(X7="",AP7=""),"",IF((E7*H7+IF(AND(AK7<>"",AL7<>""),AK7*AL7,0)+IF(AND(AM7<>"",AN7<>""),AM7*AN7,0))+IF(O7="",0,O7)<=0,"",X7/((E7*H7+IF(AND(AK7<>"",AL7<>""),AK7*AL7,0)+IF(AND(AM7<>"",AN7<>""),AM7*AN7,0))+IF(O7="",0,O7)))) | Z7: =IF(OR(AE7="",多次统计数据!$B$8=""),"",AE7-多次统计数据!$B$8) | AA7: =IF(OR(I7="",M7="",M7<I7),"",M7-I7) | AB7: =IF(OR(A7="",多次统计数据!$B$8="",多次统计数据!$B$6<=0,多次统计数据!$B$6>=1),"",1-POWER(1+多次统计数据!$B$8,-多次统计数据!$B$6/(1-多次统计数据!$B$6))) | AC7: =IF(OR(AB7="",多次统计数据!$B$9=""),"",IF(多次统计数据!$B$9<AB7,"低于上限","达到或超过上限")) | AE7: =IF(OR(X7="",C7="",C7<=0),"",X7/C7) | AJ7: =IF(OR(AG7="",AH7=""),"",IF(OR(AND(AG7="短期博反弹",OR(AH7="1～3个交易日",AH7="4～10个交易日")),AND(AG7="突破冲新高",OR(AH7="4～10个交易日",AH7="11～20个交易日")),AND(AG7="趋势波段",OR(AH7="11～20个交易日",AH7="21～60个交易日",AH7="60个交易日以上"))),"匹配","周期与交易预期不匹配，请重新确认")) | AO7: =IF(OR(A7="",H7="",H7<=0),"",(E7*H7+IF(AND(AK7<>"",AL7<>""),AK7*AL7,0)+IF(AND(AM7<>"",AN7<>""),AM7*AN7,0))/AP7) | AP7: =IF(OR(A7="",H7="",H7<=0),"",H7+IF(AL7="",0,AL7)+IF(AN7="",0,AN7)) | AQ7: =IF(A7="","",IF(M7<>"",0,IF(OR(H7="",N7=""),"",MAX(E7-MAX(N7,IFERROR(SUMPRODUCT(MAX(((持仓跟踪!$A$2:$A$497="每日跟踪")*(持仓跟踪!$B$2:$B$497=A7))*持仓跟踪!$S$2:$S$497)),0)),0)*H7+IF(OR(AK7="",AL7=""),0,MAX(AK7-MAX(N7,IFERROR(SUMPRODUCT(MAX(((持仓跟踪!$A$2:$A$497="每日跟踪")*(持仓跟踪!$B$2:$B$497=A7))*持仓跟踪!$S$2:$S$497)),0)),0)*AL7)+IF(OR(AM7="",AN7=""),0,MAX(AM7-MAX(N7,IFERROR(SUMPRODUCT(MAX(((持仓跟踪!$A$2:$A$497="每日跟踪")*(持仓跟踪!$B$2:$B$497=A7))*持仓跟踪!$S$2:$S$497)),0)),0)*AN7)))) | AR7: =IF(A7="","",IF(OR(E7="",H7=""),"违规：第一批价格或股数缺失",IF(OR(AND(AK7="",AL7<>""),AND(AK7<>"",AL7="")),"违规：第二批价格与股数须成对填写",IF(OR(AND(AM7="",AN7<>""),AND(AM7<>"",AN7="")),"违规：第三批价格与股数须成对填写",IF(AND(OR(AM7<>"",AN7<>""),OR(AK7="",AL7="")),"违规：必须先完成第二批",IF(OR(H7<=0,H7<>INT(H7),MOD(H7,100)<>0,AND(AL7<>"",OR(AL7<=0,AL7<>INT(AL7),MOD(AL7,100)<>0)),AND(AN7<>"",OR(AN7<=0,AN7<>INT(AN7),MOD(AN7,100)<>0))),"违规：股数须为100股整数倍",IF(AND(OR(AL7<>"",AN7<>""),OR(_LockStatus="已锁仓",_LockStatus="解锁信息不完整")),"违规：锁仓期间禁止加仓",IF(AQ7>C7*D7,"违规：超过单笔风险上限",IF(SUM($AQ$2:$AQ$201)>账户数据!$B$7,"违规：超过账户风险上限","通过")))))))))
F8: =IF(OR(C8="",D8="",E8="",N8="",C8<=0,D8<=0,E8<=N8),"",ROUNDDOWN((C8*D8)/(E8-N8)/100,0)*100) | G8: =IF(A8="","",IF(H8<>"","已开仓",IF(账户数据!$B$23="已锁仓","禁止开仓：连续亏损达到上限",IF(账户数据!$B$23="解锁信息不完整","禁止开仓：请完整填写解锁信息",IF(OR(F8="",E8="",N8="",E8<=N8,账户数据!$B$7=""),"",IF(OR(AG8="",AH8="",AI8=""),"禁止开仓：交易预期未填写完整",IF(COUNTIFS(持仓跟踪!$A$2:$A$497,"止损计划",持仓跟踪!$B$2:$B$497,A8,持仓跟踪!$AC$2:$AC$497,"计划有效")=0,"禁止开仓：请先填写止损计划",IF(账户数据!$B$9+F8*(E8-N8)>=账户数据!$B$7,"禁止开仓：风险额度不足",IF(AJ8="周期与交易预期不匹配，请重新确认",IF(账户数据!$B$23="接近锁仓","允许开仓（接近锁仓；周期需复核）","允许开仓（周期需复核）"),IF(账户数据!$B$23="接近锁仓","允许开仓（接近锁仓）","允许开仓")))))))))) | L8: =IF(K8="","",H8) | U8: =IF(OR(AO8="",J8="",AO8<=0),"",(J8-AO8)/AO8) | V8: =IF(OR(AO8="",N8="",AO8<=0),"",(AO8-N8)/AO8) | W8: =IF(OR(U8="",V8="",V8<=0),"",U8/V8) | X8: =IF(OR(K8="",L8="",AP8=""),"",K8*L8-(E8*H8+IF(AND(AK8<>"",AL8<>""),AK8*AL8,0)+IF(AND(AM8<>"",AN8<>""),AM8*AN8,0))-IF(O8="",0,O8)-IF(P8="",0,P8)) | Y8: =IF(OR(X8="",AP8=""),"",IF((E8*H8+IF(AND(AK8<>"",AL8<>""),AK8*AL8,0)+IF(AND(AM8<>"",AN8<>""),AM8*AN8,0))+IF(O8="",0,O8)<=0,"",X8/((E8*H8+IF(AND(AK8<>"",AL8<>""),AK8*AL8,0)+IF(AND(AM8<>"",AN8<>""),AM8*AN8,0))+IF(O8="",0,O8)))) | Z8: =IF(OR(AE8="",多次统计数据!$B$8=""),"",AE8-多次统计数据!$B$8) | AA8: =IF(OR(I8="",M8="",M8<I8),"",M8-I8) | AB8: =IF(OR(A8="",多次统计数据!$B$8="",多次统计数据!$B$6<=0,多次统计数据!$B$6>=1),"",1-POWER(1+多次统计数据!$B$8,-多次统计数据!$B$6/(1-多次统计数据!$B$6))) | AC8: =IF(OR(AB8="",多次统计数据!$B$9=""),"",IF(多次统计数据!$B$9<AB8,"低于上限","达到或超过上限")) | AE8: =IF(OR(X8="",C8="",C8<=0),"",X8/C8) | AJ8: =IF(OR(AG8="",AH8=""),"",IF(OR(AND(AG8="短期博反弹",OR(AH8="1～3个交易日",AH8="4～10个交易日")),AND(AG8="突破冲新高",OR(AH8="4～10个交易日",AH8="11～20个交易日")),AND(AG8="趋势波段",OR(AH8="11～20个交易日",AH8="21～60个交易日",AH8="60个交易日以上"))),"匹配","周期与交易预期不匹配，请重新确认")) | AO8: =IF(OR(A8="",H8="",H8<=0),"",(E8*H8+IF(AND(AK8<>"",AL8<>""),AK8*AL8,0)+IF(AND(AM8<>"",AN8<>""),AM8*AN8,0))/AP8) | AP8: =IF(OR(A8="",H8="",H8<=0),"",H8+IF(AL8="",0,AL8)+IF(AN8="",0,AN8)) | AQ8: =IF(A8="","",IF(M8<>"",0,IF(OR(H8="",N8=""),"",MAX(E8-MAX(N8,IFERROR(SUMPRODUCT(MAX(((持仓跟踪!$A$2:$A$497="每日跟踪")*(持仓跟踪!$B$2:$B$497=A8))*持仓跟踪!$S$2:$S$497)),0)),0)*H8+IF(OR(AK8="",AL8=""),0,MAX(AK8-MAX(N8,IFERROR(SUMPRODUCT(MAX(((持仓跟踪!$A$2:$A$497="每日跟踪")*(持仓跟踪!$B$2:$B$497=A8))*持仓跟踪!$S$2:$S$497)),0)),0)*AL8)+IF(OR(AM8="",AN8=""),0,MAX(AM8-MAX(N8,IFERROR(SUMPRODUCT(MAX(((持仓跟踪!$A$2:$A$497="每日跟踪")*(持仓跟踪!$B$2:$B$497=A8))*持仓跟踪!$S$2:$S$497)),0)),0)*AN8)))) | AR8: =IF(A8="","",IF(OR(E8="",H8=""),"违规：第一批价格或股数缺失",IF(OR(AND(AK8="",AL8<>""),AND(AK8<>"",AL8="")),"违规：第二批价格与股数须成对填写",IF(OR(AND(AM8="",AN8<>""),AND(AM8<>"",AN8="")),"违规：第三批价格与股数须成对填写",IF(AND(OR(AM8<>"",AN8<>""),OR(AK8="",AL8="")),"违规：必须先完成第二批",IF(OR(H8<=0,H8<>INT(H8),MOD(H8,100)<>0,AND(AL8<>"",OR(AL8<=0,AL8<>INT(AL8),MOD(AL8,100)<>0)),AND(AN8<>"",OR(AN8<=0,AN8<>INT(AN8),MOD(AN8,100)<>0))),"违规：股数须为100股整数倍",IF(AND(OR(AL8<>"",AN8<>""),OR(_LockStatus="已锁仓",_LockStatus="解锁信息不完整")),"违规：锁仓期间禁止加仓",IF(AQ8>C8*D8,"违规：超过单笔风险上限",IF(SUM($AQ$2:$AQ$201)>账户数据!$B$7,"违规：超过账户风险上限","通过")))))))))
F9: =IF(OR(C9="",D9="",E9="",N9="",C9<=0,D9<=0,E9<=N9),"",ROUNDDOWN((C9*D9)/(E9-N9)/100,0)*100) | G9: =IF(A9="","",IF(H9<>"","已开仓",IF(账户数据!$B$23="已锁仓","禁止开仓：连续亏损达到上限",IF(账户数据!$B$23="解锁信息不完整","禁止开仓：请完整填写解锁信息",IF(OR(F9="",E9="",N9="",E9<=N9,账户数据!$B$7=""),"",IF(OR(AG9="",AH9="",AI9=""),"禁止开仓：交易预期未填写完整",IF(COUNTIFS(持仓跟踪!$A$2:$A$497,"止损计划",持仓跟踪!$B$2:$B$497,A9,持仓跟踪!$AC$2:$AC$497,"计划有效")=0,"禁止开仓：请先填写止损计划",IF(账户数据!$B$9+F9*(E9-N9)>=账户数据!$B$7,"禁止开仓：风险额度不足",IF(AJ9="周期与交易预期不匹配，请重新确认",IF(账户数据!$B$23="接近锁仓","允许开仓（接近锁仓；周期需复核）","允许开仓（周期需复核）"),IF(账户数据!$B$23="接近锁仓","允许开仓（接近锁仓）","允许开仓")))))))))) | L9: =IF(K9="","",H9) | U9: =IF(OR(AO9="",J9="",AO9<=0),"",(J9-AO9)/AO9) | V9: =IF(OR(AO9="",N9="",AO9<=0),"",(AO9-N9)/AO9) | W9: =IF(OR(U9="",V9="",V9<=0),"",U9/V9) | X9: =IF(OR(K9="",L9="",AP9=""),"",K9*L9-(E9*H9+IF(AND(AK9<>"",AL9<>""),AK9*AL9,0)+IF(AND(AM9<>"",AN9<>""),AM9*AN9,0))-IF(O9="",0,O9)-IF(P9="",0,P9)) | Y9: =IF(OR(X9="",AP9=""),"",IF((E9*H9+IF(AND(AK9<>"",AL9<>""),AK9*AL9,0)+IF(AND(AM9<>"",AN9<>""),AM9*AN9,0))+IF(O9="",0,O9)<=0,"",X9/((E9*H9+IF(AND(AK9<>"",AL9<>""),AK9*AL9,0)+IF(AND(AM9<>"",AN9<>""),AM9*AN9,0))+IF(O9="",0,O9)))) | Z9: =IF(OR(AE9="",多次统计数据!$B$8=""),"",AE9-多次统计数据!$B$8) | AA9: =IF(OR(I9="",M9="",M9<I9),"",M9-I9) | AB9: =IF(OR(A9="",多次统计数据!$B$8="",多次统计数据!$B$6<=0,多次统计数据!$B$6>=1),"",1-POWER(1+多次统计数据!$B$8,-多次统计数据!$B$6/(1-多次统计数据!$B$6))) | AC9: =IF(OR(AB9="",多次统计数据!$B$9=""),"",IF(多次统计数据!$B$9<AB9,"低于上限","达到或超过上限")) | AE9: =IF(OR(X9="",C9="",C9<=0),"",X9/C9) | AJ9: =IF(OR(AG9="",AH9=""),"",IF(OR(AND(AG9="短期博反弹",OR(AH9="1～3个交易日",AH9="4～10个交易日")),AND(AG9="突破冲新高",OR(AH9="4～10个交易日",AH9="11～20个交易日")),AND(AG9="趋势波段",OR(AH9="11～20个交易日",AH9="21～60个交易日",AH9="60个交易日以上"))),"匹配","周期与交易预期不匹配，请重新确认")) | AO9: =IF(OR(A9="",H9="",H9<=0),"",(E9*H9+IF(AND(AK9<>"",AL9<>""),AK9*AL9,0)+IF(AND(AM9<>"",AN9<>""),AM9*AN9,0))/AP9) | AP9: =IF(OR(A9="",H9="",H9<=0),"",H9+IF(AL9="",0,AL9)+IF(AN9="",0,AN9)) | AQ9: =IF(A9="","",IF(M9<>"",0,IF(OR(H9="",N9=""),"",MAX(E9-MAX(N9,IFERROR(SUMPRODUCT(MAX(((持仓跟踪!$A$2:$A$497="每日跟踪")*(持仓跟踪!$B$2:$B$497=A9))*持仓跟踪!$S$2:$S$497)),0)),0)*H9+IF(OR(AK9="",AL9=""),0,MAX(AK9-MAX(N9,IFERROR(SUMPRODUCT(MAX(((持仓跟踪!$A$2:$A$497="每日跟踪")*(持仓跟踪!$B$2:$B$497=A9))*持仓跟踪!$S$2:$S$497)),0)),0)*AL9)+IF(OR(AM9="",AN9=""),0,MAX(AM9-MAX(N9,IFERROR(SUMPRODUCT(MAX(((持仓跟踪!$A$2:$A$497="每日跟踪")*(持仓跟踪!$B$2:$B$497=A9))*持仓跟踪!$S$2:$S$497)),0)),0)*AN9)))) | AR9: =IF(A9="","",IF(OR(E9="",H9=""),"违规：第一批价格或股数缺失",IF(OR(AND(AK9="",AL9<>""),AND(AK9<>"",AL9="")),"违规：第二批价格与股数须成对填写",IF(OR(AND(AM9="",AN9<>""),AND(AM9<>"",AN9="")),"违规：第三批价格与股数须成对填写",IF(AND(OR(AM9<>"",AN9<>""),OR(AK9="",AL9="")),"违规：必须先完成第二批",IF(OR(H9<=0,H9<>INT(H9),MOD(H9,100)<>0,AND(AL9<>"",OR(AL9<=0,AL9<>INT(AL9),MOD(AL9,100)<>0)),AND(AN9<>"",OR(AN9<=0,AN9<>INT(AN9),MOD(AN9,100)<>0))),"违规：股数须为100股整数倍",IF(AND(OR(AL9<>"",AN9<>""),OR(_LockStatus="已锁仓",_LockStatus="解锁信息不完整")),"违规：锁仓期间禁止加仓",IF(AQ9>C9*D9,"违规：超过单笔风险上限",IF(SUM($AQ$2:$AQ$201)>账户数据!$B$7,"违规：超过账户风险上限","通过")))))))))
F10: =IF(OR(C10="",D10="",E10="",N10="",C10<=0,D10<=0,E10<=N10),"",ROUNDDOWN((C10*D10)/(E10-N10)/100,0)*100) | G10: =IF(A10="","",IF(H10<>"","已开仓",IF(账户数据!$B$23="已锁仓","禁止开仓：连续亏损达到上限",IF(账户数据!$B$23="解锁信息不完整","禁止开仓：请完整填写解锁信息",IF(OR(F10="",E10="",N10="",E10<=N10,账户数据!$B$7=""),"",IF(OR(AG10="",AH10="",AI10=""),"禁止开仓：交易预期未填写完整",IF(COUNTIFS(持仓跟踪!$A$2:$A$497,"止损计划",持仓跟踪!$B$2:$B$497,A10,持仓跟踪!$AC$2:$AC$497,"计划有效")=0,"禁止开仓：请先填写止损计划",IF(账户数据!$B$9+F10*(E10-N10)>=账户数据!$B$7,"禁止开仓：风险额度不足",IF(AJ10="周期与交易预期不匹配，请重新确认",IF(账户数据!$B$23="接近锁仓","允许开仓（接近锁仓；周期需复核）","允许开仓（周期需复核）"),IF(账户数据!$B$23="接近锁仓","允许开仓（接近锁仓）","允许开仓")))))))))) | L10: =IF(K10="","",H10) | U10: =IF(OR(AO10="",J10="",AO10<=0),"",(J10-AO10)/AO10) | V10: =IF(OR(AO10="",N10="",AO10<=0),"",(AO10-N10)/AO10) | W10: =IF(OR(U10="",V10="",V10<=0),"",U10/V10) | X10: =IF(OR(K10="",L10="",AP10=""),"",K10*L10-(E10*H10+IF(AND(AK10<>"",AL10<>""),AK10*AL10,0)+IF(AND(AM10<>"",AN10<>""),AM10*AN10,0))-IF(O10="",0,O10)-IF(P10="",0,P10)) | Y10: =IF(OR(X10="",AP10=""),"",IF((E10*H10+IF(AND(AK10<>"",AL10<>""),AK10*AL10,0)+IF(AND(AM10<>"",AN10<>""),AM10*AN10,0))+IF(O10="",0,O10)<=0,"",X10/((E10*H10+IF(AND(AK10<>"",AL10<>""),AK10*AL10,0)+IF(AND(AM10<>"",AN10<>""),AM10*AN10,0))+IF(O10="",0,O10)))) | Z10: =IF(OR(AE10="",多次统计数据!$B$8=""),"",AE10-多次统计数据!$B$8) | AA10: =IF(OR(I10="",M10="",M10<I10),"",M10-I10) | AB10: =IF(OR(A10="",多次统计数据!$B$8="",多次统计数据!$B$6<=0,多次统计数据!$B$6>=1),"",1-POWER(1+多次统计数据!$B$8,-多次统计数据!$B$6/(1-多次统计数据!$B$6))) | AC10: =IF(OR(AB10="",多次统计数据!$B$9=""),"",IF(多次统计数据!$B$9<AB10,"低于上限","达到或超过上限")) | AE10: =IF(OR(X10="",C10="",C10<=0),"",X10/C10) | AJ10: =IF(OR(AG10="",AH10=""),"",IF(OR(AND(AG10="短期博反弹",OR(AH10="1～3个交易日",AH10="4～10个交易日")),AND(AG10="突破冲新高",OR(AH10="4～10个交易日",AH10="11～20个交易日")),AND(AG10="趋势波段",OR(AH10="11～20个交易日",AH10="21～60个交易日",AH10="60个交易日以上"))),"匹配","周期与交易预期不匹配，请重新确认")) | AO10: =IF(OR(A10="",H10="",H10<=0),"",(E10*H10+IF(AND(AK10<>"",AL10<>""),AK10*AL10,0)+IF(AND(AM10<>"",AN10<>""),AM10*AN10,0))/AP10) | AP10: =IF(OR(A10="",H10="",H10<=0),"",H10+IF(AL10="",0,AL10)+IF(AN10="",0,AN10)) | AQ10: =IF(A10="","",IF(M10<>"",0,IF(OR(H10="",N10=""),"",MAX(E10-MAX(N10,IFERROR(SUMPRODUCT(MAX(((持仓跟踪!$A$2:$A$497="每日跟踪")*(持仓跟踪!$B$2:$B$497=A10))*持仓跟踪!$S$2:$S$497)),0)),0)*H10+IF(OR(AK10="",AL10=""),0,MAX(AK10-MAX(N10,IFERROR(SUMPRODUCT(MAX(((持仓跟踪!$A$2:$A$497="每日跟踪")*(持仓跟踪!$B$2:$B$497=A10))*持仓跟踪!$S$2:$S$497)),0)),0)*AL10)+IF(OR(AM10="",AN10=""),0,MAX(AM10-MAX(N10,IFERROR(SUMPRODUCT(MAX(((持仓跟踪!$A$2:$A$497="每日跟踪")*(持仓跟踪!$B$2:$B$497=A10))*持仓跟踪!$S$2:$S$497)),0)),0)*AN10)))) | AR10: =IF(A10="","",IF(OR(E10="",H10=""),"违规：第一批价格或股数缺失",IF(OR(AND(AK10="",AL10<>""),AND(AK10<>"",AL10="")),"违规：第二批价格与股数须成对填写",IF(OR(AND(AM10="",AN10<>""),AND(AM10<>"",AN10="")),"违规：第三批价格与股数须成对填写",IF(AND(OR(AM10<>"",AN10<>""),OR(AK10="",AL10="")),"违规：必须先完成第二批",IF(OR(H10<=0,H10<>INT(H10),MOD(H10,100)<>0,AND(AL10<>"",OR(AL10<=0,AL10<>INT(AL10),MOD(AL10,100)<>0)),AND(AN10<>"",OR(AN10<=0,AN10<>INT(AN10),MOD(AN10,100)<>0))),"违规：股数须为100股整数倍",IF(AND(OR(AL10<>"",AN10<>""),OR(_LockStatus="已锁仓",_LockStatus="解锁信息不完整")),"违规：锁仓期间禁止加仓",IF(AQ10>C10*D10,"违规：超过单笔风险上限",IF(SUM($AQ$2:$AQ$201)>账户数据!$B$7,"违规：超过账户风险上限","通过")))))))))
F11: =IF(OR(C11="",D11="",E11="",N11="",C11<=0,D11<=0,E11<=N11),"",ROUNDDOWN((C11*D11)/(E11-N11)/100,0)*100) | G11: =IF(A11="","",IF(H11<>"","已开仓",IF(账户数据!$B$23="已锁仓","禁止开仓：连续亏损达到上限",IF(账户数据!$B$23="解锁信息不完整","禁止开仓：请完整填写解锁信息",IF(OR(F11="",E11="",N11="",E11<=N11,账户数据!$B$7=""),"",IF(OR(AG11="",AH11="",AI11=""),"禁止开仓：交易预期未填写完整",IF(COUNTIFS(持仓跟踪!$A$2:$A$497,"止损计划",持仓跟踪!$B$2:$B$497,A11,持仓跟踪!$AC$2:$AC$497,"计划有效")=0,"禁止开仓：请先填写止损计划",IF(账户数据!$B$9+F11*(E11-N11)>=账户数据!$B$7,"禁止开仓：风险额度不足",IF(AJ11="周期与交易预期不匹配，请重新确认",IF(账户数据!$B$23="接近锁仓","允许开仓（接近锁仓；周期需复核）","允许开仓（周期需复核）"),IF(账户数据!$B$23="接近锁仓","允许开仓（接近锁仓）","允许开仓")))))))))) | L11: =IF(K11="","",H11) | U11: =IF(OR(AO11="",J11="",AO11<=0),"",(J11-AO11)/AO11) | V11: =IF(OR(AO11="",N11="",AO11<=0),"",(AO11-N11)/AO11) | W11: =IF(OR(U11="",V11="",V11<=0),"",U11/V11) | X11: =IF(OR(K11="",L11="",AP11=""),"",K11*L11-(E11*H11+IF(AND(AK11<>"",AL11<>""),AK11*AL11,0)+IF(AND(AM11<>"",AN11<>""),AM11*AN11,0))-IF(O11="",0,O11)-IF(P11="",0,P11)) | Y11: =IF(OR(X11="",AP11=""),"",IF((E11*H11+IF(AND(AK11<>"",AL11<>""),AK11*AL11,0)+IF(AND(AM11<>"",AN11<>""),AM11*AN11,0))+IF(O11="",0,O11)<=0,"",X11/((E11*H11+IF(AND(AK11<>"",AL11<>""),AK11*AL11,0)+IF(AND(AM11<>"",AN11<>""),AM11*AN11,0))+IF(O11="",0,O11)))) | Z11: =IF(OR(AE11="",多次统计数据!$B$8=""),"",AE11-多次统计数据!$B$8) | AA11: =IF(OR(I11="",M11="",M11<I11),"",M11-I11) | AB11: =IF(OR(A11="",多次统计数据!$B$8="",多次统计数据!$B$6<=0,多次统计数据!$B$6>=1),"",1-POWER(1+多次统计数据!$B$8,-多次统计数据!$B$6/(1-多次统计数据!$B$6))) | AC11: =IF(OR(AB11="",多次统计数据!$B$9=""),"",IF(多次统计数据!$B$9<AB11,"低于上限","达到或超过上限")) | AE11: =IF(OR(X11="",C11="",C11<=0),"",X11/C11) | AJ11: =IF(OR(AG11="",AH11=""),"",IF(OR(AND(AG11="短期博反弹",OR(AH11="1～3个交易日",AH11="4～10个交易日")),AND(AG11="突破冲新高",OR(AH11="4～10个交易日",AH11="11～20个交易日")),AND(AG11="趋势波段",OR(AH11="11～20个交易日",AH11="21～60个交易日",AH11="60个交易日以上"))),"匹配","周期与交易预期不匹配，请重新确认")) | AO11: =IF(OR(A11="",H11="",H11<=0),"",(E11*H11+IF(AND(AK11<>"",AL11<>""),AK11*AL11,0)+IF(AND(AM11<>"",AN11<>""),AM11*AN11,0))/AP11) | AP11: =IF(OR(A11="",H11="",H11<=0),"",H11+IF(AL11="",0,AL11)+IF(AN11="",0,AN11)) | AQ11: =IF(A11="","",IF(M11<>"",0,IF(OR(H11="",N11=""),"",MAX(E11-MAX(N11,IFERROR(SUMPRODUCT(MAX(((持仓跟踪!$A$2:$A$497="每日跟踪")*(持仓跟踪!$B$2:$B$497=A11))*持仓跟踪!$S$2:$S$497)),0)),0)*H11+IF(OR(AK11="",AL11=""),0,MAX(AK11-MAX(N11,IFERROR(SUMPRODUCT(MAX(((持仓跟踪!$A$2:$A$497="每日跟踪")*(持仓跟踪!$B$2:$B$497=A11))*持仓跟踪!$S$2:$S$497)),0)),0)*AL11)+IF(OR(AM11="",AN11=""),0,MAX(AM11-MAX(N11,IFERROR(SUMPRODUCT(MAX(((持仓跟踪!$A$2:$A$497="每日跟踪")*(持仓跟踪!$B$2:$B$497=A11))*持仓跟踪!$S$2:$S$497)),0)),0)*AN11)))) | AR11: =IF(A11="","",IF(OR(E11="",H11=""),"违规：第一批价格或股数缺失",IF(OR(AND(AK11="",AL11<>""),AND(AK11<>"",AL11="")),"违规：第二批价格与股数须成对填写",IF(OR(AND(AM11="",AN11<>""),AND(AM11<>"",AN11="")),"违规：第三批价格与股数须成对填写",IF(AND(OR(AM11<>"",AN11<>""),OR(AK11="",AL11="")),"违规：必须先完成第二批",IF(OR(H11<=0,H11<>INT(H11),MOD(H11,100)<>0,AND(AL11<>"",OR(AL11<=0,AL11<>INT(AL11),MOD(AL11,100)<>0)),AND(AN11<>"",OR(AN11<=0,AN11<>INT(AN11),MOD(AN11,100)<>0))),"违规：股数须为100股整数倍",IF(AND(OR(AL11<>"",AN11<>""),OR(_LockStatus="已锁仓",_LockStatus="解锁信息不完整")),"违规：锁仓期间禁止加仓",IF(AQ11>C11*D11,"违规：超过单笔风险上限",IF(SUM($AQ$2:$AQ$201)>账户数据!$B$7,"违规：超过账户风险上限","通过")))))))))
F12: =IF(OR(C12="",D12="",E12="",N12="",C12<=0,D12<=0,E12<=N12),"",ROUNDDOWN((C12*D12)/(E12-N12)/100,0)*100) | G12: =IF(A12="","",IF(H12<>"","已开仓",IF(账户数据!$B$23="已锁仓","禁止开仓：连续亏损达到上限",IF(账户数据!$B$23="解锁信息不完整","禁止开仓：请完整填写解锁信息",IF(OR(F12="",E12="",N12="",E12<=N12,账户数据!$B$7=""),"",IF(OR(AG12="",AH12="",AI12=""),"禁止开仓：交易预期未填写完整",IF(COUNTIFS(持仓跟踪!$A$2:$A$497,"止损计划",持仓跟踪!$B$2:$B$497,A12,持仓跟踪!$AC$2:$AC$497,"计划有效")=0,"禁止开仓：请先填写止损计划",IF(账户数据!$B$9+F12*(E12-N12)>=账户数据!$B$7,"禁止开仓：风险额度不足",IF(AJ12="周期与交易预期不匹配，请重新确认",IF(账户数据!$B$23="接近锁仓","允许开仓（接近锁仓；周期需复核）","允许开仓（周期需复核）"),IF(账户数据!$B$23="接近锁仓","允许开仓（接近锁仓）","允许开仓")))))))))) | L12: =IF(K12="","",H12) | U12: =IF(OR(AO12="",J12="",AO12<=0),"",(J12-AO12)/AO12) | V12: =IF(OR(AO12="",N12="",AO12<=0),"",(AO12-N12)/AO12) | W12: =IF(OR(U12="",V12="",V12<=0),"",U12/V12) | X12: =IF(OR(K12="",L12="",AP12=""),"",K12*L12-(E12*H12+IF(AND(AK12<>"",AL12<>""),AK12*AL12,0)+IF(AND(AM12<>"",AN12<>""),AM12*AN12,0))-IF(O12="",0,O12)-IF(P12="",0,P12)) | Y12: =IF(OR(X12="",AP12=""),"",IF((E12*H12+IF(AND(AK12<>"",AL12<>""),AK12*AL12,0)+IF(AND(AM12<>"",AN12<>""),AM12*AN12,0))+IF(O12="",0,O12)<=0,"",X12/((E12*H12+IF(AND(AK12<>"",AL12<>""),AK12*AL12,0)+IF(AND(AM12<>"",AN12<>""),AM12*AN12,0))+IF(O12="",0,O12)))) | Z12: =IF(OR(AE12="",多次统计数据!$B$8=""),"",AE12-多次统计数据!$B$8) | AA12: =IF(OR(I12="",M12="",M12<I12),"",M12-I12) | AB12: =IF(OR(A12="",多次统计数据!$B$8="",多次统计数据!$B$6<=0,多次统计数据!$B$6>=1),"",1-POWER(1+多次统计数据!$B$8,-多次统计数据!$B$6/(1-多次统计数据!$B$6))) | AC12: =IF(OR(AB12="",多次统计数据!$B$9=""),"",IF(多次统计数据!$B$9<AB12,"低于上限","达到或超过上限")) | AE12: =IF(OR(X12="",C12="",C12<=0),"",X12/C12) | AJ12: =IF(OR(AG12="",AH12=""),"",IF(OR(AND(AG12="短期博反弹",OR(AH12="1～3个交易日",AH12="4～10个交易日")),AND(AG12="突破冲新高",OR(AH12="4～10个交易日",AH12="11～20个交易日")),AND(AG12="趋势波段",OR(AH12="11～20个交易日",AH12="21～60个交易日",AH12="60个交易日以上"))),"匹配","周期与交易预期不匹配，请重新确认")) | AO12: =IF(OR(A12="",H12="",H12<=0),"",(E12*H12+IF(AND(AK12<>"",AL12<>""),AK12*AL12,0)+IF(AND(AM12<>"",AN12<>""),AM12*AN12,0))/AP12) | AP12: =IF(OR(A12="",H12="",H12<=0),"",H12+IF(AL12="",0,AL12)+IF(AN12="",0,AN12)) | AQ12: =IF(A12="","",IF(M12<>"",0,IF(OR(H12="",N12=""),"",MAX(E12-MAX(N12,IFERROR(SUMPRODUCT(MAX(((持仓跟踪!$A$2:$A$497="每日跟踪")*(持仓跟踪!$B$2:$B$497=A12))*持仓跟踪!$S$2:$S$497)),0)),0)*H12+IF(OR(AK12="",AL12=""),0,MAX(AK12-MAX(N12,IFERROR(SUMPRODUCT(MAX(((持仓跟踪!$A$2:$A$497="每日跟踪")*(持仓跟踪!$B$2:$B$497=A12))*持仓跟踪!$S$2:$S$497)),0)),0)*AL12)+IF(OR(AM12="",AN12=""),0,MAX(AM12-MAX(N12,IFERROR(SUMPRODUCT(MAX(((持仓跟踪!$A$2:$A$497="每日跟踪")*(持仓跟踪!$B$2:$B$497=A12))*持仓跟踪!$S$2:$S$497)),0)),0)*AN12)))) | AR12: =IF(A12="","",IF(OR(E12="",H12=""),"违规：第一批价格或股数缺失",IF(OR(AND(AK12="",AL12<>""),AND(AK12<>"",AL12="")),"违规：第二批价格与股数须成对填写",IF(OR(AND(AM12="",AN12<>""),AND(AM12<>"",AN12="")),"违规：第三批价格与股数须成对填写",IF(AND(OR(AM12<>"",AN12<>""),OR(AK12="",AL12="")),"违规：必须先完成第二批",IF(OR(H12<=0,H12<>INT(H12),MOD(H12,100)<>0,AND(AL12<>"",OR(AL12<=0,AL12<>INT(AL12),MOD(AL12,100)<>0)),AND(AN12<>"",OR(AN12<=0,AN12<>INT(AN12),MOD(AN12,100)<>0))),"违规：股数须为100股整数倍",IF(AND(OR(AL12<>"",AN12<>""),OR(_LockStatus="已锁仓",_LockStatus="解锁信息不完整")),"违规：锁仓期间禁止加仓",IF(AQ12>C12*D12,"违规：超过单笔风险上限",IF(SUM($AQ$2:$AQ$201)>账户数据!$B$7,"违规：超过账户风险上限","通过")))))))))
F13: =IF(OR(C13="",D13="",E13="",N13="",C13<=0,D13<=0,E13<=N13),"",ROUNDDOWN((C13*D13)/(E13-N13)/100,0)*100) | G13: =IF(A13="","",IF(H13<>"","已开仓",IF(账户数据!$B$23="已锁仓","禁止开仓：连续亏损达到上限",IF(账户数据!$B$23="解锁信息不完整","禁止开仓：请完整填写解锁信息",IF(OR(F13="",E13="",N13="",E13<=N13,账户数据!$B$7=""),"",IF(OR(AG13="",AH13="",AI13=""),"禁止开仓：交易预期未填写完整",IF(COUNTIFS(持仓跟踪!$A$2:$A$497,"止损计划",持仓跟踪!$B$2:$B$497,A13,持仓跟踪!$AC$2:$AC$497,"计划有效")=0,"禁止开仓：请先填写止损计划",IF(账户数据!$B$9+F13*(E13-N13)>=账户数据!$B$7,"禁止开仓：风险额度不足",IF(AJ13="周期与交易预期不匹配，请重新确认",IF(账户数据!$B$23="接近锁仓","允许开仓（接近锁仓；周期需复核）","允许开仓（周期需复核）"),IF(账户数据!$B$23="接近锁仓","允许开仓（接近锁仓）","允许开仓")))))))))) | L13: =IF(K13="","",H13) | U13: =IF(OR(AO13="",J13="",AO13<=0),"",(J13-AO13)/AO13) | V13: =IF(OR(AO13="",N13="",AO13<=0),"",(AO13-N13)/AO13) | W13: =IF(OR(U13="",V13="",V13<=0),"",U13/V13) | X13: =IF(OR(K13="",L13="",AP13=""),"",K13*L13-(E13*H13+IF(AND(AK13<>"",AL13<>""),AK13*AL13,0)+IF(AND(AM13<>"",AN13<>""),AM13*AN13,0))-IF(O13="",0,O13)-IF(P13="",0,P13)) | Y13: =IF(OR(X13="",AP13=""),"",IF((E13*H13+IF(AND(AK13<>"",AL13<>""),AK13*AL13,0)+IF(AND(AM13<>"",AN13<>""),AM13*AN13,0))+IF(O13="",0,O13)<=0,"",X13/((E13*H13+IF(AND(AK13<>"",AL13<>""),AK13*AL13,0)+IF(AND(AM13<>"",AN13<>""),AM13*AN13,0))+IF(O13="",0,O13)))) | Z13: =IF(OR(AE13="",多次统计数据!$B$8=""),"",AE13-多次统计数据!$B$8) | AA13: =IF(OR(I13="",M13="",M13<I13),"",M13-I13) | AB13: =IF(OR(A13="",多次统计数据!$B$8="",多次统计数据!$B$6<=0,多次统计数据!$B$6>=1),"",1-POWER(1+多次统计数据!$B$8,-多次统计数据!$B$6/(1-多次统计数据!$B$6))) | AC13: =IF(OR(AB13="",多次统计数据!$B$9=""),"",IF(多次统计数据!$B$9<AB13,"低于上限","达到或超过上限")) | AE13: =IF(OR(X13="",C13="",C13<=0),"",X13/C13) | AJ13: =IF(OR(AG13="",AH13=""),"",IF(OR(AND(AG13="短期博反弹",OR(AH13="1～3个交易日",AH13="4～10个交易日")),AND(AG13="突破冲新高",OR(AH13="4～10个交易日",AH13="11～20个交易日")),AND(AG13="趋势波段",OR(AH13="11～20个交易日",AH13="21～60个交易日",AH13="60个交易日以上"))),"匹配","周期与交易预期不匹配，请重新确认")) | AO13: =IF(OR(A13="",H13="",H13<=0),"",(E13*H13+IF(AND(AK13<>"",AL13<>""),AK13*AL13,0)+IF(AND(AM13<>"",AN13<>""),AM13*AN13,0))/AP13) | AP13: =IF(OR(A13="",H13="",H13<=0),"",H13+IF(AL13="",0,AL13)+IF(AN13="",0,AN13)) | AQ13: =IF(A13="","",IF(M13<>"",0,IF(OR(H13="",N13=""),"",MAX(E13-MAX(N13,IFERROR(SUMPRODUCT(MAX(((持仓跟踪!$A$2:$A$497="每日跟踪")*(持仓跟踪!$B$2:$B$497=A13))*持仓跟踪!$S$2:$S$497)),0)),0)*H13+IF(OR(AK13="",AL13=""),0,MAX(AK13-MAX(N13,IFERROR(SUMPRODUCT(MAX(((持仓跟踪!$A$2:$A$497="每日跟踪")*(持仓跟踪!$B$2:$B$497=A13))*持仓跟踪!$S$2:$S$497)),0)),0)*AL13)+IF(OR(AM13="",AN13=""),0,MAX(AM13-MAX(N13,IFERROR(SUMPRODUCT(MAX(((持仓跟踪!$A$2:$A$497="每日跟踪")*(持仓跟踪!$B$2:$B$497=A13))*持仓跟踪!$S$2:$S$497)),0)),0)*AN13)))) | AR13: =IF(A13="","",IF(OR(E13="",H13=""),"违规：第一批价格或股数缺失",IF(OR(AND(AK13="",AL13<>""),AND(AK13<>"",AL13="")),"违规：第二批价格与股数须成对填写",IF(OR(AND(AM13="",AN13<>""),AND(AM13<>"",AN13="")),"违规：第三批价格与股数须成对填写",IF(AND(OR(AM13<>"",AN13<>""),OR(AK13="",AL13="")),"违规：必须先完成第二批",IF(OR(H13<=0,H13<>INT(H13),MOD(H13,100)<>0,AND(AL13<>"",OR(AL13<=0,AL13<>INT(AL13),MOD(AL13,100)<>0)),AND(AN13<>"",OR(AN13<=0,AN13<>INT(AN13),MOD(AN13,100)<>0))),"违规：股数须为100股整数倍",IF(AND(OR(AL13<>"",AN13<>""),OR(_LockStatus="已锁仓",_LockStatus="解锁信息不完整")),"违规：锁仓期间禁止加仓",IF(AQ13>C13*D13,"违规：超过单笔风险上限",IF(SUM($AQ$2:$AQ$201)>账户数据!$B$7,"违规：超过账户风险上限","通过")))))))))
F14: =IF(OR(C14="",D14="",E14="",N14="",C14<=0,D14<=0,E14<=N14),"",ROUNDDOWN((C14*D14)/(E14-N14)/100,0)*100) | G14: =IF(A14="","",IF(H14<>"","已开仓",IF(账户数据!$B$23="已锁仓","禁止开仓：连续亏损达到上限",IF(账户数据!$B$23="解锁信息不完整","禁止开仓：请完整填写解锁信息",IF(OR(F14="",E14="",N14="",E14<=N14,账户数据!$B$7=""),"",IF(OR(AG14="",AH14="",AI14=""),"禁止开仓：交易预期未填写完整",IF(COUNTIFS(持仓跟踪!$A$2:$A$497,"止损计划",持仓跟踪!$B$2:$B$497,A14,持仓跟踪!$AC$2:$AC$497,"计划有效")=0,"禁止开仓：请先填写止损计划",IF(账户数据!$B$9+F14*(E14-N14)>=账户数据!$B$7,"禁止开仓：风险额度不足",IF(AJ14="周期与交易预期不匹配，请重新确认",IF(账户数据!$B$23="接近锁仓","允许开仓（接近锁仓；周期需复核）","允许开仓（周期需复核）"),IF(账户数据!$B$23="接近锁仓","允许开仓（接近锁仓）","允许开仓")))))))))) | L14: =IF(K14="","",H14) | U14: =IF(OR(AO14="",J14="",AO14<=0),"",(J14-AO14)/AO14) | V14: =IF(OR(AO14="",N14="",AO14<=0),"",(AO14-N14)/AO14) | W14: =IF(OR(U14="",V14="",V14<=0),"",U14/V14) | X14: =IF(OR(K14="",L14="",AP14=""),"",K14*L14-(E14*H14+IF(AND(AK14<>"",AL14<>""),AK14*AL14,0)+IF(AND(AM14<>"",AN14<>""),AM14*AN14,0))-IF(O14="",0,O14)-IF(P14="",0,P14)) | Y14: =IF(OR(X14="",AP14=""),"",IF((E14*H14+IF(AND(AK14<>"",AL14<>""),AK14*AL14,0)+IF(AND(AM14<>"",AN14<>""),AM14*AN14,0))+IF(O14="",0,O14)<=0,"",X14/((E14*H14+IF(AND(AK14<>"",AL14<>""),AK14*AL14,0)+IF(AND(AM14<>"",AN14<>""),AM14*AN14,0))+IF(O14="",0,O14)))) | Z14: =IF(OR(AE14="",多次统计数据!$B$8=""),"",AE14-多次统计数据!$B$8) | AA14: =IF(OR(I14="",M14="",M14<I14),"",M14-I14) | AB14: =IF(OR(A14="",多次统计数据!$B$8="",多次统计数据!$B$6<=0,多次统计数据!$B$6>=1),"",1-POWER(1+多次统计数据!$B$8,-多次统计数据!$B$6/(1-多次统计数据!$B$6))) | AC14: =IF(OR(AB14="",多次统计数据!$B$9=""),"",IF(多次统计数据!$B$9<AB14,"低于上限","达到或超过上限")) | AE14: =IF(OR(X14="",C14="",C14<=0),"",X14/C14) | AJ14: =IF(OR(AG14="",AH14=""),"",IF(OR(AND(AG14="短期博反弹",OR(AH14="1～3个交易日",AH14="4～10个交易日")),AND(AG14="突破冲新高",OR(AH14="4～10个交易日",AH14="11～20个交易日")),AND(AG14="趋势波段",OR(AH14="11～20个交易日",AH14="21～60个交易日",AH14="60个交易日以上"))),"匹配","周期与交易预期不匹配，请重新确认")) | AO14: =IF(OR(A14="",H14="",H14<=0),"",(E14*H14+IF(AND(AK14<>"",AL14<>""),AK14*AL14,0)+IF(AND(AM14<>"",AN14<>""),AM14*AN14,0))/AP14) | AP14: =IF(OR(A14="",H14="",H14<=0),"",H14+IF(AL14="",0,AL14)+IF(AN14="",0,AN14)) | AQ14: =IF(A14="","",IF(M14<>"",0,IF(OR(H14="",N14=""),"",MAX(E14-MAX(N14,IFERROR(SUMPRODUCT(MAX(((持仓跟踪!$A$2:$A$497="每日跟踪")*(持仓跟踪!$B$2:$B$497=A14))*持仓跟踪!$S$2:$S$497)),0)),0)*H14+IF(OR(AK14="",AL14=""),0,MAX(AK14-MAX(N14,IFERROR(SUMPRODUCT(MAX(((持仓跟踪!$A$2:$A$497="每日跟踪")*(持仓跟踪!$B$2:$B$497=A14))*持仓跟踪!$S$2:$S$497)),0)),0)*AL14)+IF(OR(AM14="",AN14=""),0,MAX(AM14-MAX(N14,IFERROR(SUMPRODUCT(MAX(((持仓跟踪!$A$2:$A$497="每日跟踪")*(持仓跟踪!$B$2:$B$497=A14))*持仓跟踪!$S$2:$S$497)),0)),0)*AN14)))) | AR14: =IF(A14="","",IF(OR(E14="",H14=""),"违规：第一批价格或股数缺失",IF(OR(AND(AK14="",AL14<>""),AND(AK14<>"",AL14="")),"违规：第二批价格与股数须成对填写",IF(OR(AND(AM14="",AN14<>""),AND(AM14<>"",AN14="")),"违规：第三批价格与股数须成对填写",IF(AND(OR(AM14<>"",AN14<>""),OR(AK14="",AL14="")),"违规：必须先完成第二批",IF(OR(H14<=0,H14<>INT(H14),MOD(H14,100)<>0,AND(AL14<>"",OR(AL14<=0,AL14<>INT(AL14),MOD(AL14,100)<>0)),AND(AN14<>"",OR(AN14<=0,AN14<>INT(AN14),MOD(AN14,100)<>0))),"违规：股数须为100股整数倍",IF(AND(OR(AL14<>"",AN14<>""),OR(_LockStatus="已锁仓",_LockStatus="解锁信息不完整")),"违规：锁仓期间禁止加仓",IF(AQ14>C14*D14,"违规：超过单笔风险上限",IF(SUM($AQ$2:$AQ$201)>账户数据!$B$7,"违规：超过账户风险上限","通过")))))))))
F15: =IF(OR(C15="",D15="",E15="",N15="",C15<=0,D15<=0,E15<=N15),"",ROUNDDOWN((C15*D15)/(E15-N15)/100,0)*100) | G15: =IF(A15="","",IF(H15<>"","已开仓",IF(账户数据!$B$23="已锁仓","禁止开仓：连续亏损达到上限",IF(账户数据!$B$23="解锁信息不完整","禁止开仓：请完整填写解锁信息",IF(OR(F15="",E15="",N15="",E15<=N15,账户数据!$B$7=""),"",IF(OR(AG15="",AH15="",AI15=""),"禁止开仓：交易预期未填写完整",IF(COUNTIFS(持仓跟踪!$A$2:$A$497,"止损计划",持仓跟踪!$B$2:$B$497,A15,持仓跟踪!$AC$2:$AC$497,"计划有效")=0,"禁止开仓：请先填写止损计划",IF(账户数据!$B$9+F15*(E15-N15)>=账户数据!$B$7,"禁止开仓：风险额度不足",IF(AJ15="周期与交易预期不匹配，请重新确认",IF(账户数据!$B$23="接近锁仓","允许开仓（接近锁仓；周期需复核）","允许开仓（周期需复核）"),IF(账户数据!$B$23="接近锁仓","允许开仓（接近锁仓）","允许开仓")))))))))) | L15: =IF(K15="","",H15) | U15: =IF(OR(AO15="",J15="",AO15<=0),"",(J15-AO15)/AO15) | V15: =IF(OR(AO15="",N15="",AO15<=0),"",(AO15-N15)/AO15) | W15: =IF(OR(U15="",V15="",V15<=0),"",U15/V15) | X15: =IF(OR(K15="",L15="",AP15=""),"",K15*L15-(E15*H15+IF(AND(AK15<>"",AL15<>""),AK15*AL15,0)+IF(AND(AM15<>"",AN15<>""),AM15*AN15,0))-IF(O15="",0,O15)-IF(P15="",0,P15)) | Y15: =IF(OR(X15="",AP15=""),"",IF((E15*H15+IF(AND(AK15<>"",AL15<>""),AK15*AL15,0)+IF(AND(AM15<>"",AN15<>""),AM15*AN15,0))+IF(O15="",0,O15)<=0,"",X15/((E15*H15+IF(AND(AK15<>"",AL15<>""),AK15*AL15,0)+IF(AND(AM15<>"",AN15<>""),AM15*AN15,0))+IF(O15="",0,O15)))) | Z15: =IF(OR(AE15="",多次统计数据!$B$8=""),"",AE15-多次统计数据!$B$8) | AA15: =IF(OR(I15="",M15="",M15<I15),"",M15-I15) | AB15: =IF(OR(A15="",多次统计数据!$B$8="",多次统计数据!$B$6<=0,多次统计数据!$B$6>=1),"",1-POWER(1+多次统计数据!$B$8,-多次统计数据!$B$6/(1-多次统计数据!$B$6))) | AC15: =IF(OR(AB15="",多次统计数据!$B$9=""),"",IF(多次统计数据!$B$9<AB15,"低于上限","达到或超过上限")) | AE15: =IF(OR(X15="",C15="",C15<=0),"",X15/C15) | AJ15: =IF(OR(AG15="",AH15=""),"",IF(OR(AND(AG15="短期博反弹",OR(AH15="1～3个交易日",AH15="4～10个交易日")),AND(AG15="突破冲新高",OR(AH15="4～10个交易日",AH15="11～20个交易日")),AND(AG15="趋势波段",OR(AH15="11～20个交易日",AH15="21～60个交易日",AH15="60个交易日以上"))),"匹配","周期与交易预期不匹配，请重新确认")) | AO15: =IF(OR(A15="",H15="",H15<=0),"",(E15*H15+IF(AND(AK15<>"",AL15<>""),AK15*AL15,0)+IF(AND(AM15<>"",AN15<>""),AM15*AN15,0))/AP15) | AP15: =IF(OR(A15="",H15="",H15<=0),"",H15+IF(AL15="",0,AL15)+IF(AN15="",0,AN15)) | AQ15: =IF(A15="","",IF(M15<>"",0,IF(OR(H15="",N15=""),"",MAX(E15-MAX(N15,IFERROR(SUMPRODUCT(MAX(((持仓跟踪!$A$2:$A$497="每日跟踪")*(持仓跟踪!$B$2:$B$497=A15))*持仓跟踪!$S$2:$S$497)),0)),0)*H15+IF(OR(AK15="",AL15=""),0,MAX(AK15-MAX(N15,IFERROR(SUMPRODUCT(MAX(((持仓跟踪!$A$2:$A$497="每日跟踪")*(持仓跟踪!$B$2:$B$497=A15))*持仓跟踪!$S$2:$S$497)),0)),0)*AL15)+IF(OR(AM15="",AN15=""),0,MAX(AM15-MAX(N15,IFERROR(SUMPRODUCT(MAX(((持仓跟踪!$A$2:$A$497="每日跟踪")*(持仓跟踪!$B$2:$B$497=A15))*持仓跟踪!$S$2:$S$497)),0)),0)*AN15)))) | AR15: =IF(A15="","",IF(OR(E15="",H15=""),"违规：第一批价格或股数缺失",IF(OR(AND(AK15="",AL15<>""),AND(AK15<>"",AL15="")),"违规：第二批价格与股数须成对填写",IF(OR(AND(AM15="",AN15<>""),AND(AM15<>"",AN15="")),"违规：第三批价格与股数须成对填写",IF(AND(OR(AM15<>"",AN15<>""),OR(AK15="",AL15="")),"违规：必须先完成第二批",IF(OR(H15<=0,H15<>INT(H15),MOD(H15,100)<>0,AND(AL15<>"",OR(AL15<=0,AL15<>INT(AL15),MOD(AL15,100)<>0)),AND(AN15<>"",OR(AN15<=0,AN15<>INT(AN15),MOD(AN15,100)<>0))),"违规：股数须为100股整数倍",IF(AND(OR(AL15<>"",AN15<>""),OR(_LockStatus="已锁仓",_LockStatus="解锁信息不完整")),"违规：锁仓期间禁止加仓",IF(AQ15>C15*D15,"违规：超过单笔风险上限",IF(SUM($AQ$2:$AQ$201)>账户数据!$B$7,"违规：超过账户风险上限","通过")))))))))
... F103: =IF(OR(C103="",D103="",E103="",N103="",C103<=0,D103<=0,E103<=N103),"",ROUNDDOWN((C103*D103)/(E103-N103)/100,0)*100) | G103: =IF(A103="","",IF(H103<>"","已开仓",IF(账户数据!$B$23="已锁仓","禁止开仓：连续亏损达到上限",IF(账户数据!$B$23="解锁信息不完整","禁止开仓：请完整填写解锁信息",IF(OR(F103="",E103="",N103="",E103<=N103,账户数据!$B$7=""),"",IF(OR(AG103="",AH103="",AI103=""),"禁止开仓：交易预期未填写完整",IF(COUNTIFS(持仓跟踪!$A$2:$A$497,"止损计划",持仓跟踪!$B$2:$B$497,A103,持仓跟踪!$AC$2:$AC$497,"计划有效")=0,"禁止开仓：请先填写止损计划",IF(账户数据!$B$9+F103*(E103-N103)>=账户数据!$B$7,"禁止开仓：风险额度不足",IF(AJ103="周期与交易预期不匹配，请重新确认",IF(账户数据!$B$23="接近锁仓","允许开仓（接近锁仓；周期需复核）","允许开仓（周期需复核）"),IF(账户数据!$B$23="接近锁仓","允许开仓（接近锁仓）","允许开仓")))))))))) | L103: =IF(K103="","",H103) | U103: =IF(OR(AO103="",J103="",AO103<=0),"",(J103-AO103)/AO103) | V103: =IF(OR(AO103="",N103="",AO103<=0),"",(AO103-N103)/AO103) | W103: =IF(OR(U103="",V103="",V103<=0),"",U103/V103) | X103: =IF(OR(K103="",L103="",AP103=""),"",K103*L103-(E103*H103+IF(AND(AK103<>"",AL103<>""),AK103*AL103,0)+IF(AND(AM103<>"",AN103<>""),AM103*AN103,0))-IF(O103="",0,O103)-IF(P103="",0,P103)) | Y103: =IF(OR(X103="",AP103=""),"",IF((E103*H103+IF(AND(AK103<>"",AL103<>""),AK103*AL103,0)+IF(AND(AM103<>"",AN103<>""),AM103*AN103,0))+IF(O103="",0,O103)<=0,"",X103/((E103*H103+IF(AND(AK103<>"",AL103<>""),AK103*AL103,0)+IF(AND(AM103<>"",AN103<>""),AM103*AN103,0))+IF(O103="",0,O103)))) | Z103: =IF(OR(AE103="",多次统计数据!$B$8=""),"",AE103-多次统计数据!$B$8) | AA103: =IF(OR(I103="",M103="",M103<I103),"",M103-I103) | AB103: =IF(OR(A103="",多次统计数据!$B$8="",多次统计数据!$B$6<=0,多次统计数据!$B$6>=1),"",1-POWER(1+多次统计数据!$B$8,-多次统计数据!$B$6/(1-多次统计数据!$B$6))) | AC103: =IF(OR(AB103="",多次统计数据!$B$9=""),"",IF(多次统计数据!$B$9<AB103,"低于上限","达到或超过上限")) | AE103: =IF(OR(X103="",C103="",C103<=0),"",X103/C103) | AJ103: =IF(OR(AG103="",AH103=""),"",IF(OR(AND(AG103="短期博反弹",OR(AH103="1～3个交易日",AH103="4～10个交易日")),AND(AG103="突破冲新高",OR(AH103="4～10个交易日",AH103="11～20个交易日")),AND(AG103="趋势波段",OR(AH103="11～20个交易日",AH103="21～60个交易日",AH103="60个交易日以上"))),"匹配","周期与交易预期不匹配，请重新确认")) | AO103: =IF(OR(A103="",H103="",H103<=0),"",(E103*H103+IF(AND(AK103<>"",AL103<>""),AK103*AL103,0)+IF(AND(AM103<>"",AN103<>""),AM103*AN103,0))/AP103) | AP103: =IF(OR(A103="",H103="",H103<=0),"",H103+IF(AL103="",0,AL103)+IF(AN103="",0,AN103)) | AQ103: =IF(A103="","",IF(M103<>"",0,IF(OR(H103="",N103=""),"",MAX(E103-MAX(N103,IFERROR(SUMPRODUCT(MAX(((持仓跟踪!$A$2:$A$497="每日跟踪")*(持仓跟踪!$B$2:$B$497=A103))*持仓跟踪!$S$2:$S$497)),0)),0)*H103+IF(OR(AK103="",AL103=""),0,MAX(AK103-MAX(N103,IFERROR(SUMPRODUCT(MAX(((持仓跟踪!$A$2:$A$497="每日跟踪")*(持仓跟踪!$B$2:$B$497=A103))*持仓跟踪!$S$2:$S$497)),0)),0)*AL103)+IF(OR(AM103="",AN103=""),0,MAX(AM103-MAX(N103,IFERROR(SUMPRODUCT(MAX(((持仓跟踪!$A$2:$A$497="每日跟踪")*(持仓跟踪!$B$2:$B$497=A103))*持仓跟踪!$S$2:$S$497)),0)),0)*AN103)))) | AR103: =IF(A103="","",IF(OR(E103="",H103=""),"违规：第一批价格或股数缺失",IF(OR(AND(AK103="",AL103<>""),AND(AK103<>"",AL103="")),"违规：第二批价格与股数须成对填写",IF(OR(AND(AM103="",AN103<>""),AND(AM103<>"",AN103="")),"违规：第三批价格与股数须成对填写",IF(AND(OR(AM103<>"",AN103<>""),OR(AK103="",AL103="")),"违规：必须先完成第二批",IF(OR(H103<=0,H103<>INT(H103),MOD(H103,100)<>0,AND(AL103<>"",OR(AL103<=0,AL103<>INT(AL103),MOD(AL103,100)<>0)),AND(AN103<>"",OR(AN103<=0,AN103<>INT(AN103),MOD(AN103,100)<>0))),"违规：股数须为100股整数倍",IF(AND(OR(AL103<>"",AN103<>""),OR(_LockStatus="已锁仓",_LockStatus="解锁信息不完整")),"违规：锁仓期间禁止加仓",IF(AQ103>C103*D103,"违规：超过单笔风险上限",IF(SUM($AQ$2:$AQ$201)>账户数据!$B$7,"违规：超过账户风险上限","通过")))))))))
F104: =IF(OR(C104="",D104="",E104="",N104="",C104<=0,D104<=0,E104<=N104),"",ROUNDDOWN((C104*D104)/(E104-N104)/100,0)*100) | G104: =IF(A104="","",IF(H104<>"","已开仓",IF(账户数据!$B$23="已锁仓","禁止开仓：连续亏损达到上限",IF(账户数据!$B$23="解锁信息不完整","禁止开仓：请完整填写解锁信息",IF(OR(F104="",E104="",N104="",E104<=N104,账户数据!$B$7=""),"",IF(OR(AG104="",AH104="",AI104=""),"禁止开仓：交易预期未填写完整",IF(COUNTIFS(持仓跟踪!$A$2:$A$497,"止损计划",持仓跟踪!$B$2:$B$497,A104,持仓跟踪!$AC$2:$AC$497,"计划有效")=0,"禁止开仓：请先填写止损计划",IF(账户数据!$B$9+F104*(E104-N104)>=账户数据!$B$7,"禁止开仓：风险额度不足",IF(AJ104="周期与交易预期不匹配，请重新确认",IF(账户数据!$B$23="接近锁仓","允许开仓（接近锁仓；周期需复核）","允许开仓（周期需复核）"),IF(账户数据!$B$23="接近锁仓","允许开仓（接近锁仓）","允许开仓")))))))))) | M104: =IF(A104="","",IFERROR(LOOKUP(2,1/((持仓跟踪!$B$2:$B$497=A104)*(持仓跟踪!$X$2:$X$497="执行卖出")*(持仓跟踪!$H$2:$H$497<>"")),持仓跟踪!$H$2:$H$497),"")) | P104: =IF(A104="","",IFERROR(LOOKUP(2,1/((持仓跟踪!$B$2:$B$497=A104)*(持仓跟踪!$X$2:$X$497="执行卖出")*(持仓跟踪!$AA$2:$AA$497<>"")),持仓跟踪!$AA$2:$AA$497),"")) | U104: =IF(OR(AO104="",J104="",AO104<=0),"",(J104-AO104)/AO104) | V104: =IF(OR(AO104="",N104="",AO104<=0),"",(AO104-N104)/AO104) | W104: =IF(OR(U104="",V104="",V104<=0),"",U104/V104) | X104: =IF(OR(K104="",L104="",AP104=""),"",K104*L104-(E104*H104+IF(AND(AK104<>"",AL104<>""),AK104*AL104,0)+IF(AND(AM104<>"",AN104<>""),AM104*AN104,0))-IF(O104="",0,O104)-IF(P104="",0,P104)) | Y104: =IF(OR(X104="",AP104=""),"",IF((E104*H104+IF(AND(AK104<>"",AL104<>""),AK104*AL104,0)+IF(AND(AM104<>"",AN104<>""),AM104*AN104,0))+IF(O104="",0,O104)<=0,"",X104/((E104*H104+IF(AND(AK104<>"",AL104<>""),AK104*AL104,0)+IF(AND(AM104<>"",AN104<>""),AM104*AN104,0))+IF(O104="",0,O104)))) | Z104: =IF(OR(AE104="",多次统计数据!$B$8=""),"",AE104-多次统计数据!$B$8) | AA104: =IF(OR(I104="",M104="",M104<I104),"",M104-I104) | AB104: =IF(OR(A104="",多次统计数据!$B$8="",多次统计数据!$B$6<=0,多次统计数据!$B$6>=1),"",1-POWER(1+多次统计数据!$B$8,-多次统计数据!$B$6/(1-多次统计数据!$B$6))) | AC104: =IF(OR(AB104="",多次统计数据!$B$9=""),"",IF(多次统计数据!$B$9<AB104,"低于上限","达到或超过上限")) | AE104: =IF(OR(X104="",C104="",C104<=0),"",X104/C104) | AJ104: =IF(OR(AG104="",AH104=""),"",IF(OR(AND(AG104="短期博反弹",OR(AH104="1～3个交易日",AH104="4～10个交易日")),AND(AG104="突破冲新高",OR(AH104="4～10个交易日",AH104="11～20个交易日")),AND(AG104="趋势波段",OR(AH104="11～20个交易日",AH104="21～60个交易日",AH104="60个交易日以上"))),"匹配","周期与交易预期不匹配，请重新确认")) | AO104: =IF(OR(A104="",H104="",H104<=0),"",(E104*H104+IF(AND(AK104<>"",AL104<>""),AK104*AL104,0)+IF(AND(AM104<>"",AN104<>""),AM104*AN104,0))/AP104) | AP104: =IF(OR(A104="",H104="",H104<=0),"",H104+IF(AL104="",0,AL104)+IF(AN104="",0,AN104)) | AQ104: =IF(A104="","",IF(M104<>"",0,IF(OR(H104="",N104=""),"",MAX(E104-MAX(N104,IFERROR(SUMPRODUCT(MAX(((持仓跟踪!$A$2:$A$497="每日跟踪")*(持仓跟踪!$B$2:$B$497=A104))*持仓跟踪!$S$2:$S$497)),0)),0)*H104+IF(OR(AK104="",AL104=""),0,MAX(AK104-MAX(N104,IFERROR(SUMPRODUCT(MAX(((持仓跟踪!$A$2:$A$497="每日跟踪")*(持仓跟踪!$B$2:$B$497=A104))*持仓跟踪!$S$2:$S$497)),0)),0)*AL104)+IF(OR(AM104="",AN104=""),0,MAX(AM104-MAX(N104,IFERROR(SUMPRODUCT(MAX(((持仓跟踪!$A$2:$A$497="每日跟踪")*(持仓跟踪!$B$2:$B$497=A104))*持仓跟踪!$S$2:$S$497)),0)),0)*AN104)))) | AR104: =IF(A104="","",IF(OR(E104="",H104=""),"违规：第一批价格或股数缺失",IF(OR(AND(AK104="",AL104<>""),AND(AK104<>"",AL104="")),"违规：第二批价格与股数须成对填写",IF(OR(AND(AM104="",AN104<>""),AND(AM104<>"",AN104="")),"违规：第三批价格与股数须成对填写",IF(AND(OR(AM104<>"",AN104<>""),OR(AK104="",AL104="")),"违规：必须先完成第二批",IF(OR(H104<=0,H104<>INT(H104),MOD(H104,100)<>0,AND(AL104<>"",OR(AL104<=0,AL104<>INT(AL104),MOD(AL104,100)<>0)),AND(AN104<>"",OR(AN104<=0,AN104<>INT(AN104),MOD(AN104,100)<>0))),"违规：股数须为100股整数倍",IF(AND(OR(AL104<>"",AN104<>""),OR(_LockStatus="已锁仓",_LockStatus="解锁信息不完整")),"违规：锁仓期间禁止加仓",IF(AQ104>C104*D104,"违规：超过单笔风险上限",IF(SUM($AQ$2:$AQ$201)>账户数据!$B$7,"违规：超过账户风险上限","通过")))))))))
F105: =IF(OR(C105="",D105="",E105="",N105="",C105<=0,D105<=0,E105<=N105),"",ROUNDDOWN((C105*D105)/(E105-N105)/100,0)*100) | G105: =IF(A105="","",IF(H105<>"","已开仓",IF(账户数据!$B$23="已锁仓","禁止开仓：连续亏损达到上限",IF(账户数据!$B$23="解锁信息不完整","禁止开仓：请完整填写解锁信息",IF(OR(F105="",E105="",N105="",E105<=N105,账户数据!$B$7=""),"",IF(OR(AG105="",AH105="",AI105=""),"禁止开仓：交易预期未填写完整",IF(COUNTIFS(持仓跟踪!$A$2:$A$497,"止损计划",持仓跟踪!$B$2:$B$497,A105,持仓跟踪!$AC$2:$AC$497,"计划有效")=0,"禁止开仓：请先填写止损计划",IF(账户数据!$B$9+F105*(E105-N105)>=账户数据!$B$7,"禁止开仓：风险额度不足",IF(AJ105="周期与交易预期不匹配，请重新确认",IF(账户数据!$B$23="接近锁仓","允许开仓（接近锁仓；周期需复核）","允许开仓（周期需复核）"),IF(账户数据!$B$23="接近锁仓","允许开仓（接近锁仓）","允许开仓")))))))))) | K105: =IF(A105="","",IFERROR(LOOKUP(2,1/((持仓跟踪!$B$2:$B$497=A105)*(持仓跟踪!$X$2:$X$497="执行卖出")*(持仓跟踪!$Y$2:$Y$497<>"")),持仓跟踪!$Y$2:$Y$497),"")) | L105: =IF(A105="","",IFERROR(LOOKUP(2,1/((持仓跟踪!$B$2:$B$497=A105)*(持仓跟踪!$X$2:$X$497="执行卖出")*(持仓跟踪!$Z$2:$Z$497<>"")),持仓跟踪!$Z$2:$Z$497),"")) | M105: =IF(A105="","",IFERROR(LOOKUP(2,1/((持仓跟踪!$B$2:$B$497=A105)*(持仓跟踪!$X$2:$X$497="执行卖出")*(持仓跟踪!$H$2:$H$497<>"")),持仓跟踪!$H$2:$H$497),"")) | P105: =IF(A105="","",IFERROR(LOOKUP(2,1/((持仓跟踪!$B$2:$B$497=A105)*(持仓跟踪!$X$2:$X$497="执行卖出")*(持仓跟踪!$AA$2:$AA$497<>"")),持仓跟踪!$AA$2:$AA$497),"")) | U105: =IF(OR(AO105="",J105="",AO105<=0),"",(J105-AO105)/AO105) | V105: =IF(OR(AO105="",N105="",AO105<=0),"",(AO105-N105)/AO105) | W105: =IF(OR(U105="",V105="",V105<=0),"",U105/V105) | X105: =IF(OR(K105="",L105="",AP105=""),"",K105*L105-(E105*H105+IF(AND(AK105<>"",AL105<>""),AK105*AL105,0)+IF(AND(AM105<>"",AN105<>""),AM105*AN105,0))-IF(O105="",0,O105)-IF(P105="",0,P105)) | Y105: =IF(OR(X105="",AP105=""),"",IF((E105*H105+IF(AND(AK105<>"",AL105<>""),AK105*AL105,0)+IF(AND(AM105<>"",AN105<>""),AM105*AN105,0))+IF(O105="",0,O105)<=0,"",X105/((E105*H105+IF(AND(AK105<>"",AL105<>""),AK105*AL105,0)+IF(AND(AM105<>"",AN105<>""),AM105*AN105,0))+IF(O105="",0,O105)))) | Z105: =IF(OR(AE105="",多次统计数据!$B$8=""),"",AE105-多次统计数据!$B$8) | AA105: =IF(OR(I105="",M105="",M105<I105),"",M105-I105) | AB105: =IF(OR(A105="",多次统计数据!$B$8="",多次统计数据!$B$6<=0,多次统计数据!$B$6>=1),"",1-POWER(1+多次统计数据!$B$8,-多次统计数据!$B$6/(1-多次统计数据!$B$6))) | AC105: =IF(OR(AB105="",多次统计数据!$B$9=""),"",IF(多次统计数据!$B$9<AB105,"低于上限","达到或超过上限")) | AE105: =IF(OR(X105="",C105="",C105<=0),"",X105/C105) | AJ105: =IF(OR(AG105="",AH105=""),"",IF(OR(AND(AG105="短期博反弹",OR(AH105="1～3个交易日",AH105="4～10个交易日")),AND(AG105="突破冲新高",OR(AH105="4～10个交易日",AH105="11～20个交易日")),AND(AG105="趋势波段",OR(AH105="11～20个交易日",AH105="21～60个交易日",AH105="60个交易日以上"))),"匹配","周期与交易预期不匹配，请重新确认")) | AO105: =IF(OR(A105="",H105="",H105<=0),"",(E105*H105+IF(AND(AK105<>"",AL105<>""),AK105*AL105,0)+IF(AND(AM105<>"",AN105<>""),AM105*AN105,0))/AP105) | AP105: =IF(OR(A105="",H105="",H105<=0),"",H105+IF(AL105="",0,AL105)+IF(AN105="",0,AN105)) | AQ105: =IF(A105="","",IF(M105<>"",0,IF(OR(H105="",N105=""),"",MAX(E105-MAX(N105,IFERROR(SUMPRODUCT(MAX(((持仓跟踪!$A$2:$A$497="每日跟踪")*(持仓跟踪!$B$2:$B$497=A105))*持仓跟踪!$S$2:$S$497)),0)),0)*H105+IF(OR(AK105="",AL105=""),0,MAX(AK105-MAX(N105,IFERROR(SUMPRODUCT(MAX(((持仓跟踪!$A$2:$A$497="每日跟踪")*(持仓跟踪!$B$2:$B$497=A105))*持仓跟踪!$S$2:$S$497)),0)),0)*AL105)+IF(OR(AM105="",AN105=""),0,MAX(AM105-MAX(N105,IFERROR(SUMPRODUCT(MAX(((持仓跟踪!$A$2:$A$497="每日跟踪")*(持仓跟踪!$B$2:$B$497=A105))*持仓跟踪!$S$2:$S$497)),0)),0)*AN105)))) | AR105: =IF(A105="","",IF(OR(E105="",H105=""),"违规：第一批价格或股数缺失",IF(OR(AND(AK105="",AL105<>""),AND(AK105<>"",AL105="")),"违规：第二批价格与股数须成对填写",IF(OR(AND(AM105="",AN105<>""),AND(AM105<>"",AN105="")),"违规：第三批价格与股数须成对填写",IF(AND(OR(AM105<>"",AN105<>""),OR(AK105="",AL105="")),"违规：必须先完成第二批",IF(OR(H105<=0,H105<>INT(H105),MOD(H105,100)<>0,AND(AL105<>"",OR(AL105<=0,AL105<>INT(AL105),MOD(AL105,100)<>0)),AND(AN105<>"",OR(AN105<=0,AN105<>INT(AN105),MOD(AN105,100)<>0))),"违规：股数须为100股整数倍",IF(AND(OR(AL105<>"",AN105<>""),OR(_LockStatus="已锁仓",_LockStatus="解锁信息不完整")),"违规：锁仓期间禁止加仓",IF(AQ105>C105*D105,"违规：超过单笔风险上限",IF(SUM($AQ$2:$AQ$201)>账户数据!$B$7,"违规：超过账户风险上限","通过")))))))))
F106: =IF(OR(C106="",D106="",E106="",N106="",C106<=0,D106<=0,E106<=N106),"",ROUNDDOWN((C106*D106)/(E106-N106)/100,0)*100) | G106: =IF(A106="","",IF(H106<>"","已开仓",IF(账户数据!$B$23="已锁仓","禁止开仓：连续亏损达到上限",IF(账户数据!$B$23="解锁信息不完整","禁止开仓：请完整填写解锁信息",IF(OR(F106="",E106="",N106="",E106<=N106,账户数据!$B$7=""),"",IF(OR(AG106="",AH106="",AI106=""),"禁止开仓：交易预期未填写完整",IF(COUNTIFS(持仓跟踪!$A$2:$A$497,"止损计划",持仓跟踪!$B$2:$B$497,A106,持仓跟踪!$AC$2:$AC$497,"计划有效")=0,"禁止开仓：请先填写止损计划",IF(账户数据!$B$9+F106*(E106-N106)>=账户数据!$B$7,"禁止开仓：风险额度不足",IF(AJ106="周期与交易预期不匹配，请重新确认",IF(账户数据!$B$23="接近锁仓","允许开仓（接近锁仓；周期需复核）","允许开仓（周期需复核）"),IF(账户数据!$B$23="接近锁仓","允许开仓（接近锁仓）","允许开仓")))))))))) | K106: =IF(A106="","",IFERROR(LOOKUP(2,1/((持仓跟踪!$B$2:$B$497=A106)*(持仓跟踪!$X$2:$X$497="执行卖出")*(持仓跟踪!$Y$2:$Y$497<>"")),持仓跟踪!$Y$2:$Y$497),"")) | L106: =IF(A106="","",IFERROR(LOOKUP(2,1/((持仓跟踪!$B$2:$B$497=A106)*(持仓跟踪!$X$2:$X$497="执行卖出")*(持仓跟踪!$Z$2:$Z$497<>"")),持仓跟踪!$Z$2:$Z$497),"")) | M106: =IF(A106="","",IFERROR(LOOKUP(2,1/((持仓跟踪!$B$2:$B$497=A106)*(持仓跟踪!$X$2:$X$497="执行卖出")*(持仓跟踪!$H$2:$H$497<>"")),持仓跟踪!$H$2:$H$497),"")) | P106: =IF(A106="","",IFERROR(LOOKUP(2,1/((持仓跟踪!$B$2:$B$497=A106)*(持仓跟踪!$X$2:$X$497="执行卖出")*(持仓跟踪!$AA$2:$AA$497<>"")),持仓跟踪!$AA$2:$AA$497),"")) | U106: =IF(OR(AO106="",J106="",AO106<=0),"",(J106-AO106)/AO106) | V106: =IF(OR(AO106="",N106="",AO106<=0),"",(AO106-N106)/AO106) | W106: =IF(OR(U106="",V106="",V106<=0),"",U106/V106) | X106: =IF(OR(K106="",L106="",AP106=""),"",K106*L106-(E106*H106+IF(AND(AK106<>"",AL106<>""),AK106*AL106,0)+IF(AND(AM106<>"",AN106<>""),AM106*AN106,0))-IF(O106="",0,O106)-IF(P106="",0,P106)) | Y106: =IF(OR(X106="",AP106=""),"",IF((E106*H106+IF(AND(AK106<>"",AL106<>""),AK106*AL106,0)+IF(AND(AM106<>"",AN106<>""),AM106*AN106,0))+IF(O106="",0,O106)<=0,"",X106/((E106*H106+IF(AND(AK106<>"",AL106<>""),AK106*AL106,0)+IF(AND(AM106<>"",AN106<>""),AM106*AN106,0))+IF(O106="",0,O106)))) | Z106: =IF(OR(AE106="",多次统计数据!$B$8=""),"",AE106-多次统计数据!$B$8) | AA106: =IF(OR(I106="",M106="",M106<I106),"",M106-I106) | AB106: =IF(OR(A106="",多次统计数据!$B$8="",多次统计数据!$B$6<=0,多次统计数据!$B$6>=1),"",1-POWER(1+多次统计数据!$B$8,-多次统计数据!$B$6/(1-多次统计数据!$B$6))) | AC106: =IF(OR(AB106="",多次统计数据!$B$9=""),"",IF(多次统计数据!$B$9<AB106,"低于上限","达到或超过上限")) | AE106: =IF(OR(X106="",C106="",C106<=0),"",X106/C106) | AJ106: =IF(OR(AG106="",AH106=""),"",IF(OR(AND(AG106="短期博反弹",OR(AH106="1～3个交易日",AH106="4～10个交易日")),AND(AG106="突破冲新高",OR(AH106="4～10个交易日",AH106="11～20个交易日")),AND(AG106="趋势波段",OR(AH106="11～20个交易日",AH106="21～60个交易日",AH106="60个交易日以上"))),"匹配","周期与交易预期不匹配，请重新确认")) | AO106: =IF(OR(A106="",H106="",H106<=0),"",(E106*H106+IF(AND(AK106<>"",AL106<>""),AK106*AL106,0)+IF(AND(AM106<>"",AN106<>""),AM106*AN106,0))/AP106) | AP106: =IF(OR(A106="",H106="",H106<=0),"",H106+IF(AL106="",0,AL106)+IF(AN106="",0,AN106)) | AQ106: =IF(A106="","",IF(M106<>"",0,IF(OR(H106="",N106=""),"",MAX(E106-MAX(N106,IFERROR(SUMPRODUCT(MAX(((持仓跟踪!$A$2:$A$497="每日跟踪")*(持仓跟踪!$B$2:$B$497=A106))*持仓跟踪!$S$2:$S$497)),0)),0)*H106+IF(OR(AK106="",AL106=""),0,MAX(AK106-MAX(N106,IFERROR(SUMPRODUCT(MAX(((持仓跟踪!$A$2:$A$497="每日跟踪")*(持仓跟踪!$B$2:$B$497=A106))*持仓跟踪!$S$2:$S$497)),0)),0)*AL106)+IF(OR(AM106="",AN106=""),0,MAX(AM106-MAX(N106,IFERROR(SUMPRODUCT(MAX(((持仓跟踪!$A$2:$A$497="每日跟踪")*(持仓跟踪!$B$2:$B$497=A106))*持仓跟踪!$S$2:$S$497)),0)),0)*AN106)))) | AR106: =IF(A106="","",IF(OR(E106="",H106=""),"违规：第一批价格或股数缺失",IF(OR(AND(AK106="",AL106<>""),AND(AK106<>"",AL106="")),"违规：第二批价格与股数须成对填写",IF(OR(AND(AM106="",AN106<>""),AND(AM106<>"",AN106="")),"违规：第三批价格与股数须成对填写",IF(AND(OR(AM106<>"",AN106<>""),OR(AK106="",AL106="")),"违规：必须先完成第二批",IF(OR(H106<=0,H106<>INT(H106),MOD(H106,100)<>0,AND(AL106<>"",OR(AL106<=0,AL106<>INT(AL106),MOD(AL106,100)<>0)),AND(AN106<>"",OR(AN106<=0,AN106<>INT(AN106),MOD(AN106,100)<>0))),"违规：股数须为100股整数倍",IF(AND(OR(AL106<>"",AN106<>""),OR(_LockStatus="已锁仓",_LockStatus="解锁信息不完整")),"违规：锁仓期间禁止加仓",IF(AQ106>C106*D106,"违规：超过单笔风险上限",IF(SUM($AQ$2:$AQ$201)>账户数据!$B$7,"违规：超过账户风险上限","通过")))))))))
