Workbook
Name _AccountRiskLimit: 账户数据!$B$7
Name _LockStatus: 账户数据!$B$23
Name _TrackRule: 持仓跟踪!$AC$2:$AC$501
Name _TrackTradeId: 持仓跟踪!$B$2:$B$501
Name _TrackType: 持仓跟踪!$A$2:$A$501
Name _TradeIds: 单次交易!$A$2:$A$201
Name 技术指标列表: 技术指标!$A$2:$A$201

Sheet 单次交易
A1: 交易编号 | B1: 股票代码 | C1: 买入时账户金额 | D1: 本次允许亏损比例 | E1: 第一批买入价 | F1: 买入建议股数 | G1: 开仓风险告警 | H1: 第一批买入股数 | I1: 首次买入日期 | J1: 期望卖出价 | K1: 实际卖出价 | L1: 卖出股数 | M1: 卖出日期 | N1: 止损价 | O1: 买入总费用 | P1: 卖出费用 | Q1: 买入价的由来 | R1: 止损价的由来 | S1: 期望卖出价的由来 | T1: 实际卖出价的由来 | U1: 期望盈利比例 | V1: 期望止损比例 | W1: 盈亏比 | X1: 实际盈亏金额 | Y1: 单笔仓位收益率 | Z1: 账户收益率与平均盈利率差值 | AA1: 持有天数 | AB1: 复利容许平均亏损上限 | AC1: 复利风险判断 | AD1: 交易打分评价 | AE1: 实际账户收益率 | AF1: 列1 | AG1: 交易预期类型 | AH1: 预期持有周期 | AI1: 预期选择理由 | AJ1: 周期匹配检查 | AK1: 第二批买入价 | AL1: 第二批买入股数 | AM1: 第三批买入价 | AN1: 第三批买入股数 | AO1: 实际加权买入价 | AP1: 累计买入股数 | AQ1: 当前持仓风险 | AR1: 分仓规则检查
A2: 1 | B2: 长电科技 | C2: 100000 | D2: 0.02 | E2: 24 | F2: =IF(OR(C2="",D2="",E2="",N2="",C2<=0,D2<=0,E2<=N2),"",ROUNDDOWN((C2*D2)/(E2-N2)/100,0)*100) | G2: =IF(A2="","",IF(H2<>"","已开仓",IF(账户数据!$B$23="已锁仓","禁止开仓：连续亏损达到上限",IF(账户数据!$B$23="解锁信息不完整","禁止开仓：请完整填写解锁信息",IF(OR(F2="",E2="",N2="",E2<=N2,账户数据!$B$7=""),"",IF(OR(AG2="",AH2="",AI2=""),"禁止开仓：交易预期未填写完整",IF(COUNTIFS(持仓跟踪!$A$2:$A$501,"止损计划",持仓跟踪!$B$2:$B$501,A2,持仓跟踪!$AC$2:$AC$501,"计划有效")=0,"禁止开仓：请先填写止损计划",IF(账户数据!$B$9+F2*(E2-N2)>=账户数据!$B$7,"禁止开仓：风险额度不足",IF(AJ2="周期与交易预期不匹配，请重新确认",IF(账户数据!$B$23="接近锁仓","允许开仓（接近锁仓；周期需复核）","允许开仓（周期需复核）"),IF(账户数据!$B$23="接近锁仓","允许开仓（接近锁仓）","允许开仓")))))))))) | H2: 4000 | I2: 44701 | J2: 25 | K2: 22.97 | L2: =IF(K2="","",H2) | M2: 44705 | N2: 23.5 | R2: 之前的支撑位 | S2: 之前的压力位 | U2: =IF(OR(AO2="",J2="",AO2<=0),"",(J2-AO2)/AO2) | V2: =IF(OR(AO2="",N2="",AO2<=0),"",(AO2-N2)/AO2) | W2: =IF(OR(U2="",V2="",V2<=0),"",U2/V2) | X2: =IF(OR(K2="",L2="",AP2=""),"",K2*L2-(E2*H2+IF(AND(AK2<>"",AL2<>""),AK2*AL2,0)+IF(AND(AM2<>"",AN2<>""),AM2*AN2,0))-IF(O2="",0,O2)-IF(P2="",0,P2)) | Y2: =IF(OR(X2="",AP2=""),"",IF((E2*H2+IF(AND(AK2<>"",AL2<>""),AK2*AL2,0)+IF(AND(AM2<>"",AN2<>""),AM2*AN2,0))+IF(O2="",0,O2)<=0,"",X2/((E2*H2+IF(AND(AK2<>"",AL2<>""),AK2*AL2,0)+IF(AND(AM2<>"",AN2<>""),AM2*AN2,0))+IF(O2="",0,O2)))) | Z2: =IF(OR(AE2="",多次统计数据!$B$8=""),"",AE2-多次统计数据!$B$8) | AA2: =IF(OR(I2="",M2="",M2<I2),"",M2-I2) | AB2: =IF(OR(A2="",多次统计数据!$B$8="",多次统计数据!$B$6<=0,多次统计数据!$B$6>=1),"",1-POWER(1+多次统计数据!$B$8,-多次统计数据!$B$6/(1-多次统计数据!$B$6))) | AC2: =IF(OR(AB2="",多次统计数据!$B$9=""),"",IF(多次统计数据!$B$9<AB2,"低于上限","达到或超过上限")) | AE2: =IF(OR(X2="",C2="",C2<=0),"",X2/C2) | AJ2: =IF(OR(AG2="",AH2=""),"",IF(OR(AND(AG2="短期博反弹",OR(AH2="1～3个交易日",AH2="4～10个交易日")),AND(AG2="突破冲新高",OR(AH2="4～10个交易日",AH2="11～20个交易日")),AND(AG2="趋势波段",OR(AH2="11～20个交易日",AH2="21～60个交易日",AH2="60个交易日以上"))),"匹配","周期与交易预期不匹配，请重新确认")) | AO2: =IF(OR(A2="",H2="",H2<=0),"",(E2*H2+IF(AND(AK2<>"",AL2<>""),AK2*AL2,0)+IF(AND(AM2<>"",AN2<>""),AM2*AN2,0))/AP2) | AP2: =IF(OR(A2="",H2="",H2<=0),"",H2+IF(AL2="",0,AL2)+IF(AN2="",0,AN2)) | AQ2: =IF(A2="","",IF(M2<>"",0,IF(OR(H2="",N2=""),"",MAX(E2-MAX(N2,IFERROR(AGGREGATE(14,6,'持仓跟踪'!$S$2:$S$501/(('持仓跟踪'!$A$2:$A$501="每日跟踪")*('持仓跟踪'!$B$2:$B$501=A2)),1),0)),0)*H2+IF(OR(AK2="",AL2=""),0,MAX(AK2-MAX(N2,IFERROR(AGGREGATE(14,6,'持仓跟踪'!$S$2:$S$501/(('持仓跟踪'!$A$2:$A$501="每日跟踪")*('持仓跟踪'!$B$2:$B$501=A2)),1),0)),0)*AL2)+IF(OR(AM2="",AN2=""),0,MAX(AM2-MAX(N2,IFERROR(AGGREGATE(14,6,'持仓跟踪'!$S$2:$S$501/(('持仓跟踪'!$A$2:$A$501="每日跟踪")*('持仓跟踪'!$B$2:$B$501=A2)),1),0)),0)*AN2)))) | AR2: =IF(A2="","",IF(OR(E2="",H2=""),"违规：第一批价格或股数缺失",IF(OR(AND(AK2="",AL2<>""),AND(AK2<>"",AL2="")),"违规：第二批价格与股数须成对填写",IF(OR(AND(AM2="",AN2<>""),AND(AM2<>"",AN2="")),"违规：第三批价格与股数须成对填写",IF(AND(OR(AM2<>"",AN2<>""),OR(AK2="",AL2="")),"违规：必须先完成第二批",IF(OR(H2<=0,H2<>INT(H2),MOD(H2,100)<>0,AND(AL2<>"",OR(AL2<=0,AL2<>INT(AL2),MOD(AL2,100)<>0)),AND(AN2<>"",OR(AN2<=0,AN2<>INT(AN2),MOD(AN2,100)<>0))),"违规：股数须为100股整数倍",IF(AND(OR(AL2<>"",AN2<>""),OR(_LockStatus="已锁仓",_LockStatus="解锁信息不完整")),"违规：锁仓期间禁止加仓",IF(AQ2>C2*D2,"违规：超过单笔风险上限",IF(SUM($AQ$2:$AQ$201)>账户数据!$B$7,"违规：超过账户风险上限","通过")))))))))
A3: 2 | B3: 长电科技 | C3: =IF(C2="","",C2+SUM(单次交易!Y2:Y201)) | D3: 0.02 | E3: 33.13 | F3: =IF(OR(C3="",D3="",E3="",N3="",C3<=0,D3<=0,E3<=N3),"",ROUNDDOWN((C3*D3)/(E3-N3)/100,0)*100) | G3: =IF(A3="","",IF(H3<>"","已开仓",IF(账户数据!$B$23="已锁仓","禁止开仓：连续亏损达到上限",IF(账户数据!$B$23="解锁信息不完整","禁止开仓：请完整填写解锁信息",IF(OR(F3="",E3="",N3="",E3<=N3,账户数据!$B$7=""),"",IF(OR(AG3="",AH3="",AI3=""),"禁止开仓：交易预期未填写完整",IF(COUNTIFS(持仓跟踪!$A$2:$A$501,"止损计划",持仓跟踪!$B$2:$B$501,A3,持仓跟踪!$AC$2:$AC$501,"计划有效")=0,"禁止开仓：请先填写止损计划",IF(账户数据!$B$9+F3*(E3-N3)>=账户数据!$B$7,"禁止开仓：风险额度不足",IF(AJ3="周期与交易预期不匹配，请重新确认",IF(账户数据!$B$23="接近锁仓","允许开仓（接近锁仓；周期需复核）","允许开仓（周期需复核）"),IF(账户数据!$B$23="接近锁仓","允许开仓（接近锁仓）","允许开仓")))))))))) | H3: 3100 | I3: 45135 | J3: 36 | K3: 32.1 | L3: =IF(K3="","",H3) | M3: 45147 | N3: 32.5 | U3: =IF(OR(AO3="",J3="",AO3<=0),"",(J3-AO3)/AO3) | V3: =IF(OR(AO3="",N3="",AO3<=0),"",(AO3-N3)/AO3) | W3: =IF(OR(U3="",V3="",V3<=0),"",U3/V3) | X3: =IF(OR(K3="",L3="",AP3=""),"",K3*L3-(E3*H3+IF(AND(AK3<>"",AL3<>""),AK3*AL3,0)+IF(AND(AM3<>"",AN3<>""),AM3*AN3,0))-IF(O3="",0,O3)-IF(P3="",0,P3)) | Y3: =IF(OR(X3="",AP3=""),"",IF((E3*H3+IF(AND(AK3<>"",AL3<>""),AK3*AL3,0)+IF(AND(AM3<>"",AN3<>""),AM3*AN3,0))+IF(O3="",0,O3)<=0,"",X3/((E3*H3+IF(AND(AK3<>"",AL3<>""),AK3*AL3,0)+IF(AND(AM3<>"",AN3<>""),AM3*AN3,0))+IF(O3="",0,O3)))) | Z3: =IF(OR(AE3="",多次统计数据!$B$8=""),"",AE3-多次统计数据!$B$8) | AA3: =IF(OR(I3="",M3="",M3<I3),"",M3-I3) | AB3: =IF(OR(A3="",多次统计数据!$B$8="",多次统计数据!$B$6<=0,多次统计数据!$B$6>=1),"",1-POWER(1+多次统计数据!$B$8,-多次统计数据!$B$6/(1-多次统计数据!$B$6))) | AC3: =IF(OR(AB3="",多次统计数据!$B$9=""),"",IF(多次统计数据!$B$9<AB3,"低于上限","达到或超过上限")) | AE3: =IF(OR(X3="",C3="",C3<=0),"",X3/C3) | AJ3: =IF(OR(AG3="",AH3=""),"",IF(OR(AND(AG3="短期博反弹",OR(AH3="1～3个交易日",AH3="4～10个交易日")),AND(AG3="突破冲新高",OR(AH3="4～10个交易日",AH3="11～20个交易日")),AND(AG3="趋势波段",OR(AH3="11～20个交易日",AH3="21～60个交易日",AH3="60个交易日以上"))),"匹配","周期与交易预期不匹配，请重新确认")) | AO3: =IF(OR(A3="",H3="",H3<=0),"",(E3*H3+IF(AND(AK3<>"",AL3<>""),AK3*AL3,0)+IF(AND(AM3<>"",AN3<>""),AM3*AN3,0))/AP3) | AP3: =IF(OR(A3="",H3="",H3<=0),"",H3+IF(AL3="",0,AL3)+IF(AN3="",0,AN3)) | AQ3: =IF(A3="","",IF(M3<>"",0,IF(OR(H3="",N3=""),"",MAX(E3-MAX(N3,IFERROR(AGGREGATE(14,6,'持仓跟踪'!$S$2:$S$501/(('持仓跟踪'!$A$2:$A$501="每日跟踪")*('持仓跟踪'!$B$2:$B$501=A3)),1),0)),0)*H3+IF(OR(AK3="",AL3=""),0,MAX(AK3-MAX(N3,IFERROR(AGGREGATE(14,6,'持仓跟踪'!$S$2:$S$501/(('持仓跟踪'!$A$2:$A$501="每日跟踪")*('持仓跟踪'!$B$2:$B$501=A3)),1),0)),0)*AL3)+IF(OR(AM3="",AN3=""),0,MAX(AM3-MAX(N3,IFERROR(AGGREGATE(14,6,'持仓跟踪'!$S$2:$S$501/(('持仓跟踪'!$A$2:$A$501="每日跟踪")*('持仓跟踪'!$B$2:$B$501=A3)),1),0)),0)*AN3)))) | AR3: =IF(A3="","",IF(OR(E3="",H3=""),"违规：第一批价格或股数缺失",IF(OR(AND(AK3="",AL3<>""),AND(AK3<>"",AL3="")),"违规：第二批价格与股数须成对填写",IF(OR(AND(AM3="",AN3<>""),AND(AM3<>"",AN3="")),"违规：第三批价格与股数须成对填写",IF(AND(OR(AM3<>"",AN3<>""),OR(AK3="",AL3="")),"违规：必须先完成第二批",IF(OR(H3<=0,H3<>INT(H3),MOD(H3,100)<>0,AND(AL3<>"",OR(AL3<=0,AL3<>INT(AL3),MOD(AL3,100)<>0)),AND(AN3<>"",OR(AN3<=0,AN3<>INT(AN3),MOD(AN3,100)<>0))),"违规：股数须为100股整数倍",IF(AND(OR(AL3<>"",AN3<>""),OR(_LockStatus="已锁仓",_LockStatus="解锁信息不完整")),"违规：锁仓期间禁止加仓",IF(AQ3>C3*D3,"违规：超过单笔风险上限",IF(SUM($AQ$2:$AQ$201)>账户数据!$B$7,"违规：超过账户风险上限","通过")))))))))
A4: 3 | B4: 长电科技 | C4: 92687 | D4: 0.02 | E4: 28.16 | F4: =IF(OR(C4="",D4="",E4="",N4="",C4<=0,D4<=0,E4<=N4),"",ROUNDDOWN((C4*D4)/(E4-N4)/100,0)*100) | G4: =IF(A4="","",IF(H4<>"","已开仓",IF(账户数据!$B$23="已锁仓","禁止开仓：连续亏损达到上限",IF(账户数据!$B$23="解锁信息不完整","禁止开仓：请完整填写解锁信息",IF(OR(F4="",E4="",N4="",E4<=N4,账户数据!$B$7=""),"",IF(OR(AG4="",AH4="",AI4=""),"禁止开仓：交易预期未填写完整",IF(COUNTIFS(持仓跟踪!$A$2:$A$501,"止损计划",持仓跟踪!$B$2:$B$501,A4,持仓跟踪!$AC$2:$AC$501,"计划有效")=0,"禁止开仓：请先填写止损计划",IF(账户数据!$B$9+F4*(E4-N4)>=账户数据!$B$7,"禁止开仓：风险额度不足",IF(AJ4="周期与交易预期不匹配，请重新确认",IF(账户数据!$B$23="接近锁仓","允许开仓（接近锁仓；周期需复核）","允许开仓（周期需复核）"),IF(账户数据!$B$23="接近锁仓","允许开仓（接近锁仓）","允许开仓")))))))))) | H4: 2800 | I4: 45226 | J4: 30 | K4: 30.2 | L4: =IF(K4="","",H4) | M4: 45231 | N4: 27.5 | R4: 下方支撑位 | S4: 前高 | U4: =IF(OR(AO4="",J4="",AO4<=0),"",(J4-AO4)/AO4) | V4: =IF(OR(AO4="",N4="",AO4<=0),"",(AO4-N4)/AO4) | W4: =IF(OR(U4="",V4="",V4<=0),"",U4/V4) | X4: =IF(OR(K4="",L4="",AP4=""),"",K4*L4-(E4*H4+IF(AND(AK4<>"",AL4<>""),AK4*AL4,0)+IF(AND(AM4<>"",AN4<>""),AM4*AN4,0))-IF(O4="",0,O4)-IF(P4="",0,P4)) | Y4: =IF(OR(X4="",AP4=""),"",IF((E4*H4+IF(AND(AK4<>"",AL4<>""),AK4*AL4,0)+IF(AND(AM4<>"",AN4<>""),AM4*AN4,0))+IF(O4="",0,O4)<=0,"",X4/((E4*H4+IF(AND(AK4<>"",AL4<>""),AK4*AL4,0)+IF(AND(AM4<>"",AN4<>""),AM4*AN4,0))+IF(O4="",0,O4)))) | Z4: =IF(OR(AE4="",多次统计数据!$B$8=""),"",AE4-多次统计数据!$B$8) | AA4: =IF(OR(I4="",M4="",M4<I4),"",M4-I4) | AB4: =IF(OR(A4="",多次统计数据!$B$8="",多次统计数据!$B$6<=0,多次统计数据!$B$6>=1),"",1-POWER(1+多次统计数据!$B$8,-多次统计数据!$B$6/(1-多次统计数据!$B$6))) | AC4: =IF(OR(AB4="",多次统计数据!$B$9=""),"",IF(多次统计数据!$B$9<AB4,"低于上限","达到或超过上限")) | AE4: =IF(OR(X4="",C4="",C4<=0),"",X4/C4) | AJ4: =IF(OR(AG4="",AH4=""),"",IF(OR(AND(AG4="短期博反弹",OR(AH4="1～3个交易日",AH4="4～10个交易日")),AND(AG4="突破冲新高",OR(AH4="4～10个交易日",AH4="11～20个交易日")),AND(AG4="趋势波段",OR(AH4="11～20个交易日",AH4="21～60个交易日",AH4="60个交易日以上"))),"匹配","周期与交易预期不匹配，请重新确认")) | AO4: =IF(OR(A4="",H4="",H4<=0),"",(E4*H4+IF(AND(AK4<>"",AL4<>""),AK4*AL4,0)+IF(AND(AM4<>"",AN4<>""),AM4*AN4,0))/AP4) | AP4: =IF(OR(A4="",H4="",H4<=0),"",H4+IF(AL4="",0,AL4)+IF(AN4="",0,AN4)) | AQ4: =IF(A4="","",IF(M4<>"",0,IF(OR(H4="",N4=""),"",MAX(E4-MAX(N4,IFERROR(AGGREGATE(14,6,'持仓跟踪'!$S$2:$S$501/(('持仓跟踪'!$A$2:$A$501="每日跟踪")*('持仓跟踪'!$B$2:$B$501=A4)),1),0)),0)*H4+IF(OR(AK4="",AL4=""),0,MAX(AK4-MAX(N4,IFERROR(AGGREGATE(14,6,'持仓跟踪'!$S$2:$S$501/(('持仓跟踪'!$A$2:$A$501="每日跟踪")*('持仓跟踪'!$B$2:$B$501=A4)),1),0)),0)*AL4)+IF(OR(AM4="",AN4=""),0,MAX(AM4-MAX(N4,IFERROR(AGGREGATE(14,6,'持仓跟踪'!$S$2:$S$501/(('持仓跟踪'!$A$2:$A$501="每日跟踪")*('持仓跟踪'!$B$2:$B$501=A4)),1),0)),0)*AN4)))) | AR4: =IF(A4="","",IF(OR(E4="",H4=""),"违规：第一批价格或股数缺失",IF(OR(AND(AK4="",AL4<>""),AND(AK4<>"",AL4="")),"违规：第二批价格与股数须成对填写",IF(OR(AND(AM4="",AN4<>""),AND(AM4<>"",AN4="")),"违规：第三批价格与股数须成对填写",IF(AND(OR(AM4<>"",AN4<>""),OR(AK4="",AL4="")),"违规：必须先完成第二批",IF(OR(H4<=0,H4<>INT(H4),MOD(H4,100)<>0,AND(AL4<>"",OR(AL4<=0,AL4<>INT(AL4),MOD(AL4,100)<>0)),AND(AN4<>"",OR(AN4<=0,AN4<>INT(AN4),MOD(AN4,100)<>0))),"违规：股数须为100股整数倍",IF(AND(OR(AL4<>"",AN4<>""),OR(_LockStatus="已锁仓",_LockStatus="解锁信息不完整")),"违规：锁仓期间禁止加仓",IF(AQ4>C4*D4,"违规：超过单笔风险上限",IF(SUM($AQ$2:$AQ$201)>账户数据!$B$7,"违规：超过账户风险上限","通过")))))))))
A5: 4 | B5: 长电科技 | C5: 98399 | D5: 0.02 | E5: 25.78 | F5: =IF(OR(C5="",D5="",E5="",N5="",C5<=0,D5<=0,E5<=N5),"",ROUNDDOWN((C5*D5)/(E5-N5)/100,0)*100) | G5: =IF(A5="","",IF(H5<>"","已开仓",IF(账户数据!$B$23="已锁仓","禁止开仓：连续亏损达到上限",IF(账户数据!$B$23="解锁信息不完整","禁止开仓：请完整填写解锁信息",IF(OR(F5="",E5="",N5="",E5<=N5,账户数据!$B$7=""),"",IF(OR(AG5="",AH5="",AI5=""),"禁止开仓：交易预期未填写完整",IF(COUNTIFS(持仓跟踪!$A$2:$A$501,"止损计划",持仓跟踪!$B$2:$B$501,A5,持仓跟踪!$AC$2:$AC$501,"计划有效")=0,"禁止开仓：请先填写止损计划",IF(账户数据!$B$9+F5*(E5-N5)>=账户数据!$B$7,"禁止开仓：风险额度不足",IF(AJ5="周期与交易预期不匹配，请重新确认",IF(账户数据!$B$23="接近锁仓","允许开仓（接近锁仓；周期需复核）","允许开仓（周期需复核）"),IF(账户数据!$B$23="接近锁仓","允许开仓（接近锁仓）","允许开仓")))))))))) | H5: 2500 | I5: 45306 | J5: 30 | K5: 24.68 | L5: =IF(K5="","",H5) | M5: 45308 | N5: 25 | R5: 下方支撑位 | S5: 前高 | U5: =IF(OR(AO5="",J5="",AO5<=0),"",(J5-AO5)/AO5) | V5: =IF(OR(AO5="",N5="",AO5<=0),"",(AO5-N5)/AO5) | W5: =IF(OR(U5="",V5="",V5<=0),"",U5/V5) | X5: =IF(OR(K5="",L5="",AP5=""),"",K5*L5-(E5*H5+IF(AND(AK5<>"",AL5<>""),AK5*AL5,0)+IF(AND(AM5<>"",AN5<>""),AM5*AN5,0))-IF(O5="",0,O5)-IF(P5="",0,P5)) | Y5: =IF(OR(X5="",AP5=""),"",IF((E5*H5+IF(AND(AK5<>"",AL5<>""),AK5*AL5,0)+IF(AND(AM5<>"",AN5<>""),AM5*AN5,0))+IF(O5="",0,O5)<=0,"",X5/((E5*H5+IF(AND(AK5<>"",AL5<>""),AK5*AL5,0)+IF(AND(AM5<>"",AN5<>""),AM5*AN5,0))+IF(O5="",0,O5)))) | Z5: =IF(OR(AE5="",多次统计数据!$B$8=""),"",AE5-多次统计数据!$B$8) | AA5: =IF(OR(I5="",M5="",M5<I5),"",M5-I5) | AB5: =IF(OR(A5="",多次统计数据!$B$8="",多次统计数据!$B$6<=0,多次统计数据!$B$6>=1),"",1-POWER(1+多次统计数据!$B$8,-多次统计数据!$B$6/(1-多次统计数据!$B$6))) | AC5: =IF(OR(AB5="",多次统计数据!$B$9=""),"",IF(多次统计数据!$B$9<AB5,"低于上限","达到或超过上限")) | AE5: =IF(OR(X5="",C5="",C5<=0),"",X5/C5) | AJ5: =IF(OR(AG5="",AH5=""),"",IF(OR(AND(AG5="短期博反弹",OR(AH5="1～3个交易日",AH5="4～10个交易日")),AND(AG5="突破冲新高",OR(AH5="4～10个交易日",AH5="11～20个交易日")),AND(AG5="趋势波段",OR(AH5="11～20个交易日",AH5="21～60个交易日",AH5="60个交易日以上"))),"匹配","周期与交易预期不匹配，请重新确认")) | AO5: =IF(OR(A5="",H5="",H5<=0),"",(E5*H5+IF(AND(AK5<>"",AL5<>""),AK5*AL5,0)+IF(AND(AM5<>"",AN5<>""),AM5*AN5,0))/AP5) | AP5: =IF(OR(A5="",H5="",H5<=0),"",H5+IF(AL5="",0,AL5)+IF(AN5="",0,AN5)) | AQ5: =IF(A5="","",IF(M5<>"",0,IF(OR(H5="",N5=""),"",MAX(E5-MAX(N5,IFERROR(AGGREGATE(14,6,'持仓跟踪'!$S$2:$S$501/(('持仓跟踪'!$A$2:$A$501="每日跟踪")*('持仓跟踪'!$B$2:$B$501=A5)),1),0)),0)*H5+IF(OR(AK5="",AL5=""),0,MAX(AK5-MAX(N5,IFERROR(AGGREGATE(14,6,'持仓跟踪'!$S$2:$S$501/(('持仓跟踪'!$A$2:$A$501="每日跟踪")*('持仓跟踪'!$B$2:$B$501=A5)),1),0)),0)*AL5)+IF(OR(AM5="",AN5=""),0,MAX(AM5-MAX(N5,IFERROR(AGGREGATE(14,6,'持仓跟踪'!$S$2:$S$501/(('持仓跟踪'!$A$2:$A$501="每日跟踪")*('持仓跟踪'!$B$2:$B$501=A5)),1),0)),0)*AN5)))) | AR5: =IF(A5="","",IF(OR(E5="",H5=""),"违规：第一批价格或股数缺失",IF(OR(AND(AK5="",AL5<>""),AND(AK5<>"",AL5="")),"违规：第二批价格与股数须成对填写",IF(OR(AND(AM5="",AN5<>""),AND(AM5<>"",AN5="")),"违规：第三批价格与股数须成对填写",IF(AND(OR(AM5<>"",AN5<>""),OR(AK5="",AL5="")),"违规：必须先完成第二批",IF(OR(H5<=0,H5<>INT(H5),MOD(H5,100)<>0,AND(AL5<>"",OR(AL5<=0,AL5<>INT(AL5),MOD(AL5,100)<>0)),AND(AN5<>"",OR(AN5<=0,AN5<>INT(AN5),MOD(AN5,100)<>0))),"违规：股数须为100股整数倍",IF(AND(OR(AL5<>"",AN5<>""),OR(_LockStatus="已锁仓",_LockStatus="解锁信息不完整")),"违规：锁仓期间禁止加仓",IF(AQ5>C5*D5,"违规：超过单笔风险上限",IF(SUM($AQ$2:$AQ$201)>账户数据!$B$7,"违规：超过账户风险上限","通过")))))))))
A6: 5 | B6: 长电科技 | C6: 95649 | D6: 0.02 | E6: 35 | F6: =IF(OR(C6="",D6="",E6="",N6="",C6<=0,D6<=0,E6<=N6),"",ROUNDDOWN((C6*D6)/(E6-N6)/100,0)*100) | G6: =IF(A6="","",IF(H6<>"","已开仓",IF(账户数据!$B$23="已锁仓","禁止开仓：连续亏损达到上限",IF(账户数据!$B$23="解锁信息不完整","禁止开仓：请完整填写解锁信息",IF(OR(F6="",E6="",N6="",E6<=N6,账户数据!$B$7=""),"",IF(OR(AG6="",AH6="",AI6=""),"禁止开仓：交易预期未填写完整",IF(COUNTIFS(持仓跟踪!$A$2:$A$501,"止损计划",持仓跟踪!$B$2:$B$501,A6,持仓跟踪!$AC$2:$AC$501,"计划有效")=0,"禁止开仓：请先填写止损计划",IF(账户数据!$B$9+F6*(E6-N6)>=账户数据!$B$7,"禁止开仓：风险额度不足",IF(AJ6="周期与交易预期不匹配，请重新确认",IF(账户数据!$B$23="接近锁仓","允许开仓（接近锁仓；周期需复核）","允许开仓（周期需复核）"),IF(账户数据!$B$23="接近锁仓","允许开仓（接近锁仓）","允许开仓")))))))))) | H6: 900 | I6: 45491 | J6: 40 | K6: 31.84 | L6: =IF(K6="","",H6) | M6: 45498 | N6: 33 | R6: 下发支撑位 | S6: 从收益率的角度推断 | U6: =IF(OR(AO6="",J6="",AO6<=0),"",(J6-AO6)/AO6) | V6: =IF(OR(AO6="",N6="",AO6<=0),"",(AO6-N6)/AO6) | W6: =IF(OR(U6="",V6="",V6<=0),"",U6/V6) | X6: =IF(OR(K6="",L6="",AP6=""),"",K6*L6-(E6*H6+IF(AND(AK6<>"",AL6<>""),AK6*AL6,0)+IF(AND(AM6<>"",AN6<>""),AM6*AN6,0))-IF(O6="",0,O6)-IF(P6="",0,P6)) | Y6: =IF(OR(X6="",AP6=""),"",IF((E6*H6+IF(AND(AK6<>"",AL6<>""),AK6*AL6,0)+IF(AND(AM6<>"",AN6<>""),AM6*AN6,0))+IF(O6="",0,O6)<=0,"",X6/((E6*H6+IF(AND(AK6<>"",AL6<>""),AK6*AL6,0)+IF(AND(AM6<>"",AN6<>""),AM6*AN6,0))+IF(O6="",0,O6)))) | Z6: =IF(OR(AE6="",多次统计数据!$B$8=""),"",AE6-多次统计数据!$B$8) | AA6: =IF(OR(I6="",M6="",M6<I6),"",M6-I6) | AB6: =IF(OR(A6="",多次统计数据!$B$8="",多次统计数据!$B$6<=0,多次统计数据!$B$6>=1),"",1-POWER(1+多次统计数据!$B$8,-多次统计数据!$B$6/(1-多次统计数据!$B$6))) | AC6: =IF(OR(AB6="",多次统计数据!$B$9=""),"",IF(多次统计数据!$B$9<AB6,"低于上限","达到或超过上限")) | AE6: =IF(OR(X6="",C6="",C6<=0),"",X6/C6) | AJ6: =IF(OR(AG6="",AH6=""),"",IF(OR(AND(AG6="短期博反弹",OR(AH6="1～3个交易日",AH6="4～10个交易日")),AND(AG6="突破冲新高",OR(AH6="4～10个交易日",AH6="11～20个交易日")),AND(AG6="趋势波段",OR(AH6="11～20个交易日",AH6="21～60个交易日",AH6="60个交易日以上"))),"匹配","周期与交易预期不匹配，请重新确认")) | AO6: =IF(OR(A6="",H6="",H6<=0),"",(E6*H6+IF(AND(AK6<>"",AL6<>""),AK6*AL6,0)+IF(AND(AM6<>"",AN6<>""),AM6*AN6,0))/AP6) | AP6: =IF(OR(A6="",H6="",H6<=0),"",H6+IF(AL6="",0,AL6)+IF(AN6="",0,AN6)) | AQ6: =IF(A6="","",IF(M6<>"",0,IF(OR(H6="",N6=""),"",MAX(E6-MAX(N6,IFERROR(AGGREGATE(14,6,'持仓跟踪'!$S$2:$S$501/(('持仓跟踪'!$A$2:$A$501="每日跟踪")*('持仓跟踪'!$B$2:$B$501=A6)),1),0)),0)*H6+IF(OR(AK6="",AL6=""),0,MAX(AK6-MAX(N6,IFERROR(AGGREGATE(14,6,'持仓跟踪'!$S$2:$S$501/(('持仓跟踪'!$A$2:$A$501="每日跟踪")*('持仓跟踪'!$B$2:$B$501=A6)),1),0)),0)*AL6)+IF(OR(AM6="",AN6=""),0,MAX(AM6-MAX(N6,IFERROR(AGGREGATE(14,6,'持仓跟踪'!$S$2:$S$501/(('持仓跟踪'!$A$2:$A$501="每日跟踪")*('持仓跟踪'!$B$2:$B$501=A6)),1),0)),0)*AN6)))) | AR6: =IF(A6="","",IF(OR(E6="",H6=""),"违规：第一批价格或股数缺失",IF(OR(AND(AK6="",AL6<>""),AND(AK6<>"",AL6="")),"违规：第二批价格与股数须成对填写",IF(OR(AND(AM6="",AN6<>""),AND(AM6<>"",AN6="")),"违规：第三批价格与股数须成对填写",IF(AND(OR(AM6<>"",AN6<>""),OR(AK6="",AL6="")),"违规：必须先完成第二批",IF(OR(H6<=0,H6<>INT(H6),MOD(H6,100)<>0,AND(AL6<>"",OR(AL6<=0,AL6<>INT(AL6),MOD(AL6,100)<>0)),AND(AN6<>"",OR(AN6<=0,AN6<>INT(AN6),MOD(AN6,100)<>0))),"违规：股数须为100股整数倍",IF(AND(OR(AL6<>"",AN6<>""),OR(_LockStatus="已锁仓",_LockStatus="解锁信息不完整")),"违规：锁仓期间禁止加仓",IF(AQ6>C6*D6,"违规：超过单笔风险上限",IF(SUM($AQ$2:$AQ$201)>账户数据!$B$7,"违规：超过账户风险上限","通过")))))))))
A7: 6 | B7: 长电科技 | C7: 92805 | D7: 0.02 | E7: 30.78 | F7: =IF(OR(C7="",D7="",E7="",N7="",C7<=0,D7<=0,E7<=N7),"",ROUNDDOWN((C7*D7)/(E7-N7)/100,0)*100) | G7: =IF(A7="","",IF(H7<>"","已开仓",IF(账户数据!$B$23="已锁仓","禁止开仓：连续亏损达到上限",IF(账户数据!$B$23="解锁信息不完整","禁止开仓：请完整填写解锁信息",IF(OR(F7="",E7="",N7="",E7<=N7,账户数据!$B$7=""),"",IF(OR(AG7="",AH7="",AI7=""),"禁止开仓：交易预期未填写完整",IF(COUNTIFS(持仓跟踪!$A$2:$A$501,"止损计划",持仓跟踪!$B$2:$B$501,A7,持仓跟踪!$AC$2:$AC$501,"计划有效")=0,"禁止开仓：请先填写止损计划",IF(账户数据!$B$9+F7*(E7-N7)>=账户数据!$B$7,"禁止开仓：风险额度不足",IF(AJ7="周期与交易预期不匹配，请重新确认",IF(账户数据!$B$23="接近锁仓","允许开仓（接近锁仓；周期需复核）","允许开仓（周期需复核）"),IF(账户数据!$B$23="接近锁仓","允许开仓（接近锁仓）","允许开仓")))))))))) | H7: 6600 | I7: 45537 | J7: 34 | K7: 30.23 | L7: =IF(K7="","",H7) | M7: 45559 | N7: 30.5 | U7: =IF(OR(AO7="",J7="",AO7<=0),"",(J7-AO7)/AO7) | V7: =IF(OR(AO7="",N7="",AO7<=0),"",(AO7-N7)/AO7) | W7: =IF(OR(U7="",V7="",V7<=0),"",U7/V7) | X7: =IF(OR(K7="",L7="",AP7=""),"",K7*L7-(E7*H7+IF(AND(AK7<>"",AL7<>""),AK7*AL7,0)+IF(AND(AM7<>"",AN7<>""),AM7*AN7,0))-IF(O7="",0,O7)-IF(P7="",0,P7)) | Y7: =IF(OR(X7="",AP7=""),"",IF((E7*H7+IF(AND(AK7<>"",AL7<>""),AK7*AL7,0)+IF(AND(AM7<>"",AN7<>""),AM7*AN7,0))+IF(O7="",0,O7)<=0,"",X7/((E7*H7+IF(AND(AK7<>"",AL7<>""),AK7*AL7,0)+IF(AND(AM7<>"",AN7<>""),AM7*AN7,0))+IF(O7="",0,O7)))) | Z7: =IF(OR(AE7="",多次统计数据!$B$8=""),"",AE7-多次统计数据!$B$8) | AA7: =IF(OR(I7="",M7="",M7<I7),"",M7-I7) | AB7: =IF(OR(A7="",多次统计数据!$B$8="",多次统计数据!$B$6<=0,多次统计数据!$B$6>=1),"",1-POWER(1+多次统计数据!$B$8,-多次统计数据!$B$6/(1-多次统计数据!$B$6))) | AC7: =IF(OR(AB7="",多次统计数据!$B$9=""),"",IF(多次统计数据!$B$9<AB7,"低于上限","达到或超过上限")) | AE7: =IF(OR(X7="",C7="",C7<=0),"",X7/C7) | AJ7: =IF(OR(AG7="",AH7=""),"",IF(OR(AND(AG7="短期博反弹",OR(AH7="1～3个交易日",AH7="4～10个交易日")),AND(AG7="突破冲新高",OR(AH7="4～10个交易日",AH7="11～20个交易日")),AND(AG7="趋势波段",OR(AH7="11～20个交易日",AH7="21～60个交易日",AH7="60个交易日以上"))),"匹配","周期与交易预期不匹配，请重新确认")) | AO7: =IF(OR(A7="",H7="",H7<=0),"",(E7*H7+IF(AND(AK7<>"",AL7<>""),AK7*AL7,0)+IF(AND(AM7<>"",AN7<>""),AM7*AN7,0))/AP7) | AP7: =IF(OR(A7="",H7="",H7<=0),"",H7+IF(AL7="",0,AL7)+IF(AN7="",0,AN7)) | AQ7: =IF(A7="","",IF(M7<>"",0,IF(OR(H7="",N7=""),"",MAX(E7-MAX(N7,IFERROR(AGGREGATE(14,6,'持仓跟踪'!$S$2:$S$501/(('持仓跟踪'!$A$2:$A$501="每日跟踪")*('持仓跟踪'!$B$2:$B$501=A7)),1),0)),0)*H7+IF(OR(AK7="",AL7=""),0,MAX(AK7-MAX(N7,IFERROR(AGGREGATE(14,6,'持仓跟踪'!$S$2:$S$501/(('持仓跟踪'!$A$2:$A$501="每日跟踪")*('持仓跟踪'!$B$2:$B$501=A7)),1),0)),0)*AL7)+IF(OR(AM7="",AN7=""),0,MAX(AM7-MAX(N7,IFERROR(AGGREGATE(14,6,'持仓跟踪'!$S$2:$S$501/(('持仓跟踪'!$A$2:$A$501="每日跟踪")*('持仓跟踪'!$B$2:$B$501=A7)),1),0)),0)*AN7)))) | AR7: =IF(A7="","",IF(OR(E7="",H7=""),"违规：第一批价格或股数缺失",IF(OR(AND(AK7="",AL7<>""),AND(AK7<>"",AL7="")),"违规：第二批价格与股数须成对填写",IF(OR(AND(AM7="",AN7<>""),AND(AM7<>"",AN7="")),"违规：第三批价格与股数须成对填写",IF(AND(OR(AM7<>"",AN7<>""),OR(AK7="",AL7="")),"违规：必须先完成第二批",IF(OR(H7<=0,H7<>INT(H7),MOD(H7,100)<>0,AND(AL7<>"",OR(AL7<=0,AL7<>INT(AL7),MOD(AL7,100)<>0)),AND(AN7<>"",OR(AN7<=0,AN7<>INT(AN7),MOD(AN7,100)<>0))),"违规：股数须为100股整数倍",IF(AND(OR(AL7<>"",AN7<>""),OR(_LockStatus="已锁仓",_LockStatus="解锁信息不完整")),"违规：锁仓期间禁止加仓",IF(AQ7>C7*D7,"违规：超过单笔风险上限",IF(SUM($AQ$2:$AQ$201)>账户数据!$B$7,"违规：超过账户风险上限","通过")))))))))
F8: =IF(OR(C8="",D8="",E8="",N8="",C8<=0,D8<=0,E8<=N8),"",ROUNDDOWN((C8*D8)/(E8-N8)/100,0)*100) | G8: =IF(A8="","",IF(H8<>"","已开仓",IF(账户数据!$B$23="已锁仓","禁止开仓：连续亏损达到上限",IF(账户数据!$B$23="解锁信息不完整","禁止开仓：请完整填写解锁信息",IF(OR(F8="",E8="",N8="",E8<=N8,账户数据!$B$7=""),"",IF(OR(AG8="",AH8="",AI8=""),"禁止开仓：交易预期未填写完整",IF(COUNTIFS(持仓跟踪!$A$2:$A$501,"止损计划",持仓跟踪!$B$2:$B$501,A8,持仓跟踪!$AC$2:$AC$501,"计划有效")=0,"禁止开仓：请先填写止损计划",IF(账户数据!$B$9+F8*(E8-N8)>=账户数据!$B$7,"禁止开仓：风险额度不足",IF(AJ8="周期与交易预期不匹配，请重新确认",IF(账户数据!$B$23="接近锁仓","允许开仓（接近锁仓；周期需复核）","允许开仓（周期需复核）"),IF(账户数据!$B$23="接近锁仓","允许开仓（接近锁仓）","允许开仓")))))))))) | L8: =IF(K8="","",H8) | U8: =IF(OR(AO8="",J8="",AO8<=0),"",(J8-AO8)/AO8) | V8: =IF(OR(AO8="",N8="",AO8<=0),"",(AO8-N8)/AO8) | W8: =IF(OR(U8="",V8="",V8<=0),"",U8/V8) | X8: =IF(OR(K8="",L8="",AP8=""),"",K8*L8-(E8*H8+IF(AND(AK8<>"",AL8<>""),AK8*AL8,0)+IF(AND(AM8<>"",AN8<>""),AM8*AN8,0))-IF(O8="",0,O8)-IF(P8="",0,P8)) | Y8: =IF(OR(X8="",AP8=""),"",IF((E8*H8+IF(AND(AK8<>"",AL8<>""),AK8*AL8,0)+IF(AND(AM8<>"",AN8<>""),AM8*AN8,0))+IF(O8="",0,O8)<=0,"",X8/((E8*H8+IF(AND(AK8<>"",AL8<>""),AK8*AL8,0)+IF(AND(AM8<>"",AN8<>""),AM8*AN8,0))+IF(O8="",0,O8)))) | Z8: =IF(OR(AE8="",多次统计数据!$B$8=""),"",AE8-多次统计数据!$B$8) | AA8: =IF(OR(I8="",M8="",M8<I8),"",M8-I8) | AB8: =IF(OR(A8="",多次统计数据!$B$8="",多次统计数据!$B$6<=0,多次统计数据!$B$6>=1),"",1-POWER(1+多次统计数据!$B$8,-多次统计数据!$B$6/(1-多次统计数据!$B$6))) | AC8: =IF(OR(AB8="",多次统计数据!$B$9=""),"",IF(多次统计数据!$B$9<AB8,"低于上限","达到或超过上限")) | AE8: =IF(OR(X8="",C8="",C8<=0),"",X8/C8) | AJ8: =IF(OR(AG8="",AH8=""),"",IF(OR(AND(AG8="短期博反弹",OR(AH8="1～3个交易日",AH8="4～10个交易日")),AND(AG8="突破冲新高",OR(AH8="4～10个交易日",AH8="11～20个交易日")),AND(AG8="趋势波段",OR(AH8="11～20个交易日",AH8="21～60个交易日",AH8="60个交易日以上"))),"匹配","周期与交易预期不匹配，请重新确认")) | AO8: =IF(OR(A8="",H8="",H8<=0),"",(E8*H8+IF(AND(AK8<>"",AL8<>""),AK8*AL8,0)+IF(AND(AM8<>"",AN8<>""),AM8*AN8,0))/AP8) | AP8: =IF(OR(A8="",H8="",H8<=0),"",H8+IF(AL8="",0,AL8)+IF(AN8="",0,AN8)) | AQ8: =IF(A8="","",IF(M8<>"",0,IF(OR(H8="",N8=""),"",MAX(E8-MAX(N8,IFERROR(AGGREGATE(14,6,'持仓跟踪'!$S$2:$S$501/(('持仓跟踪'!$A$2:$A$501="每日跟踪")*('持仓跟踪'!$B$2:$B$501=A8)),1),0)),0)*H8+IF(OR(AK8="",AL8=""),0,MAX(AK8-MAX(N8,IFERROR(AGGREGATE(14,6,'持仓跟踪'!$S$2:$S$501/(('持仓跟踪'!$A$2:$A$501="每日跟踪")*('持仓跟踪'!$B$2:$B$501=A8)),1),0)),0)*AL8)+IF(OR(AM8="",AN8=""),0,MAX(AM8-MAX(N8,IFERROR(AGGREGATE(14,6,'持仓跟踪'!$S$2:$S$501/(('持仓跟踪'!$A$2:$A$501="每日跟踪")*('持仓跟踪'!$B$2:$B$501=A8)),1),0)),0)*AN8)))) | AR8: =IF(A8="","",IF(OR(E8="",H8=""),"违规：第一批价格或股数缺失",IF(OR(AND(AK8="",AL8<>""),AND(AK8<>"",AL8="")),"违规：第二批价格与股数须成对填写",IF(OR(AND(AM8="",AN8<>""),AND(AM8<>"",AN8="")),"违规：第三批价格与股数须成对填写",IF(AND(OR(AM8<>"",AN8<>""),OR(AK8="",AL8="")),"违规：必须先完成第二批",IF(OR(H8<=0,H8<>INT(H8),MOD(H8,100)<>0,AND(AL8<>"",OR(AL8<=0,AL8<>INT(AL8),MOD(AL8,100)<>0)),AND(AN8<>"",OR(AN8<=0,AN8<>INT(AN8),MOD(AN8,100)<>0))),"违规：股数须为100股整数倍",IF(AND(OR(AL8<>"",AN8<>""),OR(_LockStatus="已锁仓",_LockStatus="解锁信息不完整")),"违规：锁仓期间禁止加仓",IF(AQ8>C8*D8,"违规：超过单笔风险上限",IF(SUM($AQ$2:$AQ$201)>账户数据!$B$7,"违规：超过账户风险上限","通过")))))))))
F9: =IF(OR(C9="",D9="",E9="",N9="",C9<=0,D9<=0,E9<=N9),"",ROUNDDOWN((C9*D9)/(E9-N9)/100,0)*100) | G9: =IF(A9="","",IF(H9<>"","已开仓",IF(账户数据!$B$23="已锁仓","禁止开仓：连续亏损达到上限",IF(账户数据!$B$23="解锁信息不完整","禁止开仓：请完整填写解锁信息",IF(OR(F9="",E9="",N9="",E9<=N9,账户数据!$B$7=""),"",IF(OR(AG9="",AH9="",AI9=""),"禁止开仓：交易预期未填写完整",IF(COUNTIFS(持仓跟踪!$A$2:$A$501,"止损计划",持仓跟踪!$B$2:$B$501,A9,持仓跟踪!$AC$2:$AC$501,"计划有效")=0,"禁止开仓：请先填写止损计划",IF(账户数据!$B$9+F9*(E9-N9)>=账户数据!$B$7,"禁止开仓：风险额度不足",IF(AJ9="周期与交易预期不匹配，请重新确认",IF(账户数据!$B$23="接近锁仓","允许开仓（接近锁仓；周期需复核）","允许开仓（周期需复核）"),IF(账户数据!$B$23="接近锁仓","允许开仓（接近锁仓）","允许开仓")))))))))) | L9: =IF(K9="","",H9) | U9: =IF(OR(AO9="",J9="",AO9<=0),"",(J9-AO9)/AO9) | V9: =IF(OR(AO9="",N9="",AO9<=0),"",(AO9-N9)/AO9) | W9: =IF(OR(U9="",V9="",V9<=0),"",U9/V9) | X9: =IF(OR(K9="",L9="",AP9=""),"",K9*L9-(E9*H9+IF(AND(AK9<>"",AL9<>""),AK9*AL9,0)+IF(AND(AM9<>"",AN9<>""),AM9*AN9,0))-IF(O9="",0,O9)-IF(P9="",0,P9)) | Y9: =IF(OR(X9="",AP9=""),"",IF((E9*H9+IF(AND(AK9<>"",AL9<>""),AK9*AL9,0)+IF(AND(AM9<>"",AN9<>""),AM9*AN9,0))+IF(O9="",0,O9)<=0,"",X9/((E9*H9+IF(AND(AK9<>"",AL9<>""),AK9*AL9,0)+IF(AND(AM9<>"",AN9<>""),AM9*AN9,0))+IF(O9="",0,O9)))) | Z9: =IF(OR(AE9="",多次统计数据!$B$8=""),"",AE9-多次统计数据!$B$8) | AA9: =IF(OR(I9="",M9="",M9<I9),"",M9-I9) | AB9: =IF(OR(A9="",多次统计数据!$B$8="",多次统计数据!$B$6<=0,多次统计数据!$B$6>=1),"",1-POWER(1+多次统计数据!$B$8,-多次统计数据!$B$6/(1-多次统计数据!$B$6))) | AC9: =IF(OR(AB9="",多次统计数据!$B$9=""),"",IF(多次统计数据!$B$9<AB9,"低于上限","达到或超过上限")) | AE9: =IF(OR(X9="",C9="",C9<=0),"",X9/C9) | AJ9: =IF(OR(AG9="",AH9=""),"",IF(OR(AND(AG9="短期博反弹",OR(AH9="1～3个交易日",AH9="4～10个交易日")),AND(AG9="突破冲新高",OR(AH9="4～10个交易日",AH9="11～20个交易日")),AND(AG9="趋势波段",OR(AH9="11～20个交易日",AH9="21～60个交易日",AH9="60个交易日以上"))),"匹配","周期与交易预期不匹配，请重新确认")) | AO9: =IF(OR(A9="",H9="",H9<=0),"",(E9*H9+IF(AND(AK9<>"",AL9<>""),AK9*AL9,0)+IF(AND(AM9<>"",AN9<>""),AM9*AN9,0))/AP9) | AP9: =IF(OR(A9="",H9="",H9<=0),"",H9+IF(AL9="",0,AL9)+IF(AN9="",0,AN9)) | AQ9: =IF(A9="","",IF(M9<>"",0,IF(OR(H9="",N9=""),"",MAX(E9-MAX(N9,IFERROR(AGGREGATE(14,6,'持仓跟踪'!$S$2:$S$501/(('持仓跟踪'!$A$2:$A$501="每日跟踪")*('持仓跟踪'!$B$2:$B$501=A9)),1),0)),0)*H9+IF(OR(AK9="",AL9=""),0,MAX(AK9-MAX(N9,IFERROR(AGGREGATE(14,6,'持仓跟踪'!$S$2:$S$501/(('持仓跟踪'!$A$2:$A$501="每日跟踪")*('持仓跟踪'!$B$2:$B$501=A9)),1),0)),0)*AL9)+IF(OR(AM9="",AN9=""),0,MAX(AM9-MAX(N9,IFERROR(AGGREGATE(14,6,'持仓跟踪'!$S$2:$S$501/(('持仓跟踪'!$A$2:$A$501="每日跟踪")*('持仓跟踪'!$B$2:$B$501=A9)),1),0)),0)*AN9)))) | AR9: =IF(A9="","",IF(OR(E9="",H9=""),"违规：第一批价格或股数缺失",IF(OR(AND(AK9="",AL9<>""),AND(AK9<>"",AL9="")),"违规：第二批价格与股数须成对填写",IF(OR(AND(AM9="",AN9<>""),AND(AM9<>"",AN9="")),"违规：第三批价格与股数须成对填写",IF(AND(OR(AM9<>"",AN9<>""),OR(AK9="",AL9="")),"违规：必须先完成第二批",IF(OR(H9<=0,H9<>INT(H9),MOD(H9,100)<>0,AND(AL9<>"",OR(AL9<=0,AL9<>INT(AL9),MOD(AL9,100)<>0)),AND(AN9<>"",OR(AN9<=0,AN9<>INT(AN9),MOD(AN9,100)<>0))),"违规：股数须为100股整数倍",IF(AND(OR(AL9<>"",AN9<>""),OR(_LockStatus="已锁仓",_LockStatus="解锁信息不完整")),"违规：锁仓期间禁止加仓",IF(AQ9>C9*D9,"违规：超过单笔风险上限",IF(SUM($AQ$2:$AQ$201)>账户数据!$B$7,"违规：超过账户风险上限","通过")))))))))
A10: 9 | B10: 北方稀土 | C10: 89175 | D10: 0.02 | E10: 16.87 | F10: =IF(OR(C10="",D10="",E10="",N10="",C10<=0,D10<=0,E10<=N10),"",ROUNDDOWN((C10*D10)/(E10-N10)/100,0)*100) | G10: =IF(A10="","",IF(H10<>"","已开仓",IF(账户数据!$B$23="已锁仓","禁止开仓：连续亏损达到上限",IF(账户数据!$B$23="解锁信息不完整","禁止开仓：请完整填写解锁信息",IF(OR(F10="",E10="",N10="",E10<=N10,账户数据!$B$7=""),"",IF(OR(AG10="",AH10="",AI10=""),"禁止开仓：交易预期未填写完整",IF(COUNTIFS(持仓跟踪!$A$2:$A$501,"止损计划",持仓跟踪!$B$2:$B$501,A10,持仓跟踪!$AC$2:$AC$501,"计划有效")=0,"禁止开仓：请先填写止损计划",IF(账户数据!$B$9+F10*(E10-N10)>=账户数据!$B$7,"禁止开仓：风险额度不足",IF(AJ10="周期与交易预期不匹配，请重新确认",IF(账户数据!$B$23="接近锁仓","允许开仓（接近锁仓；周期需复核）","允许开仓（周期需复核）"),IF(账户数据!$B$23="接近锁仓","允许开仓（接近锁仓）","允许开仓")))))))))) | H10: 4200 | I10: 45559 | J10: 18 | K10: 19.73 | L10: =IF(K10="","",H10) | M10: 45576 | N10: 16.45 | R10: 下方支撑位 | S10: 前方高点，整数位，凑一下啊盈亏比 | U10: =IF(OR(AO10="",J10="",AO10<=0),"",(J10-AO10)/AO10) | V10: =IF(OR(AO10="",N10="",AO10<=0),"",(AO10-N10)/AO10) | W10: =IF(OR(U10="",V10="",V10<=0),"",U10/V10) | X10: =IF(OR(K10="",L10="",AP10=""),"",K10*L10-(E10*H10+IF(AND(AK10<>"",AL10<>""),AK10*AL10,0)+IF(AND(AM10<>"",AN10<>""),AM10*AN10,0))-IF(O10="",0,O10)-IF(P10="",0,P10)) | Y10: =IF(OR(X10="",AP10=""),"",IF((E10*H10+IF(AND(AK10<>"",AL10<>""),AK10*AL10,0)+IF(AND(AM10<>"",AN10<>""),AM10*AN10,0))+IF(O10="",0,O10)<=0,"",X10/((E10*H10+IF(AND(AK10<>"",AL10<>""),AK10*AL10,0)+IF(AND(AM10<>"",AN10<>""),AM10*AN10,0))+IF(O10="",0,O10)))) | Z10: =IF(OR(AE10="",多次统计数据!$B$8=""),"",AE10-多次统计数据!$B$8) | AA10: =IF(OR(I10="",M10="",M10<I10),"",M10-I10) | AB10: =IF(OR(A10="",多次统计数据!$B$8="",多次统计数据!$B$6<=0,多次统计数据!$B$6>=1),"",1-POWER(1+多次统计数据!$B$8,-多次统计数据!$B$6/(1-多次统计数据!$B$6))) | AC10: =IF(OR(AB10="",多次统计数据!$B$9=""),"",IF(多次统计数据!$B$9<AB10,"低于上限","达到或超过上限")) | AE10: =IF(OR(X10="",C10="",C10<=0),"",X10/C10) | AJ10: =IF(OR(AG10="",AH10=""),"",IF(OR(AND(AG10="短期博反弹",OR(AH10="1～3个交易日",AH10="4～10个交易日")),AND(AG10="突破冲新高",OR(AH10="4～10个交易日",AH10="11～20个交易日")),AND(AG10="趋势波段",OR(AH10="11～20个交易日",AH10="21～60个交易日",AH10="60个交易日以上"))),"匹配","周期与交易预期不匹配，请重新确认")) | AO10: =IF(OR(A10="",H10="",H10<=0),"",(E10*H10+IF(AND(AK10<>"",AL10<>""),AK10*AL10,0)+IF(AND(AM10<>"",AN10<>""),AM10*AN10,0))/AP10) | AP10: =IF(OR(A10="",H10="",H10<=0),"",H10+IF(AL10="",0,AL10)+IF(AN10="",0,AN10)) | AQ10: =IF(A10="","",IF(M10<>"",0,IF(OR(H10="",N10=""),"",MAX(E10-MAX(N10,IFERROR(AGGREGATE(14,6,'持仓跟踪'!$S$2:$S$501/(('持仓跟踪'!$A$2:$A$501="每日跟踪")*('持仓跟踪'!$B$2:$B$501=A10)),1),0)),0)*H10+IF(OR(AK10="",AL10=""),0,MAX(AK10-MAX(N10,IFERROR(AGGREGATE(14,6,'持仓跟踪'!$S$2:$S$501/(('持仓跟踪'!$A$2:$A$501="每日跟踪")*('持仓跟踪'!$B$2:$B$501=A10)),1),0)),0)*AL10)+IF(OR(AM10="",AN10=""),0,MAX(AM10-MAX(N10,IFERROR(AGGREGATE(14,6,'持仓跟踪'!$S$2:$S$501/(('持仓跟踪'!$A$2:$A$501="每日跟踪")*('持仓跟踪'!$B$2:$B$501=A10)),1),0)),0)*AN10)))) | AR10: =IF(A10="","",IF(OR(E10="",H10=""),"违规：第一批价格或股数缺失",IF(OR(AND(AK10="",AL10<>""),AND(AK10<>"",AL10="")),"违规：第二批价格与股数须成对填写",IF(OR(AND(AM10="",AN10<>""),AND(AM10<>"",AN10="")),"违规：第三批价格与股数须成对填写",IF(AND(OR(AM10<>"",AN10<>""),OR(AK10="",AL10="")),"违规：必须先完成第二批",IF(OR(H10<=0,H10<>INT(H10),MOD(H10,100)<>0,AND(AL10<>"",OR(AL10<=0,AL10<>INT(AL10),MOD(AL10,100)<>0)),AND(AN10<>"",OR(AN10<=0,AN10<>INT(AN10),MOD(AN10,100)<>0))),"违规：股数须为100股整数倍",IF(AND(OR(AL10<>"",AN10<>""),OR(_LockStatus="已锁仓",_LockStatus="解锁信息不完整")),"违规：锁仓期间禁止加仓",IF(AQ10>C10*D10,"违规：超过单笔风险上限",IF(SUM($AQ$2:$AQ$201)>账户数据!$B$7,"违规：超过账户风险上限","通过")))))))))
A11: 10 | B11: 北方稀土 | C11: 101187 | D11: 0.02 | E11: 24.41 | F11: =IF(OR(C11="",D11="",E11="",N11="",C11<=0,D11<=0,E11<=N11),"",ROUNDDOWN((C11*D11)/(E11-N11)/100,0)*100) | G11: =IF(A11="","",IF(H11<>"","已开仓",IF(账户数据!$B$23="已锁仓","禁止开仓：连续亏损达到上限",IF(账户数据!$B$23="解锁信息不完整","禁止开仓：请完整填写解锁信息",IF(OR(F11="",E11="",N11="",E11<=N11,账户数据!$B$7=""),"",IF(OR(AG11="",AH11="",AI11=""),"禁止开仓：交易预期未填写完整",IF(COUNTIFS(持仓跟踪!$A$2:$A$501,"止损计划",持仓跟踪!$B$2:$B$501,A11,持仓跟踪!$AC$2:$AC$501,"计划有效")=0,"禁止开仓：请先填写止损计划",IF(账户数据!$B$9+F11*(E11-N11)>=账户数据!$B$7,"禁止开仓：风险额度不足",IF(AJ11="周期与交易预期不匹配，请重新确认",IF(账户数据!$B$23="接近锁仓","允许开仓（接近锁仓；周期需复核）","允许开仓（周期需复核）"),IF(账户数据!$B$23="接近锁仓","允许开仓（接近锁仓）","允许开仓")))))))))) | H11: 1800 | I11: 45783 | J11: 26.8 | K11: 23.19 | L11: =IF(K11="","",H11) | M11: 45799 | N11: 23.3 | U11: =IF(OR(AO11="",J11="",AO11<=0),"",(J11-AO11)/AO11) | V11: =IF(OR(AO11="",N11="",AO11<=0),"",(AO11-N11)/AO11) | W11: =IF(OR(U11="",V11="",V11<=0),"",U11/V11) | X11: =IF(OR(K11="",L11="",AP11=""),"",K11*L11-(E11*H11+IF(AND(AK11<>"",AL11<>""),AK11*AL11,0)+IF(AND(AM11<>"",AN11<>""),AM11*AN11,0))-IF(O11="",0,O11)-IF(P11="",0,P11)) | Y11: =IF(OR(X11="",AP11=""),"",IF((E11*H11+IF(AND(AK11<>"",AL11<>""),AK11*AL11,0)+IF(AND(AM11<>"",AN11<>""),AM11*AN11,0))+IF(O11="",0,O11)<=0,"",X11/((E11*H11+IF(AND(AK11<>"",AL11<>""),AK11*AL11,0)+IF(AND(AM11<>"",AN11<>""),AM11*AN11,0))+IF(O11="",0,O11)))) | Z11: =IF(OR(AE11="",多次统计数据!$B$8=""),"",AE11-多次统计数据!$B$8) | AA11: =IF(OR(I11="",M11="",M11<I11),"",M11-I11) | AB11: =IF(OR(A11="",多次统计数据!$B$8="",多次统计数据!$B$6<=0,多次统计数据!$B$6>=1),"",1-POWER(1+多次统计数据!$B$8,-多次统计数据!$B$6/(1-多次统计数据!$B$6))) | AC11: =IF(OR(AB11="",多次统计数据!$B$9=""),"",IF(多次统计数据!$B$9<AB11,"低于上限","达到或超过上限")) | AE11: =IF(OR(X11="",C11="",C11<=0),"",X11/C11) | AJ11: =IF(OR(AG11="",AH11=""),"",IF(OR(AND(AG11="短期博反弹",OR(AH11="1～3个交易日",AH11="4～10个交易日")),AND(AG11="突破冲新高",OR(AH11="4～10个交易日",AH11="11～20个交易日")),AND(AG11="趋势波段",OR(AH11="11～20个交易日",AH11="21～60个交易日",AH11="60个交易日以上"))),"匹配","周期与交易预期不匹配，请重新确认")) | AO11: =IF(OR(A11="",H11="",H11<=0),"",(E11*H11+IF(AND(AK11<>"",AL11<>""),AK11*AL11,0)+IF(AND(AM11<>"",AN11<>""),AM11*AN11,0))/AP11) | AP11: =IF(OR(A11="",H11="",H11<=0),"",H11+IF(AL11="",0,AL11)+IF(AN11="",0,AN11)) | AQ11: =IF(A11="","",IF(M11<>"",0,IF(OR(H11="",N11=""),"",MAX(E11-MAX(N11,IFERROR(AGGREGATE(14,6,'持仓跟踪'!$S$2:$S$501/(('持仓跟踪'!$A$2:$A$501="每日跟踪")*('持仓跟踪'!$B$2:$B$501=A11)),1),0)),0)*H11+IF(OR(AK11="",AL11=""),0,MAX(AK11-MAX(N11,IFERROR(AGGREGATE(14,6,'持仓跟踪'!$S$2:$S$501/(('持仓跟踪'!$A$2:$A$501="每日跟踪")*('持仓跟踪'!$B$2:$B$501=A11)),1),0)),0)*AL11)+IF(OR(AM11="",AN11=""),0,MAX(AM11-MAX(N11,IFERROR(AGGREGATE(14,6,'持仓跟踪'!$S$2:$S$501/(('持仓跟踪'!$A$2:$A$501="每日跟踪")*('持仓跟踪'!$B$2:$B$501=A11)),1),0)),0)*AN11)))) | AR11: =IF(A11="","",IF(OR(E11="",H11=""),"违规：第一批价格或股数缺失",IF(OR(AND(AK11="",AL11<>""),AND(AK11<>"",AL11="")),"违规：第二批价格与股数须成对填写",IF(OR(AND(AM11="",AN11<>""),AND(AM11<>"",AN11="")),"违规：第三批价格与股数须成对填写",IF(AND(OR(AM11<>"",AN11<>""),OR(AK11="",AL11="")),"违规：必须先完成第二批",IF(OR(H11<=0,H11<>INT(H11),MOD(H11,100)<>0,AND(AL11<>"",OR(AL11<=0,AL11<>INT(AL11),MOD(AL11,100)<>0)),AND(AN11<>"",OR(AN11<=0,AN11<>INT(AN11),MOD(AN11,100)<>0))),"违规：股数须为100股整数倍",IF(AND(OR(AL11<>"",AN11<>""),OR(_LockStatus="已锁仓",_LockStatus="解锁信息不完整")),"违规：锁仓期间禁止加仓",IF(AQ11>C11*D11,"违规：超过单笔风险上限",IF(SUM($AQ$2:$AQ$201)>账户数据!$B$7,"违规：超过账户风险上限","通过")))))))))
A12: 11 | B12: 赛轮轮胎 | C12: 98991 | D12: 0.02 | E12: 8.22 | F12: =IF(OR(C12="",D12="",E12="",N12="",C12<=0,D12<=0,E12<=N12),"",ROUNDDOWN((C12*D12)/(E12-N12)/100,0)*100) | G12: =IF(A12="","",IF(H12<>"","已开仓",IF(账户数据!$B$23="已锁仓","禁止开仓：连续亏损达到上限",IF(账户数据!$B$23="解锁信息不完整","禁止开仓：请完整填写解锁信息",IF(OR(F12="",E12="",N12="",E12<=N12,账户数据!$B$7=""),"",IF(OR(AG12="",AH12="",AI12=""),"禁止开仓：交易预期未填写完整",IF(COUNTIFS(持仓跟踪!$A$2:$A$501,"止损计划",持仓跟踪!$B$2:$B$501,A12,持仓跟踪!$AC$2:$AC$501,"计划有效")=0,"禁止开仓：请先填写止损计划",IF(账户数据!$B$9+F12*(E12-N12)>=账户数据!$B$7,"禁止开仓：风险额度不足",IF(AJ12="周期与交易预期不匹配，请重新确认",IF(账户数据!$B$23="接近锁仓","允许开仓（接近锁仓；周期需复核）","允许开仓（周期需复核）"),IF(账户数据!$B$23="接近锁仓","允许开仓（接近锁仓）","允许开仓")))))))))) | H12: 3100 | I12: 44867 | J12: 9.5 | K12: 8.44 | L12: =IF(K12="","",H12) | M12: 44923 | N12: 7.6 | R12: 前方支撑位 | S12: 前方高点 | U12: =IF(OR(AO12="",J12="",AO12<=0),"",(J12-AO12)/AO12) | V12: =IF(OR(AO12="",N12="",AO12<=0),"",(AO12-N12)/AO12) | W12: =IF(OR(U12="",V12="",V12<=0),"",U12/V12) | X12: =IF(OR(K12="",L12="",AP12=""),"",K12*L12-(E12*H12+IF(AND(AK12<>"",AL12<>""),AK12*AL12,0)+IF(AND(AM12<>"",AN12<>""),AM12*AN12,0))-IF(O12="",0,O12)-IF(P12="",0,P12)) | Y12: =IF(OR(X12="",AP12=""),"",IF((E12*H12+IF(AND(AK12<>"",AL12<>""),AK12*AL12,0)+IF(AND(AM12<>"",AN12<>""),AM12*AN12,0))+IF(O12="",0,O12)<=0,"",X12/((E12*H12+IF(AND(AK12<>"",AL12<>""),AK12*AL12,0)+IF(AND(AM12<>"",AN12<>""),AM12*AN12,0))+IF(O12="",0,O12)))) | Z12: =IF(OR(AE12="",多次统计数据!$B$8=""),"",AE12-多次统计数据!$B$8) | AA12: =IF(OR(I12="",M12="",M12<I12),"",M12-I12) | AB12: =IF(OR(A12="",多次统计数据!$B$8="",多次统计数据!$B$6<=0,多次统计数据!$B$6>=1),"",1-POWER(1+多次统计数据!$B$8,-多次统计数据!$B$6/(1-多次统计数据!$B$6))) | AC12: =IF(OR(AB12="",多次统计数据!$B$9=""),"",IF(多次统计数据!$B$9<AB12,"低于上限","达到或超过上限")) | AE12: =IF(OR(X12="",C12="",C12<=0),"",X12/C12) | AJ12: =IF(OR(AG12="",AH12=""),"",IF(OR(AND(AG12="短期博反弹",OR(AH12="1～3个交易日",AH12="4～10个交易日")),AND(AG12="突破冲新高",OR(AH12="4～10个交易日",AH12="11～20个交易日")),AND(AG12="趋势波段",OR(AH12="11～20个交易日",AH12="21～60个交易日",AH12="60个交易日以上"))),"匹配","周期与交易预期不匹配，请重新确认")) | AO12: =IF(OR(A12="",H12="",H12<=0),"",(E12*H12+IF(AND(AK12<>"",AL12<>""),AK12*AL12,0)+IF(AND(AM12<>"",AN12<>""),AM12*AN12,0))/AP12) | AP12: =IF(OR(A12="",H12="",H12<=0),"",H12+IF(AL12="",0,AL12)+IF(AN12="",0,AN12)) | AQ12: =IF(A12="","",IF(M12<>"",0,IF(OR(H12="",N12=""),"",MAX(E12-MAX(N12,IFERROR(AGGREGATE(14,6,'持仓跟踪'!$S$2:$S$501/(('持仓跟踪'!$A$2:$A$501="每日跟踪")*('持仓跟踪'!$B$2:$B$501=A12)),1),0)),0)*H12+IF(OR(AK12="",AL12=""),0,MAX(AK12-MAX(N12,IFERROR(AGGREGATE(14,6,'持仓跟踪'!$S$2:$S$501/(('持仓跟踪'!$A$2:$A$501="每日跟踪")*('持仓跟踪'!$B$2:$B$501=A12)),1),0)),0)*AL12)+IF(OR(AM12="",AN12=""),0,MAX(AM12-MAX(N12,IFERROR(AGGREGATE(14,6,'持仓跟踪'!$S$2:$S$501/(('持仓跟踪'!$A$2:$A$501="每日跟踪")*('持仓跟踪'!$B$2:$B$501=A12)),1),0)),0)*AN12)))) | AR12: =IF(A12="","",IF(OR(E12="",H12=""),"违规：第一批价格或股数缺失",IF(OR(AND(AK12="",AL12<>""),AND(AK12<>"",AL12="")),"违规：第二批价格与股数须成对填写",IF(OR(AND(AM12="",AN12<>""),AND(AM12<>"",AN12="")),"违规：第三批价格与股数须成对填写",IF(AND(OR(AM12<>"",AN12<>""),OR(AK12="",AL12="")),"违规：必须先完成第二批",IF(OR(H12<=0,H12<>INT(H12),MOD(H12,100)<>0,AND(AL12<>"",OR(AL12<=0,AL12<>INT(AL12),MOD(AL12,100)<>0)),AND(AN12<>"",OR(AN12<=0,AN12<>INT(AN12),MOD(AN12,100)<>0))),"违规：股数须为100股整数倍",IF(AND(OR(AL12<>"",AN12<>""),OR(_LockStatus="已锁仓",_LockStatus="解锁信息不完整")),"违规：锁仓期间禁止加仓",IF(AQ12>C12*D12,"违规：超过单笔风险上限",IF(SUM($AQ$2:$AQ$201)>账户数据!$B$7,"违规：超过账户风险上限","通过")))))))))
A13: 12 | B13: 赛轮轮胎 | C13: 99673 | D13: 0.02 | E13: 10.38 | F13: =IF(OR(C13="",D13="",E13="",N13="",C13<=0,D13<=0,E13<=N13),"",ROUNDDOWN((C13*D13)/(E13-N13)/100,0)*100) | G13: =IF(A13="","",IF(H13<>"","已开仓",IF(账户数据!$B$23="已锁仓","禁止开仓：连续亏损达到上限",IF(账户数据!$B$23="解锁信息不完整","禁止开仓：请完整填写解锁信息",IF(OR(F13="",E13="",N13="",E13<=N13,账户数据!$B$7=""),"",IF(OR(AG13="",AH13="",AI13=""),"禁止开仓：交易预期未填写完整",IF(COUNTIFS(持仓跟踪!$A$2:$A$501,"止损计划",持仓跟踪!$B$2:$B$501,A13,持仓跟踪!$AC$2:$AC$501,"计划有效")=0,"禁止开仓：请先填写止损计划",IF(账户数据!$B$9+F13*(E13-N13)>=账户数据!$B$7,"禁止开仓：风险额度不足",IF(AJ13="周期与交易预期不匹配，请重新确认",IF(账户数据!$B$23="接近锁仓","允许开仓（接近锁仓；周期需复核）","允许开仓（周期需复核）"),IF(账户数据!$B$23="接近锁仓","允许开仓（接近锁仓）","允许开仓")))))))))) | H13: 2200 | I13: 44979 | J13: 12.17 | K13: 9.55 | L13: =IF(K13="","",H13) | M13: 44995 | N13: 9.5 | R13: 前方支撑区域 | S13: 前方高点 | U13: =IF(OR(AO13="",J13="",AO13<=0),"",(J13-AO13)/AO13) | V13: =IF(OR(AO13="",N13="",AO13<=0),"",(AO13-N13)/AO13) | W13: =IF(OR(U13="",V13="",V13<=0),"",U13/V13) | X13: =IF(OR(K13="",L13="",AP13=""),"",K13*L13-(E13*H13+IF(AND(AK13<>"",AL13<>""),AK13*AL13,0)+IF(AND(AM13<>"",AN13<>""),AM13*AN13,0))-IF(O13="",0,O13)-IF(P13="",0,P13)) | Y13: =IF(OR(X13="",AP13=""),"",IF((E13*H13+IF(AND(AK13<>"",AL13<>""),AK13*AL13,0)+IF(AND(AM13<>"",AN13<>""),AM13*AN13,0))+IF(O13="",0,O13)<=0,"",X13/((E13*H13+IF(AND(AK13<>"",AL13<>""),AK13*AL13,0)+IF(AND(AM13<>"",AN13<>""),AM13*AN13,0))+IF(O13="",0,O13)))) | Z13: =IF(OR(AE13="",多次统计数据!$B$8=""),"",AE13-多次统计数据!$B$8) | AA13: =IF(OR(I13="",M13="",M13<I13),"",M13-I13) | AB13: =IF(OR(A13="",多次统计数据!$B$8="",多次统计数据!$B$6<=0,多次统计数据!$B$6>=1),"",1-POWER(1+多次统计数据!$B$8,-多次统计数据!$B$6/(1-多次统计数据!$B$6))) | AC13: =IF(OR(AB13="",多次统计数据!$B$9=""),"",IF(多次统计数据!$B$9<AB13,"低于上限","达到或超过上限")) | AE13: =IF(OR(X13="",C13="",C13<=0),"",X13/C13) | AJ13: =IF(OR(AG13="",AH13=""),"",IF(OR(AND(AG13="短期博反弹",OR(AH13="1～3个交易日",AH13="4～10个交易日")),AND(AG13="突破冲新高",OR(AH13="4～10个交易日",AH13="11～20个交易日")),AND(AG13="趋势波段",OR(AH13="11～20个交易日",AH13="21～60个交易日",AH13="60个交易日以上"))),"匹配","周期与交易预期不匹配，请重新确认")) | AO13: =IF(OR(A13="",H13="",H13<=0),"",(E13*H13+IF(AND(AK13<>"",AL13<>""),AK13*AL13,0)+IF(AND(AM13<>"",AN13<>""),AM13*AN13,0))/AP13) | AP13: =IF(OR(A13="",H13="",H13<=0),"",H13+IF(AL13="",0,AL13)+IF(AN13="",0,AN13)) | AQ13: =IF(A13="","",IF(M13<>"",0,IF(OR(H13="",N13=""),"",MAX(E13-MAX(N13,IFERROR(AGGREGATE(14,6,'持仓跟踪'!$S$2:$S$501/(('持仓跟踪'!$A$2:$A$501="每日跟踪")*('持仓跟踪'!$B$2:$B$501=A13)),1),0)),0)*H13+IF(OR(AK13="",AL13=""),0,MAX(AK13-MAX(N13,IFERROR(AGGREGATE(14,6,'持仓跟踪'!$S$2:$S$501/(('持仓跟踪'!$A$2:$A$501="每日跟踪")*('持仓跟踪'!$B$2:$B$501=A13)),1),0)),0)*AL13)+IF(OR(AM13="",AN13=""),0,MAX(AM13-MAX(N13,IFERROR(AGGREGATE(14,6,'持仓跟踪'!$S$2:$S$501/(('持仓跟踪'!$A$2:$A$501="每日跟踪")*('持仓跟踪'!$B$2:$B$501=A13)),1),0)),0)*AN13)))) | AR13: =IF(A13="","",IF(OR(E13="",H13=""),"违规：第一批价格或股数缺失",IF(OR(AND(AK13="",AL13<>""),AND(AK13<>"",AL13="")),"违规：第二批价格与股数须成对填写",IF(OR(AND(AM13="",AN13<>""),AND(AM13<>"",AN13="")),"违规：第三批价格与股数须成对填写",IF(AND(OR(AM13<>"",AN13<>""),OR(AK13="",AL13="")),"违规：必须先完成第二批",IF(OR(H13<=0,H13<>INT(H13),MOD(H13,100)<>0,AND(AL13<>"",OR(AL13<=0,AL13<>INT(AL13),MOD(AL13,100)<>0)),AND(AN13<>"",OR(AN13<=0,AN13<>INT(AN13),MOD(AN13,100)<>0))),"违规：股数须为100股整数倍",IF(AND(OR(AL13<>"",AN13<>""),OR(_LockStatus="已锁仓",_LockStatus="解锁信息不完整")),"违规：锁仓期间禁止加仓",IF(AQ13>C13*D13,"违规：超过单笔风险上限",IF(SUM($AQ$2:$AQ$201)>账户数据!$B$7,"违规：超过账户风险上限","通过")))))))))
A14: 13 | B14: 赛轮轮胎 | C14: 97847 | D14: 0.02 | E14: 10.49 | F14: =IF(OR(C14="",D14="",E14="",N14="",C14<=0,D14<=0,E14<=N14),"",ROUNDDOWN((C14*D14)/(E14-N14)/100,0)*100) | G14: =IF(A14="","",IF(H14<>"","已开仓",IF(账户数据!$B$23="已锁仓","禁止开仓：连续亏损达到上限",IF(账户数据!$B$23="解锁信息不完整","禁止开仓：请完整填写解锁信息",IF(OR(F14="",E14="",N14="",E14<=N14,账户数据!$B$7=""),"",IF(OR(AG14="",AH14="",AI14=""),"禁止开仓：交易预期未填写完整",IF(COUNTIFS(持仓跟踪!$A$2:$A$501,"止损计划",持仓跟踪!$B$2:$B$501,A14,持仓跟踪!$AC$2:$AC$501,"计划有效")=0,"禁止开仓：请先填写止损计划",IF(账户数据!$B$9+F14*(E14-N14)>=账户数据!$B$7,"禁止开仓：风险额度不足",IF(AJ14="周期与交易预期不匹配，请重新确认",IF(账户数据!$B$23="接近锁仓","允许开仓（接近锁仓；周期需复核）","允许开仓（周期需复核）"),IF(账户数据!$B$23="接近锁仓","允许开仓（接近锁仓）","允许开仓")))))))))) | H14: 3900 | I14: 45106 | J14: 12 | K14: 10.73 | L14: =IF(K14="","",H14) | M14: 45119 | N14: 10 | R14: 前方支撑区域 | S14: 新高 | U14: =IF(OR(AO14="",J14="",AO14<=0),"",(J14-AO14)/AO14) | V14: =IF(OR(AO14="",N14="",AO14<=0),"",(AO14-N14)/AO14) | W14: =IF(OR(U14="",V14="",V14<=0),"",U14/V14) | X14: =IF(OR(K14="",L14="",AP14=""),"",K14*L14-(E14*H14+IF(AND(AK14<>"",AL14<>""),AK14*AL14,0)+IF(AND(AM14<>"",AN14<>""),AM14*AN14,0))-IF(O14="",0,O14)-IF(P14="",0,P14)) | Y14: =IF(OR(X14="",AP14=""),"",IF((E14*H14+IF(AND(AK14<>"",AL14<>""),AK14*AL14,0)+IF(AND(AM14<>"",AN14<>""),AM14*AN14,0))+IF(O14="",0,O14)<=0,"",X14/((E14*H14+IF(AND(AK14<>"",AL14<>""),AK14*AL14,0)+IF(AND(AM14<>"",AN14<>""),AM14*AN14,0))+IF(O14="",0,O14)))) | Z14: =IF(OR(AE14="",多次统计数据!$B$8=""),"",AE14-多次统计数据!$B$8) | AA14: =IF(OR(I14="",M14="",M14<I14),"",M14-I14) | AB14: =IF(OR(A14="",多次统计数据!$B$8="",多次统计数据!$B$6<=0,多次统计数据!$B$6>=1),"",1-POWER(1+多次统计数据!$B$8,-多次统计数据!$B$6/(1-多次统计数据!$B$6))) | AC14: =IF(OR(AB14="",多次统计数据!$B$9=""),"",IF(多次统计数据!$B$9<AB14,"低于上限","达到或超过上限")) | AE14: =IF(OR(X14="",C14="",C14<=0),"",X14/C14) | AJ14: =IF(OR(AG14="",AH14=""),"",IF(OR(AND(AG14="短期博反弹",OR(AH14="1～3个交易日",AH14="4～10个交易日")),AND(AG14="突破冲新高",OR(AH14="4～10个交易日",AH14="11～20个交易日")),AND(AG14="趋势波段",OR(AH14="11～20个交易日",AH14="21～60个交易日",AH14="60个交易日以上"))),"匹配","周期与交易预期不匹配，请重新确认")) | AO14: =IF(OR(A14="",H14="",H14<=0),"",(E14*H14+IF(AND(AK14<>"",AL14<>""),AK14*AL14,0)+IF(AND(AM14<>"",AN14<>""),AM14*AN14,0))/AP14) | AP14: =IF(OR(A14="",H14="",H14<=0),"",H14+IF(AL14="",0,AL14)+IF(AN14="",0,AN14)) | AQ14: =IF(A14="","",IF(M14<>"",0,IF(OR(H14="",N14=""),"",MAX(E14-MAX(N14,IFERROR(AGGREGATE(14,6,'持仓跟踪'!$S$2:$S$501/(('持仓跟踪'!$A$2:$A$501="每日跟踪")*('持仓跟踪'!$B$2:$B$501=A14)),1),0)),0)*H14+IF(OR(AK14="",AL14=""),0,MAX(AK14-MAX(N14,IFERROR(AGGREGATE(14,6,'持仓跟踪'!$S$2:$S$501/(('持仓跟踪'!$A$2:$A$501="每日跟踪")*('持仓跟踪'!$B$2:$B$501=A14)),1),0)),0)*AL14)+IF(OR(AM14="",AN14=""),0,MAX(AM14-MAX(N14,IFERROR(AGGREGATE(14,6,'持仓跟踪'!$S$2:$S$501/(('持仓跟踪'!$A$2:$A$501="每日跟踪")*('持仓跟踪'!$B$2:$B$501=A14)),1),0)),0)*AN14)))) | AR14: =IF(A14="","",IF(OR(E14="",H14=""),"违规：第一批价格或股数缺失",IF(OR(AND(AK14="",AL14<>""),AND(AK14<>"",AL14="")),"违规：第二批价格与股数须成对填写",IF(OR(AND(AM14="",AN14<>""),AND(AM14<>"",AN14="")),"违规：第三批价格与股数须成对填写",IF(AND(OR(AM14<>"",AN14<>""),OR(AK14="",AL14="")),"违规：必须先完成第二批",IF(OR(H14<=0,H14<>INT(H14),MOD(H14,100)<>0,AND(AL14<>"",OR(AL14<=0,AL14<>INT(AL14),MOD(AL14,100)<>0)),AND(AN14<>"",OR(AN14<=0,AN14<>INT(AN14),MOD(AN14,100)<>0))),"违规：股数须为100股整数倍",IF(AND(OR(AL14<>"",AN14<>""),OR(_LockStatus="已锁仓",_LockStatus="解锁信息不完整")),"违规：锁仓期间禁止加仓",IF(AQ14>C14*D14,"违规：超过单笔风险上限",IF(SUM($AQ$2:$AQ$201)>账户数据!$B$7,"违规：超过账户风险上限","通过")))))))))
A15: 14 | B15: 赛轮轮胎 | C15: 98783 | D15: 0.02 | E15: 10.44 | F15: =IF(OR(C15="",D15="",E15="",N15="",C15<=0,D15<=0,E15<=N15),"",ROUNDDOWN((C15*D15)/(E15-N15)/100,0)*100) | G15: =IF(A15="","",IF(H15<>"","已开仓",IF(账户数据!$B$23="已锁仓","禁止开仓：连续亏损达到上限",IF(账户数据!$B$23="解锁信息不完整","禁止开仓：请完整填写解锁信息",IF(OR(F15="",E15="",N15="",E15<=N15,账户数据!$B$7=""),"",IF(OR(AG15="",AH15="",AI15=""),"禁止开仓：交易预期未填写完整",IF(COUNTIFS(持仓跟踪!$A$2:$A$501,"止损计划",持仓跟踪!$B$2:$B$501,A15,持仓跟踪!$AC$2:$AC$501,"计划有效")=0,"禁止开仓：请先填写止损计划",IF(账户数据!$B$9+F15*(E15-N15)>=账户数据!$B$7,"禁止开仓：风险额度不足",IF(AJ15="周期与交易预期不匹配，请重新确认",IF(账户数据!$B$23="接近锁仓","允许开仓（接近锁仓；周期需复核）","允许开仓（周期需复核）"),IF(账户数据!$B$23="接近锁仓","允许开仓（接近锁仓）","允许开仓")))))))))) | H15: 7500 | I15: 45320 | J15: 11 | K15: 11.3 | L15: =IF(K15="","",H15) | M15: 45323 | N15: 10.18 | U15: =IF(OR(AO15="",J15="",AO15<=0),"",(J15-AO15)/AO15) | V15: =IF(OR(AO15="",N15="",AO15<=0),"",(AO15-N15)/AO15) | W15: =IF(OR(U15="",V15="",V15<=0),"",U15/V15) | X15: =IF(OR(K15="",L15="",AP15=""),"",K15*L15-(E15*H15+IF(AND(AK15<>"",AL15<>""),AK15*AL15,0)+IF(AND(AM15<>"",AN15<>""),AM15*AN15,0))-IF(O15="",0,O15)-IF(P15="",0,P15)) | Y15: =IF(OR(X15="",AP15=""),"",IF((E15*H15+IF(AND(AK15<>"",AL15<>""),AK15*AL15,0)+IF(AND(AM15<>"",AN15<>""),AM15*AN15,0))+IF(O15="",0,O15)<=0,"",X15/((E15*H15+IF(AND(AK15<>"",AL15<>""),AK15*AL15,0)+IF(AND(AM15<>"",AN15<>""),AM15*AN15,0))+IF(O15="",0,O15)))) | Z15: =IF(OR(AE15="",多次统计数据!$B$8=""),"",AE15-多次统计数据!$B$8) | AA15: =IF(OR(I15="",M15="",M15<I15),"",M15-I15) | AB15: =IF(OR(A15="",多次统计数据!$B$8="",多次统计数据!$B$6<=0,多次统计数据!$B$6>=1),"",1-POWER(1+多次统计数据!$B$8,-多次统计数据!$B$6/(1-多次统计数据!$B$6))) | AC15: =IF(OR(AB15="",多次统计数据!$B$9=""),"",IF(多次统计数据!$B$9<AB15,"低于上限","达到或超过上限")) | AE15: =IF(OR(X15="",C15="",C15<=0),"",X15/C15) | AJ15: =IF(OR(AG15="",AH15=""),"",IF(OR(AND(AG15="短期博反弹",OR(AH15="1～3个交易日",AH15="4～10个交易日")),AND(AG15="突破冲新高",OR(AH15="4～10个交易日",AH15="11～20个交易日")),AND(AG15="趋势波段",OR(AH15="11～20个交易日",AH15="21～60个交易日",AH15="60个交易日以上"))),"匹配","周期与交易预期不匹配，请重新确认")) | AO15: =IF(OR(A15="",H15="",H15<=0),"",(E15*H15+IF(AND(AK15<>"",AL15<>""),AK15*AL15,0)+IF(AND(AM15<>"",AN15<>""),AM15*AN15,0))/AP15) | AP15: =IF(OR(A15="",H15="",H15<=0),"",H15+IF(AL15="",0,AL15)+IF(AN15="",0,AN15)) | AQ15: =IF(A15="","",IF(M15<>"",0,IF(OR(H15="",N15=""),"",MAX(E15-MAX(N15,IFERROR(AGGREGATE(14,6,'持仓跟踪'!$S$2:$S$501/(('持仓跟踪'!$A$2:$A$501="每日跟踪")*('持仓跟踪'!$B$2:$B$501=A15)),1),0)),0)*H15+IF(OR(AK15="",AL15=""),0,MAX(AK15-MAX(N15,IFERROR(AGGREGATE(14,6,'持仓跟踪'!$S$2:$S$501/(('持仓跟踪'!$A$2:$A$501="每日跟踪")*('持仓跟踪'!$B$2:$B$501=A15)),1),0)),0)*AL15)+IF(OR(AM15="",AN15=""),0,MAX(AM15-MAX(N15,IFERROR(AGGREGATE(14,6,'持仓跟踪'!$S$2:$S$501/(('持仓跟踪'!$A$2:$A$501="每日跟踪")*('持仓跟踪'!$B$2:$B$501=A15)),1),0)),0)*AN15)))) | AR15: =IF(A15="","",IF(OR(E15="",H15=""),"违规：第一批价格或股数缺失",IF(OR(AND(AK15="",AL15<>""),AND(AK15<>"",AL15="")),"违规：第二批价格与股数须成对填写",IF(OR(AND(AM15="",AN15<>""),AND(AM15<>"",AN15="")),"违规：第三批价格与股数须成对填写",IF(AND(OR(AM15<>"",AN15<>""),OR(AK15="",AL15="")),"违规：必须先完成第二批",IF(OR(H15<=0,H15<>INT(H15),MOD(H15,100)<>0,AND(AL15<>"",OR(AL15<=0,AL15<>INT(AL15),MOD(AL15,100)<>0)),AND(AN15<>"",OR(AN15<=0,AN15<>INT(AN15),MOD(AN15,100)<>0))),"违规：股数须为100股整数倍",IF(AND(OR(AL15<>"",AN15<>""),OR(_LockStatus="已锁仓",_LockStatus="解锁信息不完整")),"违规：锁仓期间禁止加仓",IF(AQ15>C15*D15,"违规：超过单笔风险上限",IF(SUM($AQ$2:$AQ$201)>账户数据!$B$7,"违规：超过账户风险上限","通过")))))))))
A16: 15 | B16: 赛轮轮胎 | C16: 105233 | D16: 0.02 | E16: 14.37 | F16: =IF(OR(C16="",D16="",E16="",N16="",C16<=0,D16<=0,E16<=N16),"",ROUNDDOWN((C16*D16)/(E16-N16)/100,0)*100) | G16: =IF(A16="","",IF(H16<>"","已开仓",IF(账户数据!$B$23="已锁仓","禁止开仓：连续亏损达到上限",IF(账户数据!$B$23="解锁信息不完整","禁止开仓：请完整填写解锁信息",IF(OR(F16="",E16="",N16="",E16<=N16,账户数据!$B$7=""),"",IF(OR(AG16="",AH16="",AI16=""),"禁止开仓：交易预期未填写完整",IF(COUNTIFS(持仓跟踪!$A$2:$A$501,"止损计划",持仓跟踪!$B$2:$B$501,A16,持仓跟踪!$AC$2:$AC$501,"计划有效")=0,"禁止开仓：请先填写止损计划",IF(账户数据!$B$9+F16*(E16-N16)>=账户数据!$B$7,"禁止开仓：风险额度不足",IF(AJ16="周期与交易预期不匹配，请重新确认",IF(账户数据!$B$23="接近锁仓","允许开仓（接近锁仓；周期需复核）","允许开仓（周期需复核）"),IF(账户数据!$B$23="接近锁仓","允许开仓（接近锁仓）","允许开仓")))))))))) | H16: 5000 | I16: 45562 | J16: 16 | K16: 14.01 | L16: =IF(K16="","",H16) | M16: 45574 | N16: 14 | U16: =IF(OR(AO16="",J16="",AO16<=0),"",(J16-AO16)/AO16) | V16: =IF(OR(AO16="",N16="",AO16<=0),"",(AO16-N16)/AO16) | W16: =IF(OR(U16="",V16="",V16<=0),"",U16/V16) | X16: =IF(OR(K16="",L16="",AP16=""),"",K16*L16-(E16*H16+IF(AND(AK16<>"",AL16<>""),AK16*AL16,0)+IF(AND(AM16<>"",AN16<>""),AM16*AN16,0))-IF(O16="",0,O16)-IF(P16="",0,P16)) | Y16: =IF(OR(X16="",AP16=""),"",IF((E16*H16+IF(AND(AK16<>"",AL16<>""),AK16*AL16,0)+IF(AND(AM16<>"",AN16<>""),AM16*AN16,0))+IF(O16="",0,O16)<=0,"",X16/((E16*H16+IF(AND(AK16<>"",AL16<>""),AK16*AL16,0)+IF(AND(AM16<>"",AN16<>""),AM16*AN16,0))+IF(O16="",0,O16)))) | Z16: =IF(OR(AE16="",多次统计数据!$B$8=""),"",AE16-多次统计数据!$B$8) | AA16: =IF(OR(I16="",M16="",M16<I16),"",M16-I16) | AB16: =IF(OR(A16="",多次统计数据!$B$8="",多次统计数据!$B$6<=0,多次统计数据!$B$6>=1),"",1-POWER(1+多次统计数据!$B$8,-多次统计数据!$B$6/(1-多次统计数据!$B$6))) | AC16: =IF(OR(AB16="",多次统计数据!$B$9=""),"",IF(多次统计数据!$B$9<AB16,"低于上限","达到或超过上限")) | AE16: =IF(OR(X16="",C16="",C16<=0),"",X16/C16) | AJ16: =IF(OR(AG16="",AH16=""),"",IF(OR(AND(AG16="短期博反弹",OR(AH16="1～3个交易日",AH16="4～10个交易日")),AND(AG16="突破冲新高",OR(AH16="4～10个交易日",AH16="11～20个交易日")),AND(AG16="趋势波段",OR(AH16="11～20个交易日",AH16="21～60个交易日",AH16="60个交易日以上"))),"匹配","周期与交易预期不匹配，请重新确认")) | AO16: =IF(OR(A16="",H16="",H16<=0),"",(E16*H16+IF(AND(AK16<>"",AL16<>""),AK16*AL16,0)+IF(AND(AM16<>"",AN16<>""),AM16*AN16,0))/AP16) | AP16: =IF(OR(A16="",H16="",H16<=0),"",H16+IF(AL16="",0,AL16)+IF(AN16="",0,AN16)) | AQ16: =IF(A16="","",IF(M16<>"",0,IF(OR(H16="",N16=""),"",MAX(E16-MAX(N16,IFERROR(AGGREGATE(14,6,'持仓跟踪'!$S$2:$S$501/(('持仓跟踪'!$A$2:$A$501="每日跟踪")*('持仓跟踪'!$B$2:$B$501=A16)),1),0)),0)*H16+IF(OR(AK16="",AL16=""),0,MAX(AK16-MAX(N16,IFERROR(AGGREGATE(14,6,'持仓跟踪'!$S$2:$S$501/(('持仓跟踪'!$A$2:$A$501="每日跟踪")*('持仓跟踪'!$B$2:$B$501=A16)),1),0)),0)*AL16)+IF(OR(AM16="",AN16=""),0,MAX(AM16-MAX(N16,IFERROR(AGGREGATE(14,6,'持仓跟踪'!$S$2:$S$501/(('持仓跟踪'!$A$2:$A$501="每日跟踪")*('持仓跟踪'!$B$2:$B$501=A16)),1),0)),0)*AN16)))) | AR16: =IF(A16="","",IF(OR(E16="",H16=""),"违规：第一批价格或股数缺失",IF(OR(AND(AK16="",AL16<>""),AND(AK16<>"",AL16="")),"违规：第二批价格与股数须成对填写",IF(OR(AND(AM16="",AN16<>""),AND(AM16<>"",AN16="")),"违规：第三批价格与股数须成对填写",IF(AND(OR(AM16<>"",AN16<>""),OR(AK16="",AL16="")),"违规：必须先完成第二批",IF(OR(H16<=0,H16<>INT(H16),MOD(H16,100)<>0,AND(AL16<>"",OR(AL16<=0,AL16<>INT(AL16),MOD(AL16,100)<>0)),AND(AN16<>"",OR(AN16<=0,AN16<>INT(AN16),MOD(AN16,100)<>0))),"违规：股数须为100股整数倍",IF(AND(OR(AL16<>"",AN16<>""),OR(_LockStatus="已锁仓",_LockStatus="解锁信息不完整")),"违规：锁仓期间禁止加仓",IF(AQ16>C16*D16,"违规：超过单笔风险上限",IF(SUM($AQ$2:$AQ$201)>账户数据!$B$7,"违规：超过账户风险上限","通过")))))))))
A17: 16 | B17: 赛轮轮胎 | C17: 103433 | D17: 0.02 | E17: 14.86 | F17: =IF(OR(C17="",D17="",E17="",N17="",C17<=0,D17<=0,E17<=N17),"",ROUNDDOWN((C17*D17)/(E17-N17)/100,0)*100) | G17: =IF(A17="","",IF(H17<>"","已开仓",IF(账户数据!$B$23="已锁仓","禁止开仓：连续亏损达到上限",IF(账户数据!$B$23="解锁信息不完整","禁止开仓：请完整填写解锁信息",IF(OR(F17="",E17="",N17="",E17<=N17,账户数据!$B$7=""),"",IF(OR(AG17="",AH17="",AI17=""),"禁止开仓：交易预期未填写完整",IF(COUNTIFS(持仓跟踪!$A$2:$A$501,"止损计划",持仓跟踪!$B$2:$B$501,A17,持仓跟踪!$AC$2:$AC$501,"计划有效")=0,"禁止开仓：请先填写止损计划",IF(账户数据!$B$9+F17*(E17-N17)>=账户数据!$B$7,"禁止开仓：风险额度不足",IF(AJ17="周期与交易预期不匹配，请重新确认",IF(账户数据!$B$23="接近锁仓","允许开仓（接近锁仓；周期需复核）","允许开仓（周期需复核）"),IF(账户数据!$B$23="接近锁仓","允许开仓（接近锁仓）","允许开仓")))))))))) | H17: 3000 | I17: 45674 | J17: 16 | K17: 15.17 | L17: =IF(K17="","",H17) | M17: 45716 | N17: 14 | U17: =IF(OR(AO17="",J17="",AO17<=0),"",(J17-AO17)/AO17) | V17: =IF(OR(AO17="",N17="",AO17<=0),"",(AO17-N17)/AO17) | W17: =IF(OR(U17="",V17="",V17<=0),"",U17/V17) | X17: =IF(OR(K17="",L17="",AP17=""),"",K17*L17-(E17*H17+IF(AND(AK17<>"",AL17<>""),AK17*AL17,0)+IF(AND(AM17<>"",AN17<>""),AM17*AN17,0))-IF(O17="",0,O17)-IF(P17="",0,P17)) | Y17: =IF(OR(X17="",AP17=""),"",IF((E17*H17+IF(AND(AK17<>"",AL17<>""),AK17*AL17,0)+IF(AND(AM17<>"",AN17<>""),AM17*AN17,0))+IF(O17="",0,O17)<=0,"",X17/((E17*H17+IF(AND(AK17<>"",AL17<>""),AK17*AL17,0)+IF(AND(AM17<>"",AN17<>""),AM17*AN17,0))+IF(O17="",0,O17)))) | Z17: =IF(OR(AE17="",多次统计数据!$B$8=""),"",AE17-多次统计数据!$B$8) | AA17: =IF(OR(I17="",M17="",M17<I17),"",M17-I17) | AB17: =IF(OR(A17="",多次统计数据!$B$8="",多次统计数据!$B$6<=0,多次统计数据!$B$6>=1),"",1-POWER(1+多次统计数据!$B$8,-多次统计数据!$B$6/(1-多次统计数据!$B$6))) | AC17: =IF(OR(AB17="",多次统计数据!$B$9=""),"",IF(多次统计数据!$B$9<AB17,"低于上限","达到或超过上限")) | AE17: =IF(OR(X17="",C17="",C17<=0),"",X17/C17) | AJ17: =IF(OR(AG17="",AH17=""),"",IF(OR(AND(AG17="短期博反弹",OR(AH17="1～3个交易日",AH17="4～10个交易日")),AND(AG17="突破冲新高",OR(AH17="4～10个交易日",AH17="11～20个交易日")),AND(AG17="趋势波段",OR(AH17="11～20个交易日",AH17="21～60个交易日",AH17="60个交易日以上"))),"匹配","周期与交易预期不匹配，请重新确认")) | AO17: =IF(OR(A17="",H17="",H17<=0),"",(E17*H17+IF(AND(AK17<>"",AL17<>""),AK17*AL17,0)+IF(AND(AM17<>"",AN17<>""),AM17*AN17,0))/AP17) | AP17: =IF(OR(A17="",H17="",H17<=0),"",H17+IF(AL17="",0,AL17)+IF(AN17="",0,AN17)) | AQ17: =IF(A17="","",IF(M17<>"",0,IF(OR(H17="",N17=""),"",MAX(E17-MAX(N17,IFERROR(AGGREGATE(14,6,'持仓跟踪'!$S$2:$S$501/(('持仓跟踪'!$A$2:$A$501="每日跟踪")*('持仓跟踪'!$B$2:$B$501=A17)),1),0)),0)*H17+IF(OR(AK17="",AL17=""),0,MAX(AK17-MAX(N17,IFERROR(AGGREGATE(14,6,'持仓跟踪'!$S$2:$S$501/(('持仓跟踪'!$A$2:$A$501="每日跟踪")*('持仓跟踪'!$B$2:$B$501=A17)),1),0)),0)*AL17)+IF(OR(AM17="",AN17=""),0,MAX(AM17-MAX(N17,IFERROR(AGGREGATE(14,6,'持仓跟踪'!$S$2:$S$501/(('持仓跟踪'!$A$2:$A$501="每日跟踪")*('持仓跟踪'!$B$2:$B$501=A17)),1),0)),0)*AN17)))) | AR17: =IF(A17="","",IF(OR(E17="",H17=""),"违规：第一批价格或股数缺失",IF(OR(AND(AK17="",AL17<>""),AND(AK17<>"",AL17="")),"违规：第二批价格与股数须成对填写",IF(OR(AND(AM17="",AN17<>""),AND(AM17<>"",AN17="")),"违规：第三批价格与股数须成对填写",IF(AND(OR(AM17<>"",AN17<>""),OR(AK17="",AL17="")),"违规：必须先完成第二批",IF(OR(H17<=0,H17<>INT(H17),MOD(H17,100)<>0,AND(AL17<>"",OR(AL17<=0,AL17<>INT(AL17),MOD(AL17,100)<>0)),AND(AN17<>"",OR(AN17<=0,AN17<>INT(AN17),MOD(AN17,100)<>0))),"违规：股数须为100股整数倍",IF(AND(OR(AL17<>"",AN17<>""),OR(_LockStatus="已锁仓",_LockStatus="解锁信息不完整")),"违规：锁仓期间禁止加仓",IF(AQ17>C17*D17,"违规：超过单笔风险上限",IF(SUM($AQ$2:$AQ$201)>账户数据!$B$7,"违规：超过账户风险上限","通过")))))))))
A18: 17 | B18: 赛轮轮胎 | C18: 104364 | D18: 0.02 | E18: 12.91 | F18: =IF(OR(C18="",D18="",E18="",N18="",C18<=0,D18<=0,E18<=N18),"",ROUNDDOWN((C18*D18)/(E18-N18)/100,0)*100) | G18: =IF(A18="","",IF(H18<>"","已开仓",IF(账户数据!$B$23="已锁仓","禁止开仓：连续亏损达到上限",IF(账户数据!$B$23="解锁信息不完整","禁止开仓：请完整填写解锁信息",IF(OR(F18="",E18="",N18="",E18<=N18,账户数据!$B$7=""),"",IF(OR(AG18="",AH18="",AI18=""),"禁止开仓：交易预期未填写完整",IF(COUNTIFS(持仓跟踪!$A$2:$A$501,"止损计划",持仓跟踪!$B$2:$B$501,A18,持仓跟踪!$AC$2:$AC$501,"计划有效")=0,"禁止开仓：请先填写止损计划",IF(账户数据!$B$9+F18*(E18-N18)>=账户数据!$B$7,"禁止开仓：风险额度不足",IF(AJ18="周期与交易预期不匹配，请重新确认",IF(账户数据!$B$23="接近锁仓","允许开仓（接近锁仓；周期需复核）","允许开仓（周期需复核）"),IF(账户数据!$B$23="接近锁仓","允许开仓（接近锁仓）","允许开仓")))))))))) | H18: 5000 | I18: 45888 | J18: 14 | K18: 14.62 | L18: =IF(K18="","",H18) | M18: 45917 | N18: 12.5 | U18: =IF(OR(AO18="",J18="",AO18<=0),"",(J18-AO18)/AO18) | V18: =IF(OR(AO18="",N18="",AO18<=0),"",(AO18-N18)/AO18) | W18: =IF(OR(U18="",V18="",V18<=0),"",U18/V18) | X18: =IF(OR(K18="",L18="",AP18=""),"",K18*L18-(E18*H18+IF(AND(AK18<>"",AL18<>""),AK18*AL18,0)+IF(AND(AM18<>"",AN18<>""),AM18*AN18,0))-IF(O18="",0,O18)-IF(P18="",0,P18)) | Y18: =IF(OR(X18="",AP18=""),"",IF((E18*H18+IF(AND(AK18<>"",AL18<>""),AK18*AL18,0)+IF(AND(AM18<>"",AN18<>""),AM18*AN18,0))+IF(O18="",0,O18)<=0,"",X18/((E18*H18+IF(AND(AK18<>"",AL18<>""),AK18*AL18,0)+IF(AND(AM18<>"",AN18<>""),AM18*AN18,0))+IF(O18="",0,O18)))) | Z18: =IF(OR(AE18="",多次统计数据!$B$8=""),"",AE18-多次统计数据!$B$8) | AA18: =IF(OR(I18="",M18="",M18<I18),"",M18-I18) | AB18: =IF(OR(A18="",多次统计数据!$B$8="",多次统计数据!$B$6<=0,多次统计数据!$B$6>=1),"",1-POWER(1+多次统计数据!$B$8,-多次统计数据!$B$6/(1-多次统计数据!$B$6))) | AC18: =IF(OR(AB18="",多次统计数据!$B$9=""),"",IF(多次统计数据!$B$9<AB18,"低于上限","达到或超过上限")) | AE18: =IF(OR(X18="",C18="",C18<=0),"",X18/C18) | AJ18: =IF(OR(AG18="",AH18=""),"",IF(OR(AND(AG18="短期博反弹",OR(AH18="1～3个交易日",AH18="4～10个交易日")),AND(AG18="突破冲新高",OR(AH18="4～10个交易日",AH18="11～20个交易日")),AND(AG18="趋势波段",OR(AH18="11～20个交易日",AH18="21～60个交易日",AH18="60个交易日以上"))),"匹配","周期与交易预期不匹配，请重新确认")) | AO18: =IF(OR(A18="",H18="",H18<=0),"",(E18*H18+IF(AND(AK18<>"",AL18<>""),AK18*AL18,0)+IF(AND(AM18<>"",AN18<>""),AM18*AN18,0))/AP18) | AP18: =IF(OR(A18="",H18="",H18<=0),"",H18+IF(AL18="",0,AL18)+IF(AN18="",0,AN18)) | AQ18: =IF(A18="","",IF(M18<>"",0,IF(OR(H18="",N18=""),"",MAX(E18-MAX(N18,IFERROR(AGGREGATE(14,6,'持仓跟踪'!$S$2:$S$501/(('持仓跟踪'!$A$2:$A$501="每日跟踪")*('持仓跟踪'!$B$2:$B$501=A18)),1),0)),0)*H18+IF(OR(AK18="",AL18=""),0,MAX(AK18-MAX(N18,IFERROR(AGGREGATE(14,6,'持仓跟踪'!$S$2:$S$501/(('持仓跟踪'!$A$2:$A$501="每日跟踪")*('持仓跟踪'!$B$2:$B$501=A18)),1),0)),0)*AL18)+IF(OR(AM18="",AN18=""),0,MAX(AM18-MAX(N18,IFERROR(AGGREGATE(14,6,'持仓跟踪'!$S$2:$S$501/(('持仓跟踪'!$A$2:$A$501="每日跟踪")*('持仓跟踪'!$B$2:$B$501=A18)),1),0)),0)*AN18)))) | AR18: =IF(A18="","",IF(OR(E18="",H18=""),"违规：第一批价格或股数缺失",IF(OR(AND(AK18="",AL18<>""),AND(AK18<>"",AL18="")),"违规：第二批价格与股数须成对填写",IF(OR(AND(AM18="",AN18<>""),AND(AM18<>"",AN18="")),"违规：第三批价格与股数须成对填写",IF(AND(OR(AM18<>"",AN18<>""),OR(AK18="",AL18="")),"违规：必须先完成第二批",IF(OR(H18<=0,H18<>INT(H18),MOD(H18,100)<>0,AND(AL18<>"",OR(AL18<=0,AL18<>INT(AL18),MOD(AL18,100)<>0)),AND(AN18<>"",OR(AN18<=0,AN18<>INT(AN18),MOD(AN18,100)<>0))),"违规：股数须为100股整数倍",IF(AND(OR(AL18<>"",AN18<>""),OR(_LockStatus="已锁仓",_LockStatus="解锁信息不完整")),"违规：锁仓期间禁止加仓",IF(AQ18>C18*D18,"违规：超过单笔风险上限",IF(SUM($AQ$2:$AQ$201)>账户数据!$B$7,"违规：超过账户风险上限","通过")))))))))
A19: 18 | B19: 通富微电 | C19: 112913 | D19: 0.02 | E19: 20.1 | F19: =IF(OR(C19="",D19="",E19="",N19="",C19<=0,D19<=0,E19<=N19),"",ROUNDDOWN((C19*D19)/(E19-N19)/100,0)*100) | G19: =IF(A19="","",IF(H19<>"","已开仓",IF(账户数据!$B$23="已锁仓","禁止开仓：连续亏损达到上限",IF(账户数据!$B$23="解锁信息不完整","禁止开仓：请完整填写解锁信息",IF(OR(F19="",E19="",N19="",E19<=N19,账户数据!$B$7=""),"",IF(OR(AG19="",AH19="",AI19=""),"禁止开仓：交易预期未填写完整",IF(COUNTIFS(持仓跟踪!$A$2:$A$501,"止损计划",持仓跟踪!$B$2:$B$501,A19,持仓跟踪!$AC$2:$AC$501,"计划有效")=0,"禁止开仓：请先填写止损计划",IF(账户数据!$B$9+F19*(E19-N19)>=账户数据!$B$7,"禁止开仓：风险额度不足",IF(AJ19="周期与交易预期不匹配，请重新确认",IF(账户数据!$B$23="接近锁仓","允许开仓（接近锁仓；周期需复核）","允许开仓（周期需复核）"),IF(账户数据!$B$23="接近锁仓","允许开仓（接近锁仓）","允许开仓")))))))))) | H19: 2000 | I19: 44540 | J19: 23 | K19: 18.9 | L19: =IF(K19="","",H19) | M19: 44550 | N19: 19 | U19: =IF(OR(AO19="",J19="",AO19<=0),"",(J19-AO19)/AO19) | V19: =IF(OR(AO19="",N19="",AO19<=0),"",(AO19-N19)/AO19) | W19: =IF(OR(U19="",V19="",V19<=0),"",U19/V19) | X19: =IF(OR(K19="",L19="",AP19=""),"",K19*L19-(E19*H19+IF(AND(AK19<>"",AL19<>""),AK19*AL19,0)+IF(AND(AM19<>"",AN19<>""),AM19*AN19,0))-IF(O19="",0,O19)-IF(P19="",0,P19)) | Y19: =IF(OR(X19="",AP19=""),"",IF((E19*H19+IF(AND(AK19<>"",AL19<>""),AK19*AL19,0)+IF(AND(AM19<>"",AN19<>""),AM19*AN19,0))+IF(O19="",0,O19)<=0,"",X19/((E19*H19+IF(AND(AK19<>"",AL19<>""),AK19*AL19,0)+IF(AND(AM19<>"",AN19<>""),AM19*AN19,0))+IF(O19="",0,O19)))) | Z19: =IF(OR(AE19="",多次统计数据!$B$8=""),"",AE19-多次统计数据!$B$8) | AA19: =IF(OR(I19="",M19="",M19<I19),"",M19-I19) | AB19: =IF(OR(A19="",多次统计数据!$B$8="",多次统计数据!$B$6<=0,多次统计数据!$B$6>=1),"",1-POWER(1+多次统计数据!$B$8,-多次统计数据!$B$6/(1-多次统计数据!$B$6))) | AC19: =IF(OR(AB19="",多次统计数据!$B$9=""),"",IF(多次统计数据!$B$9<AB19,"低于上限","达到或超过上限")) | AE19: =IF(OR(X19="",C19="",C19<=0),"",X19/C19) | AJ19: =IF(OR(AG19="",AH19=""),"",IF(OR(AND(AG19="短期博反弹",OR(AH19="1～3个交易日",AH19="4～10个交易日")),AND(AG19="突破冲新高",OR(AH19="4～10个交易日",AH19="11～20个交易日")),AND(AG19="趋势波段",OR(AH19="11～20个交易日",AH19="21～60个交易日",AH19="60个交易日以上"))),"匹配","周期与交易预期不匹配，请重新确认")) | AO19: =IF(OR(A19="",H19="",H19<=0),"",(E19*H19+IF(AND(AK19<>"",AL19<>""),AK19*AL19,0)+IF(AND(AM19<>"",AN19<>""),AM19*AN19,0))/AP19) | AP19: =IF(OR(A19="",H19="",H19<=0),"",H19+IF(AL19="",0,AL19)+IF(AN19="",0,AN19)) | AQ19: =IF(A19="","",IF(M19<>"",0,IF(OR(H19="",N19=""),"",MAX(E19-MAX(N19,IFERROR(AGGREGATE(14,6,'持仓跟踪'!$S$2:$S$501/(('持仓跟踪'!$A$2:$A$501="每日跟踪")*('持仓跟踪'!$B$2:$B$501=A19)),1),0)),0)*H19+IF(OR(AK19="",AL19=""),0,MAX(AK19-MAX(N19,IFERROR(AGGREGATE(14,6,'持仓跟踪'!$S$2:$S$501/(('持仓跟踪'!$A$2:$A$501="每日跟踪")*('持仓跟踪'!$B$2:$B$501=A19)),1),0)),0)*AL19)+IF(OR(AM19="",AN19=""),0,MAX(AM19-MAX(N19,IFERROR(AGGREGATE(14,6,'持仓跟踪'!$S$2:$S$501/(('持仓跟踪'!$A$2:$A$501="每日跟踪")*('持仓跟踪'!$B$2:$B$501=A19)),1),0)),0)*AN19)))) | AR19: =IF(A19="","",IF(OR(E19="",H19=""),"违规：第一批价格或股数缺失",IF(OR(AND(AK19="",AL19<>""),AND(AK19<>"",AL19="")),"违规：第二批价格与股数须成对填写",IF(OR(AND(AM19="",AN19<>""),AND(AM19<>"",AN19="")),"违规：第三批价格与股数须成对填写",IF(AND(OR(AM19<>"",AN19<>""),OR(AK19="",AL19="")),"违规：必须先完成第二批",IF(OR(H19<=0,H19<>INT(H19),MOD(H19,100)<>0,AND(AL19<>"",OR(AL19<=0,AL19<>INT(AL19),MOD(AL19,100)<>0)),AND(AN19<>"",OR(AN19<=0,AN19<>INT(AN19),MOD(AN19,100)<>0))),"违规：股数须为100股整数倍",IF(AND(OR(AL19<>"",AN19<>""),OR(_LockStatus="已锁仓",_LockStatus="解锁信息不完整")),"违规：锁仓期间禁止加仓",IF(AQ19>C19*D19,"违规：超过单笔风险上限",IF(SUM($AQ$2:$AQ$201)>账户数据!$B$7,"违规：超过账户风险上限","通过")))))))))
