Workbook

Sheet 单次交易
A1: 交易编号 | B1: 股票代码 | C1: 买入时账户金额 | D1: 本次允许亏损比例 | E1: 买入价 | F1: 买入建议股数 | G1: 开仓风险告警 | H1: 实际买入股数 | I1: 买入日期 | J1: 期望卖出价 | K1: 实际卖出价 | L1: 卖出股数 | M1: 卖出日期 | N1: 止损价 | O1: 买入费用 | P1: 卖出费用 | Q1: 买入价的由来 | R1: 止损价的由来 | S1: 期望卖出价的由来 | T1: 实际卖出价的由来 | U1: 期望盈利比例 | V1: 期望止损比例 | W1: 盈亏比 | X1: 实际盈亏金额 | Y1: 实际收益率 | Z1: 与平均盈利比例差值 | AA1: 持有天数 | AB1: 复利容许平均亏损上限 | AC1: 复利风险判断 | AD1: 交易打分评价
A2: T2026001 | B2: 600519 | C2: 100000 | D2: 0.01 | E2: 11.25 | F2: =IF(OR(C2="",D2="",E2="",N2="",C2<=0,D2<=0,E2<=N2),"",ROUNDDOWN((C2*D2)/(E2-N2)/100,0)*100) -> 1000 | G2: =IF(OR(A2="",F2="",E2="",N2="",E2<=N2,账户数据!$B$7=""),"",IF(账户数据!$B$9+IF(H2="",F2*(E2-N2),0)>=账户数据!$B$7,"禁止开仓","允许开仓")) -> 禁止开仓 | H2: 200 | I2: 46128 | J2: 12.38 | K2: 12.71 | L2: =IF(K2="","",H2) -> 200 | M2: 46130 | N2: 10.25 | O2: 5 | P2: 5 | Q2: 蜡烛图与RSI共同确认 | R2: 止损设在10.25 | S2: 目标参考缺口 | T2: 按计划成交 | U2: =IF(OR(E2="",J2="",E2<=0),"",(J2-E2)/E2) -> 0.10044444 | V2: =IF(OR(E2="",N2="",E2<=0),"",(E2-N2)/E2) -> 0.088888889 | W2: =IF(OR(U2="",V2="",V2<=0),"",U2/V2) -> 1.13 | X2: =IF(OR(K2="",L2="",E2="",H2=""),"",K2*L2-E2*H2-IF(O2="",0,O2)-IF(P2="",0,P2)) -> 282 | Y2: =IF(OR(X2="",E2="",H2=""),"",IF(E2*H2+IF(O2="",0,O2)<=0,"",X2/(E2*H2+IF(O2="",0,O2)))) -> 0.12505543 | Z2: =IF(OR(Y2="",多次统计数据!$B$8=""),"",Y2-多次统计数据!$B$8) -> -0.0030756577 | AA2: =IF(OR(I2="",M2="",M2<I2),"",M2-I2) -> 2 | AB2: =IF(OR(A2="",多次统计数据!$B$8="",多次统计数据!$B$6<=0,多次统计数据!$B$6>=1),"",1-POWER(1+多次统计数据!$B$8,-多次统计数据!$B$6/(1-多次统计数据!$B$6))) -> 0.11918507 | AC2: =IF(OR(AB2="",多次统计数据!$B$9=""),"",IF(多次统计数据!$B$9<AB2,"低于上限","达到或超过上限")) -> 低于上限 | AD2: 4-良好
A3: T2026002 | B3: 000001 | C3: 100282 | D3: 0.01 | E3: 12.5 | F3: =IF(OR(C3="",D3="",E3="",N3="",C3<=0,D3<=0,E3<=N3),"",ROUNDDOWN((C3*D3)/(E3-N3)/100,0)*100) -> 800 | G3: =IF(OR(A3="",F3="",E3="",N3="",E3<=N3,账户数据!$B$7=""),"",IF(账户数据!$B$9+IF(H3="",F3*(E3-N3),0)>=账户数据!$B$7,"禁止开仓","允许开仓")) -> 禁止开仓 | H3: 300 | I3: 46129 | J3: 13.75 | K3: 14.25 | L3: =IF(K3="","",H3) -> 300 | M3: 46132 | N3: 11.25 | O3: 5 | P3: 5 | Q3: 趋势线与KDJ共同确认 | R3: 止损设在11.25 | S3: 目标参考形态突破 | T3: 按计划成交 | U3: =IF(OR(E3="",J3="",E3<=0),"",(J3-E3)/E3) -> 0.1 | V3: =IF(OR(E3="",N3="",E3<=0),"",(E3-N3)/E3) -> 0.1 | W3: =IF(OR(U3="",V3="",V3<=0),"",U3/V3) -> 1 | X3: =IF(OR(K3="",L3="",E3="",H3=""),"",K3*L3-E3*H3-IF(O3="",0,O3)-IF(P3="",0,P3)) -> 515 | Y3: =IF(OR(X3="",E3="",H3=""),"",IF(E3*H3+IF(O3="",0,O3)<=0,"",X3/(E3*H3+IF(O3="",0,O3)))) -> 0.13715047 | Z3: =IF(OR(Y3="",多次统计数据!$B$8=""),"",Y3-多次统计数据!$B$8) -> 0.009019376 | AA3: =IF(OR(I3="",M3="",M3<I3),"",M3-I3) -> 3 | AB3: =IF(OR(A3="",多次统计数据!$B$8="",多次统计数据!$B$6<=0,多次统计数据!$B$6>=1),"",1-POWER(1+多次统计数据!$B$8,-多次统计数据!$B$6/(1-多次统计数据!$B$6))) -> 0.11918507 | AC3: =IF(OR(AB3="",多次统计数据!$B$9=""),"",IF(多次统计数据!$B$9<AB3,"低于上限","达到或超过上限")) -> 低于上限 | AD3: 4-良好
A4: T2026003 | B4: 300750 | C4: 100797 | D4: 0.01 | E4: 13.75 | F4: =IF(OR(C4="",D4="",E4="",N4="",C4<=0,D4<=0,E4<=N4),"",ROUNDDOWN((C4*D4)/(E4-N4)/100,0)*100) -> 600 | G4: =IF(OR(A4="",F4="",E4="",N4="",E4<=N4,账户数据!$B$7=""),"",IF(账户数据!$B$9+IF(H4="",F4*(E4-N4),0)>=账户数据!$B$7,"禁止开仓","允许开仓")) -> 禁止开仓 | H4: 300 | I4: 46130 | J4: 15.13 | K4: 15.4 | L4: =IF(K4="","",H4) -> 300 | M4: 46134 | N4: 12.25 | O4: 0 | P4: 5 | Q4: MACD与布林带共同确认 | R4: 止损设在12.25 | S4: 目标参考均线金叉 | T4: 按计划成交 | U4: =IF(OR(E4="",J4="",E4<=0),"",(J4-E4)/E4) -> 0.10036364 | V4: =IF(OR(E4="",N4="",E4<=0),"",(E4-N4)/E4) -> 0.10909091 | W4: =IF(OR(U4="",V4="",V4<=0),"",U4/V4) -> 0.92 | X4: =IF(OR(K4="",L4="",E4="",H4=""),"",K4*L4-E4*H4-IF(O4="",0,O4)-IF(P4="",0,P4)) -> 490 | Y4: =IF(OR(X4="",E4="",H4=""),"",IF(E4*H4+IF(O4="",0,O4)<=0,"",X4/(E4*H4+IF(O4="",0,O4)))) -> 0.11878788 | Z4: =IF(OR(Y4="",多次统计数据!$B$8=""),"",Y4-多次统计数据!$B$8) -> -0.0093432113 | AA4: =IF(OR(I4="",M4="",M4<I4),"",M4-I4) -> 4 | AB4: =IF(OR(A4="",多次统计数据!$B$8="",多次统计数据!$B$6<=0,多次统计数据!$B$6>=1),"",1-POWER(1+多次统计数据!$B$8,-多次统计数据!$B$6/(1-多次统计数据!$B$6))) -> 0.11918507 | AC4: =IF(OR(AB4="",多次统计数据!$B$9=""),"",IF(多次统计数据!$B$9<AB4,"低于上限","达到或超过上限")) -> 低于上限 | AD4: 4-良好
A5: T2026004 | B5: 002594 | C5: 101287 | D5: 0.01 | E5: 15 | F5: =IF(OR(C5="",D5="",E5="",N5="",C5<=0,D5<=0,E5<=N5),"",ROUNDDOWN((C5*D5)/(E5-N5)/100,0)*100) -> 1300 | G5: =IF(OR(A5="",F5="",E5="",N5="",E5<=N5,账户数据!$B$7=""),"",IF(账户数据!$B$9+IF(H5="",F5*(E5-N5),0)>=账户数据!$B$7,"禁止开仓","允许开仓")) -> 禁止开仓 | H5: 1000 | I5: 46131 | J5: 16.5 | K5: 16.95 | L5: =IF(K5="","",H5) -> 1000 | M5: 46136 | N5: 14.25 | O5: 5 | P5: 0 | Q5: 移动平均线与支撑位共同确认 | R5: 止损设在14.25 | S5: 目标参考均线死叉 | T5: 按计划成交 | U5: =IF(OR(E5="",J5="",E5<=0),"",(J5-E5)/E5) -> 0.1 | V5: =IF(OR(E5="",N5="",E5<=0),"",(E5-N5)/E5) -> 0.05 | W5: =IF(OR(U5="",V5="",V5<=0),"",U5/V5) -> 2 | X5: =IF(OR(K5="",L5="",E5="",H5=""),"",K5*L5-E5*H5-IF(O5="",0,O5)-IF(P5="",0,P5)) -> 1945 | Y5: =IF(OR(X5="",E5="",H5=""),"",IF(E5*H5+IF(O5="",0,O5)<=0,"",X5/(E5*H5+IF(O5="",0,O5)))) -> 0.12962346 | Z5: =IF(OR(Y5="",多次统计数据!$B$8=""),"",Y5-多次统计数据!$B$8) -> 0.0014923688 | AA5: =IF(OR(I5="",M5="",M5<I5),"",M5-I5) -> 5 | AB5: =IF(OR(A5="",多次统计数据!$B$8="",多次统计数据!$B$6<=0,多次统计数据!$B$6>=1),"",1-POWER(1+多次统计数据!$B$8,-多次统计数据!$B$6/(1-多次统计数据!$B$6))) -> 0.11918507 | AC5: =IF(OR(AB5="",多次统计数据!$B$9=""),"",IF(多次统计数据!$B$9<AB5,"低于上限","达到或超过上限")) -> 低于上限 | AD5: 4-良好
A6: T2026005 | B6: 601318 | C6: 103232 | D6: 0.01 | E6: 16.25 | F6: =IF(OR(C6="",D6="",E6="",N6="",C6<=0,D6<=0,E6<=N6),"",ROUNDDOWN((C6*D6)/(E6-N6)/100,0)*100) -> 1000 | G6: =IF(OR(A6="",F6="",E6="",N6="",E6<=N6,账户数据!$B$7=""),"",IF(账户数据!$B$9+IF(H6="",F6*(E6-N6),0)>=账户数据!$B$7,"禁止开仓","允许开仓")) -> 禁止开仓 | H6: 1000 | I6: 46132 | J6: 17.88 | K6: 15.25 | L6: =IF(K6="","",H6) -> 1000 | M6: 46138 | N6: 15.25 | O6: 5 | P6: 5 | Q6: 成交量与压力位共同确认 | R6: 止损设在15.25 | S6: 目标参考量价背离 | T6: 按计划成交 | U6: =IF(OR(E6="",J6="",E6<=0),"",(J6-E6)/E6) -> 0.10030769 | V6: =IF(OR(E6="",N6="",E6<=0),"",(E6-N6)/E6) -> 0.061538462 | W6: =IF(OR(U6="",V6="",V6<=0),"",U6/V6) -> 1.63 | X6: =IF(OR(K6="",L6="",E6="",H6=""),"",K6*L6-E6*H6-IF(O6="",0,O6)-IF(P6="",0,P6)) -> -1010 | Y6: =IF(OR(X6="",E6="",H6=""),"",IF(E6*H6+IF(O6="",0,O6)<=0,"",X6/(E6*H6+IF(O6="",0,O6)))) -> -0.062134728 | Z6: =IF(OR(Y6="",多次统计数据!$B$8=""),"",Y6-多次统计数据!$B$8) -> -0.19026582 | AA6: =IF(OR(I6="",M6="",M6<I6),"",M6-I6) -> 6 | AB6: =IF(OR(A6="",多次统计数据!$B$8="",多次统计数据!$B$6<=0,多次统计数据!$B$6>=1),"",1-POWER(1+多次统计数据!$B$8,-多次统计数据!$B$6/(1-多次统计数据!$B$6))) -> 0.11918507 | AC6: =IF(OR(AB6="",多次统计数据!$B$9=""),"",IF(多次统计数据!$B$9<AB6,"低于上限","达到或超过上限")) -> 低于上限 | AD6: 2-较差
A7: T2026006 | B7: 688981 | C7: 102222 | D7: 0.01 | E7: 17.5 | F7: =IF(OR(C7="",D7="",E7="",N7="",C7<=0,D7<=0,E7<=N7),"",ROUNDDOWN((C7*D7)/(E7-N7)/100,0)*100) -> 800 | G7: =IF(OR(A7="",F7="",E7="",N7="",E7<=N7,账户数据!$B$7=""),"",IF(账户数据!$B$9+IF(H7="",F7*(E7-N7),0)>=账户数据!$B$7,"禁止开仓","允许开仓")) -> 禁止开仓 | H7: 100 | I7: 46133 | J7: 19.25 | K7: 16.25 | L7: =IF(K7="","",H7) -> 100 | M7: 46140 | N7: 16.25 | O7: 0 | P7: 5 | Q7: RSI与缺口共同确认 | R7: 止损设在16.25 | S7: 目标参考趋势背离 | T7: 按计划成交 | U7: =IF(OR(E7="",J7="",E7<=0),"",(J7-E7)/E7) -> 0.1 | V7: =IF(OR(E7="",N7="",E7<=0),"",(E7-N7)/E7) -> 0.071428571 | W7: =IF(OR(U7="",V7="",V7<=0),"",U7/V7) -> 1.4 | X7: =IF(OR(K7="",L7="",E7="",H7=""),"",K7*L7-E7*H7-IF(O7="",0,O7)-IF(P7="",0,P7)) -> -130 | Y7: =IF(OR(X7="",E7="",H7=""),"",IF(E7*H7+IF(O7="",0,O7)<=0,"",X7/(E7*H7+IF(O7="",0,O7)))) -> -0.074285714 | Z7: =IF(OR(Y7="",多次统计数据!$B$8=""),"",Y7-多次统计数据!$B$8) -> -0.2024168 | AA7: =IF(OR(I7="",M7="",M7<I7),"",M7-I7) -> 7 | AB7: =IF(OR(A7="",多次统计数据!$B$8="",多次统计数据!$B$6<=0,多次统计数据!$B$6>=1),"",1-POWER(1+多次统计数据!$B$8,-多次统计数据!$B$6/(1-多次统计数据!$B$6))) -> 0.11918507 | AC7: =IF(OR(AB7="",多次统计数据!$B$9=""),"",IF(多次统计数据!$B$9<AB7,"低于上限","达到或超过上限")) -> 低于上限 | AD7: 2-较差
A8: T2026007 | B8: 000858 | C8: 102092 | D8: 0.01 | E8: 18.75 | F8: =IF(OR(C8="",D8="",E8="",N8="",C8<=0,D8<=0,E8<=N8),"",ROUNDDOWN((C8*D8)/(E8-N8)/100,0)*100) -> 600 | G8: =IF(OR(A8="",F8="",E8="",N8="",E8<=N8,账户数据!$B$7=""),"",IF(账户数据!$B$9+IF(H8="",F8*(E8-N8),0)>=账户数据!$B$7,"禁止开仓","允许开仓")) -> 禁止开仓 | H8: 200 | I8: 46134 | J8: 20.62 | K8: 17.25 | L8: =IF(K8="","",H8) -> 200 | M8: 46135 | N8: 17.25 | O8: 5 | P8: 5 | Q8: KDJ与形态突破共同确认 | R8: 止损设在17.25 | S8: 目标参考ATR | T8: 按计划成交 | U8: =IF(OR(E8="",J8="",E8<=0),"",(J8-E8)/E8) -> 0.099733333 | V8: =IF(OR(E8="",N8="",E8<=0),"",(E8-N8)/E8) -> 0.08 | W8: =IF(OR(U8="",V8="",V8<=0),"",U8/V8) -> 1.2466667 | X8: =IF(OR(K8="",L8="",E8="",H8=""),"",K8*L8-E8*H8-IF(O8="",0,O8)-IF(P8="",0,P8)) -> -310 | Y8: =IF(OR(X8="",E8="",H8=""),"",IF(E8*H8+IF(O8="",0,O8)<=0,"",X8/(E8*H8+IF(O8="",0,O8)))) -> -0.082556591 | Z8: =IF(OR(Y8="",多次统计数据!$B$8=""),"",Y8-多次统计数据!$B$8) -> -0.21068768 | AA8: =IF(OR(I8="",M8="",M8<I8),"",M8-I8) -> 1 | AB8: =IF(OR(A8="",多次统计数据!$B$8="",多次统计数据!$B$6<=0,多次统计数据!$B$6>=1),"",1-POWER(1+多次统计数据!$B$8,-多次统计数据!$B$6/(1-多次统计数据!$B$6))) -> 0.11918507 | AC8: =IF(OR(AB8="",多次统计数据!$B$9=""),"",IF(多次统计数据!$B$9<AB8,"低于上限","达到或超过上限")) -> 低于上限 | AD8: 2-较差
A9: T2026008 | B9: 600036 | C9: 101782 | D9: 0.01 | E9: 20 | F9: =IF(OR(C9="",D9="",E9="",N9="",C9<=0,D9<=0,E9<=N9),"",ROUNDDOWN((C9*D9)/(E9-N9)/100,0)*100) -> 1300 | G9: =IF(OR(A9="",F9="",E9="",N9="",E9<=N9,账户数据!$B$7=""),"",IF(账户数据!$B$9+IF(H9="",F9*(E9-N9),0)>=账户数据!$B$7,"禁止开仓","允许开仓")) -> 禁止开仓 | H9: 700 | I9: 46135 | J9: 22 | K9: 19 | L9: =IF(K9="","",H9) -> 700 | M9: 46137 | N9: 19.25 | O9: 5 | P9: 0 | Q9: 布林带与均线金叉共同确认 | R9: 止损设在19.25 | S9: 目标参考换手率 | T9: 按计划成交 | U9: =IF(OR(E9="",J9="",E9<=0),"",(J9-E9)/E9) -> 0.1 | V9: =IF(OR(E9="",N9="",E9<=0),"",(E9-N9)/E9) -> 0.0375 | W9: =IF(OR(U9="",V9="",V9<=0),"",U9/V9) -> 2.6666667 | X9: =IF(OR(K9="",L9="",E9="",H9=""),"",K9*L9-E9*H9-IF(O9="",0,O9)-IF(P9="",0,P9)) -> -705 | Y9: =IF(OR(X9="",E9="",H9=""),"",IF(E9*H9+IF(O9="",0,O9)<=0,"",X9/(E9*H9+IF(O9="",0,O9)))) -> -0.050339165 | Z9: =IF(OR(Y9="",多次统计数据!$B$8=""),"",Y9-多次统计数据!$B$8) -> -0.17847025 | AA9: =IF(OR(I9="",M9="",M9<I9),"",M9-I9) -> 2 | AB9: =IF(OR(A9="",多次统计数据!$B$8="",多次统计数据!$B$6<=0,多次统计数据!$B$6>=1),"",1-POWER(1+多次统计数据!$B$8,-多次统计数据!$B$6/(1-多次统计数据!$B$6))) -> 0.11918507 | AC9: =IF(OR(AB9="",多次统计数据!$B$9=""),"",IF(多次统计数据!$B$9<AB9,"低于上限","达到或超过上限")) -> 低于上限 | AD9: 2-较差
A10: T2026009 | B10: 002415 | C10: 101077 | D10: 0.01 | E10: 21.25 | F10: =IF(OR(C10="",D10="",E10="",N10="",C10<=0,D10<=0,E10<=N10),"",ROUNDDOWN((C10*D10)/(E10-N10)/100,0)*100) -> 1000 | G10: =IF(OR(A10="",F10="",E10="",N10="",E10<=N10,账户数据!$B$7=""),"",IF(账户数据!$B$9+IF(H10="",F10*(E10-N10),0)>=账户数据!$B$7,"禁止开仓","允许开仓")) -> 禁止开仓 | H10: 800 | I10: 46136 | J10: 23.38 | K10: 21.25 | L10: =IF(K10="","",H10) -> 800 | M10: 46139 | N10: 20.25 | O10: 0 | P10: 0 | Q10: 支撑位与均线死叉共同确认 | R10: 止损设在20.25 | S10: 目标参考相对强弱 | T10: 按计划成交 | U10: =IF(OR(E10="",J10="",E10<=0),"",(J10-E10)/E10) -> 0.10023529 | V10: =IF(OR(E10="",N10="",E10<=0),"",(E10-N10)/E10) -> 0.047058824 | W10: =IF(OR(U10="",V10="",V10<=0),"",U10/V10) -> 2.13 | X10: =IF(OR(K10="",L10="",E10="",H10=""),"",K10*L10-E10*H10-IF(O10="",0,O10)-IF(P10="",0,P10)) -> 0 | Y10: =IF(OR(X10="",E10="",H10=""),"",IF(E10*H10+IF(O10="",0,O10)<=0,"",X10/(E10*H10+IF(O10="",0,O10)))) -> 0 | Z10: =IF(OR(Y10="",多次统计数据!$B$8=""),"",Y10-多次统计数据!$B$8) -> -0.12813109 | AA10: =IF(OR(I10="",M10="",M10<I10),"",M10-I10) -> 3 | AB10: =IF(OR(A10="",多次统计数据!$B$8="",多次统计数据!$B$6<=0,多次统计数据!$B$6>=1),"",1-POWER(1+多次统计数据!$B$8,-多次统计数据!$B$6/(1-多次统计数据!$B$6))) -> 0.11918507 | AC10: =IF(OR(AB10="",多次统计数据!$B$9=""),"",IF(多次统计数据!$B$9<AB10,"低于上限","达到或超过上限")) -> 低于上限 | AD10: 3-一般
A11: T2026010 | B11: 601899 | C11: 101077 | D11: 0.01 | E11: 22.5 | F11: =IF(OR(C11="",D11="",E11="",N11="",C11<=0,D11<=0,E11<=N11),"",ROUNDDOWN((C11*D11)/(E11-N11)/100,0)*100) -> 800 | G11: =IF(OR(A11="",F11="",E11="",N11="",E11<=N11,账户数据!$B$7=""),"",IF(账户数据!$B$9+IF(H11="",F11*(E11-N11),0)>=账户数据!$B$7,"禁止开仓","允许开仓")) -> 禁止开仓 | H11: 800 | I11: 46137 | J11: 24.75 | L11: =IF(K11="","",H11) | N11: 21.25 | O11: 5 | P11: 5 | Q11: 压力位与量价背离共同确认 | R11: 止损设在21.25 | S11: 目标参考板块共振 | U11: =IF(OR(E11="",J11="",E11<=0),"",(J11-E11)/E11) -> 0.1 | V11: =IF(OR(E11="",N11="",E11<=0),"",(E11-N11)/E11) -> 0.055555556 | W11: =IF(OR(U11="",V11="",V11<=0),"",U11/V11) -> 1.8 | X11: =IF(OR(K11="",L11="",E11="",H11=""),"",K11*L11-E11*H11-IF(O11="",0,O11)-IF(P11="",0,P11)) | Y11: =IF(OR(X11="",E11="",H11=""),"",IF(E11*H11+IF(O11="",0,O11)<=0,"",X11/(E11*H11+IF(O11="",0,O11)))) | Z11: =IF(OR(Y11="",多次统计数据!$B$8=""),"",Y11-多次统计数据!$B$8) | AA11: =IF(OR(I11="",M11="",M11<I11),"",M11-I11) | AB11: =IF(OR(A11="",多次统计数据!$B$8="",多次统计数据!$B$6<=0,多次统计数据!$B$6>=1),"",1-POWER(1+多次统计数据!$B$8,-多次统计数据!$B$6/(1-多次统计数据!$B$6))) -> 0.11918507 | AC11: =IF(OR(AB11="",多次统计数据!$B$9=""),"",IF(多次统计数据!$B$9<AB11,"低于上限","达到或超过上限")) -> 低于上限
A12: T2026011 | B12: 600519 | C12: 101077 | D12: 0.01 | E12: 10 | F12: =IF(OR(C12="",D12="",E12="",N12="",C12<=0,D12<=0,E12<=N12),"",ROUNDDOWN((C12*D12)/(E12-N12)/100,0)*100) -> 600 | G12: =IF(OR(A12="",F12="",E12="",N12="",E12<=N12,账户数据!$B$7=""),"",IF(账户数据!$B$9+IF(H12="",F12*(E12-N12),0)>=账户数据!$B$7,"禁止开仓","允许开仓")) -> 禁止开仓 | H12: 100 | I12: 46138 | J12: 11 | K12: 11.4 | L12: =IF(K12="","",H12) -> 100 | M12: 46143 | N12: 8.5 | O12: 5 | P12: 5 | Q12: 缺口与趋势背离共同确认 | R12: 止损设在8.50 | S12: 目标参考蜡烛图 | T12: 按计划成交 | U12: =IF(OR(E12="",J12="",E12<=0),"",(J12-E12)/E12) -> 0.1 | V12: =IF(OR(E12="",N12="",E12<=0),"",(E12-N12)/E12) -> 0.15 | W12: =IF(OR(U12="",V12="",V12<=0),"",U12/V12) -> 0.66666667 | X12: =IF(OR(K12="",L12="",E12="",H12=""),"",K12*L12-E12*H12-IF(O12="",0,O12)-IF(P12="",0,P12)) -> 130 | Y12: =IF(OR(X12="",E12="",H12=""),"",IF(E12*H12+IF(O12="",0,O12)<=0,"",X12/(E12*H12+IF(O12="",0,O12)))) -> 0.12935323 | Z12: =IF(OR(Y12="",多次统计数据!$B$8=""),"",Y12-多次统计数据!$B$8) -> 0.0012221438 | AA12: =IF(OR(I12="",M12="",M12<I12),"",M12-I12) -> 5 | AB12: =IF(OR(A12="",多次统计数据!$B$8="",多次统计数据!$B$6<=0,多次统计数据!$B$6>=1),"",1-POWER(1+多次统计数据!$B$8,-多次统计数据!$B$6/(1-多次统计数据!$B$6))) -> 0.11918507 | AC12: =IF(OR(AB12="",多次统计数据!$B$9=""),"",IF(多次统计数据!$B$9<AB12,"低于上限","达到或超过上限")) -> 低于上限 | AD12: 4-良好
A13: T2026012 | B13: 000001 | C13: 101207 | D13: 0.01 | E13: 11.25 | F13: =IF(OR(C13="",D13="",E13="",N13="",C13<=0,D13<=0,E13<=N13),"",ROUNDDOWN((C13*D13)/(E13-N13)/100,0)*100) -> 1300 | G13: =IF(OR(A13="",F13="",E13="",N13="",E13<=N13,账户数据!$B$7=""),"",IF(账户数据!$B$9+IF(H13="",F13*(E13-N13),0)>=账户数据!$B$7,"禁止开仓","允许开仓")) -> 禁止开仓 | H13: 500 | I13: 46139 | J13: 12.38 | K13: 12.6 | L13: =IF(K13="","",H13) -> 500 | M13: 46145 | N13: 10.5 | O13: 0 | P13: 0 | Q13: 形态突破与ATR共同确认 | R13: 止损设在10.50 | S13: 目标参考趋势线 | T13: 按计划成交 | U13: =IF(OR(E13="",J13="",E13<=0),"",(J13-E13)/E13) -> 0.10044444 | V13: =IF(OR(E13="",N13="",E13<=0),"",(E13-N13)/E13) -> 0.066666667 | W13: =IF(OR(U13="",V13="",V13<=0),"",U13/V13) -> 1.5066667 | X13: =IF(OR(K13="",L13="",E13="",H13=""),"",K13*L13-E13*H13-IF(O13="",0,O13)-IF(P13="",0,P13)) -> 675 | Y13: =IF(OR(X13="",E13="",H13=""),"",IF(E13*H13+IF(O13="",0,O13)<=0,"",X13/(E13*H13+IF(O13="",0,O13)))) -> 0.12 | Z13: =IF(OR(Y13="",多次统计数据!$B$8=""),"",Y13-多次统计数据!$B$8) -> -0.0081310901 | AA13: =IF(OR(I13="",M13="",M13<I13),"",M13-I13) -> 6 | AB13: =IF(OR(A13="",多次统计数据!$B$8="",多次统计数据!$B$6<=0,多次统计数据!$B$6>=1),"",1-POWER(1+多次统计数据!$B$8,-多次统计数据!$B$6/(1-多次统计数据!$B$6))) -> 0.11918507 | AC13: =IF(OR(AB13="",多次统计数据!$B$9=""),"",IF(多次统计数据!$B$9<AB13,"低于上限","达到或超过上限")) -> 低于上限 | AD13: 4-良好
A14: T2026013 | B14: 300750 | C14: 101882 | D14: 0.01 | E14: 12.5 | F14: =IF(OR(C14="",D14="",E14="",N14="",C14<=0,D14<=0,E14<=N14),"",ROUNDDOWN((C14*D14)/(E14-N14)/100,0)*100) -> 1000 | G14: =IF(OR(A14="",F14="",E14="",N14="",E14<=N14,账户数据!$B$7=""),"",IF(账户数据!$B$9+IF(H14="",F14*(E14-N14),0)>=账户数据!$B$7,"禁止开仓","允许开仓")) -> 禁止开仓 | H14: 600 | I14: 46140 | J14: 13.75 | K14: 14.13 | L14: =IF(K14="","",H14) -> 600 | M14: 46147 | N14: 11.5 | O14: 5 | P14: 5 | Q14: 均线金叉与换手率共同确认 | R14: 止损设在11.50 | S14: 目标参考MACD | T14: 按计划成交 | U14: =IF(OR(E14="",J14="",E14<=0),"",(J14-E14)/E14) -> 0.1 | V14: =IF(OR(E14="",N14="",E14<=0),"",(E14-N14)/E14) -> 0.08 | W14: =IF(OR(U14="",V14="",V14<=0),"",U14/V14) -> 1.25 | X14: =IF(OR(K14="",L14="",E14="",H14=""),"",K14*L14-E14*H14-IF(O14="",0,O14)-IF(P14="",0,P14)) -> 968 | Y14: =IF(OR(X14="",E14="",H14=""),"",IF(E14*H14+IF(O14="",0,O14)<=0,"",X14/(E14*H14+IF(O14="",0,O14)))) -> 0.12898068 | Z14: =IF(OR(Y14="",多次统计数据!$B$8=""),"",Y14-多次统计数据!$B$8) -> 0.00084958947 | AA14: =IF(OR(I14="",M14="",M14<I14),"",M14-I14) -> 7 | AB14: =IF(OR(A14="",多次统计数据!$B$8="",多次统计数据!$B$6<=0,多次统计数据!$B$6>=1),"",1-POWER(1+多次统计数据!$B$8,-多次统计数据!$B$6/(1-多次统计数据!$B$6))) -> 0.11918507 | AC14: =IF(OR(AB14="",多次统计数据!$B$9=""),"",IF(多次统计数据!$B$9<AB14,"低于上限","达到或超过上限")) -> 低于上限 | AD14: 4-良好
A15: T2026014 | B15: 002594 | C15: 102850 | D15: 0.01 | E15: 13.75 | F15: =IF(OR(C15="",D15="",E15="",N15="",C15<=0,D15<=0,E15<=N15),"",ROUNDDOWN((C15*D15)/(E15-N15)/100,0)*100) -> 800 | G15: =IF(OR(A15="",F15="",E15="",N15="",E15<=N15,账户数据!$B$7=""),"",IF(账户数据!$B$9+IF(H15="",F15*(E15-N15),0)>=账户数据!$B$7,"禁止开仓","允许开仓")) -> 禁止开仓 | H15: 600 | I15: 46141 | J15: 15.13 | K15: 15.68 | L15: =IF(K15="","",H15) -> 600 | M15: 46142 | N15: 12.5 | O15: 5 | P15: 5 | Q15: 均线死叉与相对强弱共同确认 | R15: 止损设在12.50 | S15: 目标参考移动平均线 | T15: 按计划成交 | U15: =IF(OR(E15="",J15="",E15<=0),"",(J15-E15)/E15) -> 0.10036364 | V15: =IF(OR(E15="",N15="",E15<=0),"",(E15-N15)/E15) -> 0.090909091 | W15: =IF(OR(U15="",V15="",V15<=0),"",U15/V15) -> 1.104 | X15: =IF(OR(K15="",L15="",E15="",H15=""),"",K15*L15-E15*H15-IF(O15="",0,O15)-IF(P15="",0,P15)) -> 1148 | Y15: =IF(OR(X15="",E15="",H15=""),"",IF(E15*H15+IF(O15="",0,O15)<=0,"",X15/(E15*H15+IF(O15="",0,O15)))) -> 0.13906723 | Z15: =IF(OR(Y15="",多次统计数据!$B$8=""),"",Y15-多次统计数据!$B$8) -> 0.010936142 | AA15: =IF(OR(I15="",M15="",M15<I15),"",M15-I15) -> 1 | AB15: =IF(OR(A15="",多次统计数据!$B$8="",多次统计数据!$B$6<=0,多次统计数据!$B$6>=1),"",1-POWER(1+多次统计数据!$B$8,-多次统计数据!$B$6/(1-多次统计数据!$B$6))) -> 0.11918507 | AC15: =IF(OR(AB15="",多次统计数据!$B$9=""),"",IF(多次统计数据!$B$9<AB15,"低于上限","达到或超过上限")) -> 低于上限 | AD15: 4-良好
A16: T2026015 | B16: 601318 | C16: 103998 | D16: 0.01 | E16: 15 | F16: =IF(OR(C16="",D16="",E16="",N16="",C16<=0,D16<=0,E16<=N16),"",ROUNDDOWN((C16*D16)/(E16-N16)/100,0)*100) -> 600 | G16: =IF(OR(A16="",F16="",E16="",N16="",E16<=N16,账户数据!$B$7=""),"",IF(账户数据!$B$9+IF(H16="",F16*(E16-N16),0)>=账户数据!$B$7,"禁止开仓","允许开仓")) -> 禁止开仓 | H16: 600 | I16: 46142 | J16: 16.5 | K16: 13.5 | L16: =IF(K16="","",H16) -> 600 | M16: 46144 | N16: 13.5 | O16: 0 | P16: 5 | Q16: 量价背离与板块共振共同确认 | R16: 止损设在13.50 | S16: 目标参考成交量 | T16: 按计划成交 | U16: =IF(OR(E16="",J16="",E16<=0),"",(J16-E16)/E16) -> 0.1 | V16: =IF(OR(E16="",N16="",E16<=0),"",(E16-N16)/E16) -> 0.1 | W16: =IF(OR(U16="",V16="",V16<=0),"",U16/V16) -> 1 | X16: =IF(OR(K16="",L16="",E16="",H16=""),"",K16*L16-E16*H16-IF(O16="",0,O16)-IF(P16="",0,P16)) -> -905 | Y16: =IF(OR(X16="",E16="",H16=""),"",IF(E16*H16+IF(O16="",0,O16)<=0,"",X16/(E16*H16+IF(O16="",0,O16)))) -> -0.10055556 | Z16: =IF(OR(Y16="",多次统计数据!$B$8=""),"",Y16-多次统计数据!$B$8) -> -0.22868665 | AA16: =IF(OR(I16="",M16="",M16<I16),"",M16-I16) -> 2 | AB16: =IF(OR(A16="",多次统计数据!$B$8="",多次统计数据!$B$6<=0,多次统计数据!$B$6>=1),"",1-POWER(1+多次统计数据!$B$8,-多次统计数据!$B$6/(1-多次统计数据!$B$6))) -> 0.11918507 | AC16: =IF(OR(AB16="",多次统计数据!$B$9=""),"",IF(多次统计数据!$B$9<AB16,"低于上限","达到或超过上限")) -> 低于上限 | AD16: 2-较差
A17: T2026016 | B17: 688981 | C17: 103093 | D17: 0.01 | E17: 16.25 | F17: =IF(OR(C17="",D17="",E17="",N17="",C17<=0,D17<=0,E17<=N17),"",ROUNDDOWN((C17*D17)/(E17-N17)/100,0)*100) -> 1300 | G17: =IF(OR(A17="",F17="",E17="",N17="",E17<=N17,账户数据!$B$7=""),"",IF(账户数据!$B$9+IF(H17="",F17*(E17-N17),0)>=账户数据!$B$7,"禁止开仓","允许开仓")) -> 禁止开仓 | H17: 200 | I17: 46143 | J17: 17.88 | K17: 15.44 | L17: =IF(K17="","",H17) -> 200 | M17: 46146 | N17: 15.5 | O17: 5 | P17: 0 | Q17: 趋势背离与蜡烛图共同确认 | R17: 止损设在15.50 | S17: 目标参考RSI | T17: 按计划成交 | U17: =IF(OR(E17="",J17="",E17<=0),"",(J17-E17)/E17) -> 0.10030769 | V17: =IF(OR(E17="",N17="",E17<=0),"",(E17-N17)/E17) -> 0.046153846 | W17: =IF(OR(U17="",V17="",V17<=0),"",U17/V17) -> 2.1733333 | X17: =IF(OR(K17="",L17="",E17="",H17=""),"",K17*L17-E17*H17-IF(O17="",0,O17)-IF(P17="",0,P17)) -> -167 | Y17: =IF(OR(X17="",E17="",H17=""),"",IF(E17*H17+IF(O17="",0,O17)<=0,"",X17/(E17*H17+IF(O17="",0,O17)))) -> -0.051305684 | Z17: =IF(OR(Y17="",多次统计数据!$B$8=""),"",Y17-多次统计数据!$B$8) -> -0.17943677 | AA17: =IF(OR(I17="",M17="",M17<I17),"",M17-I17) -> 3 | AB17: =IF(OR(A17="",多次统计数据!$B$8="",多次统计数据!$B$6<=0,多次统计数据!$B$6>=1),"",1-POWER(1+多次统计数据!$B$8,-多次统计数据!$B$6/(1-多次统计数据!$B$6))) -> 0.11918507 | AC17: =IF(OR(AB17="",多次统计数据!$B$9=""),"",IF(多次统计数据!$B$9<AB17,"低于上限","达到或超过上限")) -> 低于上限 | AD17: 2-较差
A18: T2026017 | B18: 000858 | C18: 102926 | D18: 0.01 | E18: 17.5 | F18: =IF(OR(C18="",D18="",E18="",N18="",C18<=0,D18<=0,E18<=N18),"",ROUNDDOWN((C18*D18)/(E18-N18)/100,0)*100) -> 1000 | G18: =IF(OR(A18="",F18="",E18="",N18="",E18<=N18,账户数据!$B$7=""),"",IF(账户数据!$B$9+IF(H18="",F18*(E18-N18),0)>=账户数据!$B$7,"禁止开仓","允许开仓")) -> 禁止开仓 | H18: 400 | I18: 46144 | J18: 19.25 | K18: 16.45 | L18: =IF(K18="","",H18) -> 400 | M18: 46148 | N18: 16.5 | O18: 5 | P18: 5 | Q18: ATR与趋势线共同确认 | R18: 止损设在16.50 | S18: 目标参考KDJ | T18: 按计划成交 | U18: =IF(OR(E18="",J18="",E18<=0),"",(J18-E18)/E18) -> 0.1 | V18: =IF(OR(E18="",N18="",E18<=0),"",(E18-N18)/E18) -> 0.057142857 | W18: =IF(OR(U18="",V18="",V18<=0),"",U18/V18) -> 1.75 | X18: =IF(OR(K18="",L18="",E18="",H18=""),"",K18*L18-E18*H18-IF(O18="",0,O18)-IF(P18="",0,P18)) -> -430 | Y18: =IF(OR(X18="",E18="",H18=""),"",IF(E18*H18+IF(O18="",0,O18)<=0,"",X18/(E18*H18+IF(O18="",0,O18)))) -> -0.061384725 | Z18: =IF(OR(Y18="",多次统计数据!$B$8=""),"",Y18-多次统计数据!$B$8) -> -0.18951582 | AA18: =IF(OR(I18="",M18="",M18<I18),"",M18-I18) -> 4 | AB18: =IF(OR(A18="",多次统计数据!$B$8="",多次统计数据!$B$6<=0,多次统计数据!$B$6>=1),"",1-POWER(1+多次统计数据!$B$8,-多次统计数据!$B$6/(1-多次统计数据!$B$6))) -> 0.11918507 | AC18: =IF(OR(AB18="",多次统计数据!$B$9=""),"",IF(多次统计数据!$B$9<AB18,"低于上限","达到或超过上限")) -> 低于上限 | AD18: 2-较差
A19: T2026018 | B19: 600036 | C19: 102496 | D19: 0.01 | E19: 18.75 | F19: =IF(OR(C19="",D19="",E19="",N19="",C19<=0,D19<=0,E19<=N19),"",ROUNDDOWN((C19*D19)/(E19-N19)/100,0)*100) -> 800 | G19: =IF(OR(A19="",F19="",E19="",N19="",E19<=N19,账户数据!$B$7=""),"",IF(账户数据!$B$9+IF(H19="",F19*(E19-N19),0)>=账户数据!$B$7,"禁止开仓","允许开仓")) -> 禁止开仓 | H19: 400 | I19: 46145 | J19: 20.62 | K19: 17.5 | L19: =IF(K19="","",H19) -> 400 | M19: 46150 | N19: 17.5 | O19: 0 | P19: 5 | Q19: 换手率与MACD共同确认 | R19: 止损设在17.50 | S19: 目标参考布林带 | T19: 按计划成交 | U19: =IF(OR(E19="",J19="",E19<=0),"",(J19-E19)/E19) -> 0.099733333 | V19: =IF(OR(E19="",N19="",E19<=0),"",(E19-N19)/E19) -> 0.066666667 | W19: =IF(OR(U19="",V19="",V19<=0),"",U19/V19) -> 1.496 | X19: =IF(OR(K19="",L19="",E19="",H19=""),"",K19*L19-E19*H19-IF(O19="",0,O19)-IF(P19="",0,P19)) -> -505 | Y19: =IF(OR(X19="",E19="",H19=""),"",IF(E19*H19+IF(O19="",0,O19)<=0,"",X19/(E19*H19+IF(O19="",0,O19)))) -> -0.067333333 | Z19: =IF(OR(Y19="",多次统计数据!$B$8=""),"",Y19-多次统计数据!$B$8) -> -0.19546442 | AA19: =IF(OR(I19="",M19="",M19<I19),"",M19-I19) -> 5 | AB19: =IF(OR(A19="",多次统计数据!$B$8="",多次统计数据!$B$6<=0,多次统计数据!$B$6>=1),"",1-POWER(1+多次统计数据!$B$8,-多次统计数据!$B$6/(1-多次统计数据!$B$6))) -> 0.11918507 | AC19: =IF(OR(AB19="",多次统计数据!$B$9=""),"",IF(多次统计数据!$B$9<AB19,"低于上限","达到或超过上限")) -> 低于上限 | AD19: 2-较差
A20: T2026019 | B20: 002415 | C20: 101991 | D20: 0.01 | E20: 20 | F20: =IF(OR(C20="",D20="",E20="",N20="",C20<=0,D20<=0,E20<=N20),"",ROUNDDOWN((C20*D20)/(E20-N20)/100,0)*100) -> 600 | G20: =IF(OR(A20="",F20="",E20="",N20="",E20<=N20,账户数据!$B$7=""),"",IF(账户数据!$B$9+IF(H20="",F20*(E20-N20),0)>=账户数据!$B$7,"禁止开仓","允许开仓")) -> 禁止开仓 | H20: 400 | I20: 46146 | J20: 22 | K20: 20 | L20: =IF(K20="","",H20) -> 400 | M20: 46152 | N20: 18.5 | O20: 0 | P20: 0 | Q20: 相对强弱与移动平均线共同确认 | R20: 止损设在18.50 | S20: 目标参考支撑位 | T20: 按计划成交 | U20: =IF(OR(E20="",J20="",E20<=0),"",(J20-E20)/E20) -> 0.1 | V20: =IF(OR(E20="",N20="",E20<=0),"",(E20-N20)/E20) -> 0.075 | W20: =IF(OR(U20="",V20="",V20<=0),"",U20/V20) -> 1.3333333 | X20: =IF(OR(K20="",L20="",E20="",H20=""),"",K20*L20-E20*H20-IF(O20="",0,O20)-IF(P20="",0,P20)) -> 0 | Y20: =IF(OR(X20="",E20="",H20=""),"",IF(E20*H20+IF(O20="",0,O20)<=0,"",X20/(E20*H20+IF(O20="",0,O20)))) -> 0 | Z20: =IF(OR(Y20="",多次统计数据!$B$8=""),"",Y20-多次统计数据!$B$8) -> -0.12813109 | AA20: =IF(OR(I20="",M20="",M20<I20),"",M20-I20) -> 6 | AB20: =IF(OR(A20="",多次统计数据!$B$8="",多次统计数据!$B$6<=0,多次统计数据!$B$6>=1),"",1-POWER(1+多次统计数据!$B$8,-多次统计数据!$B$6/(1-多次统计数据!$B$6))) -> 0.11918507 | AC20: =IF(OR(AB20="",多次统计数据!$B$9=""),"",IF(多次统计数据!$B$9<AB20,"低于上限","达到或超过上限")) -> 低于上限 | AD20: 3-一般
A21: T2026020 | B21: 601899 | C21: 101991 | D21: 0.01 | E21: 21.25 | F21: =IF(OR(C21="",D21="",E21="",N21="",C21<=0,D21<=0,E21<=N21),"",ROUNDDOWN((C21*D21)/(E21-N21)/100,0)*100) -> 1300 | G21: =IF(OR(A21="",F21="",E21="",N21="",E21<=N21,账户数据!$B$7=""),"",IF(账户数据!$B$9+IF(H21="",F21*(E21-N21),0)>=账户数据!$B$7,"禁止开仓","允许开仓")) -> 禁止开仓 | H21: 1300 | I21: 46147 | J21: 23.38 | L21: =IF(K21="","",H21) | N21: 20.5 | O21: 5 | P21: 0 | Q21: 板块共振与成交量共同确认 | R21: 止损设在20.50 | S21: 目标参考压力位 | U21: =IF(OR(E21="",J21="",E21<=0),"",(J21-E21)/E21) -> 0.10023529 | V21: =IF(OR(E21="",N21="",E21<=0),"",(E21-N21)/E21) -> 0.035294118 | W21: =IF(OR(U21="",V21="",V21<=0),"",U21/V21) -> 2.84 | X21: =IF(OR(K21="",L21="",E21="",H21=""),"",K21*L21-E21*H21-IF(O21="",0,O21)-IF(P21="",0,P21)) | Y21: =IF(OR(X21="",E21="",H21=""),"",IF(E21*H21+IF(O21="",0,O21)<=0,"",X21/(E21*H21+IF(O21="",0,O21)))) | Z21: =IF(OR(Y21="",多次统计数据!$B$8=""),"",Y21-多次统计数据!$B$8) | AA21: =IF(OR(I21="",M21="",M21<I21),"",M21-I21) | AB21: =IF(OR(A21="",多次统计数据!$B$8="",多次统计数据!$B$6<=0,多次统计数据!$B$6>=1),"",1-POWER(1+多次统计数据!$B$8,-多次统计数据!$B$6/(1-多次统计数据!$B$6))) -> 0.11918507 | AC21: =IF(OR(AB21="",多次统计数据!$B$9=""),"",IF(多次统计数据!$B$9<AB21,"低于上限","达到或超过上限")) -> 低于上限
A22: T2026021 | B22: 600519 | C22: 101991 | D22: 0.01 | E22: 22.5 | F22: =IF(OR(C22="",D22="",E22="",N22="",C22<=0,D22<=0,E22<=N22),"",ROUNDDOWN((C22*D22)/(E22-N22)/100,0)*100) -> 1000 | G22: =IF(OR(A22="",F22="",E22="",N22="",E22<=N22,账户数据!$B$7=""),"",IF(账户数据!$B$9+IF(H22="",F22*(E22-N22),0)>=账户数据!$B$7,"禁止开仓","允许开仓")) -> 禁止开仓 | H22: 200 | I22: 46148 | J22: 24.75 | K22: 25.2 | L22: =IF(K22="","",H22) -> 200 | M22: 46149 | N22: 21.5 | O22: 0 | P22: 5 | Q22: 蜡烛图与RSI共同确认 | R22: 止损设在21.50 | S22: 目标参考缺口 | T22: 按计划成交 | U22: =IF(OR(E22="",J22="",E22<=0),"",(J22-E22)/E22) -> 0.1 | V22: =IF(OR(E22="",N22="",E22<=0),"",(E22-N22)/E22) -> 0.044444444 | W22: =IF(OR(U22="",V22="",V22<=0),"",U22/V22) -> 2.25 | X22: =IF(OR(K22="",L22="",E22="",H22=""),"",K22*L22-E22*H22-IF(O22="",0,O22)-IF(P22="",0,P22)) -> 535 | Y22: =IF(OR(X22="",E22="",H22=""),"",IF(E22*H22+IF(O22="",0,O22)<=0,"",X22/(E22*H22+IF(O22="",0,O22)))) -> 0.11888889 | Z22: =IF(OR(Y22="",多次统计数据!$B$8=""),"",Y22-多次统计数据!$B$8) -> -0.0092422012 | AA22: =IF(OR(I22="",M22="",M22<I22),"",M22-I22) -> 1 | AB22: =IF(OR(A22="",多次统计数据!$B$8="",多次统计数据!$B$6<=0,多次统计数据!$B$6>=1),"",1-POWER(1+多次统计数据!$B$8,-多次统计数据!$B$6/(1-多次统计数据!$B$6))) -> 0.11918507 | AC22: =IF(OR(AB22="",多次统计数据!$B$9=""),"",IF(多次统计数据!$B$9<AB22,"低于上限","达到或超过上限")) -> 低于上限 | AD22: 4-良好
A23: T2026022 | B23: 000001 | C23: 102526 | D23: 0.01 | E23: 10 | F23: =IF(OR(C23="",D23="",E23="",N23="",C23<=0,D23<=0,E23<=N23),"",ROUNDDOWN((C23*D23)/(E23-N23)/100,0)*100) -> 800 | G23: =IF(OR(A23="",F23="",E23="",N23="",E23<=N23,账户数据!$B$7=""),"",IF(账户数据!$B$9+IF(H23="",F23*(E23-N23),0)>=账户数据!$B$7,"禁止开仓","允许开仓")) -> 禁止开仓 | H23: 300 | I23: 46149 | J23: 11 | K23: 11.3 | L23: =IF(K23="","",H23) -> 300 | M23: 46151 | N23: 8.75 | O23: 5 | P23: 5 | Q23: 趋势线与KDJ共同确认 | R23: 止损设在8.75 | S23: 目标参考形态突破 | T23: 按计划成交 | U23: =IF(OR(E23="",J23="",E23<=0),"",(J23-E23)/E23) -> 0.1 | V23: =IF(OR(E23="",N23="",E23<=0),"",(E23-N23)/E23) -> 0.125 | W23: =IF(OR(U23="",V23="",V23<=0),"",U23/V23) -> 0.8 | X23: =IF(OR(K23="",L23="",E23="",H23=""),"",K23*L23-E23*H23-IF(O23="",0,O23)-IF(P23="",0,P23)) -> 380 | Y23: =IF(OR(X23="",E23="",H23=""),"",IF(E23*H23+IF(O23="",0,O23)<=0,"",X23/(E23*H23+IF(O23="",0,O23)))) -> 0.12645591 | Z23: =IF(OR(Y23="",多次统计数据!$B$8=""),"",Y23-多次统计数据!$B$8) -> -0.0016751833 | AA23: =IF(OR(I23="",M23="",M23<I23),"",M23-I23) -> 2 | AB23: =IF(OR(A23="",多次统计数据!$B$8="",多次统计数据!$B$6<=0,多次统计数据!$B$6>=1),"",1-POWER(1+多次统计数据!$B$8,-多次统计数据!$B$6/(1-多次统计数据!$B$6))) -> 0.11918507 | AC23: =IF(OR(AB23="",多次统计数据!$B$9=""),"",IF(多次统计数据!$B$9<AB23,"低于上限","达到或超过上限")) -> 低于上限 | AD23: 4-良好
A24: T2026023 | B24: 300750 | C24: 102906 | D24: 0.01 | E24: 11.25 | F24: =IF(OR(C24="",D24="",E24="",N24="",C24<=0,D24<=0,E24<=N24),"",ROUNDDOWN((C24*D24)/(E24-N24)/100,0)*100) -> 600 | G24: =IF(OR(A24="",F24="",E24="",N24="",E24<=N24,账户数据!$B$7=""),"",IF(账户数据!$B$9+IF(H24="",F24*(E24-N24),0)>=账户数据!$B$7,"禁止开仓","允许开仓")) -> 禁止开仓 | H24: 300 | I24: 46150 | J24: 12.38 | K24: 12.83 | L24: =IF(K24="","",H24) -> 300 | M24: 46153 | N24: 9.75 | O24: 5 | P24: 5 | Q24: MACD与布林带共同确认 | R24: 止损设在9.75 | S24: 目标参考均线金叉 | T24: 按计划成交 | U24: =IF(OR(E24="",J24="",E24<=0),"",(J24-E24)/E24) -> 0.10044444 | V24: =IF(OR(E24="",N24="",E24<=0),"",(E24-N24)/E24) -> 0.13333333 | W24: =IF(OR(U24="",V24="",V24<=0),"",U24/V24) -> 0.75333333 | X24: =IF(OR(K24="",L24="",E24="",H24=""),"",K24*L24-E24*H24-IF(O24="",0,O24)-IF(P24="",0,P24)) -> 464 | Y24: =IF(OR(X24="",E24="",H24=""),"",IF(E24*H24+IF(O24="",0,O24)<=0,"",X24/(E24*H24+IF(O24="",0,O24)))) -> 0.13727811 | Z24: =IF(OR(Y24="",多次统计数据!$B$8=""),"",Y24-多次统计数据!$B$8) -> 0.0091470164 | AA24: =IF(OR(I24="",M24="",M24<I24),"",M24-I24) -> 3 | AB24: =IF(OR(A24="",多次统计数据!$B$8="",多次统计数据!$B$6<=0,多次统计数据!$B$6>=1),"",1-POWER(1+多次统计数据!$B$8,-多次统计数据!$B$6/(1-多次统计数据!$B$6))) -> 0.11918507 | AC24: =IF(OR(AB24="",多次统计数据!$B$9=""),"",IF(多次统计数据!$B$9<AB24,"低于上限","达到或超过上限")) -> 低于上限 | AD24: 4-良好
A25: T2026024 | B25: 002594 | C25: 103370 | D25: 0.01 | E25: 12.5 | F25: =IF(OR(C25="",D25="",E25="",N25="",C25<=0,D25<=0,E25<=N25),"",ROUNDDOWN((C25*D25)/(E25-N25)/100,0)*100) -> 1300 | G25: =IF(OR(A25="",F25="",E25="",N25="",E25<=N25,账户数据!$B$7=""),"",IF(账户数据!$B$9+IF(H25="",F25*(E25-N25),0)>=账户数据!$B$7,"禁止开仓","允许开仓")) -> 禁止开仓 | H25: 1000 | I25: 46151 | J25: 13.75 | K25: 14 | L25: =IF(K25="","",H25) -> 1000 | M25: 46155 | N25: 11.75 | O25: 0 | P25: 0 | Q25: 移动平均线与支撑位共同确认 | R25: 止损设在11.75 | S25: 目标参考均线死叉 | T25: 按计划成交 | U25: =IF(OR(E25="",J25="",E25<=0),"",(J25-E25)/E25) -> 0.1 | V25: =IF(OR(E25="",N25="",E25<=0),"",(E25-N25)/E25) -> 0.06 | W25: =IF(OR(U25="",V25="",V25<=0),"",U25/V25) -> 1.6666667 | X25: =IF(OR(K25="",L25="",E25="",H25=""),"",K25*L25-E25*H25-IF(O25="",0,O25)-IF(P25="",0,P25)) -> 1500 | Y25: =IF(OR(X25="",E25="",H25=""),"",IF(E25*H25+IF(O25="",0,O25)<=0,"",X25/(E25*H25+IF(O25="",0,O25)))) -> 0.12 | Z25: =IF(OR(Y25="",多次统计数据!$B$8=""),"",Y25-多次统计数据!$B$8) -> -0.0081310901 | AA25: =IF(OR(I25="",M25="",M25<I25),"",M25-I25) -> 4 | AB25: =IF(OR(A25="",多次统计数据!$B$8="",多次统计数据!$B$6<=0,多次统计数据!$B$6>=1),"",1-POWER(1+多次统计数据!$B$8,-多次统计数据!$B$6/(1-多次统计数据!$B$6))) -> 0.11918507 | AC25: =IF(OR(AB25="",多次统计数据!$B$9=""),"",IF(多次统计数据!$B$9<AB25,"低于上限","达到或超过上限")) -> 低于上限 | AD25: 4-良好
A26: T2026025 | B26: 601318 | C26: 104870 | D26: 0.01 | E26: 13.75 | F26: =IF(OR(C26="",D26="",E26="",N26="",C26<=0,D26<=0,E26<=N26),"",ROUNDDOWN((C26*D26)/(E26-N26)/100,0)*100) -> 1000 | G26: =IF(OR(A26="",F26="",E26="",N26="",E26<=N26,账户数据!$B$7=""),"",IF(账户数据!$B$9+IF(H26="",F26*(E26-N26),0)>=账户数据!$B$7,"禁止开仓","允许开仓")) -> 禁止开仓 | I26: 46152 | J26: 15.13 | L26: =IF(K26="","",H26) | N26: 12.75 | O26: 5 | P26: 5 | Q26: 成交量与压力位共同确认 | R26: 止损设在12.75 | S26: 目标参考量价背离 | U26: =IF(OR(E26="",J26="",E26<=0),"",(J26-E26)/E26) -> 0.10036364 | V26: =IF(OR(E26="",N26="",E26<=0),"",(E26-N26)/E26) -> 0.072727273 | W26: =IF(OR(U26="",V26="",V26<=0),"",U26/V26) -> 1.38 | X26: =IF(OR(K26="",L26="",E26="",H26=""),"",K26*L26-E26*H26-IF(O26="",0,O26)-IF(P26="",0,P26)) | Y26: =IF(OR(X26="",E26="",H26=""),"",IF(E26*H26+IF(O26="",0,O26)<=0,"",X26/(E26*H26+IF(O26="",0,O26)))) | Z26: =IF(OR(Y26="",多次统计数据!$B$8=""),"",Y26-多次统计数据!$B$8) | AA26: =IF(OR(I26="",M26="",M26<I26),"",M26-I26) | AB26: =IF(OR(A26="",多次统计数据!$B$8="",多次统计数据!$B$6<=0,多次统计数据!$B$6>=1),"",1-POWER(1+多次统计数据!$B$8,-多次统计数据!$B$6/(1-多次统计数据!$B$6))) -> 0.11918507 | AC26: =IF(OR(AB26="",多次统计数据!$B$9=""),"",IF(多次统计数据!$B$9<AB26,"低于上限","达到或超过上限")) -> 低于上限
A27: T2026026 | B27: 688981 | C27: 104870 | D27: 0.01 | E27: 15 | F27: =IF(OR(C27="",D27="",E27="",N27="",C27<=0,D27<=0,E27<=N27),"",ROUNDDOWN((C27*D27)/(E27-N27)/100,0)*100) -> 800 | G27: =IF(OR(A27="",F27="",E27="",N27="",E27<=N27,账户数据!$B$7=""),"",IF(账户数据!$B$9+IF(H27="",F27*(E27-N27),0)>=账户数据!$B$7,"禁止开仓","允许开仓")) -> 禁止开仓 | H27: 100 | I27: 46153 | J27: 16.5 | K27: 13.75 | L27: =IF(K27="","",H27) -> 100 | M27: 46159 | N27: 13.75 | O27: 5 | P27: 5 | Q27: RSI与缺口共同确认 | R27: 止损设在13.75 | S27: 目标参考趋势背离 | T27: 按计划成交 | U27: =IF(OR(E27="",J27="",E27<=0),"",(J27-E27)/E27) -> 0.1 | V27: =IF(OR(E27="",N27="",E27<=0),"",(E27-N27)/E27) -> 0.083333333 | W27: =IF(OR(U27="",V27="",V27<=0),"",U27/V27) -> 1.2 | X27: =IF(OR(K27="",L27="",E27="",H27=""),"",K27*L27-E27*H27-IF(O27="",0,O27)-IF(P27="",0,P27)) -> -135 | Y27: =IF(OR(X27="",E27="",H27=""),"",IF(E27*H27+IF(O27="",0,O27)<=0,"",X27/(E27*H27+IF(O27="",0,O27)))) -> -0.089700997 | Z27: =IF(OR(Y27="",多次统计数据!$B$8=""),"",Y27-多次统计数据!$B$8) -> -0.21783209 | AA27: =IF(OR(I27="",M27="",M27<I27),"",M27-I27) -> 6 | AB27: =IF(OR(A27="",多次统计数据!$B$8="",多次统计数据!$B$6<=0,多次统计数据!$B$6>=1),"",1-POWER(1+多次统计数据!$B$8,-多次统计数据!$B$6/(1-多次统计数据!$B$6))) -> 0.11918507 | AC27: =IF(OR(AB27="",多次统计数据!$B$9=""),"",IF(多次统计数据!$B$9<AB27,"低于上限","达到或超过上限")) -> 低于上限 | AD27: 2-较差
A28: T2026027 | B28: 000858 | C28: 104735 | D28: 0.01 | E28: 16.25 | F28: =IF(OR(C28="",D28="",E28="",N28="",C28<=0,D28<=0,E28<=N28),"",ROUNDDOWN((C28*D28)/(E28-N28)/100,0)*100) -> 600 | G28: =IF(OR(A28="",F28="",E28="",N28="",E28<=N28,账户数据!$B$7=""),"",IF(账户数据!$B$9+IF(H28="",F28*(E28-N28),0)>=账户数据!$B$7,"禁止开仓","允许开仓")) -> 禁止开仓 | H28: 200 | I28: 46154 | J28: 17.88 | K28: 14.75 | L28: =IF(K28="","",H28) -> 200 | M28: 46161 | N28: 14.75 | O28: 0 | P28: 5 | Q28: KDJ与形态突破共同确认 | R28: 止损设在14.75 | S28: 目标参考ATR | T28: 按计划成交 | U28: =IF(OR(E28="",J28="",E28<=0),"",(J28-E28)/E28) -> 0.10030769 | V28: =IF(OR(E28="",N28="",E28<=0),"",(E28-N28)/E28) -> 0.092307692 | W28: =IF(OR(U28="",V28="",V28<=0),"",U28/V28) -> 1.0866667 | X28: =IF(OR(K28="",L28="",E28="",H28=""),"",K28*L28-E28*H28-IF(O28="",0,O28)-IF(P28="",0,P28)) -> -305 | Y28: =IF(OR(X28="",E28="",H28=""),"",IF(E28*H28+IF(O28="",0,O28)<=0,"",X28/(E28*H28+IF(O28="",0,O28)))) -> -0.093846154 | Z28: =IF(OR(Y28="",多次统计数据!$B$8=""),"",Y28-多次统计数据!$B$8) -> -0.22197724 | AA28: =IF(OR(I28="",M28="",M28<I28),"",M28-I28) -> 7 | AB28: =IF(OR(A28="",多次统计数据!$B$8="",多次统计数据!$B$6<=0,多次统计数据!$B$6>=1),"",1-POWER(1+多次统计数据!$B$8,-多次统计数据!$B$6/(1-多次统计数据!$B$6))) -> 0.11918507 | AC28: =IF(OR(AB28="",多次统计数据!$B$9=""),"",IF(多次统计数据!$B$9<AB28,"低于上限","达到或超过上限")) -> 低于上限 | AD28: 2-较差
A29: T2026028 | B29: 600036 | C29: 104430 | D29: 0.01 | E29: 17.5 | F29: =IF(OR(C29="",D29="",E29="",N29="",C29<=0,D29<=0,E29<=N29),"",ROUNDDOWN((C29*D29)/(E29-N29)/100,0)*100) -> 1300 | G29: =IF(OR(A29="",F29="",E29="",N29="",E29<=N29,账户数据!$B$7=""),"",IF(账户数据!$B$9+IF(H29="",F29*(E29-N29),0)>=账户数据!$B$7,"禁止开仓","允许开仓")) -> 禁止开仓 | H29: 700 | I29: 46155 | J29: 19.25 | K29: 16.62 | L29: =IF(K29="","",H29) -> 700 | M29: 46156 | N29: 16.75 | O29: 5 | P29: 0 | Q29: 布林带与均线金叉共同确认 | R29: 止损设在16.75 | S29: 目标参考换手率 | T29: 按计划成交 | U29: =IF(OR(E29="",J29="",E29<=0),"",(J29-E29)/E29) -> 0.1 | V29: =IF(OR(E29="",N29="",E29<=0),"",(E29-N29)/E29) -> 0.042857143 | W29: =IF(OR(U29="",V29="",V29<=0),"",U29/V29) -> 2.3333333 | X29: =IF(OR(K29="",L29="",E29="",H29=""),"",K29*L29-E29*H29-IF(O29="",0,O29)-IF(P29="",0,P29)) -> -621 | Y29: =IF(OR(X29="",E29="",H29=""),"",IF(E29*H29+IF(O29="",0,O29)<=0,"",X29/(E29*H29+IF(O29="",0,O29)))) -> -0.050673195 | Z29: =IF(OR(Y29="",多次统计数据!$B$8=""),"",Y29-多次统计数据!$B$8) -> -0.17880428 | AA29: =IF(OR(I29="",M29="",M29<I29),"",M29-I29) -> 1 | AB29: =IF(OR(A29="",多次统计数据!$B$8="",多次统计数据!$B$6<=0,多次统计数据!$B$6>=1),"",1-POWER(1+多次统计数据!$B$8,-多次统计数据!$B$6/(1-多次统计数据!$B$6))) -> 0.11918507 | AC29: =IF(OR(AB29="",多次统计数据!$B$9=""),"",IF(多次统计数据!$B$9<AB29,"低于上限","达到或超过上限")) -> 低于上限 | AD29: 2-较差
A30: T2026029 | B30: 002415 | C30: 103809 | D30: 0.01 | E30: 18.75 | F30: =IF(OR(C30="",D30="",E30="",N30="",C30<=0,D30<=0,E30<=N30),"",ROUNDDOWN((C30*D30)/(E30-N30)/100,0)*100) -> 1000 | G30: =IF(OR(A30="",F30="",E30="",N30="",E30<=N30,账户数据!$B$7=""),"",IF(账户数据!$B$9+IF(H30="",F30*(E30-N30),0)>=账户数据!$B$7,"禁止开仓","允许开仓")) -> 禁止开仓 | H30: 800 | I30: 46156 | J30: 20.62 | K30: 18.75 | L30: =IF(K30="","",H30) -> 800 | M30: 46158 | N30: 17.75 | O30: 0 | P30: 0 | Q30: 支撑位与均线死叉共同确认 | R30: 止损设在17.75 | S30: 目标参考相对强弱 | T30: 按计划成交 | U30: =IF(OR(E30="",J30="",E30<=0),"",(J30-E30)/E30) -> 0.099733333 | V30: =IF(OR(E30="",N30="",E30<=0),"",(E30-N30)/E30) -> 0.053333333 | W30: =IF(OR(U30="",V30="",V30<=0),"",U30/V30) -> 1.87 | X30: =IF(OR(K30="",L30="",E30="",H30=""),"",K30*L30-E30*H30-IF(O30="",0,O30)-IF(P30="",0,P30)) -> 0 | Y30: =IF(OR(X30="",E30="",H30=""),"",IF(E30*H30+IF(O30="",0,O30)<=0,"",X30/(E30*H30+IF(O30="",0,O30)))) -> 0 | Z30: =IF(OR(Y30="",多次统计数据!$B$8=""),"",Y30-多次统计数据!$B$8) -> -0.12813109 | AA30: =IF(OR(I30="",M30="",M30<I30),"",M30-I30) -> 2 | AB30: =IF(OR(A30="",多次统计数据!$B$8="",多次统计数据!$B$6<=0,多次统计数据!$B$6>=1),"",1-POWER(1+多次统计数据!$B$8,-多次统计数据!$B$6/(1-多次统计数据!$B$6))) -> 0.11918507 | AC30: =IF(OR(AB30="",多次统计数据!$B$9=""),"",IF(多次统计数据!$B$9<AB30,"低于上限","达到或超过上限")) -> 低于上限 | AD30: 3-一般
A31: T2026030 | B31: 601899 | C31: 103809 | D31: 0.01 | E31: 20 | F31: =IF(OR(C31="",D31="",E31="",N31="",C31<=0,D31<=0,E31<=N31),"",ROUNDDOWN((C31*D31)/(E31-N31)/100,0)*100) -> 800 | G31: =IF(OR(A31="",F31="",E31="",N31="",E31<=N31,账户数据!$B$7=""),"",IF(账户数据!$B$9+IF(H31="",F31*(E31-N31),0)>=账户数据!$B$7,"禁止开仓","允许开仓")) -> 禁止开仓 | H31: 800 | I31: 46157 | J31: 22 | L31: =IF(K31="","",H31) | N31: 18.75 | O31: 0 | P31: 5 | Q31: 压力位与量价背离共同确认 | R31: 止损设在18.75 | S31: 目标参考板块共振 | U31: =IF(OR(E31="",J31="",E31<=0),"",(J31-E31)/E31) -> 0.1 | V31: =IF(OR(E31="",N31="",E31<=0),"",(E31-N31)/E31) -> 0.0625 | W31: =IF(OR(U31="",V31="",V31<=0),"",U31/V31) -> 1.6 | X31: =IF(OR(K31="",L31="",E31="",H31=""),"",K31*L31-E31*H31-IF(O31="",0,O31)-IF(P31="",0,P31)) | Y31: =IF(OR(X31="",E31="",H31=""),"",IF(E31*H31+IF(O31="",0,O31)<=0,"",X31/(E31*H31+IF(O31="",0,O31)))) | Z31: =IF(OR(Y31="",多次统计数据!$B$8=""),"",Y31-多次统计数据!$B$8) | AA31: =IF(OR(I31="",M31="",M31<I31),"",M31-I31) | AB31: =IF(OR(A31="",多次统计数据!$B$8="",多次统计数据!$B$6<=0,多次统计数据!$B$6>=1),"",1-POWER(1+多次统计数据!$B$8,-多次统计数据!$B$6/(1-多次统计数据!$B$6))) -> 0.11918507 | AC31: =IF(OR(AB31="",多次统计数据!$B$9=""),"",IF(多次统计数据!$B$9<AB31,"低于上限","达到或超过上限")) -> 低于上限
A32: T2026031 | B32: 600519 | C32: 103809 | D32: 0.01 | E32: 21.25 | F32: =IF(OR(C32="",D32="",E32="",N32="",C32<=0,D32<=0,E32<=N32),"",ROUNDDOWN((C32*D32)/(E32-N32)/100,0)*100) -> 600 | G32: =IF(OR(A32="",F32="",E32="",N32="",E32<=N32,账户数据!$B$7=""),"",IF(账户数据!$B$9+IF(H32="",F32*(E32-N32),0)>=账户数据!$B$7,"禁止开仓","允许开仓")) -> 禁止开仓 | H32: 100 | I32: 46158 | J32: 23.38 | K32: 24.01 | L32: =IF(K32="","",H32) -> 100 | M32: 46162 | N32: 19.75 | O32: 5 | P32: 5 | Q32: 缺口与趋势背离共同确认 | R32: 止损设在19.75 | S32: 目标参考蜡烛图 | T32: 按计划成交 | U32: =IF(OR(E32="",J32="",E32<=0),"",(J32-E32)/E32) -> 0.10023529 | V32: =IF(OR(E32="",N32="",E32<=0),"",(E32-N32)/E32) -> 0.070588235 | W32: =IF(OR(U32="",V32="",V32<=0),"",U32/V32) -> 1.42 | X32: =IF(OR(K32="",L32="",E32="",H32=""),"",K32*L32-E32*H32-IF(O32="",0,O32)-IF(P32="",0,P32)) -> 266 | Y32: =IF(OR(X32="",E32="",H32=""),"",IF(E32*H32+IF(O32="",0,O32)<=0,"",X32/(E32*H32+IF(O32="",0,O32)))) -> 0.12488263 | Z32: =IF(OR(Y32="",多次统计数据!$B$8=""),"",Y32-多次统计数据!$B$8) -> -0.003248461 | AA32: =IF(OR(I32="",M32="",M32<I32),"",M32-I32) -> 4 | AB32: =IF(OR(A32="",多次统计数据!$B$8="",多次统计数据!$B$6<=0,多次统计数据!$B$6>=1),"",1-POWER(1+多次统计数据!$B$8,-多次统计数据!$B$6/(1-多次统计数据!$B$6))) -> 0.11918507 | AC32: =IF(OR(AB32="",多次统计数据!$B$9=""),"",IF(多次统计数据!$B$9<AB32,"低于上限","达到或超过上限")) -> 低于上限 | AD32: 4-良好
A33: T2026032 | B33: 000001 | C33: 104075 | D33: 0.01 | E33: 22.5 | F33: =IF(OR(C33="",D33="",E33="",N33="",C33<=0,D33<=0,E33<=N33),"",ROUNDDOWN((C33*D33)/(E33-N33)/100,0)*100) -> 1300 | G33: =IF(OR(A33="",F33="",E33="",N33="",E33<=N33,账户数据!$B$7=""),"",IF(账户数据!$B$9+IF(H33="",F33*(E33-N33),0)>=账户数据!$B$7,"禁止开仓","允许开仓")) -> 禁止开仓 | H33: 500 | I33: 46159 | J33: 24.75 | K33: 25.65 | L33: =IF(K33="","",H33) -> 500 | M33: 46164 | N33: 21.75 | O33: 5 | P33: 0 | Q33: 形态突破与ATR共同确认 | R33: 止损设在21.75 | S33: 目标参考趋势线 | T33: 按计划成交 | U33: =IF(OR(E33="",J33="",E33<=0),"",(J33-E33)/E33) -> 0.1 | V33: =IF(OR(E33="",N33="",E33<=0),"",(E33-N33)/E33) -> 0.033333333 | W33: =IF(OR(U33="",V33="",V33<=0),"",U33/V33) -> 3 | X33: =IF(OR(K33="",L33="",E33="",H33=""),"",K33*L33-E33*H33-IF(O33="",0,O33)-IF(P33="",0,P33)) -> 1570 | Y33: =IF(OR(X33="",E33="",H33=""),"",IF(E33*H33+IF(O33="",0,O33)<=0,"",X33/(E33*H33+IF(O33="",0,O33)))) -> 0.13949356 | Z33: =IF(OR(Y33="",多次统计数据!$B$8=""),"",Y33-多次统计数据!$B$8) -> 0.011362468 | AA33: =IF(OR(I33="",M33="",M33<I33),"",M33-I33) -> 5 | AB33: =IF(OR(A33="",多次统计数据!$B$8="",多次统计数据!$B$6<=0,多次统计数据!$B$6>=1),"",1-POWER(1+多次统计数据!$B$8,-多次统计数据!$B$6/(1-多次统计数据!$B$6))) -> 0.11918507 | AC33: =IF(OR(AB33="",多次统计数据!$B$9=""),"",IF(多次统计数据!$B$9<AB33,"低于上限","达到或超过上限")) -> 低于上限 | AD33: 4-良好
A34: T2026033 | B34: 300750 | C34: 105645 | D34: 0.01 | E34: 10 | F34: =IF(OR(C34="",D34="",E34="",N34="",C34<=0,D34<=0,E34<=N34),"",ROUNDDOWN((C34*D34)/(E34-N34)/100,0)*100) -> 1000 | G34: =IF(OR(A34="",F34="",E34="",N34="",E34<=N34,账户数据!$B$7=""),"",IF(账户数据!$B$9+IF(H34="",F34*(E34-N34),0)>=账户数据!$B$7,"禁止开仓","允许开仓")) -> 禁止开仓 | H34: 600 | I34: 46160 | J34: 11 | K34: 11.2 | L34: =IF(K34="","",H34) -> 600 | M34: 46166 | N34: 9 | O34: 0 | P34: 5 | Q34: 均线金叉与换手率共同确认 | R34: 止损设在9.00 | S34: 目标参考MACD | T34: 按计划成交 | U34: =IF(OR(E34="",J34="",E34<=0),"",(J34-E34)/E34) -> 0.1 | V34: =IF(OR(E34="",N34="",E34<=0),"",(E34-N34)/E34) -> 0.1 | W34: =IF(OR(U34="",V34="",V34<=0),"",U34/V34) -> 1 | X34: =IF(OR(K34="",L34="",E34="",H34=""),"",K34*L34-E34*H34-IF(O34="",0,O34)-IF(P34="",0,P34)) -> 715 | Y34: =IF(OR(X34="",E34="",H34=""),"",IF(E34*H34+IF(O34="",0,O34)<=0,"",X34/(E34*H34+IF(O34="",0,O34)))) -> 0.11916667 | Z34: =IF(OR(Y34="",多次统计数据!$B$8=""),"",Y34-多次统计数据!$B$8) -> -0.0089644234 | AA34: =IF(OR(I34="",M34="",M34<I34),"",M34-I34) -> 6 | AB34: =IF(OR(A34="",多次统计数据!$B$8="",多次统计数据!$B$6<=0,多次统计数据!$B$6>=1),"",1-POWER(1+多次统计数据!$B$8,-多次统计数据!$B$6/(1-多次统计数据!$B$6))) -> 0.11918507 | AC34: =IF(OR(AB34="",多次统计数据!$B$9=""),"",IF(多次统计数据!$B$9<AB34,"低于上限","达到或超过上限")) -> 低于上限 | AD34: 4-良好
A35: T2026034 | B35: 002594 | C35: 106360 | D35: 0.01 | E35: 11.25 | F35: =IF(OR(C35="",D35="",E35="",N35="",C35<=0,D35<=0,E35<=N35),"",ROUNDDOWN((C35*D35)/(E35-N35)/100,0)*100) -> 800 | G35: =IF(OR(A35="",F35="",E35="",N35="",E35<=N35,账户数据!$B$7=""),"",IF(账户数据!$B$9+IF(H35="",F35*(E35-N35),0)>=账户数据!$B$7,"禁止开仓","允许开仓")) -> 禁止开仓 | H35: 600 | I35: 46161 | J35: 12.38 | K35: 12.71 | L35: =IF(K35="","",H35) -> 600 | M35: 46168 | N35: 10 | O35: 5 | P35: 5 | Q35: 均线死叉与相对强弱共同确认 | R35: 止损设在10.00 | S35: 目标参考移动平均线 | T35: 按计划成交 | U35: =IF(OR(E35="",J35="",E35<=0),"",(J35-E35)/E35) -> 0.10044444 | V35: =IF(OR(E35="",N35="",E35<=0),"",(E35-N35)/E35) -> 0.11111111 | W35: =IF(OR(U35="",V35="",V35<=0),"",U35/V35) -> 0.904 | X35: =IF(OR(K35="",L35="",E35="",H35=""),"",K35*L35-E35*H35-IF(O35="",0,O35)-IF(P35="",0,P35)) -> 866 | Y35: =IF(OR(X35="",E35="",H35=""),"",IF(E35*H35+IF(O35="",0,O35)<=0,"",X35/(E35*H35+IF(O35="",0,O35)))) -> 0.12820133 | Z35: =IF(OR(Y35="",多次统计数据!$B$8=""),"",Y35-多次统计数据!$B$8) -> 7.0242274e-05 | AA35: =IF(OR(I35="",M35="",M35<I35),"",M35-I35) -> 7 | AB35: =IF(OR(A35="",多次统计数据!$B$8="",多次统计数据!$B$6<=0,多次统计数据!$B$6>=1),"",1-POWER(1+多次统计数据!$B$8,-多次统计数据!$B$6/(1-多次统计数据!$B$6))) -> 0.11918507 | AC35: =IF(OR(AB35="",多次统计数据!$B$9=""),"",IF(多次统计数据!$B$9<AB35,"低于上限","达到或超过上限")) -> 低于上限 | AD35: 4-良好
A36: T2026035 | B36: 601318 | C36: 107226 | D36: 0.01 | E36: 12.5 | F36: =IF(OR(C36="",D36="",E36="",N36="",C36<=0,D36<=0,E36<=N36),"",ROUNDDOWN((C36*D36)/(E36-N36)/100,0)*100) -> 700 | G36: =IF(OR(A36="",F36="",E36="",N36="",E36<=N36,账户数据!$B$7=""),"",IF(账户数据!$B$9+IF(H36="",F36*(E36-N36),0)>=账户数据!$B$7,"禁止开仓","允许开仓")) -> 禁止开仓 | H36: 700 | I36: 46162 | J36: 13.75 | K36: 11 | L36: =IF(K36="","",H36) -> 700 | M36: 46163 | N36: 11 | O36: 5 | P36: 5 | Q36: 量价背离与板块共振共同确认 | R36: 止损设在11.00 | S36: 目标参考成交量 | T36: 按计划成交 | U36: =IF(OR(E36="",J36="",E36<=0),"",(J36-E36)/E36) -> 0.1 | V36: =IF(OR(E36="",N36="",E36<=0),"",(E36-N36)/E36) -> 0.12 | W36: =IF(OR(U36="",V36="",V36<=0),"",U36/V36) -> 0.83333333 | X36: =IF(OR(K36="",L36="",E36="",H36=""),"",K36*L36-E36*H36-IF(O36="",0,O36)-IF(P36="",0,P36)) -> -1060 | Y36: =IF(OR(X36="",E36="",H36=""),"",IF(E36*H36+IF(O36="",0,O36)<=0,"",X36/(E36*H36+IF(O36="",0,O36)))) -> -0.12107367 | Z36: =IF(OR(Y36="",多次统计数据!$B$8=""),"",Y36-多次统计数据!$B$8) -> -0.24920476 | AA36: =IF(OR(I36="",M36="",M36<I36),"",M36-I36) -> 1 | AB36: =IF(OR(A36="",多次统计数据!$B$8="",多次统计数据!$B$6<=0,多次统计数据!$B$6>=1),"",1-POWER(1+多次统计数据!$B$8,-多次统计数据!$B$6/(1-多次统计数据!$B$6))) -> 0.11918507 | AC36: =IF(OR(AB36="",多次统计数据!$B$9=""),"",IF(多次统计数据!$B$9<AB36,"低于上限","达到或超过上限")) -> 低于上限 | AD36: 2-较差
A37: T2026036 | B37: 688981 | C37: 106166 | D37: 0.01 | E37: 13.75 | F37: =IF(OR(C37="",D37="",E37="",N37="",C37<=0,D37<=0,E37<=N37),"",ROUNDDOWN((C37*D37)/(E37-N37)/100,0)*100) -> 1400 | G37: =IF(OR(A37="",F37="",E37="",N37="",E37<=N37,账户数据!$B$7=""),"",IF(账户数据!$B$9+IF(H37="",F37*(E37-N37),0)>=账户数据!$B$7,"禁止开仓","允许开仓")) -> 禁止开仓 | H37: 200 | I37: 46163 | J37: 15.13 | K37: 13 | L37: =IF(K37="","",H37) -> 200 | M37: 46165 | N37: 13 | O37: 0 | P37: 0 | Q37: 趋势背离与蜡烛图共同确认 | R37: 止损设在13.00 | S37: 目标参考RSI | T37: 按计划成交 | U37: =IF(OR(E37="",J37="",E37<=0),"",(J37-E37)/E37) -> 0.10036364 | V37: =IF(OR(E37="",N37="",E37<=0),"",(E37-N37)/E37) -> 0.054545455 | W37: =IF(OR(U37="",V37="",V37<=0),"",U37/V37) -> 1.84 | X37: =IF(OR(K37="",L37="",E37="",H37=""),"",K37*L37-E37*H37-IF(O37="",0,O37)-IF(P37="",0,P37)) -> -150 | Y37: =IF(OR(X37="",E37="",H37=""),"",IF(E37*H37+IF(O37="",0,O37)<=0,"",X37/(E37*H37+IF(O37="",0,O37)))) -> -0.054545455 | Z37: =IF(OR(Y37="",多次统计数据!$B$8=""),"",Y37-多次统计数据!$B$8) -> -0.18267654 | AA37: =IF(OR(I37="",M37="",M37<I37),"",M37-I37) -> 2 | AB37: =IF(OR(A37="",多次统计数据!$B$8="",多次统计数据!$B$6<=0,多次统计数据!$B$6>=1),"",1-POWER(1+多次统计数据!$B$8,-多次统计数据!$B$6/(1-多次统计数据!$B$6))) -> 0.11918507 | AC37: =IF(OR(AB37="",多次统计数据!$B$9=""),"",IF(多次统计数据!$B$9<AB37,"低于上限","达到或超过上限")) -> 低于上限 | AD37: 2-较差
A38: T2026037 | B38: 000858 | C38: 106016 | D38: 0.01 | E38: 15 | F38: =IF(OR(C38="",D38="",E38="",N38="",C38<=0,D38<=0,E38<=N38),"",ROUNDDOWN((C38*D38)/(E38-N38)/100,0)*100) -> 1000 | G38: =IF(OR(A38="",F38="",E38="",N38="",E38<=N38,账户数据!$B$7=""),"",IF(账户数据!$B$9+IF(H38="",F38*(E38-N38),0)>=账户数据!$B$7,"禁止开仓","允许开仓")) -> 禁止开仓 | H38: 400 | I38: 46164 | J38: 16.5 | K38: 14 | L38: =IF(K38="","",H38) -> 400 | M38: 46167 | N38: 14 | O38: 5 | P38: 5 | Q38: ATR与趋势线共同确认 | R38: 止损设在14.00 | S38: 目标参考KDJ | T38: 按计划成交 | U38: =IF(OR(E38="",J38="",E38<=0),"",(J38-E38)/E38) -> 0.1 | V38: =IF(OR(E38="",N38="",E38<=0),"",(E38-N38)/E38) -> 0.066666667 | W38: =IF(OR(U38="",V38="",V38<=0),"",U38/V38) -> 1.5 | X38: =IF(OR(K38="",L38="",E38="",H38=""),"",K38*L38-E38*H38-IF(O38="",0,O38)-IF(P38="",0,P38)) -> -410 | Y38: =IF(OR(X38="",E38="",H38=""),"",IF(E38*H38+IF(O38="",0,O38)<=0,"",X38/(E38*H38+IF(O38="",0,O38)))) -> -0.068276436 | Z38: =IF(OR(Y38="",多次统计数据!$B$8=""),"",Y38-多次统计数据!$B$8) -> -0.19640753 | AA38: =IF(OR(I38="",M38="",M38<I38),"",M38-I38) -> 3 | AB38: =IF(OR(A38="",多次统计数据!$B$8="",多次统计数据!$B$6<=0,多次统计数据!$B$6>=1),"",1-POWER(1+多次统计数据!$B$8,-多次统计数据!$B$6/(1-多次统计数据!$B$6))) -> 0.11918507 | AC38: =IF(OR(AB38="",多次统计数据!$B$9=""),"",IF(多次统计数据!$B$9<AB38,"低于上限","达到或超过上限")) -> 低于上限 | AD38: 2-较差
A39: T2026038 | B39: 600036 | C39: 105606 | D39: 0.01 | E39: 16.25 | F39: =IF(OR(C39="",D39="",E39="",N39="",C39<=0,D39<=0,E39<=N39),"",ROUNDDOWN((C39*D39)/(E39-N39)/100,0)*100) -> 800 | G39: =IF(OR(A39="",F39="",E39="",N39="",E39<=N39,账户数据!$B$7=""),"",IF(账户数据!$B$9+IF(H39="",F39*(E39-N39),0)>=账户数据!$B$7,"禁止开仓","允许开仓")) -> 禁止开仓 | H39: 400 | I39: 46165 | J39: 17.88 | K39: 15 | L39: =IF(K39="","",H39) -> 400 | M39: 46169 | N39: 15 | O39: 5 | P39: 5 | Q39: 换手率与MACD共同确认 | R39: 止损设在15.00 | S39: 目标参考布林带 | T39: 按计划成交 | U39: =IF(OR(E39="",J39="",E39<=0),"",(J39-E39)/E39) -> 0.10030769 | V39: =IF(OR(E39="",N39="",E39<=0),"",(E39-N39)/E39) -> 0.076923077 | W39: =IF(OR(U39="",V39="",V39<=0),"",U39/V39) -> 1.304 | X39: =IF(OR(K39="",L39="",E39="",H39=""),"",K39*L39-E39*H39-IF(O39="",0,O39)-IF(P39="",0,P39)) -> -510 | Y39: =IF(OR(X39="",E39="",H39=""),"",IF(E39*H39+IF(O39="",0,O39)<=0,"",X39/(E39*H39+IF(O39="",0,O39)))) -> -0.07840123 | Z39: =IF(OR(Y39="",多次统计数据!$B$8=""),"",Y39-多次统计数据!$B$8) -> -0.20653232 | AA39: =IF(OR(I39="",M39="",M39<I39),"",M39-I39) -> 4 | AB39: =IF(OR(A39="",多次统计数据!$B$8="",多次统计数据!$B$6<=0,多次统计数据!$B$6>=1),"",1-POWER(1+多次统计数据!$B$8,-多次统计数据!$B$6/(1-多次统计数据!$B$6))) -> 0.11918507 | AC39: =IF(OR(AB39="",多次统计数据!$B$9=""),"",IF(多次统计数据!$B$9<AB39,"低于上限","达到或超过上限")) -> 低于上限 | AD39: 2-较差
A40: T2026039 | B40: 002415 | C40: 105096 | D40: 0.01 | E40: 17.5 | F40: =IF(OR(C40="",D40="",E40="",N40="",C40<=0,D40<=0,E40<=N40),"",ROUNDDOWN((C40*D40)/(E40-N40)/100,0)*100) -> 700 | G40: =IF(OR(A40="",F40="",E40="",N40="",E40<=N40,账户数据!$B$7=""),"",IF(账户数据!$B$9+IF(H40="",F40*(E40-N40),0)>=账户数据!$B$7,"禁止开仓","允许开仓")) -> 禁止开仓 | H40: 500 | I40: 46166 | J40: 19.25 | K40: 17.5 | L40: =IF(K40="","",H40) -> 500 | M40: 46171 | N40: 16 | O40: 0 | P40: 0 | Q40: 相对强弱与移动平均线共同确认 | R40: 止损设在16.00 | S40: 目标参考支撑位 | T40: 按计划成交 | U40: =IF(OR(E40="",J40="",E40<=0),"",(J40-E40)/E40) -> 0.1 | V40: =IF(OR(E40="",N40="",E40<=0),"",(E40-N40)/E40) -> 0.085714286 | W40: =IF(OR(U40="",V40="",V40<=0),"",U40/V40) -> 1.1666667 | X40: =IF(OR(K40="",L40="",E40="",H40=""),"",K40*L40-E40*H40-IF(O40="",0,O40)-IF(P40="",0,P40)) -> 0 | Y40: =IF(OR(X40="",E40="",H40=""),"",IF(E40*H40+IF(O40="",0,O40)<=0,"",X40/(E40*H40+IF(O40="",0,O40)))) -> 0 | Z40: =IF(OR(Y40="",多次统计数据!$B$8=""),"",Y40-多次统计数据!$B$8) -> -0.12813109 | AA40: =IF(OR(I40="",M40="",M40<I40),"",M40-I40) -> 5 | AB40: =IF(OR(A40="",多次统计数据!$B$8="",多次统计数据!$B$6<=0,多次统计数据!$B$6>=1),"",1-POWER(1+多次统计数据!$B$8,-多次统计数据!$B$6/(1-多次统计数据!$B$6))) -> 0.11918507 | AC40: =IF(OR(AB40="",多次统计数据!$B$9=""),"",IF(多次统计数据!$B$9<AB40,"低于上限","达到或超过上限")) -> 低于上限 | AD40: 3-一般
...

Sheet 买入理由
A1: 交易编号 | B1: 股票代码 | C1: 所属板块 | D1: 阶段 | E1: 记录日期 | F1: 技术指标1 | G1: 技术指标2 | H1: 技术指标3 | I1: 综述
A2: T2026001 | B2: 600519 | C2: 消费 | D2: 买入 | E2: 46128 | F2: 蜡烛图 | G2: RSI | H2: 缺口 | I2: win场景，第1笔逐步验证数据
A3: T2026002 | B3: 000001 | C3: 银行 | D3: 买入 | E3: 46129 | F3: 趋势线 | G3: KDJ | H3: 形态突破 | I3: win场景，第2笔逐步验证数据
A4: T2026003 | B4: 300750 | C4: 新能源 | D4: 买入 | E4: 46130 | F4: MACD | G4: 布林带 | H4: 均线金叉 | I4: win场景，第3笔逐步验证数据
A5: T2026004 | B5: 002594 | C5: 汽车 | D5: 买入 | E5: 46131 | F5: 移动平均线 | G5: 支撑位 | H5: 均线死叉 | I5: win场景，第4笔逐步验证数据
A6: T2026005 | B6: 601318 | C6: 保险 | D6: 买入 | E6: 46132 | F6: 成交量 | G6: 压力位 | H6: 量价背离 | I6: loss场景，第5笔逐步验证数据
A7: T2026006 | B7: 688981 | C7: 半导体 | D7: 买入 | E7: 46133 | F7: RSI | G7: 缺口 | H7: 趋势背离 | I7: loss场景，第6笔逐步验证数据
A8: T2026007 | B8: 000858 | C8: 食品饮料 | D8: 买入 | E8: 46134 | F8: KDJ | G8: 形态突破 | H8: ATR | I8: loss场景，第7笔逐步验证数据
A9: T2026008 | B9: 600036 | C9: 金融 | D9: 买入 | E9: 46135 | F9: 布林带 | G9: 均线金叉 | H9: 换手率 | I9: loss场景，第8笔逐步验证数据
A10: T2026009 | B10: 002415 | C10: 电子 | D10: 买入 | E10: 46136 | F10: 支撑位 | G10: 均线死叉 | H10: 相对强弱 | I10: flat场景，第9笔逐步验证数据
A11: T2026010 | B11: 601899 | C11: 资源 | D11: 买入 | E11: 46137 | F11: 压力位 | G11: 量价背离 | H11: 板块共振 | I11: open场景，第10笔逐步验证数据
A12: T2026011 | B12: 600519 | C12: 消费 | D12: 买入 | E12: 46138 | F12: 缺口 | G12: 趋势背离 | H12: 蜡烛图 | I12: win场景，第11笔逐步验证数据
A13: T2026012 | B13: 000001 | C13: 银行 | D13: 买入 | E13: 46139 | F13: 形态突破 | G13: ATR | H13: 趋势线 | I13: win场景，第12笔逐步验证数据
... A101: T2026100 | B101: 601899 | C101: 资源 | D101: 买入 | E101: 46227 | F101: 板块共振 | G101: 成交量 | H101: 压力位 | I101: candidate场景，第100笔逐步验证数据

Sheet 多次统计数据
A1: 指标 | B1: 当前统计 | C1: 口径说明
A2: 已完成交易数 | B2: =COUNT(单次交易!M2:M201) -> 88 | C2: 存在卖出日期的交易
A3: 盈利交易数 | B3: =COUNTIF(单次交易!X2:X201,">0") -> 40 | C3: 实际盈亏金额大于0
A4: 亏损交易数 | B4: =COUNTIF(单次交易!X2:X201,"<0") -> 38 | C4: 实际盈亏金额小于0
A5: 持平交易数 | B5: =COUNTIFS(单次交易!M2:M201,"<>",单次交易!X2:X201,"=0") -> 10 | C5: 已卖出且实际盈亏为0；不进入胜负样本
A6: 盈利概率 | B6: =IFERROR(B3/(B3+B4),"") -> 0.51282051 | C6: 盈利数÷胜负交易数
A7: 亏损概率 | B7: =IFERROR(B4/(B3+B4),"") -> 0.48717949 | C7: 亏损数÷胜负交易数
A8: 平均盈利百分比 | B8: =IFERROR(AVERAGEIF(单次交易!X2:X201,">0",单次交易!Y2:Y201),"") -> 0.12813109 | C8: 盈利交易实际收益率的平均值
A9: 平均亏损百分比 | B9: =IFERROR(-AVERAGEIF(单次交易!X2:X201,"<0",单次交易!Y2:Y201),"") -> 0.079689039 | C9: 以正数显示亏损幅度
A10: 盈利的持有总天数 | B10: =SUMIF(单次交易!X2:X201,">0",单次交易!AA2:AA201) -> 155 | C10: 自然日
A11: 亏损的持有总天数 | B11: =SUMIF(单次交易!X2:X201,"<0",单次交易!AA2:AA201) -> 144 | C11: 自然日
A12: 平均交易金额 | B12: =IFERROR(SUMPRODUCT(单次交易!E2:E201,单次交易!H2:H201)/COUNT(单次交易!H2:H201),"") -> 8902.3438 | C12: 买入价×实际买入股数的平均值，包含未卖出交易
A13: 期望收益率 | B13: =IF(OR(B6="",B7="",B8="",B9=""),"",B6*B8-B7*B9) -> 0.026885386 | C13: 盈利贡献减亏损贡献
A14: 迄今为止的复利净利润率 | B14: =IF(OR(B3+B4=0,B8="",B9=""),"",POWER(1+B8,B3)*POWER(1-B9,B4)-1) -> 4.2953822 | C14: 基于历史平均盈亏率的几何复利模拟

Sheet 账户数据
A1: 指标 | B1: 值 | C1: 录入/计算说明
A2: 初始总金额 | B2: 100000 | C2: 手动输入；当前金额从此值开始累计
A3: 当前总金额 | B3: =IF(B2="","",B2+SUM(单次交易!X2:X201)) -> 119514 | C3: 初始总金额＋全部已实现盈亏
A4: 单次交易允许的亏损比例 | B4: 0.01 | C4: 默认1%，可调整；开仓时复制为交易快照
A5: 单次交易允许的亏损金额 | B5: =IF(B3="","",B3*B4) -> 1195.14 | C5: 当前总金额×单次允许亏损比例
A6: 当月允许最大亏损比例 | B6: 0.05 | C6: 默认5%，可调整
A7: 当月允许最大亏损金额 | B7: =IF(B3="","",B3*B6) -> 5975.7 | C7: 当前总金额×当月最大亏损比例
A8: 当月亏损金额 | B8: =SUMIFS(单次交易!X2:X201,单次交易!X2:X201,"<0",单次交易!M2:M201,">="&EOMONTH(TODAY(),-1)+1,单次交易!M2:M201,"<="&EOMONTH(TODAY(),0)) -> -6618 | C8: 按卖出日期统计本月已实现亏损，保留负号
A9: 当前未平仓理论亏损 | B9: =IFERROR(SUMPRODUCT((单次交易!M2:M201="")*(单次交易!H2:H201>0)*(单次交易!E2:E201>单次交易!N2:N201)*单次交易!H2:H201*(单次交易!E2:E201-单次交易!N2:N201)),0) -> 8325 | C9: 未填写卖出日期的实际持仓×买入价与止损价之差
A10: 当月剩余可开仓风险额度 | B10: =IF(OR(B7="",B9=""),"",B7-B9) -> -2349.3 | C10: 当月允许最大亏损金额－当前未平仓理论亏损

Sheet 目标收益
A1: 指标 | B1: 值 | C1: 口径说明
A2: 总金额 | B2: =账户数据!B3 -> 119514 | C2: 来自账户当前总金额
A3: 目标收益率 | B3: 0.1 | C3: 手动输入
A4: 目标收益金额 | B4: =IF(OR(B2="",B3=""),"",B2*B3) -> 11951.4 | C4: 总金额×目标收益率
A5: 平均交易金额 | B5: =多次统计数据!B12 -> 8902.3438 | C5: 来自历史交易统计
A6: 历史期望收益率 | B6: =多次统计数据!B13 -> 0.026885386 | C6: 来自历史胜率与平均盈亏
A7: 所需投资笔数 | B7: =IF(OR(B4="",B5="",B6="",B5<=0,B6<=0),"暂不可计算",ROUNDUP(B4/(B5*B6),0)) -> 50 | C7: 向上取整；历史期望收益率不为正时不计算

Sheet 技术指标
A1: 技术指标 | B1: 分类 | C1: 说明
A2: 蜡烛图 | B2: 价格形态 | C2: 观察实体、上下影线及组合形态
A3: 趋势线 | B3: 趋势 | C3: 连接关键高点或低点判断趋势方向
A4: MACD | B4: 动量 | C4: 观察快慢线、信号线和柱状图
A5: 移动平均线 | B5: 趋势 | C5: 观察价格与不同周期均线的位置关系
A6: 成交量 | B6: 量价 | C6: 确认突破、回调和趋势的参与强度
A7: RSI | B7: 动量 | C7: 衡量相对强弱及超买超卖状态
A8: KDJ | B8: 动量 | C8: 观察随机指标交叉和极值区域
A9: 布林带 | B9: 波动 | C9: 观察价格相对中轨和上下轨的位置
A10: 支撑位 | B10: 关键价位 | C10: 记录预期获得买盘支撑的价格区域
A11: 压力位 | B11: 关键价位 | C11: 记录预期遇到卖压的价格区域
A12: 缺口 | B12: 价格形态 | C12: 观察跳空缺口是否回补或延续
... A21: 板块共振 | B21: 市场环境 | C21: 确认个股信号与所属板块方向一致
