Workbook
Name _AccountRiskLimit: 账户数据!$B$7
Name _LockStatus: 账户数据!$B$23
Name _TradeIds: 单次交易!$A$2:$A$201

Sheet 单次交易
A1: 交易编号 | B1: 股票代码 | C1: 买入时账户金额 | D1: 本次允许亏损比例 | E1: 第一批买入价 | F1: 买入建议股数 | G1: 开仓风险告警 | H1: 第一批买入股数 | I1: 首次买入日期 | J1: 期望卖出价 | K1: 实际卖出价（填写） | L1: 最终卖出股数（自动） | M1: 卖出日期（填写） | N1: 止损价 | O1: 买入总费用 | P1: 卖出费用（填写） | Q1: 买入价的由来 | R1: 止损价的由来 | S1: 期望卖出价的由来 | T1: 实际卖出价的由来 | U1: 期望盈利比例 | V1: 期望止损比例 | W1: 盈亏比 | X1: 加权后实际盈亏 | Y1: 单笔仓位收益率 | Z1: 账户收益率与平均盈利率差值 | AA1: 持有天数 | AB1: 复利容许平均亏损上限 | AC1: 复利风险判断 | AD1: 交易打分评价 | AE1: 实际账户收益率 | AF1: 列1 | AG1: 交易预期类型 | AH1: 预期持有周期 | AI1: 预期选择理由 | AJ1: 周期匹配检查 | AK1: 已执行加仓次数 | AL1: 加仓总股数 | AM1: 最近加仓价 | AN1: 最新加仓止损价 | AO1: 实际加权买入价 | AP1: 最终持仓股数 | AQ1: 当前净止损风险 | AR1: 加仓规则检查
A2: 1 | B2: 新和成 | C2: 100000 | D2: 0.02 | E2: 4.15 | F2: =IF(OR(C2="",D2="",E2="",N2="",C2<=0,D2<=0,E2<=N2),"",ROUNDDOWN((C2*D2)/(E2-N2)/100,0)*100) -> 6600 | G2: =IF(A2="","",IF(H2<>"","已开仓",IF(账户数据!$B$23="已锁仓","禁止开仓：连续亏损达到上限",IF(账户数据!$B$23="解锁信息不完整","禁止开仓：请完整填写解锁信息",IF(OR(F2="",E2="",N2="",E2<=N2,账户数据!$B$7=""),"",IF(OR(AG2="",AH2="",AI2=""),"禁止开仓：交易预期未填写完整",IF(账户数据!$B$9+F2*(E2-N2)>=账户数据!$B$7,"禁止开仓：风险额度不足",IF(AJ2="周期与交易预期不匹配，请重新确认",IF(账户数据!$B$23="接近锁仓","允许开仓（接近锁仓；周期需复核）","允许开仓（周期需复核）"),IF(账户数据!$B$23="接近锁仓","允许开仓（接近锁仓）","允许开仓"))))))))) -> 已开仓 | H2: 6000 | I2: 42609 | J2: 5 | K2: 4 | L2: =IF(AP2="","",AP2) -> 10500 | M2: 42671 | N2: 3.85 | U2: =IF(OR(AO2="",J2="",AO2<=0),"",(J2-AO2)/AO2) -> 0.16952551 | V2: =IF(OR(AO2="",N2="",AO2<=0),"",(AO2-N2)/AO2) -> 0.09946536 | W2: =IF(OR(U2="",V2="",V2<=0),"",U2/V2) -> 1.7043673 | X2: =IF(OR(K2="",L2="",AO2="",AP2=""),"",(K2-AO2)*L2-IF(O2="",0,O2)-IF(P2="",0,P2)) -> -2890 | Y2: =IF(OR(X2="",AO2="",L2=""),"",IF(AO2*L2+IF(O2="",0,O2)<=0,"",X2/(AO2*L2+IF(O2="",0,O2)))) -> -0.064379595 | Z2: =IF(OR(AE2="",多次统计数据!$B$8=""),"",AE2-多次统计数据!$B$8) -> -0.12710997 | AA2: =IF(OR(I2="",M2="",M2<I2),"",M2-I2) -> 62 | AB2: =IF(OR(A2="",多次统计数据!$B$8="",多次统计数据!$B$6<=0,多次统计数据!$B$6>=1),"",1-POWER(1+多次统计数据!$B$8,-多次统计数据!$B$6/(1-多次统计数据!$B$6))) -> 0.096508292 | AC2: =IF(OR(AB2="",多次统计数据!$B$9=""),"",IF(多次统计数据!$B$9<AB2,"低于上限","达到或超过上限")) -> 低于上限 | AE2: =IF(OR(X2="",C2="",C2<=0),"",X2/C2) -> -0.0289 | AG2: 趋势波段 | AH2: 11～20个交易日 | AI2: 吸筹冲新高 | AJ2: =IF(OR(AG2="",AH2=""),"",IF(OR(AND(AG2="短期博反弹",OR(AH2="1～3个交易日",AH2="4～10个交易日")),AND(AG2="突破冲新高",OR(AH2="4～10个交易日",AH2="11～20个交易日")),AND(AG2="趋势波段",OR(AH2="11～20个交易日",AH2="21～60个交易日",AH2="60个交易日以上"))),"匹配","周期与交易预期不匹配，请重新确认")) -> 匹配 | AK2: =IF(A2="","",COUNTIFS(加仓管理!$A$2:$A$1001,A2,加仓管理!$G$2:$G$1001,">0")) -> 2 | AL2: =IF(A2="","",SUMIFS(加仓管理!$G$2:$G$1001,加仓管理!$A$2:$A$1001,A2)) -> 4500 | AM2: =IF(AK2=0,"",IFERROR(LOOKUP(2,1/((加仓管理!$A$2:$A$1001=A2)*(加仓管理!$G$2:$G$1001>0)),加仓管理!$D$2:$D$1001),"")) -> 4.57 | AN2: =IF(AK2=0,"",IFERROR(LOOKUP(2,1/((加仓管理!$A$2:$A$1001=A2)*(加仓管理!$G$2:$G$1001>0)),加仓管理!$E$2:$E$1001),"")) -> 4 | AO2: =IF(OR(A2="",H2="",H2<=0),"",(E2*H2+SUMIFS(加仓管理!$H$2:$H$1001,加仓管理!$A$2:$A$1001,A2))/AP2) -> 4.2752381 | AP2: =IF(OR(A2="",H2="",H2<=0),"",H2+AL2) -> 10500 | AQ2: =IF(A2="","",IF(M2<>"",0,IF(OR(H2="",N2=""),"",MAX((E2*H2+SUMIFS(加仓管理!$H$2:$H$1001,加仓管理!$A$2:$A$1001,A2))-MAX(N2,AN2)*AP2,0)))) -> 0 | AR2: =IF(A2="","",IF(OR(E2="",H2=""),"违规：首次买入价格或股数缺失",IF(COUNTIFS(加仓管理!$A$2:$A$1001,A2,加仓管理!$R$2:$R$1001,"违规*")>0,"违规：请检查加仓管理表",IF(SUM($AQ$2:$AQ$201)>账户数据!$B$7,"预警：超过账户风险上限",IF(COUNTIFS(加仓管理!$A$2:$A$1001,A2,加仓管理!$N$2:$N$1001,">0",加仓管理!$G$2:$G$1001,"")>0,"提示：存在待执行加仓计划","通过"))))) -> 违规：请检查加仓管理表
A3: 2 | B3: 新和成 | C3: 97110 | D3: 0.02 | E3: 3.7 | F3: =IF(OR(C3="",D3="",E3="",N3="",C3<=0,D3<=0,E3<=N3),"",ROUNDDOWN((C3*D3)/(E3-N3)/100,0)*100) -> 4800 | G3: =IF(A3="","",IF(H3<>"","已开仓",IF(账户数据!$B$23="已锁仓","禁止开仓：连续亏损达到上限",IF(账户数据!$B$23="解锁信息不完整","禁止开仓：请完整填写解锁信息",IF(OR(F3="",E3="",N3="",E3<=N3,账户数据!$B$7=""),"",IF(OR(AG3="",AH3="",AI3=""),"禁止开仓：交易预期未填写完整",IF(账户数据!$B$9+F3*(E3-N3)>=账户数据!$B$7,"禁止开仓：风险额度不足",IF(AJ3="周期与交易预期不匹配，请重新确认",IF(账户数据!$B$23="接近锁仓","允许开仓（接近锁仓；周期需复核）","允许开仓（周期需复核）"),IF(账户数据!$B$23="接近锁仓","允许开仓（接近锁仓）","允许开仓"))))))))) -> 已开仓 | H3: 4800 | I3: 42697 | J3: 4.2 | K3: 3.26 | L3: =IF(AP3="","",AP3) -> 4800 | M3: 42706 | N3: 3.3 | U3: =IF(OR(AO3="",J3="",AO3<=0),"",(J3-AO3)/AO3) -> 0.13513514 | V3: =IF(OR(AO3="",N3="",AO3<=0),"",(AO3-N3)/AO3) -> 0.10810811 | W3: =IF(OR(U3="",V3="",V3<=0),"",U3/V3) -> 1.25 | X3: =IF(OR(K3="",L3="",AO3="",AP3=""),"",(K3-AO3)*L3-IF(O3="",0,O3)-IF(P3="",0,P3)) -> -2112 | Y3: =IF(OR(X3="",AO3="",L3=""),"",IF(AO3*L3+IF(O3="",0,O3)<=0,"",X3/(AO3*L3+IF(O3="",0,O3)))) -> -0.11891892 | Z3: =IF(OR(AE3="",多次统计数据!$B$8=""),"",AE3-多次统计数据!$B$8) -> -0.1199585 | AA3: =IF(OR(I3="",M3="",M3<I3),"",M3-I3) -> 9 | AB3: =IF(OR(A3="",多次统计数据!$B$8="",多次统计数据!$B$6<=0,多次统计数据!$B$6>=1),"",1-POWER(1+多次统计数据!$B$8,-多次统计数据!$B$6/(1-多次统计数据!$B$6))) -> 0.096508292 | AC3: =IF(OR(AB3="",多次统计数据!$B$9=""),"",IF(多次统计数据!$B$9<AB3,"低于上限","达到或超过上限")) -> 低于上限 | AE3: =IF(OR(X3="",C3="",C3<=0),"",X3/C3) -> -0.021748533 | AG3: 趋势波段 | AH3: 11～20个交易日 | AI3: 吸筹冲新高 | AJ3: =IF(OR(AG3="",AH3=""),"",IF(OR(AND(AG3="短期博反弹",OR(AH3="1～3个交易日",AH3="4～10个交易日")),AND(AG3="突破冲新高",OR(AH3="4～10个交易日",AH3="11～20个交易日")),AND(AG3="趋势波段",OR(AH3="11～20个交易日",AH3="21～60个交易日",AH3="60个交易日以上"))),"匹配","周期与交易预期不匹配，请重新确认")) -> 匹配 | AK3: =IF(A3="","",COUNTIFS(加仓管理!$A$2:$A$1001,A3,加仓管理!$G$2:$G$1001,">0")) -> 0 | AL3: =IF(A3="","",SUMIFS(加仓管理!$G$2:$G$1001,加仓管理!$A$2:$A$1001,A3)) -> 0 | AM3: =IF(AK3=0,"",IFERROR(LOOKUP(2,1/((加仓管理!$A$2:$A$1001=A3)*(加仓管理!$G$2:$G$1001>0)),加仓管理!$D$2:$D$1001),"")) | AN3: =IF(AK3=0,"",IFERROR(LOOKUP(2,1/((加仓管理!$A$2:$A$1001=A3)*(加仓管理!$G$2:$G$1001>0)),加仓管理!$E$2:$E$1001),"")) | AO3: =IF(OR(A3="",H3="",H3<=0),"",(E3*H3+SUMIFS(加仓管理!$H$2:$H$1001,加仓管理!$A$2:$A$1001,A3))/AP3) -> 3.7 | AP3: =IF(OR(A3="",H3="",H3<=0),"",H3+AL3) -> 4800 | AQ3: =IF(A3="","",IF(M3<>"",0,IF(OR(H3="",N3=""),"",MAX((E3*H3+SUMIFS(加仓管理!$H$2:$H$1001,加仓管理!$A$2:$A$1001,A3))-MAX(N3,AN3)*AP3,0)))) -> 0 | AR3: =IF(A3="","",IF(OR(E3="",H3=""),"违规：首次买入价格或股数缺失",IF(COUNTIFS(加仓管理!$A$2:$A$1001,A3,加仓管理!$R$2:$R$1001,"违规*")>0,"违规：请检查加仓管理表",IF(SUM($AQ$2:$AQ$201)>账户数据!$B$7,"预警：超过账户风险上限",IF(COUNTIFS(加仓管理!$A$2:$A$1001,A3,加仓管理!$N$2:$N$1001,">0",加仓管理!$G$2:$G$1001,"")>0,"提示：存在待执行加仓计划","通过"))))) -> 通过
A4: 3 | B4: 新和成 | C4: 94998 | D4: 0.02 | E4: 3.12 | F4: =IF(OR(C4="",D4="",E4="",N4="",C4<=0,D4<=0,E4<=N4),"",ROUNDDOWN((C4*D4)/(E4-N4)/100,0)*100) -> 15800 | G4: =IF(A4="","",IF(H4<>"","已开仓",IF(账户数据!$B$23="已锁仓","禁止开仓：连续亏损达到上限",IF(账户数据!$B$23="解锁信息不完整","禁止开仓：请完整填写解锁信息",IF(OR(F4="",E4="",N4="",E4<=N4,账户数据!$B$7=""),"",IF(OR(AG4="",AH4="",AI4=""),"禁止开仓：交易预期未填写完整",IF(账户数据!$B$9+F4*(E4-N4)>=账户数据!$B$7,"禁止开仓：风险额度不足",IF(AJ4="周期与交易预期不匹配，请重新确认",IF(账户数据!$B$23="接近锁仓","允许开仓（接近锁仓；周期需复核）","允许开仓（周期需复核）"),IF(账户数据!$B$23="接近锁仓","允许开仓（接近锁仓）","允许开仓"))))))))) -> 已开仓 | H4: 10000 | I4: 42797 | J4: 3.5 | K4: 2.83 | L4: =IF(AP4="","",AP4) -> 10000 | M4: 42809 | N4: 3 | U4: =IF(OR(AO4="",J4="",AO4<=0),"",(J4-AO4)/AO4) -> 0.12179487 | V4: =IF(OR(AO4="",N4="",AO4<=0),"",(AO4-N4)/AO4) -> 0.038461538 | W4: =IF(OR(U4="",V4="",V4<=0),"",U4/V4) -> 3.1666667 | X4: =IF(OR(K4="",L4="",AO4="",AP4=""),"",(K4-AO4)*L4-IF(O4="",0,O4)-IF(P4="",0,P4)) -> -2900 | Y4: =IF(OR(X4="",AO4="",L4=""),"",IF(AO4*L4+IF(O4="",0,O4)<=0,"",X4/(AO4*L4+IF(O4="",0,O4)))) -> -0.092948718 | Z4: =IF(OR(AE4="",多次统计数据!$B$8=""),"",AE4-多次统计数据!$B$8) -> -0.12873692 | AA4: =IF(OR(I4="",M4="",M4<I4),"",M4-I4) -> 12 | AB4: =IF(OR(A4="",多次统计数据!$B$8="",多次统计数据!$B$6<=0,多次统计数据!$B$6>=1),"",1-POWER(1+多次统计数据!$B$8,-多次统计数据!$B$6/(1-多次统计数据!$B$6))) -> 0.096508292 | AC4: =IF(OR(AB4="",多次统计数据!$B$9=""),"",IF(多次统计数据!$B$9<AB4,"低于上限","达到或超过上限")) -> 低于上限 | AE4: =IF(OR(X4="",C4="",C4<=0),"",X4/C4) -> -0.030526958 | AG4: 短期博反弹 | AH4: 4～10个交易日 | AI4: 反弹 | AJ4: =IF(OR(AG4="",AH4=""),"",IF(OR(AND(AG4="短期博反弹",OR(AH4="1～3个交易日",AH4="4～10个交易日")),AND(AG4="突破冲新高",OR(AH4="4～10个交易日",AH4="11～20个交易日")),AND(AG4="趋势波段",OR(AH4="11～20个交易日",AH4="21～60个交易日",AH4="60个交易日以上"))),"匹配","周期与交易预期不匹配，请重新确认")) -> 匹配 | AK4: =IF(A4="","",COUNTIFS(加仓管理!$A$2:$A$1001,A4,加仓管理!$G$2:$G$1001,">0")) -> 0 | AL4: =IF(A4="","",SUMIFS(加仓管理!$G$2:$G$1001,加仓管理!$A$2:$A$1001,A4)) -> 0 | AM4: =IF(AK4=0,"",IFERROR(LOOKUP(2,1/((加仓管理!$A$2:$A$1001=A4)*(加仓管理!$G$2:$G$1001>0)),加仓管理!$D$2:$D$1001),"")) | AN4: =IF(AK4=0,"",IFERROR(LOOKUP(2,1/((加仓管理!$A$2:$A$1001=A4)*(加仓管理!$G$2:$G$1001>0)),加仓管理!$E$2:$E$1001),"")) | AO4: =IF(OR(A4="",H4="",H4<=0),"",(E4*H4+SUMIFS(加仓管理!$H$2:$H$1001,加仓管理!$A$2:$A$1001,A4))/AP4) -> 3.12 | AP4: =IF(OR(A4="",H4="",H4<=0),"",H4+AL4) -> 10000 | AQ4: =IF(A4="","",IF(M4<>"",0,IF(OR(H4="",N4=""),"",MAX((E4*H4+SUMIFS(加仓管理!$H$2:$H$1001,加仓管理!$A$2:$A$1001,A4))-MAX(N4,AN4)*AP4,0)))) -> 0 | AR4: =IF(A4="","",IF(OR(E4="",H4=""),"违规：首次买入价格或股数缺失",IF(COUNTIFS(加仓管理!$A$2:$A$1001,A4,加仓管理!$R$2:$R$1001,"违规*")>0,"违规：请检查加仓管理表",IF(SUM($AQ$2:$AQ$201)>账户数据!$B$7,"预警：超过账户风险上限",IF(COUNTIFS(加仓管理!$A$2:$A$1001,A4,加仓管理!$N$2:$N$1001,">0",加仓管理!$G$2:$G$1001,"")>0,"提示：存在待执行加仓计划","通过"))))) -> 通过
A5: 4 | B5: 新和成 | C5: 92098 | D5: 0.02 | E5: 3.15 | F5: =IF(OR(C5="",D5="",E5="",N5="",C5<=0,D5<=0,E5<=N5),"",ROUNDDOWN((C5*D5)/(E5-N5)/100,0)*100) -> 12200 | G5: =IF(A5="","",IF(H5<>"","已开仓",IF(账户数据!$B$23="已锁仓","禁止开仓：连续亏损达到上限",IF(账户数据!$B$23="解锁信息不完整","禁止开仓：请完整填写解锁信息",IF(OR(F5="",E5="",N5="",E5<=N5,账户数据!$B$7=""),"",IF(OR(AG5="",AH5="",AI5=""),"禁止开仓：交易预期未填写完整",IF(账户数据!$B$9+F5*(E5-N5)>=账户数据!$B$7,"禁止开仓：风险额度不足",IF(AJ5="周期与交易预期不匹配，请重新确认",IF(账户数据!$B$23="接近锁仓","允许开仓（接近锁仓；周期需复核）","允许开仓（周期需复核）"),IF(账户数据!$B$23="接近锁仓","允许开仓（接近锁仓）","允许开仓"))))))))) -> 已开仓 | H5: 10000 | I5: 42817 | J5: 3.5 | K5: 3.76 | L5: =IF(AP5="","",AP5) -> 33000 | M5: 42970 | N5: 3 | U5: =IF(OR(AO5="",J5="",AO5<=0),"",(J5-AO5)/AO5) -> 0.29950495 | V5: =IF(OR(AO5="",N5="",AO5<=0),"",(AO5-N5)/AO5) -> -0.11386139 | W5: =IF(OR(U5="",V5="",V5<=0),"",U5/V5) | X5: =IF(OR(K5="",L5="",AO5="",AP5=""),"",(K5-AO5)*L5-IF(O5="",0,O5)-IF(P5="",0,P5)) -> 35200 | Y5: =IF(OR(X5="",AO5="",L5=""),"",IF(AO5*L5+IF(O5="",0,O5)<=0,"",X5/(AO5*L5+IF(O5="",0,O5)))) -> 0.3960396 | Z5: =IF(OR(AE5="",多次统计数据!$B$8=""),"",AE5-多次统计数据!$B$8) -> 0.2839916 | AA5: =IF(OR(I5="",M5="",M5<I5),"",M5-I5) -> 153 | AB5: =IF(OR(A5="",多次统计数据!$B$8="",多次统计数据!$B$6<=0,多次统计数据!$B$6>=1),"",1-POWER(1+多次统计数据!$B$8,-多次统计数据!$B$6/(1-多次统计数据!$B$6))) -> 0.096508292 | AC5: =IF(OR(AB5="",多次统计数据!$B$9=""),"",IF(多次统计数据!$B$9<AB5,"低于上限","达到或超过上限")) -> 低于上限 | AE5: =IF(OR(X5="",C5="",C5<=0),"",X5/C5) -> 0.38220157 | AG5: 趋势波段 | AH5: 11～20个交易日 | AI5: 吸筹 | AJ5: =IF(OR(AG5="",AH5=""),"",IF(OR(AND(AG5="短期博反弹",OR(AH5="1～3个交易日",AH5="4～10个交易日")),AND(AG5="突破冲新高",OR(AH5="4～10个交易日",AH5="11～20个交易日")),AND(AG5="趋势波段",OR(AH5="11～20个交易日",AH5="21～60个交易日",AH5="60个交易日以上"))),"匹配","周期与交易预期不匹配，请重新确认")) -> 匹配 | AK5: =IF(A5="","",COUNTIFS(加仓管理!$A$2:$A$1001,A5,加仓管理!$G$2:$G$1001,">0")) -> 4 | AL5: =IF(A5="","",SUMIFS(加仓管理!$G$2:$G$1001,加仓管理!$A$2:$A$1001,A5)) -> 23000 | AM5: =IF(AK5=0,"",IFERROR(LOOKUP(2,1/((加仓管理!$A$2:$A$1001=A5)*(加仓管理!$G$2:$G$1001>0)),加仓管理!$D$2:$D$1001),"")) -> 2.16 | AN5: =IF(AK5=0,"",IFERROR(LOOKUP(2,1/((加仓管理!$A$2:$A$1001=A5)*(加仓管理!$G$2:$G$1001>0)),加仓管理!$E$2:$E$1001),"")) -> 2 | AO5: =IF(OR(A5="",H5="",H5<=0),"",(E5*H5+SUMIFS(加仓管理!$H$2:$H$1001,加仓管理!$A$2:$A$1001,A5))/AP5) -> 2.6933333 | AP5: =IF(OR(A5="",H5="",H5<=0),"",H5+AL5) -> 33000 | AQ5: =IF(A5="","",IF(M5<>"",0,IF(OR(H5="",N5=""),"",MAX((E5*H5+SUMIFS(加仓管理!$H$2:$H$1001,加仓管理!$A$2:$A$1001,A5))-MAX(N5,AN5)*AP5,0)))) -> 0 | AR5: =IF(A5="","",IF(OR(E5="",H5=""),"违规：首次买入价格或股数缺失",IF(COUNTIFS(加仓管理!$A$2:$A$1001,A5,加仓管理!$R$2:$R$1001,"违规*")>0,"违规：请检查加仓管理表",IF(SUM($AQ$2:$AQ$201)>账户数据!$B$7,"预警：超过账户风险上限",IF(COUNTIFS(加仓管理!$A$2:$A$1001,A5,加仓管理!$N$2:$N$1001,">0",加仓管理!$G$2:$G$1001,"")>0,"提示：存在待执行加仓计划","通过"))))) -> 违规：请检查加仓管理表
A6: 5 | B6: 新和成 | C6: 127298 | D6: 0.02 | E6: 4.39 | F6: =IF(OR(C6="",D6="",E6="",N6="",C6<=0,D6<=0,E6<=N6),"",ROUNDDOWN((C6*D6)/(E6-N6)/100,0)*100) -> 6500 | G6: =IF(A6="","",IF(H6<>"","已开仓",IF(账户数据!$B$23="已锁仓","禁止开仓：连续亏损达到上限",IF(账户数据!$B$23="解锁信息不完整","禁止开仓：请完整填写解锁信息",IF(OR(F6="",E6="",N6="",E6<=N6,账户数据!$B$7=""),"",IF(OR(AG6="",AH6="",AI6=""),"禁止开仓：交易预期未填写完整",IF(账户数据!$B$9+F6*(E6-N6)>=账户数据!$B$7,"禁止开仓：风险额度不足",IF(AJ6="周期与交易预期不匹配，请重新确认",IF(账户数据!$B$23="接近锁仓","允许开仓（接近锁仓；周期需复核）","允许开仓（周期需复核）"),IF(账户数据!$B$23="接近锁仓","允许开仓（接近锁仓）","允许开仓"))))))))) -> 已开仓 | H6: 6500 | I6: 42979 | J6: 5 | K6: 5.38 | L6: =IF(AP6="","",AP6) -> 9000 | M6: 43003 | N6: 4 | U6: =IF(OR(AO6="",J6="",AO6<=0),"",(J6-AO6)/AO6) -> 0.1282437 | V6: =IF(OR(AO6="",N6="",AO6<=0),"",(AO6-N6)/AO6) -> 0.097405039 | W6: =IF(OR(U6="",V6="",V6<=0),"",U6/V6) -> 1.3166023 | X6: =IF(OR(K6="",L6="",AO6="",AP6=""),"",(K6-AO6)*L6-IF(O6="",0,O6)-IF(P6="",0,P6)) -> 8535 | Y6: =IF(OR(X6="",AO6="",L6=""),"",IF(AO6*L6+IF(O6="",0,O6)<=0,"",X6/(AO6*L6+IF(O6="",0,O6)))) -> 0.21399022 | Z6: =IF(OR(AE6="",多次统计数据!$B$8=""),"",AE6-多次统计数据!$B$8) -> -0.031162565 | AA6: =IF(OR(I6="",M6="",M6<I6),"",M6-I6) -> 24 | AB6: =IF(OR(A6="",多次统计数据!$B$8="",多次统计数据!$B$6<=0,多次统计数据!$B$6>=1),"",1-POWER(1+多次统计数据!$B$8,-多次统计数据!$B$6/(1-多次统计数据!$B$6))) -> 0.096508292 | AC6: =IF(OR(AB6="",多次统计数据!$B$9=""),"",IF(多次统计数据!$B$9<AB6,"低于上限","达到或超过上限")) -> 低于上限 | AE6: =IF(OR(X6="",C6="",C6<=0),"",X6/C6) -> 0.067047401 | AG6: 突破冲新高 | AH6: 4～10个交易日 | AI6: 新高 | AJ6: =IF(OR(AG6="",AH6=""),"",IF(OR(AND(AG6="短期博反弹",OR(AH6="1～3个交易日",AH6="4～10个交易日")),AND(AG6="突破冲新高",OR(AH6="4～10个交易日",AH6="11～20个交易日")),AND(AG6="趋势波段",OR(AH6="11～20个交易日",AH6="21～60个交易日",AH6="60个交易日以上"))),"匹配","周期与交易预期不匹配，请重新确认")) -> 匹配 | AK6: =IF(A6="","",COUNTIFS(加仓管理!$A$2:$A$1001,A6,加仓管理!$G$2:$G$1001,">0")) -> 1 | AL6: =IF(A6="","",SUMIFS(加仓管理!$G$2:$G$1001,加仓管理!$A$2:$A$1001,A6)) -> 2500 | AM6: =IF(AK6=0,"",IFERROR(LOOKUP(2,1/((加仓管理!$A$2:$A$1001=A6)*(加仓管理!$G$2:$G$1001>0)),加仓管理!$D$2:$D$1001),"")) -> 4.54 | AN6: =IF(AK6=0,"",IFERROR(LOOKUP(2,1/((加仓管理!$A$2:$A$1001=A6)*(加仓管理!$G$2:$G$1001>0)),加仓管理!$E$2:$E$1001),"")) -> 4 | AO6: =IF(OR(A6="",H6="",H6<=0),"",(E6*H6+SUMIFS(加仓管理!$H$2:$H$1001,加仓管理!$A$2:$A$1001,A6))/AP6) -> 4.4316667 | AP6: =IF(OR(A6="",H6="",H6<=0),"",H6+AL6) -> 9000 | AQ6: =IF(A6="","",IF(M6<>"",0,IF(OR(H6="",N6=""),"",MAX((E6*H6+SUMIFS(加仓管理!$H$2:$H$1001,加仓管理!$A$2:$A$1001,A6))-MAX(N6,AN6)*AP6,0)))) -> 0 | AR6: =IF(A6="","",IF(OR(E6="",H6=""),"违规：首次买入价格或股数缺失",IF(COUNTIFS(加仓管理!$A$2:$A$1001,A6,加仓管理!$R$2:$R$1001,"违规*")>0,"违规：请检查加仓管理表",IF(SUM($AQ$2:$AQ$201)>账户数据!$B$7,"预警：超过账户风险上限",IF(COUNTIFS(加仓管理!$A$2:$A$1001,A6,加仓管理!$N$2:$N$1001,">0",加仓管理!$G$2:$G$1001,"")>0,"提示：存在待执行加仓计划","通过"))))) -> 违规：请检查加仓管理表
A7: 6 | B7: 新和成 | C7: 135833 | D7: 0.02 | E7: 5.65 | F7: =IF(OR(C7="",D7="",E7="",N7="",C7<=0,D7<=0,E7<=N7),"",ROUNDDOWN((C7*D7)/(E7-N7)/100,0)*100) -> 5600 | G7: =IF(A7="","",IF(H7<>"","已开仓",IF(账户数据!$B$23="已锁仓","禁止开仓：连续亏损达到上限",IF(账户数据!$B$23="解锁信息不完整","禁止开仓：请完整填写解锁信息",IF(OR(F7="",E7="",N7="",E7<=N7,账户数据!$B$7=""),"",IF(OR(AG7="",AH7="",AI7=""),"禁止开仓：交易预期未填写完整",IF(账户数据!$B$9+F7*(E7-N7)>=账户数据!$B$7,"禁止开仓：风险额度不足",IF(AJ7="周期与交易预期不匹配，请重新确认",IF(账户数据!$B$23="接近锁仓","允许开仓（接近锁仓；周期需复核）","允许开仓（周期需复核）"),IF(账户数据!$B$23="接近锁仓","允许开仓（接近锁仓）","允许开仓"))))))))) -> 已开仓 | H7: 5600 | I7: 43038 | J7: 6 | K7: 6.48 | L7: =IF(AP7="","",AP7) -> 7600 | M7: 43052 | N7: 5.17 | U7: =IF(OR(AO7="",J7="",AO7<=0),"",(J7-AO7)/AO7) -> 0.04875805 | V7: =IF(OR(AO7="",N7="",AO7<=0),"",(AO7-N7)/AO7) -> 0.096320147 | W7: =IF(OR(U7="",V7="",V7<=0),"",U7/V7) -> 0.50620821 | X7: =IF(OR(K7="",L7="",AO7="",AP7=""),"",(K7-AO7)*L7-IF(O7="",0,O7)-IF(P7="",0,P7)) -> 5768 | Y7: =IF(OR(X7="",AO7="",L7=""),"",IF(AO7*L7+IF(O7="",0,O7)<=0,"",X7/(AO7*L7+IF(O7="",0,O7)))) -> 0.13265869 | Z7: =IF(OR(AE7="",多次统计数据!$B$8=""),"",AE7-多次统计数据!$B$8) -> -0.055746058 | AA7: =IF(OR(I7="",M7="",M7<I7),"",M7-I7) -> 14 | AB7: =IF(OR(A7="",多次统计数据!$B$8="",多次统计数据!$B$6<=0,多次统计数据!$B$6>=1),"",1-POWER(1+多次统计数据!$B$8,-多次统计数据!$B$6/(1-多次统计数据!$B$6))) -> 0.096508292 | AC7: =IF(OR(AB7="",多次统计数据!$B$9=""),"",IF(多次统计数据!$B$9<AB7,"低于上限","达到或超过上限")) -> 低于上限 | AE7: =IF(OR(X7="",C7="",C7<=0),"",X7/C7) -> 0.042463908 | AG7: 突破冲新高 | AH7: 4～10个交易日 | AI7: 新高 | AJ7: =IF(OR(AG7="",AH7=""),"",IF(OR(AND(AG7="短期博反弹",OR(AH7="1～3个交易日",AH7="4～10个交易日")),AND(AG7="突破冲新高",OR(AH7="4～10个交易日",AH7="11～20个交易日")),AND(AG7="趋势波段",OR(AH7="11～20个交易日",AH7="21～60个交易日",AH7="60个交易日以上"))),"匹配","周期与交易预期不匹配，请重新确认")) -> 匹配 | AK7: =IF(A7="","",COUNTIFS(加仓管理!$A$2:$A$1001,A7,加仓管理!$G$2:$G$1001,">0")) -> 1 | AL7: =IF(A7="","",SUMIFS(加仓管理!$G$2:$G$1001,加仓管理!$A$2:$A$1001,A7)) -> 2000 | AM7: =IF(AK7=0,"",IFERROR(LOOKUP(2,1/((加仓管理!$A$2:$A$1001=A7)*(加仓管理!$G$2:$G$1001>0)),加仓管理!$D$2:$D$1001),"")) -> 5.92 | AN7: =IF(AK7=0,"",IFERROR(LOOKUP(2,1/((加仓管理!$A$2:$A$1001=A7)*(加仓管理!$G$2:$G$1001>0)),加仓管理!$E$2:$E$1001),"")) -> 5.5 | AO7: =IF(OR(A7="",H7="",H7<=0),"",(E7*H7+SUMIFS(加仓管理!$H$2:$H$1001,加仓管理!$A$2:$A$1001,A7))/AP7) -> 5.7210526 | AP7: =IF(OR(A7="",H7="",H7<=0),"",H7+AL7) -> 7600 | AQ7: =IF(A7="","",IF(M7<>"",0,IF(OR(H7="",N7=""),"",MAX((E7*H7+SUMIFS(加仓管理!$H$2:$H$1001,加仓管理!$A$2:$A$1001,A7))-MAX(N7,AN7)*AP7,0)))) -> 0 | AR7: =IF(A7="","",IF(OR(E7="",H7=""),"违规：首次买入价格或股数缺失",IF(COUNTIFS(加仓管理!$A$2:$A$1001,A7,加仓管理!$R$2:$R$1001,"违规*")>0,"违规：请检查加仓管理表",IF(SUM($AQ$2:$AQ$201)>账户数据!$B$7,"预警：超过账户风险上限",IF(COUNTIFS(加仓管理!$A$2:$A$1001,A7,加仓管理!$N$2:$N$1001,">0",加仓管理!$G$2:$G$1001,"")>0,"提示：存在待执行加仓计划","通过"))))) -> 违规：请检查加仓管理表
A8: 7 | B8: 新和成 | C8: 141601 | D8: 0.02 | E8: 10.93 | F8: =IF(OR(C8="",D8="",E8="",N8="",C8<=0,D8<=0,E8<=N8),"",ROUNDDOWN((C8*D8)/(E8-N8)/100,0)*100) -> 3000 | G8: =IF(A8="","",IF(H8<>"","已开仓",IF(账户数据!$B$23="已锁仓","禁止开仓：连续亏损达到上限",IF(账户数据!$B$23="解锁信息不完整","禁止开仓：请完整填写解锁信息",IF(OR(F8="",E8="",N8="",E8<=N8,账户数据!$B$7=""),"",IF(OR(AG8="",AH8="",AI8=""),"禁止开仓：交易预期未填写完整",IF(账户数据!$B$9+F8*(E8-N8)>=账户数据!$B$7,"禁止开仓：风险额度不足",IF(AJ8="周期与交易预期不匹配，请重新确认",IF(账户数据!$B$23="接近锁仓","允许开仓（接近锁仓；周期需复核）","允许开仓（周期需复核）"),IF(账户数据!$B$23="接近锁仓","允许开仓（接近锁仓）","允许开仓"))))))))) -> 已开仓 | H8: 3000 | I8: 43244 | J8: 13 | K8: 9.92 | L8: =IF(AP8="","",AP8) -> 3000 | M8: 43249 | N8: 10 | U8: =IF(OR(AO8="",J8="",AO8<=0),"",(J8-AO8)/AO8) -> 0.18938701 | V8: =IF(OR(AO8="",N8="",AO8<=0),"",(AO8-N8)/AO8) -> 0.085086917 | W8: =IF(OR(U8="",V8="",V8<=0),"",U8/V8) -> 2.2258065 | X8: =IF(OR(K8="",L8="",AO8="",AP8=""),"",(K8-AO8)*L8-IF(O8="",0,O8)-IF(P8="",0,P8)) -> -3030 | Y8: =IF(OR(X8="",AO8="",L8=""),"",IF(AO8*L8+IF(O8="",0,O8)<=0,"",X8/(AO8*L8+IF(O8="",0,O8)))) -> -0.092406221 | Z8: =IF(OR(AE8="",多次统计数据!$B$8=""),"",AE8-多次统计数据!$B$8) -> -0.11960812 | AA8: =IF(OR(I8="",M8="",M8<I8),"",M8-I8) -> 5 | AB8: =IF(OR(A8="",多次统计数据!$B$8="",多次统计数据!$B$6<=0,多次统计数据!$B$6>=1),"",1-POWER(1+多次统计数据!$B$8,-多次统计数据!$B$6/(1-多次统计数据!$B$6))) -> 0.096508292 | AC8: =IF(OR(AB8="",多次统计数据!$B$9=""),"",IF(多次统计数据!$B$9<AB8,"低于上限","达到或超过上限")) -> 低于上限 | AE8: =IF(OR(X8="",C8="",C8<=0),"",X8/C8) -> -0.021398154 | AG8: 趋势波段 | AH8: 11～20个交易日 | AI8: 吸筹 | AJ8: =IF(OR(AG8="",AH8=""),"",IF(OR(AND(AG8="短期博反弹",OR(AH8="1～3个交易日",AH8="4～10个交易日")),AND(AG8="突破冲新高",OR(AH8="4～10个交易日",AH8="11～20个交易日")),AND(AG8="趋势波段",OR(AH8="11～20个交易日",AH8="21～60个交易日",AH8="60个交易日以上"))),"匹配","周期与交易预期不匹配，请重新确认")) -> 匹配 | AK8: =IF(A8="","",COUNTIFS(加仓管理!$A$2:$A$1001,A8,加仓管理!$G$2:$G$1001,">0")) -> 0 | AL8: =IF(A8="","",SUMIFS(加仓管理!$G$2:$G$1001,加仓管理!$A$2:$A$1001,A8)) -> 0 | AM8: =IF(AK8=0,"",IFERROR(LOOKUP(2,1/((加仓管理!$A$2:$A$1001=A8)*(加仓管理!$G$2:$G$1001>0)),加仓管理!$D$2:$D$1001),"")) | AN8: =IF(AK8=0,"",IFERROR(LOOKUP(2,1/((加仓管理!$A$2:$A$1001=A8)*(加仓管理!$G$2:$G$1001>0)),加仓管理!$E$2:$E$1001),"")) | AO8: =IF(OR(A8="",H8="",H8<=0),"",(E8*H8+SUMIFS(加仓管理!$H$2:$H$1001,加仓管理!$A$2:$A$1001,A8))/AP8) -> 10.93 | AP8: =IF(OR(A8="",H8="",H8<=0),"",H8+AL8) -> 3000 | AQ8: =IF(A8="","",IF(M8<>"",0,IF(OR(H8="",N8=""),"",MAX((E8*H8+SUMIFS(加仓管理!$H$2:$H$1001,加仓管理!$A$2:$A$1001,A8))-MAX(N8,AN8)*AP8,0)))) -> 0 | AR8: =IF(A8="","",IF(OR(E8="",H8=""),"违规：首次买入价格或股数缺失",IF(COUNTIFS(加仓管理!$A$2:$A$1001,A8,加仓管理!$R$2:$R$1001,"违规*")>0,"违规：请检查加仓管理表",IF(SUM($AQ$2:$AQ$201)>账户数据!$B$7,"预警：超过账户风险上限",IF(COUNTIFS(加仓管理!$A$2:$A$1001,A8,加仓管理!$N$2:$N$1001,">0",加仓管理!$G$2:$G$1001,"")>0,"提示：存在待执行加仓计划","通过"))))) -> 通过
A9: 8 | B9: 新和成 | C9: 138571 | D9: 0.02 | E9: 7.54 | F9: =IF(OR(C9="",D9="",E9="",N9="",C9<=0,D9<=0,E9<=N9),"",ROUNDDOWN((C9*D9)/(E9-N9)/100,0)*100) -> 5100 | G9: =IF(A9="","",IF(H9<>"","已开仓",IF(账户数据!$B$23="已锁仓","禁止开仓：连续亏损达到上限",IF(账户数据!$B$23="解锁信息不完整","禁止开仓：请完整填写解锁信息",IF(OR(F9="",E9="",N9="",E9<=N9,账户数据!$B$7=""),"",IF(OR(AG9="",AH9="",AI9=""),"禁止开仓：交易预期未填写完整",IF(账户数据!$B$9+F9*(E9-N9)>=账户数据!$B$7,"禁止开仓：风险额度不足",IF(AJ9="周期与交易预期不匹配，请重新确认",IF(账户数据!$B$23="接近锁仓","允许开仓（接近锁仓；周期需复核）","允许开仓（周期需复核）"),IF(账户数据!$B$23="接近锁仓","允许开仓（接近锁仓）","允许开仓"))))))))) -> 已开仓 | H9: 4000 | I9: 43523 | J9: 9 | K9: 8.47 | L9: =IF(AP9="","",AP9) -> 11500 | M9: 43545 | N9: 7 | U9: =IF(OR(AO9="",J9="",AO9<=0),"",(J9-AO9)/AO9) -> 0.10065401 | V9: =IF(OR(AO9="",N9="",AO9<=0),"",(AO9-N9)/AO9) -> 0.14393577 | W9: =IF(OR(U9="",V9="",V9<=0),"",U9/V9) -> 0.69929812 | X9: =IF(OR(K9="",L9="",AO9="",AP9=""),"",(K9-AO9)*L9-IF(O9="",0,O9)-IF(P9="",0,P9)) -> 3370 | Y9: =IF(OR(X9="",AO9="",L9=""),"",IF(AO9*L9+IF(O9="",0,O9)<=0,"",X9/(AO9*L9+IF(O9="",0,O9)))) -> 0.03583772 | Z9: =IF(OR(AE9="",多次统计数据!$B$8=""),"",AE9-多次统计数据!$B$8) -> -0.073890303 | AA9: =IF(OR(I9="",M9="",M9<I9),"",M9-I9) -> 22 | AB9: =IF(OR(A9="",多次统计数据!$B$8="",多次统计数据!$B$6<=0,多次统计数据!$B$6>=1),"",1-POWER(1+多次统计数据!$B$8,-多次统计数据!$B$6/(1-多次统计数据!$B$6))) -> 0.096508292 | AC9: =IF(OR(AB9="",多次统计数据!$B$9=""),"",IF(多次统计数据!$B$9<AB9,"低于上限","达到或超过上限")) -> 低于上限 | AE9: =IF(OR(X9="",C9="",C9<=0),"",X9/C9) -> 0.024319663 | AG9: 短期博反弹 | AH9: 4～10个交易日 | AI9: 吸筹 | AJ9: =IF(OR(AG9="",AH9=""),"",IF(OR(AND(AG9="短期博反弹",OR(AH9="1～3个交易日",AH9="4～10个交易日")),AND(AG9="突破冲新高",OR(AH9="4～10个交易日",AH9="11～20个交易日")),AND(AG9="趋势波段",OR(AH9="11～20个交易日",AH9="21～60个交易日",AH9="60个交易日以上"))),"匹配","周期与交易预期不匹配，请重新确认")) -> 匹配 | AK9: =IF(A9="","",COUNTIFS(加仓管理!$A$2:$A$1001,A9,加仓管理!$G$2:$G$1001,">0")) -> 4 | AL9: =IF(A9="","",SUMIFS(加仓管理!$G$2:$G$1001,加仓管理!$A$2:$A$1001,A9)) -> 7500 | AM9: =IF(AK9=0,"",IFERROR(LOOKUP(2,1/((加仓管理!$A$2:$A$1001=A9)*(加仓管理!$G$2:$G$1001>0)),加仓管理!$D$2:$D$1001),"")) -> 9.32 | AN9: =IF(AK9=0,"",IFERROR(LOOKUP(2,1/((加仓管理!$A$2:$A$1001=A9)*(加仓管理!$G$2:$G$1001>0)),加仓管理!$E$2:$E$1001),"")) -> 8.5 | AO9: =IF(OR(A9="",H9="",H9<=0),"",(E9*H9+SUMIFS(加仓管理!$H$2:$H$1001,加仓管理!$A$2:$A$1001,A9))/AP9) -> 8.1769565 | AP9: =IF(OR(A9="",H9="",H9<=0),"",H9+AL9) -> 11500 | AQ9: =IF(A9="","",IF(M9<>"",0,IF(OR(H9="",N9=""),"",MAX((E9*H9+SUMIFS(加仓管理!$H$2:$H$1001,加仓管理!$A$2:$A$1001,A9))-MAX(N9,AN9)*AP9,0)))) -> 0 | AR9: =IF(A9="","",IF(OR(E9="",H9=""),"违规：首次买入价格或股数缺失",IF(COUNTIFS(加仓管理!$A$2:$A$1001,A9,加仓管理!$R$2:$R$1001,"违规*")>0,"违规：请检查加仓管理表",IF(SUM($AQ$2:$AQ$201)>账户数据!$B$7,"预警：超过账户风险上限",IF(COUNTIFS(加仓管理!$A$2:$A$1001,A9,加仓管理!$N$2:$N$1001,">0",加仓管理!$G$2:$G$1001,"")>0,"提示：存在待执行加仓计划","通过"))))) -> 违规：请检查加仓管理表
A10: 9 | B10: 新和成 | C10: 141941 | D10: 0.02 | E10: 8.02 | F10: =IF(OR(C10="",D10="",E10="",N10="",C10<=0,D10<=0,E10<=N10),"",ROUNDDOWN((C10*D10)/(E10-N10)/100,0)*100) -> 3900 | G10: =IF(A10="","",IF(H10<>"","已开仓",IF(账户数据!$B$23="已锁仓","禁止开仓：连续亏损达到上限",IF(账户数据!$B$23="解锁信息不完整","禁止开仓：请完整填写解锁信息",IF(OR(F10="",E10="",N10="",E10<=N10,账户数据!$B$7=""),"",IF(OR(AG10="",AH10="",AI10=""),"禁止开仓：交易预期未填写完整",IF(账户数据!$B$9+F10*(E10-N10)>=账户数据!$B$7,"禁止开仓：风险额度不足",IF(AJ10="周期与交易预期不匹配，请重新确认",IF(账户数据!$B$23="接近锁仓","允许开仓（接近锁仓；周期需复核）","允许开仓（周期需复核）"),IF(账户数据!$B$23="接近锁仓","允许开仓（接近锁仓）","允许开仓"))))))))) -> 已开仓 | H10: 3000 | I10: 43550 | J10: 9 | K10: 10.18 | L10: =IF(AP10="","",AP10) -> 11000 | M10: 43572 | N10: 7.3 | U10: =IF(OR(AO10="",J10="",AO10<=0),"",(J10-AO10)/AO10) -> 0.011029412 | V10: =IF(OR(AO10="",N10="",AO10<=0),"",(AO10-N10)/AO10) -> 0.17994281 | W10: =IF(OR(U10="",V10="",V10<=0),"",U10/V10) -> 0.061293984 | X10: =IF(OR(K10="",L10="",AO10="",AP10=""),"",(K10-AO10)*L10-IF(O10="",0,O10)-IF(P10="",0,P10)) -> 14060 | Y10: =IF(OR(X10="",AO10="",L10=""),"",IF(AO10*L10+IF(O10="",0,O10)<=0,"",X10/(AO10*L10+IF(O10="",0,O10)))) -> 0.1435866 | Z10: =IF(OR(AE10="",多次统计数据!$B$8=""),"",AE10-多次统计数据!$B$8) -> 0.00084527524 | AA10: =IF(OR(I10="",M10="",M10<I10),"",M10-I10) -> 22 | AB10: =IF(OR(A10="",多次统计数据!$B$8="",多次统计数据!$B$6<=0,多次统计数据!$B$6>=1),"",1-POWER(1+多次统计数据!$B$8,-多次统计数据!$B$6/(1-多次统计数据!$B$6))) -> 0.096508292 | AC10: =IF(OR(AB10="",多次统计数据!$B$9=""),"",IF(多次统计数据!$B$9<AB10,"低于上限","达到或超过上限")) -> 低于上限 | AE10: =IF(OR(X10="",C10="",C10<=0),"",X10/C10) -> 0.099055241 | AG10: 趋势波段 | AH10: 11～20个交易日 | AI10: 吸筹 | AJ10: =IF(OR(AG10="",AH10=""),"",IF(OR(AND(AG10="短期博反弹",OR(AH10="1～3个交易日",AH10="4～10个交易日")),AND(AG10="突破冲新高",OR(AH10="4～10个交易日",AH10="11～20个交易日")),AND(AG10="趋势波段",OR(AH10="11～20个交易日",AH10="21～60个交易日",AH10="60个交易日以上"))),"匹配","周期与交易预期不匹配，请重新确认")) -> 匹配 | AK10: =IF(A10="","",COUNTIFS(加仓管理!$A$2:$A$1001,A10,加仓管理!$G$2:$G$1001,">0")) -> 4 | AL10: =IF(A10="","",SUMIFS(加仓管理!$G$2:$G$1001,加仓管理!$A$2:$A$1001,A10)) -> 8000 | AM10: =IF(AK10=0,"",IFERROR(LOOKUP(2,1/((加仓管理!$A$2:$A$1001=A10)*(加仓管理!$G$2:$G$1001>0)),加仓管理!$D$2:$D$1001),"")) -> 9.69 | AN10: =IF(AK10=0,"",IFERROR(LOOKUP(2,1/((加仓管理!$A$2:$A$1001=A10)*(加仓管理!$G$2:$G$1001>0)),加仓管理!$E$2:$E$1001),"")) -> 9 | AO10: =IF(OR(A10="",H10="",H10<=0),"",(E10*H10+SUMIFS(加仓管理!$H$2:$H$1001,加仓管理!$A$2:$A$1001,A10))/AP10) -> 8.9018182 | AP10: =IF(OR(A10="",H10="",H10<=0),"",H10+AL10) -> 11000 | AQ10: =IF(A10="","",IF(M10<>"",0,IF(OR(H10="",N10=""),"",MAX((E10*H10+SUMIFS(加仓管理!$H$2:$H$1001,加仓管理!$A$2:$A$1001,A10))-MAX(N10,AN10)*AP10,0)))) -> 0 | AR10: =IF(A10="","",IF(OR(E10="",H10=""),"违规：首次买入价格或股数缺失",IF(COUNTIFS(加仓管理!$A$2:$A$1001,A10,加仓管理!$R$2:$R$1001,"违规*")>0,"违规：请检查加仓管理表",IF(SUM($AQ$2:$AQ$201)>账户数据!$B$7,"预警：超过账户风险上限",IF(COUNTIFS(加仓管理!$A$2:$A$1001,A10,加仓管理!$N$2:$N$1001,">0",加仓管理!$G$2:$G$1001,"")>0,"提示：存在待执行加仓计划","通过"))))) -> 违规：请检查加仓管理表
A11: 10 | B11: 新和成 | C11: 156001 | D11: 0.02 | E11: 9.07 | F11: =IF(OR(C11="",D11="",E11="",N11="",C11<=0,D11<=0,E11<=N11),"",ROUNDDOWN((C11*D11)/(E11-N11)/100,0)*100) -> 5400 | G11: =IF(A11="","",IF(H11<>"","已开仓",IF(账户数据!$B$23="已锁仓","禁止开仓：连续亏损达到上限",IF(账户数据!$B$23="解锁信息不完整","禁止开仓：请完整填写解锁信息",IF(OR(F11="",E11="",N11="",E11<=N11,账户数据!$B$7=""),"",IF(OR(AG11="",AH11="",AI11=""),"禁止开仓：交易预期未填写完整",IF(账户数据!$B$9+F11*(E11-N11)>=账户数据!$B$7,"禁止开仓：风险额度不足",IF(AJ11="周期与交易预期不匹配，请重新确认",IF(账户数据!$B$23="接近锁仓","允许开仓（接近锁仓；周期需复核）","允许开仓（周期需复核）"),IF(账户数据!$B$23="接近锁仓","允许开仓（接近锁仓）","允许开仓"))))))))) -> 已开仓 | H11: 2000 | I11: 43598 | J11: 10 | K11: 8.48 | L11: =IF(AP11="","",AP11) -> 4000 | M11: 43602 | N11: 8.5 | U11: =IF(OR(AO11="",J11="",AO11<=0),"",(J11-AO11)/AO11) -> 0.083423619 | V11: =IF(OR(AO11="",N11="",AO11<=0),"",(AO11-N11)/AO11) -> 0.079089924 | W11: =IF(OR(U11="",V11="",V11<=0),"",U11/V11) -> 1.0547945 | X11: =IF(OR(K11="",L11="",AO11="",AP11=""),"",(K11-AO11)*L11-IF(O11="",0,O11)-IF(P11="",0,P11)) -> -3000 | Y11: =IF(OR(X11="",AO11="",L11=""),"",IF(AO11*L11+IF(O11="",0,O11)<=0,"",X11/(AO11*L11+IF(O11="",0,O11)))) -> -0.081256771 | Z11: =IF(OR(AE11="",多次统计数据!$B$8=""),"",AE11-多次统计数据!$B$8) -> -0.11744061 | AA11: =IF(OR(I11="",M11="",M11<I11),"",M11-I11) -> 4 | AB11: =IF(OR(A11="",多次统计数据!$B$8="",多次统计数据!$B$6<=0,多次统计数据!$B$6>=1),"",1-POWER(1+多次统计数据!$B$8,-多次统计数据!$B$6/(1-多次统计数据!$B$6))) -> 0.096508292 | AC11: =IF(OR(AB11="",多次统计数据!$B$9=""),"",IF(多次统计数据!$B$9<AB11,"低于上限","达到或超过上限")) -> 低于上限 | AE11: =IF(OR(X11="",C11="",C11<=0),"",X11/C11) -> -0.019230646 | AG11: 短期博反弹 | AH11: 4～10个交易日 | AI11: 吸筹 | AJ11: =IF(OR(AG11="",AH11=""),"",IF(OR(AND(AG11="短期博反弹",OR(AH11="1～3个交易日",AH11="4～10个交易日")),AND(AG11="突破冲新高",OR(AH11="4～10个交易日",AH11="11～20个交易日")),AND(AG11="趋势波段",OR(AH11="11～20个交易日",AH11="21～60个交易日",AH11="60个交易日以上"))),"匹配","周期与交易预期不匹配，请重新确认")) -> 匹配 | AK11: =IF(A11="","",COUNTIFS(加仓管理!$A$2:$A$1001,A11,加仓管理!$G$2:$G$1001,">0")) -> 1 | AL11: =IF(A11="","",SUMIFS(加仓管理!$G$2:$G$1001,加仓管理!$A$2:$A$1001,A11)) -> 2000 | AM11: =IF(AK11=0,"",IFERROR(LOOKUP(2,1/((加仓管理!$A$2:$A$1001=A11)*(加仓管理!$G$2:$G$1001>0)),加仓管理!$D$2:$D$1001),"")) -> 9.39 | AN11: =IF(AK11=0,"",IFERROR(LOOKUP(2,1/((加仓管理!$A$2:$A$1001=A11)*(加仓管理!$G$2:$G$1001>0)),加仓管理!$E$2:$E$1001),"")) -> 9 | AO11: =IF(OR(A11="",H11="",H11<=0),"",(E11*H11+SUMIFS(加仓管理!$H$2:$H$1001,加仓管理!$A$2:$A$1001,A11))/AP11) -> 9.23 | AP11: =IF(OR(A11="",H11="",H11<=0),"",H11+AL11) -> 4000 | AQ11: =IF(A11="","",IF(M11<>"",0,IF(OR(H11="",N11=""),"",MAX((E11*H11+SUMIFS(加仓管理!$H$2:$H$1001,加仓管理!$A$2:$A$1001,A11))-MAX(N11,AN11)*AP11,0)))) -> 0 | AR11: =IF(A11="","",IF(OR(E11="",H11=""),"违规：首次买入价格或股数缺失",IF(COUNTIFS(加仓管理!$A$2:$A$1001,A11,加仓管理!$R$2:$R$1001,"违规*")>0,"违规：请检查加仓管理表",IF(SUM($AQ$2:$AQ$201)>账户数据!$B$7,"预警：超过账户风险上限",IF(COUNTIFS(加仓管理!$A$2:$A$1001,A11,加仓管理!$N$2:$N$1001,">0",加仓管理!$G$2:$G$1001,"")>0,"提示：存在待执行加仓计划","通过"))))) -> 违规：请检查加仓管理表
A12: 11 | B12: 新和成 | C12: 153001 | D12: 0.02 | E12: 8.92 | F12: =IF(OR(C12="",D12="",E12="",N12="",C12<=0,D12<=0,E12<=N12),"",ROUNDDOWN((C12*D12)/(E12-N12)/100,0)*100) -> 7200 | G12: =IF(A12="","",IF(H12<>"","已开仓",IF(账户数据!$B$23="已锁仓","禁止开仓：连续亏损达到上限",IF(账户数据!$B$23="解锁信息不完整","禁止开仓：请完整填写解锁信息",IF(OR(F12="",E12="",N12="",E12<=N12,账户数据!$B$7=""),"",IF(OR(AG12="",AH12="",AI12=""),"禁止开仓：交易预期未填写完整",IF(账户数据!$B$9+F12*(E12-N12)>=账户数据!$B$7,"禁止开仓：风险额度不足",IF(AJ12="周期与交易预期不匹配，请重新确认",IF(账户数据!$B$23="接近锁仓","允许开仓（接近锁仓；周期需复核）","允许开仓（周期需复核）"),IF(账户数据!$B$23="接近锁仓","允许开仓（接近锁仓）","允许开仓"))))))))) -> 已开仓 | H12: 4000 | I12: 43609 | J12: 10 | K12: 11.07 | L12: =IF(AP12="","",AP12) -> 15000 | M12: 43731 | N12: 8.5 | U12: =IF(OR(AO12="",J12="",AO12<=0),"",(J12-AO12)/AO12) -> 0.07434465 | V12: =IF(OR(AO12="",N12="",AO12<=0),"",(AO12-N12)/AO12) -> 0.086807048 | W12: =IF(OR(U12="",V12="",V12<=0),"",U12/V12) -> 0.85643564 | X12: =IF(OR(K12="",L12="",AO12="",AP12=""),"",(K12-AO12)*L12-IF(O12="",0,O12)-IF(P12="",0,P12)) -> 26430 | Y12: =IF(OR(X12="",AO12="",L12=""),"",IF(AO12*L12+IF(O12="",0,O12)<=0,"",X12/(AO12*L12+IF(O12="",0,O12)))) -> 0.18929953 | Z12: =IF(OR(AE12="",多次统计数据!$B$8=""),"",AE12-多次统计数据!$B$8) -> 0.074534003 | AA12: =IF(OR(I12="",M12="",M12<I12),"",M12-I12) -> 122 | AB12: =IF(OR(A12="",多次统计数据!$B$8="",多次统计数据!$B$6<=0,多次统计数据!$B$6>=1),"",1-POWER(1+多次统计数据!$B$8,-多次统计数据!$B$6/(1-多次统计数据!$B$6))) -> 0.096508292 | AC12: =IF(OR(AB12="",多次统计数据!$B$9=""),"",IF(多次统计数据!$B$9<AB12,"低于上限","达到或超过上限")) -> 低于上限 | AE12: =IF(OR(X12="",C12="",C12<=0),"",X12/C12) -> 0.17274397 | AG12: 趋势波段 | AH12: 11～20个交易日 | AI12: 吸筹 | AJ12: =IF(OR(AG12="",AH12=""),"",IF(OR(AND(AG12="短期博反弹",OR(AH12="1～3个交易日",AH12="4～10个交易日")),AND(AG12="突破冲新高",OR(AH12="4～10个交易日",AH12="11～20个交易日")),AND(AG12="趋势波段",OR(AH12="11～20个交易日",AH12="21～60个交易日",AH12="60个交易日以上"))),"匹配","周期与交易预期不匹配，请重新确认")) -> 匹配 | AK12: =IF(A12="","",COUNTIFS(加仓管理!$A$2:$A$1001,A12,加仓管理!$G$2:$G$1001,">0")) -> 4 | AL12: =IF(A12="","",SUMIFS(加仓管理!$G$2:$G$1001,加仓管理!$A$2:$A$1001,A12)) -> 11000 | AM12: =IF(AK12=0,"",IFERROR(LOOKUP(2,1/((加仓管理!$A$2:$A$1001=A12)*(加仓管理!$G$2:$G$1001>0)),加仓管理!$D$2:$D$1001),"")) -> 9.84 | AN12: =IF(AK12=0,"",IFERROR(LOOKUP(2,1/((加仓管理!$A$2:$A$1001=A12)*(加仓管理!$G$2:$G$1001>0)),加仓管理!$E$2:$E$1001),"")) -> 9.5 | AO12: =IF(OR(A12="",H12="",H12<=0),"",(E12*H12+SUMIFS(加仓管理!$H$2:$H$1001,加仓管理!$A$2:$A$1001,A12))/AP12) -> 9.308 | AP12: =IF(OR(A12="",H12="",H12<=0),"",H12+AL12) -> 15000 | AQ12: =IF(A12="","",IF(M12<>"",0,IF(OR(H12="",N12=""),"",MAX((E12*H12+SUMIFS(加仓管理!$H$2:$H$1001,加仓管理!$A$2:$A$1001,A12))-MAX(N12,AN12)*AP12,0)))) -> 0 | AR12: =IF(A12="","",IF(OR(E12="",H12=""),"违规：首次买入价格或股数缺失",IF(COUNTIFS(加仓管理!$A$2:$A$1001,A12,加仓管理!$R$2:$R$1001,"违规*")>0,"违规：请检查加仓管理表",IF(SUM($AQ$2:$AQ$201)>账户数据!$B$7,"预警：超过账户风险上限",IF(COUNTIFS(加仓管理!$A$2:$A$1001,A12,加仓管理!$N$2:$N$1001,">0",加仓管理!$G$2:$G$1001,"")>0,"提示：存在待执行加仓计划","通过"))))) -> 违规：请检查加仓管理表
A13: 12 | B13: 新和成 | C13: 179431 | D13: 0.02 | E13: 10.17 | F13: =IF(OR(C13="",D13="",E13="",N13="",C13<=0,D13<=0,E13<=N13),"",ROUNDDOWN((C13*D13)/(E13-N13)/100,0)*100) -> 5300 | G13: =IF(A13="","",IF(H13<>"","已开仓",IF(账户数据!$B$23="已锁仓","禁止开仓：连续亏损达到上限",IF(账户数据!$B$23="解锁信息不完整","禁止开仓：请完整填写解锁信息",IF(OR(F13="",E13="",N13="",E13<=N13,账户数据!$B$7=""),"",IF(OR(AG13="",AH13="",AI13=""),"禁止开仓：交易预期未填写完整",IF(账户数据!$B$9+F13*(E13-N13)>=账户数据!$B$7,"禁止开仓：风险额度不足",IF(AJ13="周期与交易预期不匹配，请重新确认",IF(账户数据!$B$23="接近锁仓","允许开仓（接近锁仓；周期需复核）","允许开仓（周期需复核）"),IF(账户数据!$B$23="接近锁仓","允许开仓（接近锁仓）","允许开仓"))))))))) -> 已开仓 | H13: 2000 | I13: 43755 | J13: 11 | K13: 9.55 | L13: =IF(AP13="","",AP13) -> 2000 | M13: 43767 | N13: 9.5 | U13: =IF(OR(AO13="",J13="",AO13<=0),"",(J13-AO13)/AO13) -> 0.081612586 | V13: =IF(OR(AO13="",N13="",AO13<=0),"",(AO13-N13)/AO13) -> 0.065880039 | W13: =IF(OR(U13="",V13="",V13<=0),"",U13/V13) -> 1.238806 | X13: =IF(OR(K13="",L13="",AO13="",AP13=""),"",(K13-AO13)*L13-IF(O13="",0,O13)-IF(P13="",0,P13)) -> -1240 | Y13: =IF(OR(X13="",AO13="",L13=""),"",IF(AO13*L13+IF(O13="",0,O13)<=0,"",X13/(AO13*L13+IF(O13="",0,O13)))) -> -0.060963618 | Z13: =IF(OR(AE13="",多次统计数据!$B$8=""),"",AE13-多次统计数据!$B$8) -> -0.1051207 | AA13: =IF(OR(I13="",M13="",M13<I13),"",M13-I13) -> 12 | AB13: =IF(OR(A13="",多次统计数据!$B$8="",多次统计数据!$B$6<=0,多次统计数据!$B$6>=1),"",1-POWER(1+多次统计数据!$B$8,-多次统计数据!$B$6/(1-多次统计数据!$B$6))) -> 0.096508292 | AC13: =IF(OR(AB13="",多次统计数据!$B$9=""),"",IF(多次统计数据!$B$9<AB13,"低于上限","达到或超过上限")) -> 低于上限 | AE13: =IF(OR(X13="",C13="",C13<=0),"",X13/C13) -> -0.0069107345 | AG13: 短期博反弹 | AH13: 4～10个交易日 | AI13: 反弹 | AJ13: =IF(OR(AG13="",AH13=""),"",IF(OR(AND(AG13="短期博反弹",OR(AH13="1～3个交易日",AH13="4～10个交易日")),AND(AG13="突破冲新高",OR(AH13="4～10个交易日",AH13="11～20个交易日")),AND(AG13="趋势波段",OR(AH13="11～20个交易日",AH13="21～60个交易日",AH13="60个交易日以上"))),"匹配","周期与交易预期不匹配，请重新确认")) -> 匹配 | AK13: =IF(A13="","",COUNTIFS(加仓管理!$A$2:$A$1001,A13,加仓管理!$G$2:$G$1001,">0")) -> 0 | AL13: =IF(A13="","",SUMIFS(加仓管理!$G$2:$G$1001,加仓管理!$A$2:$A$1001,A13)) -> 0 | AM13: =IF(AK13=0,"",IFERROR(LOOKUP(2,1/((加仓管理!$A$2:$A$1001=A13)*(加仓管理!$G$2:$G$1001>0)),加仓管理!$D$2:$D$1001),"")) | AN13: =IF(AK13=0,"",IFERROR(LOOKUP(2,1/((加仓管理!$A$2:$A$1001=A13)*(加仓管理!$G$2:$G$1001>0)),加仓管理!$E$2:$E$1001),"")) | AO13: =IF(OR(A13="",H13="",H13<=0),"",(E13*H13+SUMIFS(加仓管理!$H$2:$H$1001,加仓管理!$A$2:$A$1001,A13))/AP13) -> 10.17 | AP13: =IF(OR(A13="",H13="",H13<=0),"",H13+AL13) -> 2000 | AQ13: =IF(A13="","",IF(M13<>"",0,IF(OR(H13="",N13=""),"",MAX((E13*H13+SUMIFS(加仓管理!$H$2:$H$1001,加仓管理!$A$2:$A$1001,A13))-MAX(N13,AN13)*AP13,0)))) -> 0 | AR13: =IF(A13="","",IF(OR(E13="",H13=""),"违规：首次买入价格或股数缺失",IF(COUNTIFS(加仓管理!$A$2:$A$1001,A13,加仓管理!$R$2:$R$1001,"违规*")>0,"违规：请检查加仓管理表",IF(SUM($AQ$2:$AQ$201)>账户数据!$B$7,"预警：超过账户风险上限",IF(COUNTIFS(加仓管理!$A$2:$A$1001,A13,加仓管理!$N$2:$N$1001,">0",加仓管理!$G$2:$G$1001,"")>0,"提示：存在待执行加仓计划","通过"))))) -> 通过
... A101: 99 | B101: 爱尔眼科 | C101: 1145478 | D101: 0.02 | E101: 20.46 | F101: =IF(OR(C101="",D101="",E101="",N101="",C101<=0,D101<=0,E101<=N101),"",ROUNDDOWN((C101*D101)/(E101-N101)/100,0)*100) -> 6600 | G101: =IF(A101="","",IF(H101<>"","已开仓",IF(账户数据!$B$23="已锁仓","禁止开仓：连续亏损达到上限",IF(账户数据!$B$23="解锁信息不完整","禁止开仓：请完整填写解锁信息",IF(OR(F101="",E101="",N101="",E101<=N101,账户数据!$B$7=""),"",IF(OR(AG101="",AH101="",AI101=""),"禁止开仓：交易预期未填写完整",IF(账户数据!$B$9+F101*(E101-N101)>=账户数据!$B$7,"禁止开仓：风险额度不足",IF(AJ101="周期与交易预期不匹配，请重新确认",IF(账户数据!$B$23="接近锁仓","允许开仓（接近锁仓；周期需复核）","允许开仓（周期需复核）"),IF(账户数据!$B$23="接近锁仓","允许开仓（接近锁仓）","允许开仓"))))))))) -> 已开仓 | H101: 5000 | I101: 44021 | J101: 22 | K101: 21.08 | L101: =IF(AP101="","",AP101) -> 5000 | M101: 44027 | N101: 17 | U101: =IF(OR(AO101="",J101="",AO101<=0),"",(J101-AO101)/AO101) -> 0.075268817 | V101: =IF(OR(AO101="",N101="",AO101<=0),"",(AO101-N101)/AO101) -> 0.16911046 | W101: =IF(OR(U101="",V101="",V101<=0),"",U101/V101) -> 0.44508671 | X101: =IF(OR(K101="",L101="",AO101="",AP101=""),"",(K101-AO101)*L101-IF(O101="",0,O101)-IF(P101="",0,P101)) -> 3100 | Y101: =IF(OR(X101="",AO101="",L101=""),"",IF(AO101*L101+IF(O101="",0,O101)<=0,"",X101/(AO101*L101+IF(O101="",0,O101)))) -> 0.03030303 | Z101: =IF(OR(AE101="",多次统计数据!$B$8=""),"",AE101-多次统计数据!$B$8) -> -0.095503672 | AA101: =IF(OR(I101="",M101="",M101<I101),"",M101-I101) -> 6 | AB101: =IF(OR(A101="",多次统计数据!$B$8="",多次统计数据!$B$6<=0,多次统计数据!$B$6>=1),"",1-POWER(1+多次统计数据!$B$8,-多次统计数据!$B$6/(1-多次统计数据!$B$6))) -> 0.096508292 | AC101: =IF(OR(AB101="",多次统计数据!$B$9=""),"",IF(多次统计数据!$B$9<AB101,"低于上限","达到或超过上限")) -> 低于上限 | AE101: =IF(OR(X101="",C101="",C101<=0),"",X101/C101) -> 0.0027062938 | AG101: 短期博反弹 | AH101: 4～10个交易日 | AI101: 反弹 | AJ101: =IF(OR(AG101="",AH101=""),"",IF(OR(AND(AG101="短期博反弹",OR(AH101="1～3个交易日",AH101="4～10个交易日")),AND(AG101="突破冲新高",OR(AH101="4～10个交易日",AH101="11～20个交易日")),AND(AG101="趋势波段",OR(AH101="11～20个交易日",AH101="21～60个交易日",AH101="60个交易日以上"))),"匹配","周期与交易预期不匹配，请重新确认")) -> 匹配 | AK101: =IF(A101="","",COUNTIFS(加仓管理!$A$2:$A$1001,A101,加仓管理!$G$2:$G$1001,">0")) -> 0 | AL101: =IF(A101="","",SUMIFS(加仓管理!$G$2:$G$1001,加仓管理!$A$2:$A$1001,A101)) -> 0 | AM101: =IF(AK101=0,"",IFERROR(LOOKUP(2,1/((加仓管理!$A$2:$A$1001=A101)*(加仓管理!$G$2:$G$1001>0)),加仓管理!$D$2:$D$1001),"")) | AN101: =IF(AK101=0,"",IFERROR(LOOKUP(2,1/((加仓管理!$A$2:$A$1001=A101)*(加仓管理!$G$2:$G$1001>0)),加仓管理!$E$2:$E$1001),"")) | AO101: =IF(OR(A101="",H101="",H101<=0),"",(E101*H101+SUMIFS(加仓管理!$H$2:$H$1001,加仓管理!$A$2:$A$1001,A101))/AP101) -> 20.46 | AP101: =IF(OR(A101="",H101="",H101<=0),"",H101+AL101) -> 5000 | AQ101: =IF(A101="","",IF(M101<>"",0,IF(OR(H101="",N101=""),"",MAX((E101*H101+SUMIFS(加仓管理!$H$2:$H$1001,加仓管理!$A$2:$A$1001,A101))-MAX(N101,AN101)*AP101,0)))) -> 0 | AR101: =IF(A101="","",IF(OR(E101="",H101=""),"违规：首次买入价格或股数缺失",IF(COUNTIFS(加仓管理!$A$2:$A$1001,A101,加仓管理!$R$2:$R$1001,"违规*")>0,"违规：请检查加仓管理表",IF(SUM($AQ$2:$AQ$201)>账户数据!$B$7,"预警：超过账户风险上限",IF(COUNTIFS(加仓管理!$A$2:$A$1001,A101,加仓管理!$N$2:$N$1001,">0",加仓管理!$G$2:$G$1001,"")>0,"提示：存在待执行加仓计划","通过"))))) -> 通过
F102: =IF(OR(C102="",D102="",E102="",N102="",C102<=0,D102<=0,E102<=N102),"",ROUNDDOWN((C102*D102)/(E102-N102)/100,0)*100) | G102: =IF(A102="","",IF(H102<>"","已开仓",IF(账户数据!$B$23="已锁仓","禁止开仓：连续亏损达到上限",IF(账户数据!$B$23="解锁信息不完整","禁止开仓：请完整填写解锁信息",IF(OR(F102="",E102="",N102="",E102<=N102,账户数据!$B$7=""),"",IF(OR(AG102="",AH102="",AI102=""),"禁止开仓：交易预期未填写完整",IF(账户数据!$B$9+F102*(E102-N102)>=账户数据!$B$7,"禁止开仓：风险额度不足",IF(AJ102="周期与交易预期不匹配，请重新确认",IF(账户数据!$B$23="接近锁仓","允许开仓（接近锁仓；周期需复核）","允许开仓（周期需复核）"),IF(账户数据!$B$23="接近锁仓","允许开仓（接近锁仓）","允许开仓"))))))))) | L102: =IF(AP102="","",AP102) | U102: =IF(OR(AO102="",J102="",AO102<=0),"",(J102-AO102)/AO102) | V102: =IF(OR(AO102="",N102="",AO102<=0),"",(AO102-N102)/AO102) | W102: =IF(OR(U102="",V102="",V102<=0),"",U102/V102) | X102: =IF(OR(K102="",L102="",AO102="",AP102=""),"",(K102-AO102)*L102-IF(O102="",0,O102)-IF(P102="",0,P102)) | Y102: =IF(OR(X102="",AO102="",L102=""),"",IF(AO102*L102+IF(O102="",0,O102)<=0,"",X102/(AO102*L102+IF(O102="",0,O102)))) | Z102: =IF(OR(AE102="",多次统计数据!$B$8=""),"",AE102-多次统计数据!$B$8) | AA102: =IF(OR(I102="",M102="",M102<I102),"",M102-I102) | AB102: =IF(OR(A102="",多次统计数据!$B$8="",多次统计数据!$B$6<=0,多次统计数据!$B$6>=1),"",1-POWER(1+多次统计数据!$B$8,-多次统计数据!$B$6/(1-多次统计数据!$B$6))) | AC102: =IF(OR(AB102="",多次统计数据!$B$9=""),"",IF(多次统计数据!$B$9<AB102,"低于上限","达到或超过上限")) | AE102: =IF(OR(X102="",C102="",C102<=0),"",X102/C102) | AJ102: =IF(OR(AG102="",AH102=""),"",IF(OR(AND(AG102="短期博反弹",OR(AH102="1～3个交易日",AH102="4～10个交易日")),AND(AG102="突破冲新高",OR(AH102="4～10个交易日",AH102="11～20个交易日")),AND(AG102="趋势波段",OR(AH102="11～20个交易日",AH102="21～60个交易日",AH102="60个交易日以上"))),"匹配","周期与交易预期不匹配，请重新确认")) | AK102: =IF(A102="","",COUNTIFS(加仓管理!$A$2:$A$1001,A102,加仓管理!$G$2:$G$1001,">0")) | AL102: =IF(A102="","",SUMIFS(加仓管理!$G$2:$G$1001,加仓管理!$A$2:$A$1001,A102)) | AM102: =IF(AK102=0,"",IFERROR(LOOKUP(2,1/((加仓管理!$A$2:$A$1001=A102)*(加仓管理!$G$2:$G$1001>0)),加仓管理!$D$2:$D$1001),"")) | AN102: =IF(AK102=0,"",IFERROR(LOOKUP(2,1/((加仓管理!$A$2:$A$1001=A102)*(加仓管理!$G$2:$G$1001>0)),加仓管理!$E$2:$E$1001),"")) | AO102: =IF(OR(A102="",H102="",H102<=0),"",(E102*H102+SUMIFS(加仓管理!$H$2:$H$1001,加仓管理!$A$2:$A$1001,A102))/AP102) | AP102: =IF(OR(A102="",H102="",H102<=0),"",H102+AL102) | AQ102: =IF(A102="","",IF(M102<>"",0,IF(OR(H102="",N102=""),"",MAX((E102*H102+SUMIFS(加仓管理!$H$2:$H$1001,加仓管理!$A$2:$A$1001,A102))-MAX(N102,AN102)*AP102,0)))) | AR102: =IF(A102="","",IF(OR(E102="",H102=""),"违规：首次买入价格或股数缺失",IF(COUNTIFS(加仓管理!$A$2:$A$1001,A102,加仓管理!$R$2:$R$1001,"违规*")>0,"违规：请检查加仓管理表",IF(SUM($AQ$2:$AQ$201)>账户数据!$B$7,"预警：超过账户风险上限",IF(COUNTIFS(加仓管理!$A$2:$A$1001,A102,加仓管理!$N$2:$N$1001,">0",加仓管理!$G$2:$G$1001,"")>0,"提示：存在待执行加仓计划","通过")))))
F103: =IF(OR(C103="",D103="",E103="",N103="",C103<=0,D103<=0,E103<=N103),"",ROUNDDOWN((C103*D103)/(E103-N103)/100,0)*100) | G103: =IF(A103="","",IF(H103<>"","已开仓",IF(账户数据!$B$23="已锁仓","禁止开仓：连续亏损达到上限",IF(账户数据!$B$23="解锁信息不完整","禁止开仓：请完整填写解锁信息",IF(OR(F103="",E103="",N103="",E103<=N103,账户数据!$B$7=""),"",IF(OR(AG103="",AH103="",AI103=""),"禁止开仓：交易预期未填写完整",IF(账户数据!$B$9+F103*(E103-N103)>=账户数据!$B$7,"禁止开仓：风险额度不足",IF(AJ103="周期与交易预期不匹配，请重新确认",IF(账户数据!$B$23="接近锁仓","允许开仓（接近锁仓；周期需复核）","允许开仓（周期需复核）"),IF(账户数据!$B$23="接近锁仓","允许开仓（接近锁仓）","允许开仓"))))))))) | L103: =IF(AP103="","",AP103) | U103: =IF(OR(AO103="",J103="",AO103<=0),"",(J103-AO103)/AO103) | V103: =IF(OR(AO103="",N103="",AO103<=0),"",(AO103-N103)/AO103) | W103: =IF(OR(U103="",V103="",V103<=0),"",U103/V103) | X103: =IF(OR(K103="",L103="",AO103="",AP103=""),"",(K103-AO103)*L103-IF(O103="",0,O103)-IF(P103="",0,P103)) | Y103: =IF(OR(X103="",AO103="",L103=""),"",IF(AO103*L103+IF(O103="",0,O103)<=0,"",X103/(AO103*L103+IF(O103="",0,O103)))) | Z103: =IF(OR(AE103="",多次统计数据!$B$8=""),"",AE103-多次统计数据!$B$8) | AA103: =IF(OR(I103="",M103="",M103<I103),"",M103-I103) | AB103: =IF(OR(A103="",多次统计数据!$B$8="",多次统计数据!$B$6<=0,多次统计数据!$B$6>=1),"",1-POWER(1+多次统计数据!$B$8,-多次统计数据!$B$6/(1-多次统计数据!$B$6))) | AC103: =IF(OR(AB103="",多次统计数据!$B$9=""),"",IF(多次统计数据!$B$9<AB103,"低于上限","达到或超过上限")) | AE103: =IF(OR(X103="",C103="",C103<=0),"",X103/C103) | AJ103: =IF(OR(AG103="",AH103=""),"",IF(OR(AND(AG103="短期博反弹",OR(AH103="1～3个交易日",AH103="4～10个交易日")),AND(AG103="突破冲新高",OR(AH103="4～10个交易日",AH103="11～20个交易日")),AND(AG103="趋势波段",OR(AH103="11～20个交易日",AH103="21～60个交易日",AH103="60个交易日以上"))),"匹配","周期与交易预期不匹配，请重新确认")) | AK103: =IF(A103="","",COUNTIFS(加仓管理!$A$2:$A$1001,A103,加仓管理!$G$2:$G$1001,">0")) | AL103: =IF(A103="","",SUMIFS(加仓管理!$G$2:$G$1001,加仓管理!$A$2:$A$1001,A103)) | AM103: =IF(AK103=0,"",IFERROR(LOOKUP(2,1/((加仓管理!$A$2:$A$1001=A103)*(加仓管理!$G$2:$G$1001>0)),加仓管理!$D$2:$D$1001),"")) | AN103: =IF(AK103=0,"",IFERROR(LOOKUP(2,1/((加仓管理!$A$2:$A$1001=A103)*(加仓管理!$G$2:$G$1001>0)),加仓管理!$E$2:$E$1001),"")) | AO103: =IF(OR(A103="",H103="",H103<=0),"",(E103*H103+SUMIFS(加仓管理!$H$2:$H$1001,加仓管理!$A$2:$A$1001,A103))/AP103) | AP103: =IF(OR(A103="",H103="",H103<=0),"",H103+AL103) | AQ103: =IF(A103="","",IF(M103<>"",0,IF(OR(H103="",N103=""),"",MAX((E103*H103+SUMIFS(加仓管理!$H$2:$H$1001,加仓管理!$A$2:$A$1001,A103))-MAX(N103,AN103)*AP103,0)))) | AR103: =IF(A103="","",IF(OR(E103="",H103=""),"违规：首次买入价格或股数缺失",IF(COUNTIFS(加仓管理!$A$2:$A$1001,A103,加仓管理!$R$2:$R$1001,"违规*")>0,"违规：请检查加仓管理表",IF(SUM($AQ$2:$AQ$201)>账户数据!$B$7,"预警：超过账户风险上限",IF(COUNTIFS(加仓管理!$A$2:$A$1001,A103,加仓管理!$N$2:$N$1001,">0",加仓管理!$G$2:$G$1001,"")>0,"提示：存在待执行加仓计划","通过")))))
F104: =IF(OR(C104="",D104="",E104="",N104="",C104<=0,D104<=0,E104<=N104),"",ROUNDDOWN((C104*D104)/(E104-N104)/100,0)*100) | G104: =IF(A104="","",IF(H104<>"","已开仓",IF(账户数据!$B$23="已锁仓","禁止开仓：连续亏损达到上限",IF(账户数据!$B$23="解锁信息不完整","禁止开仓：请完整填写解锁信息",IF(OR(F104="",E104="",N104="",E104<=N104,账户数据!$B$7=""),"",IF(OR(AG104="",AH104="",AI104=""),"禁止开仓：交易预期未填写完整",IF(账户数据!$B$9+F104*(E104-N104)>=账户数据!$B$7,"禁止开仓：风险额度不足",IF(AJ104="周期与交易预期不匹配，请重新确认",IF(账户数据!$B$23="接近锁仓","允许开仓（接近锁仓；周期需复核）","允许开仓（周期需复核）"),IF(账户数据!$B$23="接近锁仓","允许开仓（接近锁仓）","允许开仓"))))))))) | L104: =IF(AP104="","",AP104) | U104: =IF(OR(AO104="",J104="",AO104<=0),"",(J104-AO104)/AO104) | V104: =IF(OR(AO104="",N104="",AO104<=0),"",(AO104-N104)/AO104) | W104: =IF(OR(U104="",V104="",V104<=0),"",U104/V104) | X104: =IF(OR(K104="",L104="",AO104="",AP104=""),"",(K104-AO104)*L104-IF(O104="",0,O104)-IF(P104="",0,P104)) | Y104: =IF(OR(X104="",AO104="",L104=""),"",IF(AO104*L104+IF(O104="",0,O104)<=0,"",X104/(AO104*L104+IF(O104="",0,O104)))) | Z104: =IF(OR(AE104="",多次统计数据!$B$8=""),"",AE104-多次统计数据!$B$8) | AA104: =IF(OR(I104="",M104="",M104<I104),"",M104-I104) | AB104: =IF(OR(A104="",多次统计数据!$B$8="",多次统计数据!$B$6<=0,多次统计数据!$B$6>=1),"",1-POWER(1+多次统计数据!$B$8,-多次统计数据!$B$6/(1-多次统计数据!$B$6))) | AC104: =IF(OR(AB104="",多次统计数据!$B$9=""),"",IF(多次统计数据!$B$9<AB104,"低于上限","达到或超过上限")) | AE104: =IF(OR(X104="",C104="",C104<=0),"",X104/C104) | AJ104: =IF(OR(AG104="",AH104=""),"",IF(OR(AND(AG104="短期博反弹",OR(AH104="1～3个交易日",AH104="4～10个交易日")),AND(AG104="突破冲新高",OR(AH104="4～10个交易日",AH104="11～20个交易日")),AND(AG104="趋势波段",OR(AH104="11～20个交易日",AH104="21～60个交易日",AH104="60个交易日以上"))),"匹配","周期与交易预期不匹配，请重新确认")) | AK104: =IF(A104="","",COUNTIFS(加仓管理!$A$2:$A$1001,A104,加仓管理!$G$2:$G$1001,">0")) | AL104: =IF(A104="","",SUMIFS(加仓管理!$G$2:$G$1001,加仓管理!$A$2:$A$1001,A104)) | AM104: =IF(AK104=0,"",IFERROR(LOOKUP(2,1/((加仓管理!$A$2:$A$1001=A104)*(加仓管理!$G$2:$G$1001>0)),加仓管理!$D$2:$D$1001),"")) | AN104: =IF(AK104=0,"",IFERROR(LOOKUP(2,1/((加仓管理!$A$2:$A$1001=A104)*(加仓管理!$G$2:$G$1001>0)),加仓管理!$E$2:$E$1001),"")) | AO104: =IF(OR(A104="",H104="",H104<=0),"",(E104*H104+SUMIFS(加仓管理!$H$2:$H$1001,加仓管理!$A$2:$A$1001,A104))/AP104) | AP104: =IF(OR(A104="",H104="",H104<=0),"",H104+AL104) | AQ104: =IF(A104="","",IF(M104<>"",0,IF(OR(H104="",N104=""),"",MAX((E104*H104+SUMIFS(加仓管理!$H$2:$H$1001,加仓管理!$A$2:$A$1001,A104))-MAX(N104,AN104)*AP104,0)))) | AR104: =IF(A104="","",IF(OR(E104="",H104=""),"违规：首次买入价格或股数缺失",IF(COUNTIFS(加仓管理!$A$2:$A$1001,A104,加仓管理!$R$2:$R$1001,"违规*")>0,"违规：请检查加仓管理表",IF(SUM($AQ$2:$AQ$201)>账户数据!$B$7,"预警：超过账户风险上限",IF(COUNTIFS(加仓管理!$A$2:$A$1001,A104,加仓管理!$N$2:$N$1001,">0",加仓管理!$G$2:$G$1001,"")>0,"提示：存在待执行加仓计划","通过")))))
F105: =IF(OR(C105="",D105="",E105="",N105="",C105<=0,D105<=0,E105<=N105),"",ROUNDDOWN((C105*D105)/(E105-N105)/100,0)*100) | G105: =IF(A105="","",IF(H105<>"","已开仓",IF(账户数据!$B$23="已锁仓","禁止开仓：连续亏损达到上限",IF(账户数据!$B$23="解锁信息不完整","禁止开仓：请完整填写解锁信息",IF(OR(F105="",E105="",N105="",E105<=N105,账户数据!$B$7=""),"",IF(OR(AG105="",AH105="",AI105=""),"禁止开仓：交易预期未填写完整",IF(账户数据!$B$9+F105*(E105-N105)>=账户数据!$B$7,"禁止开仓：风险额度不足",IF(AJ105="周期与交易预期不匹配，请重新确认",IF(账户数据!$B$23="接近锁仓","允许开仓（接近锁仓；周期需复核）","允许开仓（周期需复核）"),IF(账户数据!$B$23="接近锁仓","允许开仓（接近锁仓）","允许开仓"))))))))) | L105: =IF(AP105="","",AP105) | U105: =IF(OR(AO105="",J105="",AO105<=0),"",(J105-AO105)/AO105) | V105: =IF(OR(AO105="",N105="",AO105<=0),"",(AO105-N105)/AO105) | W105: =IF(OR(U105="",V105="",V105<=0),"",U105/V105) | X105: =IF(OR(K105="",L105="",AO105="",AP105=""),"",(K105-AO105)*L105-IF(O105="",0,O105)-IF(P105="",0,P105)) | Y105: =IF(OR(X105="",AO105="",L105=""),"",IF(AO105*L105+IF(O105="",0,O105)<=0,"",X105/(AO105*L105+IF(O105="",0,O105)))) | Z105: =IF(OR(AE105="",多次统计数据!$B$8=""),"",AE105-多次统计数据!$B$8) | AA105: =IF(OR(I105="",M105="",M105<I105),"",M105-I105) | AB105: =IF(OR(A105="",多次统计数据!$B$8="",多次统计数据!$B$6<=0,多次统计数据!$B$6>=1),"",1-POWER(1+多次统计数据!$B$8,-多次统计数据!$B$6/(1-多次统计数据!$B$6))) | AC105: =IF(OR(AB105="",多次统计数据!$B$9=""),"",IF(多次统计数据!$B$9<AB105,"低于上限","达到或超过上限")) | AE105: =IF(OR(X105="",C105="",C105<=0),"",X105/C105) | AJ105: =IF(OR(AG105="",AH105=""),"",IF(OR(AND(AG105="短期博反弹",OR(AH105="1～3个交易日",AH105="4～10个交易日")),AND(AG105="突破冲新高",OR(AH105="4～10个交易日",AH105="11～20个交易日")),AND(AG105="趋势波段",OR(AH105="11～20个交易日",AH105="21～60个交易日",AH105="60个交易日以上"))),"匹配","周期与交易预期不匹配，请重新确认")) | AK105: =IF(A105="","",COUNTIFS(加仓管理!$A$2:$A$1001,A105,加仓管理!$G$2:$G$1001,">0")) | AL105: =IF(A105="","",SUMIFS(加仓管理!$G$2:$G$1001,加仓管理!$A$2:$A$1001,A105)) | AM105: =IF(AK105=0,"",IFERROR(LOOKUP(2,1/((加仓管理!$A$2:$A$1001=A105)*(加仓管理!$G$2:$G$1001>0)),加仓管理!$D$2:$D$1001),"")) | AN105: =IF(AK105=0,"",IFERROR(LOOKUP(2,1/((加仓管理!$A$2:$A$1001=A105)*(加仓管理!$G$2:$G$1001>0)),加仓管理!$E$2:$E$1001),"")) | AO105: =IF(OR(A105="",H105="",H105<=0),"",(E105*H105+SUMIFS(加仓管理!$H$2:$H$1001,加仓管理!$A$2:$A$1001,A105))/AP105) | AP105: =IF(OR(A105="",H105="",H105<=0),"",H105+AL105) | AQ105: =IF(A105="","",IF(M105<>"",0,IF(OR(H105="",N105=""),"",MAX((E105*H105+SUMIFS(加仓管理!$H$2:$H$1001,加仓管理!$A$2:$A$1001,A105))-MAX(N105,AN105)*AP105,0)))) | AR105: =IF(A105="","",IF(OR(E105="",H105=""),"违规：首次买入价格或股数缺失",IF(COUNTIFS(加仓管理!$A$2:$A$1001,A105,加仓管理!$R$2:$R$1001,"违规*")>0,"违规：请检查加仓管理表",IF(SUM($AQ$2:$AQ$201)>账户数据!$B$7,"预警：超过账户风险上限",IF(COUNTIFS(加仓管理!$A$2:$A$1001,A105,加仓管理!$N$2:$N$1001,">0",加仓管理!$G$2:$G$1001,"")>0,"提示：存在待执行加仓计划","通过")))))
F106: =IF(OR(C106="",D106="",E106="",N106="",C106<=0,D106<=0,E106<=N106),"",ROUNDDOWN((C106*D106)/(E106-N106)/100,0)*100) | G106: =IF(A106="","",IF(H106<>"","已开仓",IF(账户数据!$B$23="已锁仓","禁止开仓：连续亏损达到上限",IF(账户数据!$B$23="解锁信息不完整","禁止开仓：请完整填写解锁信息",IF(OR(F106="",E106="",N106="",E106<=N106,账户数据!$B$7=""),"",IF(OR(AG106="",AH106="",AI106=""),"禁止开仓：交易预期未填写完整",IF(账户数据!$B$9+F106*(E106-N106)>=账户数据!$B$7,"禁止开仓：风险额度不足",IF(AJ106="周期与交易预期不匹配，请重新确认",IF(账户数据!$B$23="接近锁仓","允许开仓（接近锁仓；周期需复核）","允许开仓（周期需复核）"),IF(账户数据!$B$23="接近锁仓","允许开仓（接近锁仓）","允许开仓"))))))))) | L106: =IF(AP106="","",AP106) | U106: =IF(OR(AO106="",J106="",AO106<=0),"",(J106-AO106)/AO106) | V106: =IF(OR(AO106="",N106="",AO106<=0),"",(AO106-N106)/AO106) | W106: =IF(OR(U106="",V106="",V106<=0),"",U106/V106) | X106: =IF(OR(K106="",L106="",AO106="",AP106=""),"",(K106-AO106)*L106-IF(O106="",0,O106)-IF(P106="",0,P106)) | Y106: =IF(OR(X106="",AO106="",L106=""),"",IF(AO106*L106+IF(O106="",0,O106)<=0,"",X106/(AO106*L106+IF(O106="",0,O106)))) | Z106: =IF(OR(AE106="",多次统计数据!$B$8=""),"",AE106-多次统计数据!$B$8) | AA106: =IF(OR(I106="",M106="",M106<I106),"",M106-I106) | AB106: =IF(OR(A106="",多次统计数据!$B$8="",多次统计数据!$B$6<=0,多次统计数据!$B$6>=1),"",1-POWER(1+多次统计数据!$B$8,-多次统计数据!$B$6/(1-多次统计数据!$B$6))) | AC106: =IF(OR(AB106="",多次统计数据!$B$9=""),"",IF(多次统计数据!$B$9<AB106,"低于上限","达到或超过上限")) | AE106: =IF(OR(X106="",C106="",C106<=0),"",X106/C106) | AJ106: =IF(OR(AG106="",AH106=""),"",IF(OR(AND(AG106="短期博反弹",OR(AH106="1～3个交易日",AH106="4～10个交易日")),AND(AG106="突破冲新高",OR(AH106="4～10个交易日",AH106="11～20个交易日")),AND(AG106="趋势波段",OR(AH106="11～20个交易日",AH106="21～60个交易日",AH106="60个交易日以上"))),"匹配","周期与交易预期不匹配，请重新确认")) | AK106: =IF(A106="","",COUNTIFS(加仓管理!$A$2:$A$1001,A106,加仓管理!$G$2:$G$1001,">0")) | AL106: =IF(A106="","",SUMIFS(加仓管理!$G$2:$G$1001,加仓管理!$A$2:$A$1001,A106)) | AM106: =IF(AK106=0,"",IFERROR(LOOKUP(2,1/((加仓管理!$A$2:$A$1001=A106)*(加仓管理!$G$2:$G$1001>0)),加仓管理!$D$2:$D$1001),"")) | AN106: =IF(AK106=0,"",IFERROR(LOOKUP(2,1/((加仓管理!$A$2:$A$1001=A106)*(加仓管理!$G$2:$G$1001>0)),加仓管理!$E$2:$E$1001),"")) | AO106: =IF(OR(A106="",H106="",H106<=0),"",(E106*H106+SUMIFS(加仓管理!$H$2:$H$1001,加仓管理!$A$2:$A$1001,A106))/AP106) | AP106: =IF(OR(A106="",H106="",H106<=0),"",H106+AL106) | AQ106: =IF(A106="","",IF(M106<>"",0,IF(OR(H106="",N106=""),"",MAX((E106*H106+SUMIFS(加仓管理!$H$2:$H$1001,加仓管理!$A$2:$A$1001,A106))-MAX(N106,AN106)*AP106,0)))) | AR106: =IF(A106="","",IF(OR(E106="",H106=""),"违规：首次买入价格或股数缺失",IF(COUNTIFS(加仓管理!$A$2:$A$1001,A106,加仓管理!$R$2:$R$1001,"违规*")>0,"违规：请检查加仓管理表",IF(SUM($AQ$2:$AQ$201)>账户数据!$B$7,"预警：超过账户风险上限",IF(COUNTIFS(加仓管理!$A$2:$A$1001,A106,加仓管理!$N$2:$N$1001,">0",加仓管理!$G$2:$G$1001,"")>0,"提示：存在待执行加仓计划","通过")))))
F107: =IF(OR(C107="",D107="",E107="",N107="",C107<=0,D107<=0,E107<=N107),"",ROUNDDOWN((C107*D107)/(E107-N107)/100,0)*100) | G107: =IF(A107="","",IF(H107<>"","已开仓",IF(账户数据!$B$23="已锁仓","禁止开仓：连续亏损达到上限",IF(账户数据!$B$23="解锁信息不完整","禁止开仓：请完整填写解锁信息",IF(OR(F107="",E107="",N107="",E107<=N107,账户数据!$B$7=""),"",IF(OR(AG107="",AH107="",AI107=""),"禁止开仓：交易预期未填写完整",IF(账户数据!$B$9+F107*(E107-N107)>=账户数据!$B$7,"禁止开仓：风险额度不足",IF(AJ107="周期与交易预期不匹配，请重新确认",IF(账户数据!$B$23="接近锁仓","允许开仓（接近锁仓；周期需复核）","允许开仓（周期需复核）"),IF(账户数据!$B$23="接近锁仓","允许开仓（接近锁仓）","允许开仓"))))))))) | L107: =IF(AP107="","",AP107) | U107: =IF(OR(AO107="",J107="",AO107<=0),"",(J107-AO107)/AO107) | V107: =IF(OR(AO107="",N107="",AO107<=0),"",(AO107-N107)/AO107) | W107: =IF(OR(U107="",V107="",V107<=0),"",U107/V107) | X107: =IF(OR(K107="",L107="",AO107="",AP107=""),"",(K107-AO107)*L107-IF(O107="",0,O107)-IF(P107="",0,P107)) | Y107: =IF(OR(X107="",AO107="",L107=""),"",IF(AO107*L107+IF(O107="",0,O107)<=0,"",X107/(AO107*L107+IF(O107="",0,O107)))) | Z107: =IF(OR(AE107="",多次统计数据!$B$8=""),"",AE107-多次统计数据!$B$8) | AA107: =IF(OR(I107="",M107="",M107<I107),"",M107-I107) | AB107: =IF(OR(A107="",多次统计数据!$B$8="",多次统计数据!$B$6<=0,多次统计数据!$B$6>=1),"",1-POWER(1+多次统计数据!$B$8,-多次统计数据!$B$6/(1-多次统计数据!$B$6))) | AC107: =IF(OR(AB107="",多次统计数据!$B$9=""),"",IF(多次统计数据!$B$9<AB107,"低于上限","达到或超过上限")) | AE107: =IF(OR(X107="",C107="",C107<=0),"",X107/C107) | AJ107: =IF(OR(AG107="",AH107=""),"",IF(OR(AND(AG107="短期博反弹",OR(AH107="1～3个交易日",AH107="4～10个交易日")),AND(AG107="突破冲新高",OR(AH107="4～10个交易日",AH107="11～20个交易日")),AND(AG107="趋势波段",OR(AH107="11～20个交易日",AH107="21～60个交易日",AH107="60个交易日以上"))),"匹配","周期与交易预期不匹配，请重新确认")) | AK107: =IF(A107="","",COUNTIFS(加仓管理!$A$2:$A$1001,A107,加仓管理!$G$2:$G$1001,">0")) | AL107: =IF(A107="","",SUMIFS(加仓管理!$G$2:$G$1001,加仓管理!$A$2:$A$1001,A107)) | AM107: =IF(AK107=0,"",IFERROR(LOOKUP(2,1/((加仓管理!$A$2:$A$1001=A107)*(加仓管理!$G$2:$G$1001>0)),加仓管理!$D$2:$D$1001),"")) | AN107: =IF(AK107=0,"",IFERROR(LOOKUP(2,1/((加仓管理!$A$2:$A$1001=A107)*(加仓管理!$G$2:$G$1001>0)),加仓管理!$E$2:$E$1001),"")) | AO107: =IF(OR(A107="",H107="",H107<=0),"",(E107*H107+SUMIFS(加仓管理!$H$2:$H$1001,加仓管理!$A$2:$A$1001,A107))/AP107) | AP107: =IF(OR(A107="",H107="",H107<=0),"",H107+AL107) | AQ107: =IF(A107="","",IF(M107<>"",0,IF(OR(H107="",N107=""),"",MAX((E107*H107+SUMIFS(加仓管理!$H$2:$H$1001,加仓管理!$A$2:$A$1001,A107))-MAX(N107,AN107)*AP107,0)))) | AR107: =IF(A107="","",IF(OR(E107="",H107=""),"违规：首次买入价格或股数缺失",IF(COUNTIFS(加仓管理!$A$2:$A$1001,A107,加仓管理!$R$2:$R$1001,"违规*")>0,"违规：请检查加仓管理表",IF(SUM($AQ$2:$AQ$201)>账户数据!$B$7,"预警：超过账户风险上限",IF(COUNTIFS(加仓管理!$A$2:$A$1001,A107,加仓管理!$N$2:$N$1001,">0",加仓管理!$G$2:$G$1001,"")>0,"提示：存在待执行加仓计划","通过")))))
F108: =IF(OR(C108="",D108="",E108="",N108="",C108<=0,D108<=0,E108<=N108),"",ROUNDDOWN((C108*D108)/(E108-N108)/100,0)*100) | G108: =IF(A108="","",IF(H108<>"","已开仓",IF(账户数据!$B$23="已锁仓","禁止开仓：连续亏损达到上限",IF(账户数据!$B$23="解锁信息不完整","禁止开仓：请完整填写解锁信息",IF(OR(F108="",E108="",N108="",E108<=N108,账户数据!$B$7=""),"",IF(OR(AG108="",AH108="",AI108=""),"禁止开仓：交易预期未填写完整",IF(账户数据!$B$9+F108*(E108-N108)>=账户数据!$B$7,"禁止开仓：风险额度不足",IF(AJ108="周期与交易预期不匹配，请重新确认",IF(账户数据!$B$23="接近锁仓","允许开仓（接近锁仓；周期需复核）","允许开仓（周期需复核）"),IF(账户数据!$B$23="接近锁仓","允许开仓（接近锁仓）","允许开仓"))))))))) | L108: =IF(AP108="","",AP108) | U108: =IF(OR(AO108="",J108="",AO108<=0),"",(J108-AO108)/AO108) | V108: =IF(OR(AO108="",N108="",AO108<=0),"",(AO108-N108)/AO108) | W108: =IF(OR(U108="",V108="",V108<=0),"",U108/V108) | X108: =IF(OR(K108="",L108="",AO108="",AP108=""),"",(K108-AO108)*L108-IF(O108="",0,O108)-IF(P108="",0,P108)) | Y108: =IF(OR(X108="",AO108="",L108=""),"",IF(AO108*L108+IF(O108="",0,O108)<=0,"",X108/(AO108*L108+IF(O108="",0,O108)))) | Z108: =IF(OR(AE108="",多次统计数据!$B$8=""),"",AE108-多次统计数据!$B$8) | AA108: =IF(OR(I108="",M108="",M108<I108),"",M108-I108) | AB108: =IF(OR(A108="",多次统计数据!$B$8="",多次统计数据!$B$6<=0,多次统计数据!$B$6>=1),"",1-POWER(1+多次统计数据!$B$8,-多次统计数据!$B$6/(1-多次统计数据!$B$6))) | AC108: =IF(OR(AB108="",多次统计数据!$B$9=""),"",IF(多次统计数据!$B$9<AB108,"低于上限","达到或超过上限")) | AE108: =IF(OR(X108="",C108="",C108<=0),"",X108/C108) | AJ108: =IF(OR(AG108="",AH108=""),"",IF(OR(AND(AG108="短期博反弹",OR(AH108="1～3个交易日",AH108="4～10个交易日")),AND(AG108="突破冲新高",OR(AH108="4～10个交易日",AH108="11～20个交易日")),AND(AG108="趋势波段",OR(AH108="11～20个交易日",AH108="21～60个交易日",AH108="60个交易日以上"))),"匹配","周期与交易预期不匹配，请重新确认")) | AK108: =IF(A108="","",COUNTIFS(加仓管理!$A$2:$A$1001,A108,加仓管理!$G$2:$G$1001,">0")) | AL108: =IF(A108="","",SUMIFS(加仓管理!$G$2:$G$1001,加仓管理!$A$2:$A$1001,A108)) | AM108: =IF(AK108=0,"",IFERROR(LOOKUP(2,1/((加仓管理!$A$2:$A$1001=A108)*(加仓管理!$G$2:$G$1001>0)),加仓管理!$D$2:$D$1001),"")) | AN108: =IF(AK108=0,"",IFERROR(LOOKUP(2,1/((加仓管理!$A$2:$A$1001=A108)*(加仓管理!$G$2:$G$1001>0)),加仓管理!$E$2:$E$1001),"")) | AO108: =IF(OR(A108="",H108="",H108<=0),"",(E108*H108+SUMIFS(加仓管理!$H$2:$H$1001,加仓管理!$A$2:$A$1001,A108))/AP108) | AP108: =IF(OR(A108="",H108="",H108<=0),"",H108+AL108) | AQ108: =IF(A108="","",IF(M108<>"",0,IF(OR(H108="",N108=""),"",MAX((E108*H108+SUMIFS(加仓管理!$H$2:$H$1001,加仓管理!$A$2:$A$1001,A108))-MAX(N108,AN108)*AP108,0)))) | AR108: =IF(A108="","",IF(OR(E108="",H108=""),"违规：首次买入价格或股数缺失",IF(COUNTIFS(加仓管理!$A$2:$A$1001,A108,加仓管理!$R$2:$R$1001,"违规*")>0,"违规：请检查加仓管理表",IF(SUM($AQ$2:$AQ$201)>账户数据!$B$7,"预警：超过账户风险上限",IF(COUNTIFS(加仓管理!$A$2:$A$1001,A108,加仓管理!$N$2:$N$1001,">0",加仓管理!$G$2:$G$1001,"")>0,"提示：存在待执行加仓计划","通过")))))
F109: =IF(OR(C109="",D109="",E109="",N109="",C109<=0,D109<=0,E109<=N109),"",ROUNDDOWN((C109*D109)/(E109-N109)/100,0)*100) | G109: =IF(A109="","",IF(H109<>"","已开仓",IF(账户数据!$B$23="已锁仓","禁止开仓：连续亏损达到上限",IF(账户数据!$B$23="解锁信息不完整","禁止开仓：请完整填写解锁信息",IF(OR(F109="",E109="",N109="",E109<=N109,账户数据!$B$7=""),"",IF(OR(AG109="",AH109="",AI109=""),"禁止开仓：交易预期未填写完整",IF(账户数据!$B$9+F109*(E109-N109)>=账户数据!$B$7,"禁止开仓：风险额度不足",IF(AJ109="周期与交易预期不匹配，请重新确认",IF(账户数据!$B$23="接近锁仓","允许开仓（接近锁仓；周期需复核）","允许开仓（周期需复核）"),IF(账户数据!$B$23="接近锁仓","允许开仓（接近锁仓）","允许开仓"))))))))) | L109: =IF(AP109="","",AP109) | U109: =IF(OR(AO109="",J109="",AO109<=0),"",(J109-AO109)/AO109) | V109: =IF(OR(AO109="",N109="",AO109<=0),"",(AO109-N109)/AO109) | W109: =IF(OR(U109="",V109="",V109<=0),"",U109/V109) | X109: =IF(OR(K109="",L109="",AO109="",AP109=""),"",(K109-AO109)*L109-IF(O109="",0,O109)-IF(P109="",0,P109)) | Y109: =IF(OR(X109="",AO109="",L109=""),"",IF(AO109*L109+IF(O109="",0,O109)<=0,"",X109/(AO109*L109+IF(O109="",0,O109)))) | Z109: =IF(OR(AE109="",多次统计数据!$B$8=""),"",AE109-多次统计数据!$B$8) | AA109: =IF(OR(I109="",M109="",M109<I109),"",M109-I109) | AB109: =IF(OR(A109="",多次统计数据!$B$8="",多次统计数据!$B$6<=0,多次统计数据!$B$6>=1),"",1-POWER(1+多次统计数据!$B$8,-多次统计数据!$B$6/(1-多次统计数据!$B$6))) | AC109: =IF(OR(AB109="",多次统计数据!$B$9=""),"",IF(多次统计数据!$B$9<AB109,"低于上限","达到或超过上限")) | AE109: =IF(OR(X109="",C109="",C109<=0),"",X109/C109) | AJ109: =IF(OR(AG109="",AH109=""),"",IF(OR(AND(AG109="短期博反弹",OR(AH109="1～3个交易日",AH109="4～10个交易日")),AND(AG109="突破冲新高",OR(AH109="4～10个交易日",AH109="11～20个交易日")),AND(AG109="趋势波段",OR(AH109="11～20个交易日",AH109="21～60个交易日",AH109="60个交易日以上"))),"匹配","周期与交易预期不匹配，请重新确认")) | AK109: =IF(A109="","",COUNTIFS(加仓管理!$A$2:$A$1001,A109,加仓管理!$G$2:$G$1001,">0")) | AL109: =IF(A109="","",SUMIFS(加仓管理!$G$2:$G$1001,加仓管理!$A$2:$A$1001,A109)) | AM109: =IF(AK109=0,"",IFERROR(LOOKUP(2,1/((加仓管理!$A$2:$A$1001=A109)*(加仓管理!$G$2:$G$1001>0)),加仓管理!$D$2:$D$1001),"")) | AN109: =IF(AK109=0,"",IFERROR(LOOKUP(2,1/((加仓管理!$A$2:$A$1001=A109)*(加仓管理!$G$2:$G$1001>0)),加仓管理!$E$2:$E$1001),"")) | AO109: =IF(OR(A109="",H109="",H109<=0),"",(E109*H109+SUMIFS(加仓管理!$H$2:$H$1001,加仓管理!$A$2:$A$1001,A109))/AP109) | AP109: =IF(OR(A109="",H109="",H109<=0),"",H109+AL109) | AQ109: =IF(A109="","",IF(M109<>"",0,IF(OR(H109="",N109=""),"",MAX((E109*H109+SUMIFS(加仓管理!$H$2:$H$1001,加仓管理!$A$2:$A$1001,A109))-MAX(N109,AN109)*AP109,0)))) | AR109: =IF(A109="","",IF(OR(E109="",H109=""),"违规：首次买入价格或股数缺失",IF(COUNTIFS(加仓管理!$A$2:$A$1001,A109,加仓管理!$R$2:$R$1001,"违规*")>0,"违规：请检查加仓管理表",IF(SUM($AQ$2:$AQ$201)>账户数据!$B$7,"预警：超过账户风险上限",IF(COUNTIFS(加仓管理!$A$2:$A$1001,A109,加仓管理!$N$2:$N$1001,">0",加仓管理!$G$2:$G$1001,"")>0,"提示：存在待执行加仓计划","通过")))))
