Workbook
Name _AccountRiskLimit: 账户数据!$B$7
Name _LockStatus: 账户数据!$B$23
Name _TradeIds: 单次交易!$A$2:$A$201

Sheet 单次交易
A1: 交易编号 | B1: 股票代码 | C1: 买入时账户金额 | D1: 本次允许亏损比例 | E1: 第一批买入价 | F1: 买入建议股数 | G1: 开仓风险告警 | H1: 第一批买入股数 | I1: 首次买入日期 | J1: 期望卖出价 | K1: 实际卖出价（填写） | L1: 最终卖出股数（自动） | M1: 卖出日期（填写） | N1: 止损价 | O1: 买入总费用 | P1: 卖出费用（填写） | Q1: 买入价的由来 | R1: 止损价的由来 | S1: 期望卖出价的由来 | T1: 实际卖出价的由来 | U1: 期望盈利比例 | V1: 期望止损比例 | W1: 盈亏比 | X1: 加权后实际盈亏 | Y1: 单笔仓位收益率 | Z1: 账户收益率与平均盈利率差值 | AA1: 持有天数 | AB1: 复利容许平均亏损上限 | AC1: 复利风险判断 | AD1: 交易打分评价 | AE1: 实际账户收益率 | AF1: 列1 | AG1: 交易预期类型 | AH1: 预期持有周期 | AI1: 预期选择理由 | AJ1: 周期匹配检查 | AK1: 已执行加仓次数 | AL1: 加仓总股数 | AM1: 最近加仓价 | AN1: 最新加仓止损价 | AO1: 实际加权买入价 | AP1: 最终持仓股数 | AQ1: 当前净止损风险 | AR1: 加仓规则检查
A2: 1 | B2: 中国卫通 | C2: 100000 | D2: 0.02 | E2: 20.87 | F2: =IF(OR(C2="",D2="",E2="",N2="",C2<=0,D2<=0,E2<=N2),"",ROUNDDOWN((C2*D2)/(E2-N2)/100,0)*100) -> 1100 | G2: =IF(A2="","",IF(H2<>"","已开仓",IF(账户数据!$B$23="已锁仓","禁止开仓：连续亏损达到上限",IF(账户数据!$B$23="解锁信息不完整","禁止开仓：请完整填写解锁信息",IF(OR(F2="",E2="",N2="",E2<=N2,账户数据!$B$7=""),"",IF(OR(AG2="",AH2="",AI2=""),"禁止开仓：交易预期未填写完整",IF(账户数据!$B$9+F2*(E2-N2)>=账户数据!$B$7,"禁止开仓：风险额度不足",IF(AJ2="周期与交易预期不匹配，请重新确认",IF(账户数据!$B$23="接近锁仓","允许开仓（接近锁仓；周期需复核）","允许开仓（周期需复核）"),IF(账户数据!$B$23="接近锁仓","允许开仓（接近锁仓）","允许开仓"))))))))) -> 已开仓 | H2: 1100 | I2: 44020 | J2: 24 | K2: 21.57 | L2: =IF(AP2="","",AP2) -> 2600 | M2: 44036 | N2: 19.17 | U2: =IF(OR(AO2="",J2="",AO2<=0),"",(J2-AO2)/AO2) -> 0.088872215 | V2: =IF(OR(AO2="",N2="",AO2<=0),"",(AO2-N2)/AO2) -> 0.13026332 | W2: =IF(OR(U2="",V2="",V2<=0),"",U2/V2) -> 0.6822505 | X2: =IF(OR(K2="",L2="",AO2="",AP2=""),"",(K2-AO2)*L2-IF(O2="",0,O2)-IF(P2="",0,P2)) -> -1225 | Y2: =IF(OR(X2="",AO2="",L2=""),"",IF(AO2*L2+IF(O2="",0,O2)<=0,"",X2/(AO2*L2+IF(O2="",0,O2)))) -> -0.021376097 | Z2: =IF(OR(AE2="",多次统计数据!$B$8=""),"",AE2-多次统计数据!$B$8) -> -0.12246267 | AA2: =IF(OR(I2="",M2="",M2<I2),"",M2-I2) -> 16 | AB2: =IF(OR(A2="",多次统计数据!$B$8="",多次统计数据!$B$6<=0,多次统计数据!$B$6>=1),"",1-POWER(1+多次统计数据!$B$8,-多次统计数据!$B$6/(1-多次统计数据!$B$6))) -> 0.081520133 | AC2: =IF(OR(AB2="",多次统计数据!$B$9=""),"",IF(多次统计数据!$B$9<AB2,"低于上限","达到或超过上限")) -> 低于上限 | AE2: =IF(OR(X2="",C2="",C2<=0),"",X2/C2) -> -0.01225 | AG2: 突破冲新高 | AH2: 4～10个交易日 | AI2: 新高 | AJ2: =IF(OR(AG2="",AH2=""),"",IF(OR(AND(AG2="短期博反弹",OR(AH2="1～3个交易日",AH2="4～10个交易日")),AND(AG2="突破冲新高",OR(AH2="4～10个交易日",AH2="11～20个交易日")),AND(AG2="趋势波段",OR(AH2="11～20个交易日",AH2="21～60个交易日",AH2="60个交易日以上"))),"匹配","周期与交易预期不匹配，请重新确认")) -> 匹配 | AK2: =IF(A2="","",COUNTIFS(加仓管理!$A$2:$A$1001,A2,加仓管理!$G$2:$G$1001,">0")) -> 2 | AL2: =IF(A2="","",SUMIFS(加仓管理!$G$2:$G$1001,加仓管理!$A$2:$A$1001,A2)) -> 1500 | AM2: =IF(AK2=0,"",IFERROR(LOOKUP(2,1/((加仓管理!$A$2:$A$1001=A2)*(加仓管理!$G$2:$G$1001>0)),加仓管理!$D$2:$D$1001),"")) -> 24 | AN2: =IF(AK2=0,"",IFERROR(LOOKUP(2,1/((加仓管理!$A$2:$A$1001=A2)*(加仓管理!$G$2:$G$1001>0)),加仓管理!$E$2:$E$1001),"")) -> 22 | AO2: =IF(OR(A2="",H2="",H2<=0),"",(E2*H2+SUMIFS(加仓管理!$H$2:$H$1001,加仓管理!$A$2:$A$1001,A2))/AP2) -> 22.041154 | AP2: =IF(OR(A2="",H2="",H2<=0),"",H2+AL2) -> 2600 | AQ2: =IF(A2="","",IF(M2<>"",0,IF(OR(H2="",N2=""),"",MAX((E2*H2+SUMIFS(加仓管理!$H$2:$H$1001,加仓管理!$A$2:$A$1001,A2))-MAX(N2,AN2)*AP2,0)))) -> 0 | AR2: =IF(A2="","",IF(OR(E2="",H2=""),"违规：首次买入价格或股数缺失",IF(COUNTIFS(加仓管理!$A$2:$A$1001,A2,加仓管理!$R$2:$R$1001,"违规*")>0,"违规：请检查加仓管理表",IF(SUM($AQ$2:$AQ$201)>账户数据!$B$7,"预警：超过账户风险上限",IF(COUNTIFS(加仓管理!$A$2:$A$1001,A2,加仓管理!$N$2:$N$1001,">0",加仓管理!$G$2:$G$1001,"")>0,"提示：存在待执行加仓计划","通过"))))) -> 违规：请检查加仓管理表
A3: 2 | B3: 中国卫通 | C3: 98775 | D3: 0.02 | E3: 17.88 | F3: =IF(OR(C3="",D3="",E3="",N3="",C3<=0,D3<=0,E3<=N3),"",ROUNDDOWN((C3*D3)/(E3-N3)/100,0)*100) -> 1400 | G3: =IF(A3="","",IF(H3<>"","已开仓",IF(账户数据!$B$23="已锁仓","禁止开仓：连续亏损达到上限",IF(账户数据!$B$23="解锁信息不完整","禁止开仓：请完整填写解锁信息",IF(OR(F3="",E3="",N3="",E3<=N3,账户数据!$B$7=""),"",IF(OR(AG3="",AH3="",AI3=""),"禁止开仓：交易预期未填写完整",IF(账户数据!$B$9+F3*(E3-N3)>=账户数据!$B$7,"禁止开仓：风险额度不足",IF(AJ3="周期与交易预期不匹配，请重新确认",IF(账户数据!$B$23="接近锁仓","允许开仓（接近锁仓；周期需复核）","允许开仓（周期需复核）"),IF(账户数据!$B$23="接近锁仓","允许开仓（接近锁仓）","允许开仓"))))))))) -> 已开仓 | H3: 1000 | I3: 44176 | J3: 20 | K3: 15.56 | L3: =IF(AP3="","",AP3) -> 3000 | M3: 44235 | N3: 16.5 | U3: =IF(OR(AO3="",J3="",AO3<=0),"",(J3-AO3)/AO3) -> 0.1082379 | V3: =IF(OR(AO3="",N3="",AO3<=0),"",(AO3-N3)/AO3) -> 0.085703731 | W3: =IF(OR(U3="",V3="",V3<=0),"",U3/V3) -> 1.262931 | X3: =IF(OR(K3="",L3="",AO3="",AP3=""),"",(K3-AO3)*L3-IF(O3="",0,O3)-IF(P3="",0,P3)) -> -7460 | Y3: =IF(OR(X3="",AO3="",L3=""),"",IF(AO3*L3+IF(O3="",0,O3)<=0,"",X3/(AO3*L3+IF(O3="",0,O3)))) -> -0.13779091 | Z3: =IF(OR(AE3="",多次统计数据!$B$8=""),"",AE3-多次统计数据!$B$8) -> -0.18573785 | AA3: =IF(OR(I3="",M3="",M3<I3),"",M3-I3) -> 59 | AB3: =IF(OR(A3="",多次统计数据!$B$8="",多次统计数据!$B$6<=0,多次统计数据!$B$6>=1),"",1-POWER(1+多次统计数据!$B$8,-多次统计数据!$B$6/(1-多次统计数据!$B$6))) -> 0.081520133 | AC3: =IF(OR(AB3="",多次统计数据!$B$9=""),"",IF(多次统计数据!$B$9<AB3,"低于上限","达到或超过上限")) -> 低于上限 | AE3: =IF(OR(X3="",C3="",C3<=0),"",X3/C3) -> -0.075525183 | AG3: 短期博反弹 | AH3: 4～10个交易日 | AI3: 吸筹 | AJ3: =IF(OR(AG3="",AH3=""),"",IF(OR(AND(AG3="短期博反弹",OR(AH3="1～3个交易日",AH3="4～10个交易日")),AND(AG3="突破冲新高",OR(AH3="4～10个交易日",AH3="11～20个交易日")),AND(AG3="趋势波段",OR(AH3="11～20个交易日",AH3="21～60个交易日",AH3="60个交易日以上"))),"匹配","周期与交易预期不匹配，请重新确认")) -> 匹配 | AK3: =IF(A3="","",COUNTIFS(加仓管理!$A$2:$A$1001,A3,加仓管理!$G$2:$G$1001,">0")) -> 2 | AL3: =IF(A3="","",SUMIFS(加仓管理!$G$2:$G$1001,加仓管理!$A$2:$A$1001,A3)) -> 2000 | AM3: =IF(AK3=0,"",IFERROR(LOOKUP(2,1/((加仓管理!$A$2:$A$1001=A3)*(加仓管理!$G$2:$G$1001>0)),加仓管理!$D$2:$D$1001),"")) -> 17.21 | AN3: =IF(AK3=0,"",IFERROR(LOOKUP(2,1/((加仓管理!$A$2:$A$1001=A3)*(加仓管理!$G$2:$G$1001>0)),加仓管理!$E$2:$E$1001),"")) -> 16.5 | AO3: =IF(OR(A3="",H3="",H3<=0),"",(E3*H3+SUMIFS(加仓管理!$H$2:$H$1001,加仓管理!$A$2:$A$1001,A3))/AP3) -> 18.046667 | AP3: =IF(OR(A3="",H3="",H3<=0),"",H3+AL3) -> 3000 | AQ3: =IF(A3="","",IF(M3<>"",0,IF(OR(H3="",N3=""),"",MAX((E3*H3+SUMIFS(加仓管理!$H$2:$H$1001,加仓管理!$A$2:$A$1001,A3))-MAX(N3,AN3)*AP3,0)))) -> 0 | AR3: =IF(A3="","",IF(OR(E3="",H3=""),"违规：首次买入价格或股数缺失",IF(COUNTIFS(加仓管理!$A$2:$A$1001,A3,加仓管理!$R$2:$R$1001,"违规*")>0,"违规：请检查加仓管理表",IF(SUM($AQ$2:$AQ$201)>账户数据!$B$7,"预警：超过账户风险上限",IF(COUNTIFS(加仓管理!$A$2:$A$1001,A3,加仓管理!$N$2:$N$1001,">0",加仓管理!$G$2:$G$1001,"")>0,"提示：存在待执行加仓计划","通过"))))) -> 违规：请检查加仓管理表
A4: 3 | B4: 中国卫通 | C4: 91315 | D4: 0.02 | E4: 15.12 | F4: =IF(OR(C4="",D4="",E4="",N4="",C4<=0,D4<=0,E4<=N4),"",ROUNDDOWN((C4*D4)/(E4-N4)/100,0)*100) -> 2900 | G4: =IF(A4="","",IF(H4<>"","已开仓",IF(账户数据!$B$23="已锁仓","禁止开仓：连续亏损达到上限",IF(账户数据!$B$23="解锁信息不完整","禁止开仓：请完整填写解锁信息",IF(OR(F4="",E4="",N4="",E4<=N4,账户数据!$B$7=""),"",IF(OR(AG4="",AH4="",AI4=""),"禁止开仓：交易预期未填写完整",IF(账户数据!$B$9+F4*(E4-N4)>=账户数据!$B$7,"禁止开仓：风险额度不足",IF(AJ4="周期与交易预期不匹配，请重新确认",IF(账户数据!$B$23="接近锁仓","允许开仓（接近锁仓；周期需复核）","允许开仓（周期需复核）"),IF(账户数据!$B$23="接近锁仓","允许开仓（接近锁仓）","允许开仓"))))))))) -> 已开仓 | H4: 2900 | I4: 44264 | J4: 18 | K4: 13.94 | L4: =IF(AP4="","",AP4) -> 5700 | M4: 44434 | N4: 14.5 | U4: =IF(OR(AO4="",J4="",AO4<=0),"",(J4-AO4)/AO4) -> 0.13534509 | V4: =IF(OR(AO4="",N4="",AO4<=0),"",(AO4-N4)/AO4) -> 0.085416459 | W4: =IF(OR(U4="",V4="",V4<=0),"",U4/V4) -> 1.5845317 | X4: =IF(OR(K4="",L4="",AO4="",AP4=""),"",(K4-AO4)*L4-IF(O4="",0,O4)-IF(P4="",0,P4)) -> -10911 | Y4: =IF(OR(X4="",AO4="",L4=""),"",IF(AO4*L4+IF(O4="",0,O4)<=0,"",X4/(AO4*L4+IF(O4="",0,O4)))) -> -0.12073831 | Z4: =IF(OR(AE4="",多次统计数据!$B$8=""),"",AE4-多次统计数据!$B$8) -> -0.22970016 | AA4: =IF(OR(I4="",M4="",M4<I4),"",M4-I4) -> 170 | AB4: =IF(OR(A4="",多次统计数据!$B$8="",多次统计数据!$B$6<=0,多次统计数据!$B$6>=1),"",1-POWER(1+多次统计数据!$B$8,-多次统计数据!$B$6/(1-多次统计数据!$B$6))) -> 0.081520133 | AC4: =IF(OR(AB4="",多次统计数据!$B$9=""),"",IF(多次统计数据!$B$9<AB4,"低于上限","达到或超过上限")) -> 低于上限 | AE4: =IF(OR(X4="",C4="",C4<=0),"",X4/C4) -> -0.11948749 | AG4: 短期博反弹 | AH4: 4～10个交易日 | AI4: 吸筹 | AJ4: =IF(OR(AG4="",AH4=""),"",IF(OR(AND(AG4="短期博反弹",OR(AH4="1～3个交易日",AH4="4～10个交易日")),AND(AG4="突破冲新高",OR(AH4="4～10个交易日",AH4="11～20个交易日")),AND(AG4="趋势波段",OR(AH4="11～20个交易日",AH4="21～60个交易日",AH4="60个交易日以上"))),"匹配","周期与交易预期不匹配，请重新确认")) -> 匹配 | AK4: =IF(A4="","",COUNTIFS(加仓管理!$A$2:$A$1001,A4,加仓管理!$G$2:$G$1001,">0")) -> 3 | AL4: =IF(A4="","",SUMIFS(加仓管理!$G$2:$G$1001,加仓管理!$A$2:$A$1001,A4)) -> 2800 | AM4: =IF(AK4=0,"",IFERROR(LOOKUP(2,1/((加仓管理!$A$2:$A$1001=A4)*(加仓管理!$G$2:$G$1001>0)),加仓管理!$D$2:$D$1001),"")) -> 15.42 | AN4: =IF(AK4=0,"",IFERROR(LOOKUP(2,1/((加仓管理!$A$2:$A$1001=A4)*(加仓管理!$G$2:$G$1001>0)),加仓管理!$E$2:$E$1001),"")) -> 14.81 | AO4: =IF(OR(A4="",H4="",H4<=0),"",(E4*H4+SUMIFS(加仓管理!$H$2:$H$1001,加仓管理!$A$2:$A$1001,A4))/AP4) -> 15.854211 | AP4: =IF(OR(A4="",H4="",H4<=0),"",H4+AL4) -> 5700 | AQ4: =IF(A4="","",IF(M4<>"",0,IF(OR(H4="",N4=""),"",MAX((E4*H4+SUMIFS(加仓管理!$H$2:$H$1001,加仓管理!$A$2:$A$1001,A4))-MAX(N4,AN4)*AP4,0)))) -> 0 | AR4: =IF(A4="","",IF(OR(E4="",H4=""),"违规：首次买入价格或股数缺失",IF(COUNTIFS(加仓管理!$A$2:$A$1001,A4,加仓管理!$R$2:$R$1001,"违规*")>0,"违规：请检查加仓管理表",IF(SUM($AQ$2:$AQ$201)>账户数据!$B$7,"预警：超过账户风险上限",IF(COUNTIFS(加仓管理!$A$2:$A$1001,A4,加仓管理!$N$2:$N$1001,">0",加仓管理!$G$2:$G$1001,"")>0,"提示：存在待执行加仓计划","通过"))))) -> 违规：请检查加仓管理表
A5: 4 | B5: 中国卫通 | C5: 80404 | D5: 0.02 | E5: 15.62 | F5: =IF(OR(C5="",D5="",E5="",N5="",C5<=0,D5<=0,E5<=N5),"",ROUNDDOWN((C5*D5)/(E5-N5)/100,0)*100) -> 2500 | G5: =IF(A5="","",IF(H5<>"","已开仓",IF(账户数据!$B$23="已锁仓","禁止开仓：连续亏损达到上限",IF(账户数据!$B$23="解锁信息不完整","禁止开仓：请完整填写解锁信息",IF(OR(F5="",E5="",N5="",E5<=N5,账户数据!$B$7=""),"",IF(OR(AG5="",AH5="",AI5=""),"禁止开仓：交易预期未填写完整",IF(账户数据!$B$9+F5*(E5-N5)>=账户数据!$B$7,"禁止开仓：风险额度不足",IF(AJ5="周期与交易预期不匹配，请重新确认",IF(账户数据!$B$23="接近锁仓","允许开仓（接近锁仓；周期需复核）","允许开仓（周期需复核）"),IF(账户数据!$B$23="接近锁仓","允许开仓（接近锁仓）","允许开仓"))))))))) -> 已开仓 | H5: 2500 | I5: 44799 | J5: 10.59 | K5: 10.59 | L5: =IF(AP5="","",AP5) -> 4900 | M5: 44799 | N5: 15 | U5: =IF(OR(AO5="",J5="",AO5<=0),"",(J5-AO5)/AO5) -> -0.34779166 | V5: =IF(OR(AO5="",N5="",AO5<=0),"",(AO5-N5)/AO5) -> 0.076192152 | W5: =IF(OR(U5="",V5="",V5<=0),"",U5/V5) -> -4.5646651 | X5: =IF(OR(K5="",L5="",AO5="",AP5=""),"",(K5-AO5)*L5-IF(O5="",0,O5)-IF(P5="",0,P5)) -> -27671 | Y5: =IF(OR(X5="",AO5="",L5=""),"",IF(AO5*L5+IF(O5="",0,O5)<=0,"",X5/(AO5*L5+IF(O5="",0,O5)))) -> -0.34779166 | Z5: =IF(OR(AE5="",多次统计数据!$B$8=""),"",AE5-多次统计数据!$B$8) -> -0.45436221 | AA5: =IF(OR(I5="",M5="",M5<I5),"",M5-I5) -> 0 | AB5: =IF(OR(A5="",多次统计数据!$B$8="",多次统计数据!$B$6<=0,多次统计数据!$B$6>=1),"",1-POWER(1+多次统计数据!$B$8,-多次统计数据!$B$6/(1-多次统计数据!$B$6))) -> 0.081520133 | AC5: =IF(OR(AB5="",多次统计数据!$B$9=""),"",IF(多次统计数据!$B$9<AB5,"低于上限","达到或超过上限")) -> 低于上限 | AE5: =IF(OR(X5="",C5="",C5<=0),"",X5/C5) -> -0.34414954 | AG5: 短期博反弹 | AH5: 4～10个交易日 | AI5: 反弹 | AJ5: =IF(OR(AG5="",AH5=""),"",IF(OR(AND(AG5="短期博反弹",OR(AH5="1～3个交易日",AH5="4～10个交易日")),AND(AG5="突破冲新高",OR(AH5="4～10个交易日",AH5="11～20个交易日")),AND(AG5="趋势波段",OR(AH5="11～20个交易日",AH5="21～60个交易日",AH5="60个交易日以上"))),"匹配","周期与交易预期不匹配，请重新确认")) -> 匹配 | AK5: =IF(A5="","",COUNTIFS(加仓管理!$A$2:$A$1001,A5,加仓管理!$G$2:$G$1001,">0")) -> 3 | AL5: =IF(A5="","",SUMIFS(加仓管理!$G$2:$G$1001,加仓管理!$A$2:$A$1001,A5)) -> 2400 | AM5: =IF(AK5=0,"",IFERROR(LOOKUP(2,1/((加仓管理!$A$2:$A$1001=A5)*(加仓管理!$G$2:$G$1001>0)),加仓管理!$D$2:$D$1001),"")) -> 16.08 | AN5: =IF(AK5=0,"",IFERROR(LOOKUP(2,1/((加仓管理!$A$2:$A$1001=A5)*(加仓管理!$G$2:$G$1001>0)),加仓管理!$E$2:$E$1001),"")) -> 16 | AO5: =IF(OR(A5="",H5="",H5<=0),"",(E5*H5+SUMIFS(加仓管理!$H$2:$H$1001,加仓管理!$A$2:$A$1001,A5))/AP5) -> 16.237143 | AP5: =IF(OR(A5="",H5="",H5<=0),"",H5+AL5) -> 4900 | AQ5: =IF(A5="","",IF(M5<>"",0,IF(OR(H5="",N5=""),"",MAX((E5*H5+SUMIFS(加仓管理!$H$2:$H$1001,加仓管理!$A$2:$A$1001,A5))-MAX(N5,AN5)*AP5,0)))) -> 0 | AR5: =IF(A5="","",IF(OR(E5="",H5=""),"违规：首次买入价格或股数缺失",IF(COUNTIFS(加仓管理!$A$2:$A$1001,A5,加仓管理!$R$2:$R$1001,"违规*")>0,"违规：请检查加仓管理表",IF(SUM($AQ$2:$AQ$201)>账户数据!$B$7,"预警：超过账户风险上限",IF(COUNTIFS(加仓管理!$A$2:$A$1001,A5,加仓管理!$N$2:$N$1001,">0",加仓管理!$G$2:$G$1001,"")>0,"提示：存在待执行加仓计划","通过"))))) -> 违规：请检查加仓管理表
A6: 5 | B6: 中国卫通 | C6: 52733 | D6: 0.02 | E6: 10.59 | F6: =IF(OR(C6="",D6="",E6="",N6="",C6<=0,D6<=0,E6<=N6),"",ROUNDDOWN((C6*D6)/(E6-N6)/100,0)*100) -> 1700 | G6: =IF(A6="","",IF(H6<>"","已开仓",IF(账户数据!$B$23="已锁仓","禁止开仓：连续亏损达到上限",IF(账户数据!$B$23="解锁信息不完整","禁止开仓：请完整填写解锁信息",IF(OR(F6="",E6="",N6="",E6<=N6,账户数据!$B$7=""),"",IF(OR(AG6="",AH6="",AI6=""),"禁止开仓：交易预期未填写完整",IF(账户数据!$B$9+F6*(E6-N6)>=账户数据!$B$7,"禁止开仓：风险额度不足",IF(AJ6="周期与交易预期不匹配，请重新确认",IF(账户数据!$B$23="接近锁仓","允许开仓（接近锁仓；周期需复核）","允许开仓（周期需复核）"),IF(账户数据!$B$23="接近锁仓","允许开仓（接近锁仓）","允许开仓"))))))))) -> 已开仓 | H6: 1700 | I6: 44707 | J6: 12 | K6: 11.29 | L6: =IF(AP6="","",AP6) -> 4700 | M6: 44925 | N6: 10 | U6: =IF(OR(AO6="",J6="",AO6<=0),"",(J6-AO6)/AO6) -> 0.09063485 | V6: =IF(OR(AO6="",N6="",AO6<=0),"",(AO6-N6)/AO6) -> 0.091137625 | W6: =IF(OR(U6="",V6="",V6<=0),"",U6/V6) -> 0.99448334 | X6: =IF(OR(K6="",L6="",AO6="",AP6=""),"",(K6-AO6)*L6-IF(O6="",0,O6)-IF(P6="",0,P6)) -> 1350 | Y6: =IF(OR(X6="",AO6="",L6=""),"",IF(AO6*L6+IF(O6="",0,O6)<=0,"",X6/(AO6*L6+IF(O6="",0,O6)))) -> 0.026105621 | Z6: =IF(OR(AE6="",多次统计数据!$B$8=""),"",AE6-多次统计数据!$B$8) -> -0.084612001 | AA6: =IF(OR(I6="",M6="",M6<I6),"",M6-I6) -> 218 | AB6: =IF(OR(A6="",多次统计数据!$B$8="",多次统计数据!$B$6<=0,多次统计数据!$B$6>=1),"",1-POWER(1+多次统计数据!$B$8,-多次统计数据!$B$6/(1-多次统计数据!$B$6))) -> 0.081520133 | AC6: =IF(OR(AB6="",多次统计数据!$B$9=""),"",IF(多次统计数据!$B$9<AB6,"低于上限","达到或超过上限")) -> 低于上限 | AE6: =IF(OR(X6="",C6="",C6<=0),"",X6/C6) -> 0.025600668 | AG6: 趋势波段 | AH6: 11～20个交易日 | AI6: 吸筹 | AJ6: =IF(OR(AG6="",AH6=""),"",IF(OR(AND(AG6="短期博反弹",OR(AH6="1～3个交易日",AH6="4～10个交易日")),AND(AG6="突破冲新高",OR(AH6="4～10个交易日",AH6="11～20个交易日")),AND(AG6="趋势波段",OR(AH6="11～20个交易日",AH6="21～60个交易日",AH6="60个交易日以上"))),"匹配","周期与交易预期不匹配，请重新确认")) -> 匹配 | AK6: =IF(A6="","",COUNTIFS(加仓管理!$A$2:$A$1001,A6,加仓管理!$G$2:$G$1001,">0")) -> 2 | AL6: =IF(A6="","",SUMIFS(加仓管理!$G$2:$G$1001,加仓管理!$A$2:$A$1001,A6)) -> 3000 | AM6: =IF(AK6=0,"",IFERROR(LOOKUP(2,1/((加仓管理!$A$2:$A$1001=A6)*(加仓管理!$G$2:$G$1001>0)),加仓管理!$D$2:$D$1001),"")) -> 10.66 | AN6: =IF(AK6=0,"",IFERROR(LOOKUP(2,1/((加仓管理!$A$2:$A$1001=A6)*(加仓管理!$G$2:$G$1001>0)),加仓管理!$E$2:$E$1001),"")) -> 10 | AO6: =IF(OR(A6="",H6="",H6<=0),"",(E6*H6+SUMIFS(加仓管理!$H$2:$H$1001,加仓管理!$A$2:$A$1001,A6))/AP6) -> 11.002766 | AP6: =IF(OR(A6="",H6="",H6<=0),"",H6+AL6) -> 4700 | AQ6: =IF(A6="","",IF(M6<>"",0,IF(OR(H6="",N6=""),"",MAX((E6*H6+SUMIFS(加仓管理!$H$2:$H$1001,加仓管理!$A$2:$A$1001,A6))-MAX(N6,AN6)*AP6,0)))) -> 0 | AR6: =IF(A6="","",IF(OR(E6="",H6=""),"违规：首次买入价格或股数缺失",IF(COUNTIFS(加仓管理!$A$2:$A$1001,A6,加仓管理!$R$2:$R$1001,"违规*")>0,"违规：请检查加仓管理表",IF(SUM($AQ$2:$AQ$201)>账户数据!$B$7,"预警：超过账户风险上限",IF(COUNTIFS(加仓管理!$A$2:$A$1001,A6,加仓管理!$N$2:$N$1001,">0",加仓管理!$G$2:$G$1001,"")>0,"提示：存在待执行加仓计划","通过"))))) -> 违规：请检查加仓管理表
A7: 6 | B7: 中国卫通 | C7: 54083 | D7: 0.02 | E7: 12.5 | F7: =IF(OR(C7="",D7="",E7="",N7="",C7<=0,D7<=0,E7<=N7),"",ROUNDDOWN((C7*D7)/(E7-N7)/100,0)*100) -> 1000 | G7: =IF(A7="","",IF(H7<>"","已开仓",IF(账户数据!$B$23="已锁仓","禁止开仓：连续亏损达到上限",IF(账户数据!$B$23="解锁信息不完整","禁止开仓：请完整填写解锁信息",IF(OR(F7="",E7="",N7="",E7<=N7,账户数据!$B$7=""),"",IF(OR(AG7="",AH7="",AI7=""),"禁止开仓：交易预期未填写完整",IF(账户数据!$B$9+F7*(E7-N7)>=账户数据!$B$7,"禁止开仓：风险额度不足",IF(AJ7="周期与交易预期不匹配，请重新确认",IF(账户数据!$B$23="接近锁仓","允许开仓（接近锁仓；周期需复核）","允许开仓（周期需复核）"),IF(账户数据!$B$23="接近锁仓","允许开仓（接近锁仓）","允许开仓"))))))))) -> 已开仓 | H7: 1000 | I7: 44943 | J7: 13 | K7: 16.89 | L7: =IF(AP7="","",AP7) -> 3000 | M7: 44988 | N7: 11.5 | U7: =IF(OR(AO7="",J7="",AO7<=0),"",(J7-AO7)/AO7) -> -0.07648591 | V7: =IF(OR(AO7="",N7="",AO7<=0),"",(AO7-N7)/AO7) -> 0.18304523 | W7: =IF(OR(U7="",V7="",V7<=0),"",U7/V7) -> -0.41785252 | X7: =IF(OR(K7="",L7="",AO7="",AP7=""),"",(K7-AO7)*L7-IF(O7="",0,O7)-IF(P7="",0,P7)) -> 8440 | Y7: =IF(OR(X7="",AO7="",L7=""),"",IF(AO7*L7+IF(O7="",0,O7)<=0,"",X7/(AO7*L7+IF(O7="",0,O7)))) -> 0.19985792 | Z7: =IF(OR(AE7="",多次统计数据!$B$8=""),"",AE7-多次统计数据!$B$8) -> 0.045843763 | AA7: =IF(OR(I7="",M7="",M7<I7),"",M7-I7) -> 45 | AB7: =IF(OR(A7="",多次统计数据!$B$8="",多次统计数据!$B$6<=0,多次统计数据!$B$6>=1),"",1-POWER(1+多次统计数据!$B$8,-多次统计数据!$B$6/(1-多次统计数据!$B$6))) -> 0.081520133 | AC7: =IF(OR(AB7="",多次统计数据!$B$9=""),"",IF(多次统计数据!$B$9<AB7,"低于上限","达到或超过上限")) -> 低于上限 | AE7: =IF(OR(X7="",C7="",C7<=0),"",X7/C7) -> 0.15605643 | AG7: 趋势波段 | AH7: 11～20个交易日 | AI7: 吸筹 | AJ7: =IF(OR(AG7="",AH7=""),"",IF(OR(AND(AG7="短期博反弹",OR(AH7="1～3个交易日",AH7="4～10个交易日")),AND(AG7="突破冲新高",OR(AH7="4～10个交易日",AH7="11～20个交易日")),AND(AG7="趋势波段",OR(AH7="11～20个交易日",AH7="21～60个交易日",AH7="60个交易日以上"))),"匹配","周期与交易预期不匹配，请重新确认")) -> 匹配 | AK7: =IF(A7="","",COUNTIFS(加仓管理!$A$2:$A$1001,A7,加仓管理!$G$2:$G$1001,">0")) -> 2 | AL7: =IF(A7="","",SUMIFS(加仓管理!$G$2:$G$1001,加仓管理!$A$2:$A$1001,A7)) -> 2000 | AM7: =IF(AK7=0,"",IFERROR(LOOKUP(2,1/((加仓管理!$A$2:$A$1001=A7)*(加仓管理!$G$2:$G$1001>0)),加仓管理!$D$2:$D$1001),"")) -> 15.71 | AN7: =IF(AK7=0,"",IFERROR(LOOKUP(2,1/((加仓管理!$A$2:$A$1001=A7)*(加仓管理!$G$2:$G$1001>0)),加仓管理!$E$2:$E$1001),"")) -> 14.02 | AO7: =IF(OR(A7="",H7="",H7<=0),"",(E7*H7+SUMIFS(加仓管理!$H$2:$H$1001,加仓管理!$A$2:$A$1001,A7))/AP7) -> 14.076667 | AP7: =IF(OR(A7="",H7="",H7<=0),"",H7+AL7) -> 3000 | AQ7: =IF(A7="","",IF(M7<>"",0,IF(OR(H7="",N7=""),"",MAX((E7*H7+SUMIFS(加仓管理!$H$2:$H$1001,加仓管理!$A$2:$A$1001,A7))-MAX(N7,AN7)*AP7,0)))) -> 0 | AR7: =IF(A7="","",IF(OR(E7="",H7=""),"违规：首次买入价格或股数缺失",IF(COUNTIFS(加仓管理!$A$2:$A$1001,A7,加仓管理!$R$2:$R$1001,"违规*")>0,"违规：请检查加仓管理表",IF(SUM($AQ$2:$AQ$201)>账户数据!$B$7,"预警：超过账户风险上限",IF(COUNTIFS(加仓管理!$A$2:$A$1001,A7,加仓管理!$N$2:$N$1001,">0",加仓管理!$G$2:$G$1001,"")>0,"提示：存在待执行加仓计划","通过"))))) -> 违规：请检查加仓管理表
A8: 7 | B8: 中国卫通 | C8: 62523 | D8: 0.02 | E8: 18.63 | F8: =IF(OR(C8="",D8="",E8="",N8="",C8<=0,D8<=0,E8<=N8),"",ROUNDDOWN((C8*D8)/(E8-N8)/100,0)*100) -> 1100 | G8: =IF(A8="","",IF(H8<>"","已开仓",IF(账户数据!$B$23="已锁仓","禁止开仓：连续亏损达到上限",IF(账户数据!$B$23="解锁信息不完整","禁止开仓：请完整填写解锁信息",IF(OR(F8="",E8="",N8="",E8<=N8,账户数据!$B$7=""),"",IF(OR(AG8="",AH8="",AI8=""),"禁止开仓：交易预期未填写完整",IF(账户数据!$B$9+F8*(E8-N8)>=账户数据!$B$7,"禁止开仓：风险额度不足",IF(AJ8="周期与交易预期不匹配，请重新确认",IF(账户数据!$B$23="接近锁仓","允许开仓（接近锁仓；周期需复核）","允许开仓（周期需复核）"),IF(账户数据!$B$23="接近锁仓","允许开仓（接近锁仓）","允许开仓"))))))))) -> 已开仓 | H8: 1100 | I8: 45041 | J8: 20 | K8: 17.74 | L8: =IF(AP8="","",AP8) -> 1100 | M8: 45044 | N8: 17.5 | U8: =IF(OR(AO8="",J8="",AO8<=0),"",(J8-AO8)/AO8) -> 0.073537305 | V8: =IF(OR(AO8="",N8="",AO8<=0),"",(AO8-N8)/AO8) -> 0.060654858 | W8: =IF(OR(U8="",V8="",V8<=0),"",U8/V8) -> 1.2123894 | X8: =IF(OR(K8="",L8="",AO8="",AP8=""),"",(K8-AO8)*L8-IF(O8="",0,O8)-IF(P8="",0,P8)) -> -979 | Y8: =IF(OR(X8="",AO8="",L8=""),"",IF(AO8*L8+IF(O8="",0,O8)<=0,"",X8/(AO8*L8+IF(O8="",0,O8)))) -> -0.04777241 | Z8: =IF(OR(AE8="",多次统计数据!$B$8=""),"",AE8-多次统计数据!$B$8) -> -0.12587091 | AA8: =IF(OR(I8="",M8="",M8<I8),"",M8-I8) -> 3 | AB8: =IF(OR(A8="",多次统计数据!$B$8="",多次统计数据!$B$6<=0,多次统计数据!$B$6>=1),"",1-POWER(1+多次统计数据!$B$8,-多次统计数据!$B$6/(1-多次统计数据!$B$6))) -> 0.081520133 | AC8: =IF(OR(AB8="",多次统计数据!$B$9=""),"",IF(多次统计数据!$B$9<AB8,"低于上限","达到或超过上限")) -> 低于上限 | AE8: =IF(OR(X8="",C8="",C8<=0),"",X8/C8) -> -0.015658238 | AG8: 短期博反弹 | AH8: 4～10个交易日 | AI8: 反弹 | AJ8: =IF(OR(AG8="",AH8=""),"",IF(OR(AND(AG8="短期博反弹",OR(AH8="1～3个交易日",AH8="4～10个交易日")),AND(AG8="突破冲新高",OR(AH8="4～10个交易日",AH8="11～20个交易日")),AND(AG8="趋势波段",OR(AH8="11～20个交易日",AH8="21～60个交易日",AH8="60个交易日以上"))),"匹配","周期与交易预期不匹配，请重新确认")) -> 匹配 | AK8: =IF(A8="","",COUNTIFS(加仓管理!$A$2:$A$1001,A8,加仓管理!$G$2:$G$1001,">0")) -> 0 | AL8: =IF(A8="","",SUMIFS(加仓管理!$G$2:$G$1001,加仓管理!$A$2:$A$1001,A8)) -> 0 | AM8: =IF(AK8=0,"",IFERROR(LOOKUP(2,1/((加仓管理!$A$2:$A$1001=A8)*(加仓管理!$G$2:$G$1001>0)),加仓管理!$D$2:$D$1001),"")) | AN8: =IF(AK8=0,"",IFERROR(LOOKUP(2,1/((加仓管理!$A$2:$A$1001=A8)*(加仓管理!$G$2:$G$1001>0)),加仓管理!$E$2:$E$1001),"")) | AO8: =IF(OR(A8="",H8="",H8<=0),"",(E8*H8+SUMIFS(加仓管理!$H$2:$H$1001,加仓管理!$A$2:$A$1001,A8))/AP8) -> 18.63 | AP8: =IF(OR(A8="",H8="",H8<=0),"",H8+AL8) -> 1100 | AQ8: =IF(A8="","",IF(M8<>"",0,IF(OR(H8="",N8=""),"",MAX((E8*H8+SUMIFS(加仓管理!$H$2:$H$1001,加仓管理!$A$2:$A$1001,A8))-MAX(N8,AN8)*AP8,0)))) -> 0 | AR8: =IF(A8="","",IF(OR(E8="",H8=""),"违规：首次买入价格或股数缺失",IF(COUNTIFS(加仓管理!$A$2:$A$1001,A8,加仓管理!$R$2:$R$1001,"违规*")>0,"违规：请检查加仓管理表",IF(SUM($AQ$2:$AQ$201)>账户数据!$B$7,"预警：超过账户风险上限",IF(COUNTIFS(加仓管理!$A$2:$A$1001,A8,加仓管理!$N$2:$N$1001,">0",加仓管理!$G$2:$G$1001,"")>0,"提示：存在待执行加仓计划","通过"))))) -> 通过
A9: 8 | B9: 中国卫通 | C9: 61544 | D9: 0.02 | E9: 20.42 | F9: =IF(OR(C9="",D9="",E9="",N9="",C9<=0,D9<=0,E9<=N9),"",ROUNDDOWN((C9*D9)/(E9-N9)/100,0)*100) -> 1300 | G9: =IF(A9="","",IF(H9<>"","已开仓",IF(账户数据!$B$23="已锁仓","禁止开仓：连续亏损达到上限",IF(账户数据!$B$23="解锁信息不完整","禁止开仓：请完整填写解锁信息",IF(OR(F9="",E9="",N9="",E9<=N9,账户数据!$B$7=""),"",IF(OR(AG9="",AH9="",AI9=""),"禁止开仓：交易预期未填写完整",IF(账户数据!$B$9+F9*(E9-N9)>=账户数据!$B$7,"禁止开仓：风险额度不足",IF(AJ9="周期与交易预期不匹配，请重新确认",IF(账户数据!$B$23="接近锁仓","允许开仓（接近锁仓；周期需复核）","允许开仓（周期需复核）"),IF(账户数据!$B$23="接近锁仓","允许开仓（接近锁仓）","允许开仓"))))))))) -> 已开仓 | H9: 1300 | I9: 45103 | J9: 24 | K9: 19.71 | L9: =IF(AP9="","",AP9) -> 1300 | M9: 45112 | N9: 19.5 | U9: =IF(OR(AO9="",J9="",AO9<=0),"",(J9-AO9)/AO9) -> 0.17531832 | V9: =IF(OR(AO9="",N9="",AO9<=0),"",(AO9-N9)/AO9) -> 0.045053869 | W9: =IF(OR(U9="",V9="",V9<=0),"",U9/V9) -> 3.8913043 | X9: =IF(OR(K9="",L9="",AO9="",AP9=""),"",(K9-AO9)*L9-IF(O9="",0,O9)-IF(P9="",0,P9)) -> -923 | Y9: =IF(OR(X9="",AO9="",L9=""),"",IF(AO9*L9+IF(O9="",0,O9)<=0,"",X9/(AO9*L9+IF(O9="",0,O9)))) -> -0.034769833 | Z9: =IF(OR(AE9="",多次统计数据!$B$8=""),"",AE9-多次统计数据!$B$8) -> -0.12521007 | AA9: =IF(OR(I9="",M9="",M9<I9),"",M9-I9) -> 9 | AB9: =IF(OR(A9="",多次统计数据!$B$8="",多次统计数据!$B$6<=0,多次统计数据!$B$6>=1),"",1-POWER(1+多次统计数据!$B$8,-多次统计数据!$B$6/(1-多次统计数据!$B$6))) -> 0.081520133 | AC9: =IF(OR(AB9="",多次统计数据!$B$9=""),"",IF(多次统计数据!$B$9<AB9,"低于上限","达到或超过上限")) -> 低于上限 | AE9: =IF(OR(X9="",C9="",C9<=0),"",X9/C9) -> -0.0149974 | AG9: 趋势波段 | AH9: 11～20个交易日 | AI9: 吸筹 | AJ9: =IF(OR(AG9="",AH9=""),"",IF(OR(AND(AG9="短期博反弹",OR(AH9="1～3个交易日",AH9="4～10个交易日")),AND(AG9="突破冲新高",OR(AH9="4～10个交易日",AH9="11～20个交易日")),AND(AG9="趋势波段",OR(AH9="11～20个交易日",AH9="21～60个交易日",AH9="60个交易日以上"))),"匹配","周期与交易预期不匹配，请重新确认")) -> 匹配 | AK9: =IF(A9="","",COUNTIFS(加仓管理!$A$2:$A$1001,A9,加仓管理!$G$2:$G$1001,">0")) -> 0 | AL9: =IF(A9="","",SUMIFS(加仓管理!$G$2:$G$1001,加仓管理!$A$2:$A$1001,A9)) -> 0 | AM9: =IF(AK9=0,"",IFERROR(LOOKUP(2,1/((加仓管理!$A$2:$A$1001=A9)*(加仓管理!$G$2:$G$1001>0)),加仓管理!$D$2:$D$1001),"")) | AN9: =IF(AK9=0,"",IFERROR(LOOKUP(2,1/((加仓管理!$A$2:$A$1001=A9)*(加仓管理!$G$2:$G$1001>0)),加仓管理!$E$2:$E$1001),"")) | AO9: =IF(OR(A9="",H9="",H9<=0),"",(E9*H9+SUMIFS(加仓管理!$H$2:$H$1001,加仓管理!$A$2:$A$1001,A9))/AP9) -> 20.42 | AP9: =IF(OR(A9="",H9="",H9<=0),"",H9+AL9) -> 1300 | AQ9: =IF(A9="","",IF(M9<>"",0,IF(OR(H9="",N9=""),"",MAX((E9*H9+SUMIFS(加仓管理!$H$2:$H$1001,加仓管理!$A$2:$A$1001,A9))-MAX(N9,AN9)*AP9,0)))) -> 0 | AR9: =IF(A9="","",IF(OR(E9="",H9=""),"违规：首次买入价格或股数缺失",IF(COUNTIFS(加仓管理!$A$2:$A$1001,A9,加仓管理!$R$2:$R$1001,"违规*")>0,"违规：请检查加仓管理表",IF(SUM($AQ$2:$AQ$201)>账户数据!$B$7,"预警：超过账户风险上限",IF(COUNTIFS(加仓管理!$A$2:$A$1001,A9,加仓管理!$N$2:$N$1001,">0",加仓管理!$G$2:$G$1001,"")>0,"提示：存在待执行加仓计划","通过"))))) -> 通过
A10: 9 | B10: 中国卫通 | C10: 60621 | D10: 0.02 | E10: 19.79 | F10: =IF(OR(C10="",D10="",E10="",N10="",C10<=0,D10<=0,E10<=N10),"",ROUNDDOWN((C10*D10)/(E10-N10)/100,0)*100) -> 900 | G10: =IF(A10="","",IF(H10<>"","已开仓",IF(账户数据!$B$23="已锁仓","禁止开仓：连续亏损达到上限",IF(账户数据!$B$23="解锁信息不完整","禁止开仓：请完整填写解锁信息",IF(OR(F10="",E10="",N10="",E10<=N10,账户数据!$B$7=""),"",IF(OR(AG10="",AH10="",AI10=""),"禁止开仓：交易预期未填写完整",IF(账户数据!$B$9+F10*(E10-N10)>=账户数据!$B$7,"禁止开仓：风险额度不足",IF(AJ10="周期与交易预期不匹配，请重新确认",IF(账户数据!$B$23="接近锁仓","允许开仓（接近锁仓；周期需复核）","允许开仓（周期需复核）"),IF(账户数据!$B$23="接近锁仓","允许开仓（接近锁仓）","允许开仓"))))))))) -> 已开仓 | H10: 900 | I10: 45181 | J10: 23 | K10: 16.91 | L10: =IF(AP10="","",AP10) -> 900 | M10: 45188 | N10: 18.5 | U10: =IF(OR(AO10="",J10="",AO10<=0),"",(J10-AO10)/AO10) -> 0.16220313 | V10: =IF(OR(AO10="",N10="",AO10<=0),"",(AO10-N10)/AO10) -> 0.065184437 | W10: =IF(OR(U10="",V10="",V10<=0),"",U10/V10) -> 2.4883721 | X10: =IF(OR(K10="",L10="",AO10="",AP10=""),"",(K10-AO10)*L10-IF(O10="",0,O10)-IF(P10="",0,P10)) -> -2592 | Y10: =IF(OR(X10="",AO10="",L10=""),"",IF(AO10*L10+IF(O10="",0,O10)<=0,"",X10/(AO10*L10+IF(O10="",0,O10)))) -> -0.14552804 | Z10: =IF(OR(AE10="",多次统计数据!$B$8=""),"",AE10-多次统计数据!$B$8) -> -0.15297013 | AA10: =IF(OR(I10="",M10="",M10<I10),"",M10-I10) -> 7 | AB10: =IF(OR(A10="",多次统计数据!$B$8="",多次统计数据!$B$6<=0,多次统计数据!$B$6>=1),"",1-POWER(1+多次统计数据!$B$8,-多次统计数据!$B$6/(1-多次统计数据!$B$6))) -> 0.081520133 | AC10: =IF(OR(AB10="",多次统计数据!$B$9=""),"",IF(多次统计数据!$B$9<AB10,"低于上限","达到或超过上限")) -> 低于上限 | AE10: =IF(OR(X10="",C10="",C10<=0),"",X10/C10) -> -0.04275746 | AG10: 趋势波段 | AH10: 11～20个交易日 | AI10: 吸筹 | AJ10: =IF(OR(AG10="",AH10=""),"",IF(OR(AND(AG10="短期博反弹",OR(AH10="1～3个交易日",AH10="4～10个交易日")),AND(AG10="突破冲新高",OR(AH10="4～10个交易日",AH10="11～20个交易日")),AND(AG10="趋势波段",OR(AH10="11～20个交易日",AH10="21～60个交易日",AH10="60个交易日以上"))),"匹配","周期与交易预期不匹配，请重新确认")) -> 匹配 | AK10: =IF(A10="","",COUNTIFS(加仓管理!$A$2:$A$1001,A10,加仓管理!$G$2:$G$1001,">0")) -> 0 | AL10: =IF(A10="","",SUMIFS(加仓管理!$G$2:$G$1001,加仓管理!$A$2:$A$1001,A10)) -> 0 | AM10: =IF(AK10=0,"",IFERROR(LOOKUP(2,1/((加仓管理!$A$2:$A$1001=A10)*(加仓管理!$G$2:$G$1001>0)),加仓管理!$D$2:$D$1001),"")) | AN10: =IF(AK10=0,"",IFERROR(LOOKUP(2,1/((加仓管理!$A$2:$A$1001=A10)*(加仓管理!$G$2:$G$1001>0)),加仓管理!$E$2:$E$1001),"")) | AO10: =IF(OR(A10="",H10="",H10<=0),"",(E10*H10+SUMIFS(加仓管理!$H$2:$H$1001,加仓管理!$A$2:$A$1001,A10))/AP10) -> 19.79 | AP10: =IF(OR(A10="",H10="",H10<=0),"",H10+AL10) -> 900 | AQ10: =IF(A10="","",IF(M10<>"",0,IF(OR(H10="",N10=""),"",MAX((E10*H10+SUMIFS(加仓管理!$H$2:$H$1001,加仓管理!$A$2:$A$1001,A10))-MAX(N10,AN10)*AP10,0)))) -> 0 | AR10: =IF(A10="","",IF(OR(E10="",H10=""),"违规：首次买入价格或股数缺失",IF(COUNTIFS(加仓管理!$A$2:$A$1001,A10,加仓管理!$R$2:$R$1001,"违规*")>0,"违规：请检查加仓管理表",IF(SUM($AQ$2:$AQ$201)>账户数据!$B$7,"预警：超过账户风险上限",IF(COUNTIFS(加仓管理!$A$2:$A$1001,A10,加仓管理!$N$2:$N$1001,">0",加仓管理!$G$2:$G$1001,"")>0,"提示：存在待执行加仓计划","通过"))))) -> 通过
A11: 10 | B11: 中国卫通 | C11: 58029 | D11: 0.02 | E11: 15.27 | F11: =IF(OR(C11="",D11="",E11="",N11="",C11<=0,D11<=0,E11<=N11),"",ROUNDDOWN((C11*D11)/(E11-N11)/100,0)*100) -> 1500 | G11: =IF(A11="","",IF(H11<>"","已开仓",IF(账户数据!$B$23="已锁仓","禁止开仓：连续亏损达到上限",IF(账户数据!$B$23="解锁信息不完整","禁止开仓：请完整填写解锁信息",IF(OR(F11="",E11="",N11="",E11<=N11,账户数据!$B$7=""),"",IF(OR(AG11="",AH11="",AI11=""),"禁止开仓：交易预期未填写完整",IF(账户数据!$B$9+F11*(E11-N11)>=账户数据!$B$7,"禁止开仓：风险额度不足",IF(AJ11="周期与交易预期不匹配，请重新确认",IF(账户数据!$B$23="接近锁仓","允许开仓（接近锁仓；周期需复核）","允许开仓（周期需复核）"),IF(账户数据!$B$23="接近锁仓","允许开仓（接近锁仓）","允许开仓"))))))))) -> 已开仓 | H11: 1500 | I11: 45502 | J11: 18 | K11: 16.33 | L11: =IF(AP11="","",AP11) -> 3500 | M11: 45512 | N11: 14.5 | U11: =IF(OR(AO11="",J11="",AO11<=0),"",(J11-AO11)/AO11) -> 0.094415009 | V11: =IF(OR(AO11="",N11="",AO11<=0),"",(AO11-N11)/AO11) -> 0.11838791 | W11: =IF(OR(U11="",V11="",V11<=0),"",U11/V11) -> 0.7975055 | X11: =IF(OR(K11="",L11="",AO11="",AP11=""),"",(K11-AO11)*L11-IF(O11="",0,O11)-IF(P11="",0,P11)) -> -410 | Y11: =IF(OR(X11="",AO11="",L11=""),"",IF(AO11*L11+IF(O11="",0,O11)<=0,"",X11/(AO11*L11+IF(O11="",0,O11)))) -> -0.0071223834 | Z11: =IF(OR(AE11="",多次统计数据!$B$8=""),"",AE11-多次统计数据!$B$8) -> -0.1172781 | AA11: =IF(OR(I11="",M11="",M11<I11),"",M11-I11) -> 10 | AB11: =IF(OR(A11="",多次统计数据!$B$8="",多次统计数据!$B$6<=0,多次统计数据!$B$6>=1),"",1-POWER(1+多次统计数据!$B$8,-多次统计数据!$B$6/(1-多次统计数据!$B$6))) -> 0.081520133 | AC11: =IF(OR(AB11="",多次统计数据!$B$9=""),"",IF(多次统计数据!$B$9<AB11,"低于上限","达到或超过上限")) -> 低于上限 | AE11: =IF(OR(X11="",C11="",C11<=0),"",X11/C11) -> -0.0070654328 | AG11: 趋势波段 | AH11: 11～20个交易日 | AI11: 吸筹 | AJ11: =IF(OR(AG11="",AH11=""),"",IF(OR(AND(AG11="短期博反弹",OR(AH11="1～3个交易日",AH11="4～10个交易日")),AND(AG11="突破冲新高",OR(AH11="4～10个交易日",AH11="11～20个交易日")),AND(AG11="趋势波段",OR(AH11="11～20个交易日",AH11="21～60个交易日",AH11="60个交易日以上"))),"匹配","周期与交易预期不匹配，请重新确认")) -> 匹配 | AK11: =IF(A11="","",COUNTIFS(加仓管理!$A$2:$A$1001,A11,加仓管理!$G$2:$G$1001,">0")) -> 2 | AL11: =IF(A11="","",SUMIFS(加仓管理!$G$2:$G$1001,加仓管理!$A$2:$A$1001,A11)) -> 2000 | AM11: =IF(AK11=0,"",IFERROR(LOOKUP(2,1/((加仓管理!$A$2:$A$1001=A11)*(加仓管理!$G$2:$G$1001>0)),加仓管理!$D$2:$D$1001),"")) -> 17.86 | AN11: =IF(AK11=0,"",IFERROR(LOOKUP(2,1/((加仓管理!$A$2:$A$1001=A11)*(加仓管理!$G$2:$G$1001>0)),加仓管理!$E$2:$E$1001),"")) -> 16.5 | AO11: =IF(OR(A11="",H11="",H11<=0),"",(E11*H11+SUMIFS(加仓管理!$H$2:$H$1001,加仓管理!$A$2:$A$1001,A11))/AP11) -> 16.447143 | AP11: =IF(OR(A11="",H11="",H11<=0),"",H11+AL11) -> 3500 | AQ11: =IF(A11="","",IF(M11<>"",0,IF(OR(H11="",N11=""),"",MAX((E11*H11+SUMIFS(加仓管理!$H$2:$H$1001,加仓管理!$A$2:$A$1001,A11))-MAX(N11,AN11)*AP11,0)))) -> 0 | AR11: =IF(A11="","",IF(OR(E11="",H11=""),"违规：首次买入价格或股数缺失",IF(COUNTIFS(加仓管理!$A$2:$A$1001,A11,加仓管理!$R$2:$R$1001,"违规*")>0,"违规：请检查加仓管理表",IF(SUM($AQ$2:$AQ$201)>账户数据!$B$7,"预警：超过账户风险上限",IF(COUNTIFS(加仓管理!$A$2:$A$1001,A11,加仓管理!$N$2:$N$1001,">0",加仓管理!$G$2:$G$1001,"")>0,"提示：存在待执行加仓计划","通过"))))) -> 通过
A12: 11 | B12: 中国卫通 | C12: 57619 | D12: 0.02 | E12: 20.34 | F12: =IF(OR(C12="",D12="",E12="",N12="",C12<=0,D12<=0,E12<=N12),"",ROUNDDOWN((C12*D12)/(E12-N12)/100,0)*100) -> 1300 | G12: =IF(A12="","",IF(H12<>"","已开仓",IF(账户数据!$B$23="已锁仓","禁止开仓：连续亏损达到上限",IF(账户数据!$B$23="解锁信息不完整","禁止开仓：请完整填写解锁信息",IF(OR(F12="",E12="",N12="",E12<=N12,账户数据!$B$7=""),"",IF(OR(AG12="",AH12="",AI12=""),"禁止开仓：交易预期未填写完整",IF(账户数据!$B$9+F12*(E12-N12)>=账户数据!$B$7,"禁止开仓：风险额度不足",IF(AJ12="周期与交易预期不匹配，请重新确认",IF(账户数据!$B$23="接近锁仓","允许开仓（接近锁仓；周期需复核）","允许开仓（周期需复核）"),IF(账户数据!$B$23="接近锁仓","允许开仓（接近锁仓）","允许开仓"))))))))) -> 已开仓 | H12: 1300 | I12: 45603 | J12: 24 | K12: 26.66 | L12: =IF(AP12="","",AP12) -> 1800 | M12: 45608 | N12: 19.5 | U12: =IF(OR(AO12="",J12="",AO12<=0),"",(J12-AO12)/AO12) -> 0.14795918 | V12: =IF(OR(AO12="",N12="",AO12<=0),"",(AO12-N12)/AO12) -> 0.067283163 | W12: =IF(OR(U12="",V12="",V12<=0),"",U12/V12) -> 2.1990521 | X12: =IF(OR(K12="",L12="",AO12="",AP12=""),"",(K12-AO12)*L12-IF(O12="",0,O12)-IF(P12="",0,P12)) -> 10356 | Y12: =IF(OR(X12="",AO12="",L12=""),"",IF(AO12*L12+IF(O12="",0,O12)<=0,"",X12/(AO12*L12+IF(O12="",0,O12)))) -> 0.27519133 | Z12: =IF(OR(AE12="",多次统计数据!$B$8=""),"",AE12-多次统计数据!$B$8) -> 0.069519711 | AA12: =IF(OR(I12="",M12="",M12<I12),"",M12-I12) -> 5 | AB12: =IF(OR(A12="",多次统计数据!$B$8="",多次统计数据!$B$6<=0,多次统计数据!$B$6>=1),"",1-POWER(1+多次统计数据!$B$8,-多次统计数据!$B$6/(1-多次统计数据!$B$6))) -> 0.081520133 | AC12: =IF(OR(AB12="",多次统计数据!$B$9=""),"",IF(多次统计数据!$B$9<AB12,"低于上限","达到或超过上限")) -> 低于上限 | AE12: =IF(OR(X12="",C12="",C12<=0),"",X12/C12) -> 0.17973238 | AG12: 突破冲新高 | AH12: 4～10个交易日 | AI12: 新高 | AJ12: =IF(OR(AG12="",AH12=""),"",IF(OR(AND(AG12="短期博反弹",OR(AH12="1～3个交易日",AH12="4～10个交易日")),AND(AG12="突破冲新高",OR(AH12="4～10个交易日",AH12="11～20个交易日")),AND(AG12="趋势波段",OR(AH12="11～20个交易日",AH12="21～60个交易日",AH12="60个交易日以上"))),"匹配","周期与交易预期不匹配，请重新确认")) -> 匹配 | AK12: =IF(A12="","",COUNTIFS(加仓管理!$A$2:$A$1001,A12,加仓管理!$G$2:$G$1001,">0")) -> 1 | AL12: =IF(A12="","",SUMIFS(加仓管理!$G$2:$G$1001,加仓管理!$A$2:$A$1001,A12)) -> 500 | AM12: =IF(AK12=0,"",IFERROR(LOOKUP(2,1/((加仓管理!$A$2:$A$1001=A12)*(加仓管理!$G$2:$G$1001>0)),加仓管理!$D$2:$D$1001),"")) -> 22.38 | AN12: =IF(AK12=0,"",IFERROR(LOOKUP(2,1/((加仓管理!$A$2:$A$1001=A12)*(加仓管理!$G$2:$G$1001>0)),加仓管理!$E$2:$E$1001),"")) -> 20 | AO12: =IF(OR(A12="",H12="",H12<=0),"",(E12*H12+SUMIFS(加仓管理!$H$2:$H$1001,加仓管理!$A$2:$A$1001,A12))/AP12) -> 20.906667 | AP12: =IF(OR(A12="",H12="",H12<=0),"",H12+AL12) -> 1800 | AQ12: =IF(A12="","",IF(M12<>"",0,IF(OR(H12="",N12=""),"",MAX((E12*H12+SUMIFS(加仓管理!$H$2:$H$1001,加仓管理!$A$2:$A$1001,A12))-MAX(N12,AN12)*AP12,0)))) -> 0 | AR12: =IF(A12="","",IF(OR(E12="",H12=""),"违规：首次买入价格或股数缺失",IF(COUNTIFS(加仓管理!$A$2:$A$1001,A12,加仓管理!$R$2:$R$1001,"违规*")>0,"违规：请检查加仓管理表",IF(SUM($AQ$2:$AQ$201)>账户数据!$B$7,"预警：超过账户风险上限",IF(COUNTIFS(加仓管理!$A$2:$A$1001,A12,加仓管理!$N$2:$N$1001,">0",加仓管理!$G$2:$G$1001,"")>0,"提示：存在待执行加仓计划","通过"))))) -> 违规：请检查加仓管理表
A13: 12 | B13: 中国卫通 | C13: 67975 | D13: 0.02 | E13: 20.46 | F13: =IF(OR(C13="",D13="",E13="",N13="",C13<=0,D13<=0,E13<=N13),"",ROUNDDOWN((C13*D13)/(E13-N13)/100,0)*100) -> 1400 | G13: =IF(A13="","",IF(H13<>"","已开仓",IF(账户数据!$B$23="已锁仓","禁止开仓：连续亏损达到上限",IF(账户数据!$B$23="解锁信息不完整","禁止开仓：请完整填写解锁信息",IF(OR(F13="",E13="",N13="",E13<=N13,账户数据!$B$7=""),"",IF(OR(AG13="",AH13="",AI13=""),"禁止开仓：交易预期未填写完整",IF(账户数据!$B$9+F13*(E13-N13)>=账户数据!$B$7,"禁止开仓：风险额度不足",IF(AJ13="周期与交易预期不匹配，请重新确认",IF(账户数据!$B$23="接近锁仓","允许开仓（接近锁仓；周期需复核）","允许开仓（周期需复核）"),IF(账户数据!$B$23="接近锁仓","允许开仓（接近锁仓）","允许开仓"))))))))) -> 已开仓 | H13: 1400 | I13: 45734 | J13: 24 | K13: 22.03 | L13: =IF(AP13="","",AP13) -> 3000 | M13: 45910 | N13: 19.5 | U13: =IF(OR(AO13="",J13="",AO13<=0),"",(J13-AO13)/AO13) -> 0.095790339 | V13: =IF(OR(AO13="",N13="",AO13<=0),"",(AO13-N13)/AO13) -> 0.10967035 | W13: =IF(OR(U13="",V13="",V13<=0),"",U13/V13) -> 0.8734388 | X13: =IF(OR(K13="",L13="",AO13="",AP13=""),"",(K13-AO13)*L13-IF(O13="",0,O13)-IF(P13="",0,P13)) -> 384 | Y13: =IF(OR(X13="",AO13="",L13=""),"",IF(AO13*L13+IF(O13="",0,O13)<=0,"",X13/(AO13*L13+IF(O13="",0,O13)))) -> 0.0058442151 | Z13: =IF(OR(AE13="",多次统计数据!$B$8=""),"",AE13-多次统计数据!$B$8) -> -0.10456353 | AA13: =IF(OR(I13="",M13="",M13<I13),"",M13-I13) -> 176 | AB13: =IF(OR(A13="",多次统计数据!$B$8="",多次统计数据!$B$6<=0,多次统计数据!$B$6>=1),"",1-POWER(1+多次统计数据!$B$8,-多次统计数据!$B$6/(1-多次统计数据!$B$6))) -> 0.081520133 | AC13: =IF(OR(AB13="",多次统计数据!$B$9=""),"",IF(多次统计数据!$B$9<AB13,"低于上限","达到或超过上限")) -> 低于上限 | AE13: =IF(OR(X13="",C13="",C13<=0),"",X13/C13) -> 0.0056491357 | AG13: 趋势波段 | AH13: 11～20个交易日 | AI13: 吸筹 | AJ13: =IF(OR(AG13="",AH13=""),"",IF(OR(AND(AG13="短期博反弹",OR(AH13="1～3个交易日",AH13="4～10个交易日")),AND(AG13="突破冲新高",OR(AH13="4～10个交易日",AH13="11～20个交易日")),AND(AG13="趋势波段",OR(AH13="11～20个交易日",AH13="21～60个交易日",AH13="60个交易日以上"))),"匹配","周期与交易预期不匹配，请重新确认")) -> 匹配 | AK13: =IF(A13="","",COUNTIFS(加仓管理!$A$2:$A$1001,A13,加仓管理!$G$2:$G$1001,">0")) -> 2 | AL13: =IF(A13="","",SUMIFS(加仓管理!$G$2:$G$1001,加仓管理!$A$2:$A$1001,A13)) -> 1600 | AM13: =IF(AK13=0,"",IFERROR(LOOKUP(2,1/((加仓管理!$A$2:$A$1001=A13)*(加仓管理!$G$2:$G$1001>0)),加仓管理!$D$2:$D$1001),"")) -> 25.27 | AN13: =IF(AK13=0,"",IFERROR(LOOKUP(2,1/((加仓管理!$A$2:$A$1001=A13)*(加仓管理!$G$2:$G$1001>0)),加仓管理!$E$2:$E$1001),"")) -> 23 | AO13: =IF(OR(A13="",H13="",H13<=0),"",(E13*H13+SUMIFS(加仓管理!$H$2:$H$1001,加仓管理!$A$2:$A$1001,A13))/AP13) -> 21.902 | AP13: =IF(OR(A13="",H13="",H13<=0),"",H13+AL13) -> 3000 | AQ13: =IF(A13="","",IF(M13<>"",0,IF(OR(H13="",N13=""),"",MAX((E13*H13+SUMIFS(加仓管理!$H$2:$H$1001,加仓管理!$A$2:$A$1001,A13))-MAX(N13,AN13)*AP13,0)))) -> 0 | AR13: =IF(A13="","",IF(OR(E13="",H13=""),"违规：首次买入价格或股数缺失",IF(COUNTIFS(加仓管理!$A$2:$A$1001,A13,加仓管理!$R$2:$R$1001,"违规*")>0,"违规：请检查加仓管理表",IF(SUM($AQ$2:$AQ$201)>账户数据!$B$7,"预警：超过账户风险上限",IF(COUNTIFS(加仓管理!$A$2:$A$1001,A13,加仓管理!$N$2:$N$1001,">0",加仓管理!$G$2:$G$1001,"")>0,"提示：存在待执行加仓计划","通过"))))) -> 违规：请检查加仓管理表
... A136: 135 | B136: 亿纬锂能 | C136: 1235288 | D136: 0.02 | E136: 35.39 | F136: =IF(OR(C136="",D136="",E136="",N136="",C136<=0,D136<=0,E136<=N136),"",ROUNDDOWN((C136*D136)/(E136-N136)/100,0)*100) -> 13000 | G136: =IF(A136="","",IF(H136<>"","已开仓",IF(账户数据!$B$23="已锁仓","禁止开仓：连续亏损达到上限",IF(账户数据!$B$23="解锁信息不完整","禁止开仓：请完整填写解锁信息",IF(OR(F136="",E136="",N136="",E136<=N136,账户数据!$B$7=""),"",IF(OR(AG136="",AH136="",AI136=""),"禁止开仓：交易预期未填写完整",IF(账户数据!$B$9+F136*(E136-N136)>=账户数据!$B$7,"禁止开仓：风险额度不足",IF(AJ136="周期与交易预期不匹配，请重新确认",IF(账户数据!$B$23="接近锁仓","允许开仓（接近锁仓；周期需复核）","允许开仓（周期需复核）"),IF(账户数据!$B$23="接近锁仓","允许开仓（接近锁仓）","允许开仓"))))))))) -> 已开仓 | H136: 13000 | I136: 45512 | J136: 40 | K136: 32.99 | L136: =IF(AP136="","",AP136) -> 13000 | M136: 45526 | N136: 33.5 | U136: =IF(OR(AO136="",J136="",AO136<=0),"",(J136-AO136)/AO136) -> 0.13026279 | V136: =IF(OR(AO136="",N136="",AO136<=0),"",(AO136-N136)/AO136) -> 0.053404917 | W136: =IF(OR(U136="",V136="",V136<=0),"",U136/V136) -> 2.4391534 | X136: =IF(OR(K136="",L136="",AO136="",AP136=""),"",(K136-AO136)*L136-IF(O136="",0,O136)-IF(P136="",0,P136)) -> -31200 | Y136: =IF(OR(X136="",AO136="",L136=""),"",IF(AO136*L136+IF(O136="",0,O136)<=0,"",X136/(AO136*L136+IF(O136="",0,O136)))) -> -0.067815767 | Z136: =IF(OR(AE136="",多次统计数据!$B$8=""),"",AE136-多次统计数据!$B$8) -> -0.13546994 | AA136: =IF(OR(I136="",M136="",M136<I136),"",M136-I136) -> 14 | AB136: =IF(OR(A136="",多次统计数据!$B$8="",多次统计数据!$B$6<=0,多次统计数据!$B$6>=1),"",1-POWER(1+多次统计数据!$B$8,-多次统计数据!$B$6/(1-多次统计数据!$B$6))) -> 0.081520133 | AC136: =IF(OR(AB136="",多次统计数据!$B$9=""),"",IF(多次统计数据!$B$9<AB136,"低于上限","达到或超过上限")) -> 低于上限 | AE136: =IF(OR(X136="",C136="",C136<=0),"",X136/C136) -> -0.025257268 | AG136: 趋势波段 | AH136: 11～20个交易日 | AI136: 吸筹 | AJ136: =IF(OR(AG136="",AH136=""),"",IF(OR(AND(AG136="短期博反弹",OR(AH136="1～3个交易日",AH136="4～10个交易日")),AND(AG136="突破冲新高",OR(AH136="4～10个交易日",AH136="11～20个交易日")),AND(AG136="趋势波段",OR(AH136="11～20个交易日",AH136="21～60个交易日",AH136="60个交易日以上"))),"匹配","周期与交易预期不匹配，请重新确认")) -> 匹配 | AK136: =IF(A136="","",COUNTIFS(加仓管理!$A$2:$A$1001,A136,加仓管理!$G$2:$G$1001,">0")) -> 0 | AL136: =IF(A136="","",SUMIFS(加仓管理!$G$2:$G$1001,加仓管理!$A$2:$A$1001,A136)) -> 0 | AM136: =IF(AK136=0,"",IFERROR(LOOKUP(2,1/((加仓管理!$A$2:$A$1001=A136)*(加仓管理!$G$2:$G$1001>0)),加仓管理!$D$2:$D$1001),"")) | AN136: =IF(AK136=0,"",IFERROR(LOOKUP(2,1/((加仓管理!$A$2:$A$1001=A136)*(加仓管理!$G$2:$G$1001>0)),加仓管理!$E$2:$E$1001),"")) | AO136: =IF(OR(A136="",H136="",H136<=0),"",(E136*H136+SUMIFS(加仓管理!$H$2:$H$1001,加仓管理!$A$2:$A$1001,A136))/AP136) -> 35.39 | AP136: =IF(OR(A136="",H136="",H136<=0),"",H136+AL136) -> 13000 | AQ136: =IF(A136="","",IF(M136<>"",0,IF(OR(H136="",N136=""),"",MAX((E136*H136+SUMIFS(加仓管理!$H$2:$H$1001,加仓管理!$A$2:$A$1001,A136))-MAX(N136,AN136)*AP136,0)))) -> 0 | AR136: =IF(A136="","",IF(OR(E136="",H136=""),"违规：首次买入价格或股数缺失",IF(COUNTIFS(加仓管理!$A$2:$A$1001,A136,加仓管理!$R$2:$R$1001,"违规*")>0,"违规：请检查加仓管理表",IF(SUM($AQ$2:$AQ$201)>账户数据!$B$7,"预警：超过账户风险上限",IF(COUNTIFS(加仓管理!$A$2:$A$1001,A136,加仓管理!$N$2:$N$1001,">0",加仓管理!$G$2:$G$1001,"")>0,"提示：存在待执行加仓计划","通过"))))) -> 通过
A137: 136 | B137: 亿纬锂能 | C137: 1204088 | D137: 0.02 | E137: 31.25 | F137: =IF(OR(C137="",D137="",E137="",N137="",C137<=0,D137<=0,E137<=N137),"",ROUNDDOWN((C137*D137)/(E137-N137)/100,0)*100) -> 10700 | G137: =IF(A137="","",IF(H137<>"","已开仓",IF(账户数据!$B$23="已锁仓","禁止开仓：连续亏损达到上限",IF(账户数据!$B$23="解锁信息不完整","禁止开仓：请完整填写解锁信息",IF(OR(F137="",E137="",N137="",E137<=N137,账户数据!$B$7=""),"",IF(OR(AG137="",AH137="",AI137=""),"禁止开仓：交易预期未填写完整",IF(账户数据!$B$9+F137*(E137-N137)>=账户数据!$B$7,"禁止开仓：风险额度不足",IF(AJ137="周期与交易预期不匹配，请重新确认",IF(账户数据!$B$23="接近锁仓","允许开仓（接近锁仓；周期需复核）","允许开仓（周期需复核）"),IF(账户数据!$B$23="接近锁仓","允许开仓（接近锁仓）","允许开仓"))))))))) -> 已开仓 | H137: 10000 | I137: 45527 | J137: 35 | K137: 31.35 | L137: =IF(AP137="","",AP137) -> 10000 | N137: 29 | U137: =IF(OR(AO137="",J137="",AO137<=0),"",(J137-AO137)/AO137) -> 0.12 | V137: =IF(OR(AO137="",N137="",AO137<=0),"",(AO137-N137)/AO137) -> 0.072 | W137: =IF(OR(U137="",V137="",V137<=0),"",U137/V137) -> 1.6666667 | X137: =IF(OR(K137="",L137="",AO137="",AP137=""),"",(K137-AO137)*L137-IF(O137="",0,O137)-IF(P137="",0,P137)) -> 1000 | Y137: =IF(OR(X137="",AO137="",L137=""),"",IF(AO137*L137+IF(O137="",0,O137)<=0,"",X137/(AO137*L137+IF(O137="",0,O137)))) -> 0.0032 | Z137: =IF(OR(AE137="",多次统计数据!$B$8=""),"",AE137-多次统计数据!$B$8) -> -0.10938216 | AA137: =IF(OR(I137="",M137="",M137<I137),"",M137-I137) | AB137: =IF(OR(A137="",多次统计数据!$B$8="",多次统计数据!$B$6<=0,多次统计数据!$B$6>=1),"",1-POWER(1+多次统计数据!$B$8,-多次统计数据!$B$6/(1-多次统计数据!$B$6))) -> 0.081520133 | AC137: =IF(OR(AB137="",多次统计数据!$B$9=""),"",IF(多次统计数据!$B$9<AB137,"低于上限","达到或超过上限")) -> 低于上限 | AE137: =IF(OR(X137="",C137="",C137<=0),"",X137/C137) -> 0.00083050408 | AG137: 短期博反弹 | AH137: 4～10个交易日 | AI137: 反弹 | AJ137: =IF(OR(AG137="",AH137=""),"",IF(OR(AND(AG137="短期博反弹",OR(AH137="1～3个交易日",AH137="4～10个交易日")),AND(AG137="突破冲新高",OR(AH137="4～10个交易日",AH137="11～20个交易日")),AND(AG137="趋势波段",OR(AH137="11～20个交易日",AH137="21～60个交易日",AH137="60个交易日以上"))),"匹配","周期与交易预期不匹配，请重新确认")) -> 匹配 | AK137: =IF(A137="","",COUNTIFS(加仓管理!$A$2:$A$1001,A137,加仓管理!$G$2:$G$1001,">0")) -> 0 | AL137: =IF(A137="","",SUMIFS(加仓管理!$G$2:$G$1001,加仓管理!$A$2:$A$1001,A137)) -> 0 | AM137: =IF(AK137=0,"",IFERROR(LOOKUP(2,1/((加仓管理!$A$2:$A$1001=A137)*(加仓管理!$G$2:$G$1001>0)),加仓管理!$D$2:$D$1001),"")) | AN137: =IF(AK137=0,"",IFERROR(LOOKUP(2,1/((加仓管理!$A$2:$A$1001=A137)*(加仓管理!$G$2:$G$1001>0)),加仓管理!$E$2:$E$1001),"")) | AO137: =IF(OR(A137="",H137="",H137<=0),"",(E137*H137+SUMIFS(加仓管理!$H$2:$H$1001,加仓管理!$A$2:$A$1001,A137))/AP137) -> 31.25 | AP137: =IF(OR(A137="",H137="",H137<=0),"",H137+AL137) -> 10000 | AQ137: =IF(A137="","",IF(M137<>"",0,IF(OR(H137="",N137=""),"",MAX((E137*H137+SUMIFS(加仓管理!$H$2:$H$1001,加仓管理!$A$2:$A$1001,A137))-MAX(N137,AN137)*AP137,0)))) -> 22500 | AR137: =IF(A137="","",IF(OR(E137="",H137=""),"违规：首次买入价格或股数缺失",IF(COUNTIFS(加仓管理!$A$2:$A$1001,A137,加仓管理!$R$2:$R$1001,"违规*")>0,"违规：请检查加仓管理表",IF(SUM($AQ$2:$AQ$201)>账户数据!$B$7,"预警：超过账户风险上限",IF(COUNTIFS(加仓管理!$A$2:$A$1001,A137,加仓管理!$N$2:$N$1001,">0",加仓管理!$G$2:$G$1001,"")>0,"提示：存在待执行加仓计划","通过"))))) -> 通过
F138: =IF(OR(C138="",D138="",E138="",N138="",C138<=0,D138<=0,E138<=N138),"",ROUNDDOWN((C138*D138)/(E138-N138)/100,0)*100) | G138: =IF(A138="","",IF(H138<>"","已开仓",IF(账户数据!$B$23="已锁仓","禁止开仓：连续亏损达到上限",IF(账户数据!$B$23="解锁信息不完整","禁止开仓：请完整填写解锁信息",IF(OR(F138="",E138="",N138="",E138<=N138,账户数据!$B$7=""),"",IF(OR(AG138="",AH138="",AI138=""),"禁止开仓：交易预期未填写完整",IF(账户数据!$B$9+F138*(E138-N138)>=账户数据!$B$7,"禁止开仓：风险额度不足",IF(AJ138="周期与交易预期不匹配，请重新确认",IF(账户数据!$B$23="接近锁仓","允许开仓（接近锁仓；周期需复核）","允许开仓（周期需复核）"),IF(账户数据!$B$23="接近锁仓","允许开仓（接近锁仓）","允许开仓"))))))))) | L138: =IF(AP138="","",AP138) | U138: =IF(OR(AO138="",J138="",AO138<=0),"",(J138-AO138)/AO138) | V138: =IF(OR(AO138="",N138="",AO138<=0),"",(AO138-N138)/AO138) | W138: =IF(OR(U138="",V138="",V138<=0),"",U138/V138) | X138: =IF(OR(K138="",L138="",AO138="",AP138=""),"",(K138-AO138)*L138-IF(O138="",0,O138)-IF(P138="",0,P138)) | Y138: =IF(OR(X138="",AO138="",L138=""),"",IF(AO138*L138+IF(O138="",0,O138)<=0,"",X138/(AO138*L138+IF(O138="",0,O138)))) | Z138: =IF(OR(AE138="",多次统计数据!$B$8=""),"",AE138-多次统计数据!$B$8) | AA138: =IF(OR(I138="",M138="",M138<I138),"",M138-I138) | AB138: =IF(OR(A138="",多次统计数据!$B$8="",多次统计数据!$B$6<=0,多次统计数据!$B$6>=1),"",1-POWER(1+多次统计数据!$B$8,-多次统计数据!$B$6/(1-多次统计数据!$B$6))) | AC138: =IF(OR(AB138="",多次统计数据!$B$9=""),"",IF(多次统计数据!$B$9<AB138,"低于上限","达到或超过上限")) | AE138: =IF(OR(X138="",C138="",C138<=0),"",X138/C138) | AJ138: =IF(OR(AG138="",AH138=""),"",IF(OR(AND(AG138="短期博反弹",OR(AH138="1～3个交易日",AH138="4～10个交易日")),AND(AG138="突破冲新高",OR(AH138="4～10个交易日",AH138="11～20个交易日")),AND(AG138="趋势波段",OR(AH138="11～20个交易日",AH138="21～60个交易日",AH138="60个交易日以上"))),"匹配","周期与交易预期不匹配，请重新确认")) | AK138: =IF(A138="","",COUNTIFS(加仓管理!$A$2:$A$1001,A138,加仓管理!$G$2:$G$1001,">0")) | AL138: =IF(A138="","",SUMIFS(加仓管理!$G$2:$G$1001,加仓管理!$A$2:$A$1001,A138)) | AM138: =IF(AK138=0,"",IFERROR(LOOKUP(2,1/((加仓管理!$A$2:$A$1001=A138)*(加仓管理!$G$2:$G$1001>0)),加仓管理!$D$2:$D$1001),"")) | AN138: =IF(AK138=0,"",IFERROR(LOOKUP(2,1/((加仓管理!$A$2:$A$1001=A138)*(加仓管理!$G$2:$G$1001>0)),加仓管理!$E$2:$E$1001),"")) | AO138: =IF(OR(A138="",H138="",H138<=0),"",(E138*H138+SUMIFS(加仓管理!$H$2:$H$1001,加仓管理!$A$2:$A$1001,A138))/AP138) | AP138: =IF(OR(A138="",H138="",H138<=0),"",H138+AL138) | AQ138: =IF(A138="","",IF(M138<>"",0,IF(OR(H138="",N138=""),"",MAX((E138*H138+SUMIFS(加仓管理!$H$2:$H$1001,加仓管理!$A$2:$A$1001,A138))-MAX(N138,AN138)*AP138,0)))) | AR138: =IF(A138="","",IF(OR(E138="",H138=""),"违规：首次买入价格或股数缺失",IF(COUNTIFS(加仓管理!$A$2:$A$1001,A138,加仓管理!$R$2:$R$1001,"违规*")>0,"违规：请检查加仓管理表",IF(SUM($AQ$2:$AQ$201)>账户数据!$B$7,"预警：超过账户风险上限",IF(COUNTIFS(加仓管理!$A$2:$A$1001,A138,加仓管理!$N$2:$N$1001,">0",加仓管理!$G$2:$G$1001,"")>0,"提示：存在待执行加仓计划","通过")))))
F139: =IF(OR(C139="",D139="",E139="",N139="",C139<=0,D139<=0,E139<=N139),"",ROUNDDOWN((C139*D139)/(E139-N139)/100,0)*100) | G139: =IF(A139="","",IF(H139<>"","已开仓",IF(账户数据!$B$23="已锁仓","禁止开仓：连续亏损达到上限",IF(账户数据!$B$23="解锁信息不完整","禁止开仓：请完整填写解锁信息",IF(OR(F139="",E139="",N139="",E139<=N139,账户数据!$B$7=""),"",IF(OR(AG139="",AH139="",AI139=""),"禁止开仓：交易预期未填写完整",IF(账户数据!$B$9+F139*(E139-N139)>=账户数据!$B$7,"禁止开仓：风险额度不足",IF(AJ139="周期与交易预期不匹配，请重新确认",IF(账户数据!$B$23="接近锁仓","允许开仓（接近锁仓；周期需复核）","允许开仓（周期需复核）"),IF(账户数据!$B$23="接近锁仓","允许开仓（接近锁仓）","允许开仓"))))))))) | L139: =IF(AP139="","",AP139) | U139: =IF(OR(AO139="",J139="",AO139<=0),"",(J139-AO139)/AO139) | V139: =IF(OR(AO139="",N139="",AO139<=0),"",(AO139-N139)/AO139) | W139: =IF(OR(U139="",V139="",V139<=0),"",U139/V139) | X139: =IF(OR(K139="",L139="",AO139="",AP139=""),"",(K139-AO139)*L139-IF(O139="",0,O139)-IF(P139="",0,P139)) | Y139: =IF(OR(X139="",AO139="",L139=""),"",IF(AO139*L139+IF(O139="",0,O139)<=0,"",X139/(AO139*L139+IF(O139="",0,O139)))) | Z139: =IF(OR(AE139="",多次统计数据!$B$8=""),"",AE139-多次统计数据!$B$8) | AA139: =IF(OR(I139="",M139="",M139<I139),"",M139-I139) | AB139: =IF(OR(A139="",多次统计数据!$B$8="",多次统计数据!$B$6<=0,多次统计数据!$B$6>=1),"",1-POWER(1+多次统计数据!$B$8,-多次统计数据!$B$6/(1-多次统计数据!$B$6))) | AC139: =IF(OR(AB139="",多次统计数据!$B$9=""),"",IF(多次统计数据!$B$9<AB139,"低于上限","达到或超过上限")) | AE139: =IF(OR(X139="",C139="",C139<=0),"",X139/C139) | AJ139: =IF(OR(AG139="",AH139=""),"",IF(OR(AND(AG139="短期博反弹",OR(AH139="1～3个交易日",AH139="4～10个交易日")),AND(AG139="突破冲新高",OR(AH139="4～10个交易日",AH139="11～20个交易日")),AND(AG139="趋势波段",OR(AH139="11～20个交易日",AH139="21～60个交易日",AH139="60个交易日以上"))),"匹配","周期与交易预期不匹配，请重新确认")) | AK139: =IF(A139="","",COUNTIFS(加仓管理!$A$2:$A$1001,A139,加仓管理!$G$2:$G$1001,">0")) | AL139: =IF(A139="","",SUMIFS(加仓管理!$G$2:$G$1001,加仓管理!$A$2:$A$1001,A139)) | AM139: =IF(AK139=0,"",IFERROR(LOOKUP(2,1/((加仓管理!$A$2:$A$1001=A139)*(加仓管理!$G$2:$G$1001>0)),加仓管理!$D$2:$D$1001),"")) | AN139: =IF(AK139=0,"",IFERROR(LOOKUP(2,1/((加仓管理!$A$2:$A$1001=A139)*(加仓管理!$G$2:$G$1001>0)),加仓管理!$E$2:$E$1001),"")) | AO139: =IF(OR(A139="",H139="",H139<=0),"",(E139*H139+SUMIFS(加仓管理!$H$2:$H$1001,加仓管理!$A$2:$A$1001,A139))/AP139) | AP139: =IF(OR(A139="",H139="",H139<=0),"",H139+AL139) | AQ139: =IF(A139="","",IF(M139<>"",0,IF(OR(H139="",N139=""),"",MAX((E139*H139+SUMIFS(加仓管理!$H$2:$H$1001,加仓管理!$A$2:$A$1001,A139))-MAX(N139,AN139)*AP139,0)))) | AR139: =IF(A139="","",IF(OR(E139="",H139=""),"违规：首次买入价格或股数缺失",IF(COUNTIFS(加仓管理!$A$2:$A$1001,A139,加仓管理!$R$2:$R$1001,"违规*")>0,"违规：请检查加仓管理表",IF(SUM($AQ$2:$AQ$201)>账户数据!$B$7,"预警：超过账户风险上限",IF(COUNTIFS(加仓管理!$A$2:$A$1001,A139,加仓管理!$N$2:$N$1001,">0",加仓管理!$G$2:$G$1001,"")>0,"提示：存在待执行加仓计划","通过")))))
F140: =IF(OR(C140="",D140="",E140="",N140="",C140<=0,D140<=0,E140<=N140),"",ROUNDDOWN((C140*D140)/(E140-N140)/100,0)*100) | G140: =IF(A140="","",IF(H140<>"","已开仓",IF(账户数据!$B$23="已锁仓","禁止开仓：连续亏损达到上限",IF(账户数据!$B$23="解锁信息不完整","禁止开仓：请完整填写解锁信息",IF(OR(F140="",E140="",N140="",E140<=N140,账户数据!$B$7=""),"",IF(OR(AG140="",AH140="",AI140=""),"禁止开仓：交易预期未填写完整",IF(账户数据!$B$9+F140*(E140-N140)>=账户数据!$B$7,"禁止开仓：风险额度不足",IF(AJ140="周期与交易预期不匹配，请重新确认",IF(账户数据!$B$23="接近锁仓","允许开仓（接近锁仓；周期需复核）","允许开仓（周期需复核）"),IF(账户数据!$B$23="接近锁仓","允许开仓（接近锁仓）","允许开仓"))))))))) | L140: =IF(AP140="","",AP140) | U140: =IF(OR(AO140="",J140="",AO140<=0),"",(J140-AO140)/AO140) | V140: =IF(OR(AO140="",N140="",AO140<=0),"",(AO140-N140)/AO140) | W140: =IF(OR(U140="",V140="",V140<=0),"",U140/V140) | X140: =IF(OR(K140="",L140="",AO140="",AP140=""),"",(K140-AO140)*L140-IF(O140="",0,O140)-IF(P140="",0,P140)) | Y140: =IF(OR(X140="",AO140="",L140=""),"",IF(AO140*L140+IF(O140="",0,O140)<=0,"",X140/(AO140*L140+IF(O140="",0,O140)))) | Z140: =IF(OR(AE140="",多次统计数据!$B$8=""),"",AE140-多次统计数据!$B$8) | AA140: =IF(OR(I140="",M140="",M140<I140),"",M140-I140) | AB140: =IF(OR(A140="",多次统计数据!$B$8="",多次统计数据!$B$6<=0,多次统计数据!$B$6>=1),"",1-POWER(1+多次统计数据!$B$8,-多次统计数据!$B$6/(1-多次统计数据!$B$6))) | AC140: =IF(OR(AB140="",多次统计数据!$B$9=""),"",IF(多次统计数据!$B$9<AB140,"低于上限","达到或超过上限")) | AE140: =IF(OR(X140="",C140="",C140<=0),"",X140/C140) | AJ140: =IF(OR(AG140="",AH140=""),"",IF(OR(AND(AG140="短期博反弹",OR(AH140="1～3个交易日",AH140="4～10个交易日")),AND(AG140="突破冲新高",OR(AH140="4～10个交易日",AH140="11～20个交易日")),AND(AG140="趋势波段",OR(AH140="11～20个交易日",AH140="21～60个交易日",AH140="60个交易日以上"))),"匹配","周期与交易预期不匹配，请重新确认")) | AK140: =IF(A140="","",COUNTIFS(加仓管理!$A$2:$A$1001,A140,加仓管理!$G$2:$G$1001,">0")) | AL140: =IF(A140="","",SUMIFS(加仓管理!$G$2:$G$1001,加仓管理!$A$2:$A$1001,A140)) | AM140: =IF(AK140=0,"",IFERROR(LOOKUP(2,1/((加仓管理!$A$2:$A$1001=A140)*(加仓管理!$G$2:$G$1001>0)),加仓管理!$D$2:$D$1001),"")) | AN140: =IF(AK140=0,"",IFERROR(LOOKUP(2,1/((加仓管理!$A$2:$A$1001=A140)*(加仓管理!$G$2:$G$1001>0)),加仓管理!$E$2:$E$1001),"")) | AO140: =IF(OR(A140="",H140="",H140<=0),"",(E140*H140+SUMIFS(加仓管理!$H$2:$H$1001,加仓管理!$A$2:$A$1001,A140))/AP140) | AP140: =IF(OR(A140="",H140="",H140<=0),"",H140+AL140) | AQ140: =IF(A140="","",IF(M140<>"",0,IF(OR(H140="",N140=""),"",MAX((E140*H140+SUMIFS(加仓管理!$H$2:$H$1001,加仓管理!$A$2:$A$1001,A140))-MAX(N140,AN140)*AP140,0)))) | AR140: =IF(A140="","",IF(OR(E140="",H140=""),"违规：首次买入价格或股数缺失",IF(COUNTIFS(加仓管理!$A$2:$A$1001,A140,加仓管理!$R$2:$R$1001,"违规*")>0,"违规：请检查加仓管理表",IF(SUM($AQ$2:$AQ$201)>账户数据!$B$7,"预警：超过账户风险上限",IF(COUNTIFS(加仓管理!$A$2:$A$1001,A140,加仓管理!$N$2:$N$1001,">0",加仓管理!$G$2:$G$1001,"")>0,"提示：存在待执行加仓计划","通过")))))
F141: =IF(OR(C141="",D141="",E141="",N141="",C141<=0,D141<=0,E141<=N141),"",ROUNDDOWN((C141*D141)/(E141-N141)/100,0)*100) | G141: =IF(A141="","",IF(H141<>"","已开仓",IF(账户数据!$B$23="已锁仓","禁止开仓：连续亏损达到上限",IF(账户数据!$B$23="解锁信息不完整","禁止开仓：请完整填写解锁信息",IF(OR(F141="",E141="",N141="",E141<=N141,账户数据!$B$7=""),"",IF(OR(AG141="",AH141="",AI141=""),"禁止开仓：交易预期未填写完整",IF(账户数据!$B$9+F141*(E141-N141)>=账户数据!$B$7,"禁止开仓：风险额度不足",IF(AJ141="周期与交易预期不匹配，请重新确认",IF(账户数据!$B$23="接近锁仓","允许开仓（接近锁仓；周期需复核）","允许开仓（周期需复核）"),IF(账户数据!$B$23="接近锁仓","允许开仓（接近锁仓）","允许开仓"))))))))) | L141: =IF(AP141="","",AP141) | U141: =IF(OR(AO141="",J141="",AO141<=0),"",(J141-AO141)/AO141) | V141: =IF(OR(AO141="",N141="",AO141<=0),"",(AO141-N141)/AO141) | W141: =IF(OR(U141="",V141="",V141<=0),"",U141/V141) | X141: =IF(OR(K141="",L141="",AO141="",AP141=""),"",(K141-AO141)*L141-IF(O141="",0,O141)-IF(P141="",0,P141)) | Y141: =IF(OR(X141="",AO141="",L141=""),"",IF(AO141*L141+IF(O141="",0,O141)<=0,"",X141/(AO141*L141+IF(O141="",0,O141)))) | Z141: =IF(OR(AE141="",多次统计数据!$B$8=""),"",AE141-多次统计数据!$B$8) | AA141: =IF(OR(I141="",M141="",M141<I141),"",M141-I141) | AB141: =IF(OR(A141="",多次统计数据!$B$8="",多次统计数据!$B$6<=0,多次统计数据!$B$6>=1),"",1-POWER(1+多次统计数据!$B$8,-多次统计数据!$B$6/(1-多次统计数据!$B$6))) | AC141: =IF(OR(AB141="",多次统计数据!$B$9=""),"",IF(多次统计数据!$B$9<AB141,"低于上限","达到或超过上限")) | AE141: =IF(OR(X141="",C141="",C141<=0),"",X141/C141) | AJ141: =IF(OR(AG141="",AH141=""),"",IF(OR(AND(AG141="短期博反弹",OR(AH141="1～3个交易日",AH141="4～10个交易日")),AND(AG141="突破冲新高",OR(AH141="4～10个交易日",AH141="11～20个交易日")),AND(AG141="趋势波段",OR(AH141="11～20个交易日",AH141="21～60个交易日",AH141="60个交易日以上"))),"匹配","周期与交易预期不匹配，请重新确认")) | AK141: =IF(A141="","",COUNTIFS(加仓管理!$A$2:$A$1001,A141,加仓管理!$G$2:$G$1001,">0")) | AL141: =IF(A141="","",SUMIFS(加仓管理!$G$2:$G$1001,加仓管理!$A$2:$A$1001,A141)) | AM141: =IF(AK141=0,"",IFERROR(LOOKUP(2,1/((加仓管理!$A$2:$A$1001=A141)*(加仓管理!$G$2:$G$1001>0)),加仓管理!$D$2:$D$1001),"")) | AN141: =IF(AK141=0,"",IFERROR(LOOKUP(2,1/((加仓管理!$A$2:$A$1001=A141)*(加仓管理!$G$2:$G$1001>0)),加仓管理!$E$2:$E$1001),"")) | AO141: =IF(OR(A141="",H141="",H141<=0),"",(E141*H141+SUMIFS(加仓管理!$H$2:$H$1001,加仓管理!$A$2:$A$1001,A141))/AP141) | AP141: =IF(OR(A141="",H141="",H141<=0),"",H141+AL141) | AQ141: =IF(A141="","",IF(M141<>"",0,IF(OR(H141="",N141=""),"",MAX((E141*H141+SUMIFS(加仓管理!$H$2:$H$1001,加仓管理!$A$2:$A$1001,A141))-MAX(N141,AN141)*AP141,0)))) | AR141: =IF(A141="","",IF(OR(E141="",H141=""),"违规：首次买入价格或股数缺失",IF(COUNTIFS(加仓管理!$A$2:$A$1001,A141,加仓管理!$R$2:$R$1001,"违规*")>0,"违规：请检查加仓管理表",IF(SUM($AQ$2:$AQ$201)>账户数据!$B$7,"预警：超过账户风险上限",IF(COUNTIFS(加仓管理!$A$2:$A$1001,A141,加仓管理!$N$2:$N$1001,">0",加仓管理!$G$2:$G$1001,"")>0,"提示：存在待执行加仓计划","通过")))))
F142: =IF(OR(C142="",D142="",E142="",N142="",C142<=0,D142<=0,E142<=N142),"",ROUNDDOWN((C142*D142)/(E142-N142)/100,0)*100) | G142: =IF(A142="","",IF(H142<>"","已开仓",IF(账户数据!$B$23="已锁仓","禁止开仓：连续亏损达到上限",IF(账户数据!$B$23="解锁信息不完整","禁止开仓：请完整填写解锁信息",IF(OR(F142="",E142="",N142="",E142<=N142,账户数据!$B$7=""),"",IF(OR(AG142="",AH142="",AI142=""),"禁止开仓：交易预期未填写完整",IF(账户数据!$B$9+F142*(E142-N142)>=账户数据!$B$7,"禁止开仓：风险额度不足",IF(AJ142="周期与交易预期不匹配，请重新确认",IF(账户数据!$B$23="接近锁仓","允许开仓（接近锁仓；周期需复核）","允许开仓（周期需复核）"),IF(账户数据!$B$23="接近锁仓","允许开仓（接近锁仓）","允许开仓"))))))))) | L142: =IF(AP142="","",AP142) | U142: =IF(OR(AO142="",J142="",AO142<=0),"",(J142-AO142)/AO142) | V142: =IF(OR(AO142="",N142="",AO142<=0),"",(AO142-N142)/AO142) | W142: =IF(OR(U142="",V142="",V142<=0),"",U142/V142) | X142: =IF(OR(K142="",L142="",AO142="",AP142=""),"",(K142-AO142)*L142-IF(O142="",0,O142)-IF(P142="",0,P142)) | Y142: =IF(OR(X142="",AO142="",L142=""),"",IF(AO142*L142+IF(O142="",0,O142)<=0,"",X142/(AO142*L142+IF(O142="",0,O142)))) | Z142: =IF(OR(AE142="",多次统计数据!$B$8=""),"",AE142-多次统计数据!$B$8) | AA142: =IF(OR(I142="",M142="",M142<I142),"",M142-I142) | AB142: =IF(OR(A142="",多次统计数据!$B$8="",多次统计数据!$B$6<=0,多次统计数据!$B$6>=1),"",1-POWER(1+多次统计数据!$B$8,-多次统计数据!$B$6/(1-多次统计数据!$B$6))) | AC142: =IF(OR(AB142="",多次统计数据!$B$9=""),"",IF(多次统计数据!$B$9<AB142,"低于上限","达到或超过上限")) | AE142: =IF(OR(X142="",C142="",C142<=0),"",X142/C142) | AJ142: =IF(OR(AG142="",AH142=""),"",IF(OR(AND(AG142="短期博反弹",OR(AH142="1～3个交易日",AH142="4～10个交易日")),AND(AG142="突破冲新高",OR(AH142="4～10个交易日",AH142="11～20个交易日")),AND(AG142="趋势波段",OR(AH142="11～20个交易日",AH142="21～60个交易日",AH142="60个交易日以上"))),"匹配","周期与交易预期不匹配，请重新确认")) | AK142: =IF(A142="","",COUNTIFS(加仓管理!$A$2:$A$1001,A142,加仓管理!$G$2:$G$1001,">0")) | AL142: =IF(A142="","",SUMIFS(加仓管理!$G$2:$G$1001,加仓管理!$A$2:$A$1001,A142)) | AM142: =IF(AK142=0,"",IFERROR(LOOKUP(2,1/((加仓管理!$A$2:$A$1001=A142)*(加仓管理!$G$2:$G$1001>0)),加仓管理!$D$2:$D$1001),"")) | AN142: =IF(AK142=0,"",IFERROR(LOOKUP(2,1/((加仓管理!$A$2:$A$1001=A142)*(加仓管理!$G$2:$G$1001>0)),加仓管理!$E$2:$E$1001),"")) | AO142: =IF(OR(A142="",H142="",H142<=0),"",(E142*H142+SUMIFS(加仓管理!$H$2:$H$1001,加仓管理!$A$2:$A$1001,A142))/AP142) | AP142: =IF(OR(A142="",H142="",H142<=0),"",H142+AL142) | AQ142: =IF(A142="","",IF(M142<>"",0,IF(OR(H142="",N142=""),"",MAX((E142*H142+SUMIFS(加仓管理!$H$2:$H$1001,加仓管理!$A$2:$A$1001,A142))-MAX(N142,AN142)*AP142,0)))) | AR142: =IF(A142="","",IF(OR(E142="",H142=""),"违规：首次买入价格或股数缺失",IF(COUNTIFS(加仓管理!$A$2:$A$1001,A142,加仓管理!$R$2:$R$1001,"违规*")>0,"违规：请检查加仓管理表",IF(SUM($AQ$2:$AQ$201)>账户数据!$B$7,"预警：超过账户风险上限",IF(COUNTIFS(加仓管理!$A$2:$A$1001,A142,加仓管理!$N$2:$N$1001,">0",加仓管理!$G$2:$G$1001,"")>0,"提示：存在待执行加仓计划","通过")))))
F143: =IF(OR(C143="",D143="",E143="",N143="",C143<=0,D143<=0,E143<=N143),"",ROUNDDOWN((C143*D143)/(E143-N143)/100,0)*100) | G143: =IF(A143="","",IF(H143<>"","已开仓",IF(账户数据!$B$23="已锁仓","禁止开仓：连续亏损达到上限",IF(账户数据!$B$23="解锁信息不完整","禁止开仓：请完整填写解锁信息",IF(OR(F143="",E143="",N143="",E143<=N143,账户数据!$B$7=""),"",IF(OR(AG143="",AH143="",AI143=""),"禁止开仓：交易预期未填写完整",IF(账户数据!$B$9+F143*(E143-N143)>=账户数据!$B$7,"禁止开仓：风险额度不足",IF(AJ143="周期与交易预期不匹配，请重新确认",IF(账户数据!$B$23="接近锁仓","允许开仓（接近锁仓；周期需复核）","允许开仓（周期需复核）"),IF(账户数据!$B$23="接近锁仓","允许开仓（接近锁仓）","允许开仓"))))))))) | L143: =IF(AP143="","",AP143) | U143: =IF(OR(AO143="",J143="",AO143<=0),"",(J143-AO143)/AO143) | V143: =IF(OR(AO143="",N143="",AO143<=0),"",(AO143-N143)/AO143) | W143: =IF(OR(U143="",V143="",V143<=0),"",U143/V143) | X143: =IF(OR(K143="",L143="",AO143="",AP143=""),"",(K143-AO143)*L143-IF(O143="",0,O143)-IF(P143="",0,P143)) | Y143: =IF(OR(X143="",AO143="",L143=""),"",IF(AO143*L143+IF(O143="",0,O143)<=0,"",X143/(AO143*L143+IF(O143="",0,O143)))) | Z143: =IF(OR(AE143="",多次统计数据!$B$8=""),"",AE143-多次统计数据!$B$8) | AA143: =IF(OR(I143="",M143="",M143<I143),"",M143-I143) | AB143: =IF(OR(A143="",多次统计数据!$B$8="",多次统计数据!$B$6<=0,多次统计数据!$B$6>=1),"",1-POWER(1+多次统计数据!$B$8,-多次统计数据!$B$6/(1-多次统计数据!$B$6))) | AC143: =IF(OR(AB143="",多次统计数据!$B$9=""),"",IF(多次统计数据!$B$9<AB143,"低于上限","达到或超过上限")) | AE143: =IF(OR(X143="",C143="",C143<=0),"",X143/C143) | AJ143: =IF(OR(AG143="",AH143=""),"",IF(OR(AND(AG143="短期博反弹",OR(AH143="1～3个交易日",AH143="4～10个交易日")),AND(AG143="突破冲新高",OR(AH143="4～10个交易日",AH143="11～20个交易日")),AND(AG143="趋势波段",OR(AH143="11～20个交易日",AH143="21～60个交易日",AH143="60个交易日以上"))),"匹配","周期与交易预期不匹配，请重新确认")) | AK143: =IF(A143="","",COUNTIFS(加仓管理!$A$2:$A$1001,A143,加仓管理!$G$2:$G$1001,">0")) | AL143: =IF(A143="","",SUMIFS(加仓管理!$G$2:$G$1001,加仓管理!$A$2:$A$1001,A143)) | AM143: =IF(AK143=0,"",IFERROR(LOOKUP(2,1/((加仓管理!$A$2:$A$1001=A143)*(加仓管理!$G$2:$G$1001>0)),加仓管理!$D$2:$D$1001),"")) | AN143: =IF(AK143=0,"",IFERROR(LOOKUP(2,1/((加仓管理!$A$2:$A$1001=A143)*(加仓管理!$G$2:$G$1001>0)),加仓管理!$E$2:$E$1001),"")) | AO143: =IF(OR(A143="",H143="",H143<=0),"",(E143*H143+SUMIFS(加仓管理!$H$2:$H$1001,加仓管理!$A$2:$A$1001,A143))/AP143) | AP143: =IF(OR(A143="",H143="",H143<=0),"",H143+AL143) | AQ143: =IF(A143="","",IF(M143<>"",0,IF(OR(H143="",N143=""),"",MAX((E143*H143+SUMIFS(加仓管理!$H$2:$H$1001,加仓管理!$A$2:$A$1001,A143))-MAX(N143,AN143)*AP143,0)))) | AR143: =IF(A143="","",IF(OR(E143="",H143=""),"违规：首次买入价格或股数缺失",IF(COUNTIFS(加仓管理!$A$2:$A$1001,A143,加仓管理!$R$2:$R$1001,"违规*")>0,"违规：请检查加仓管理表",IF(SUM($AQ$2:$AQ$201)>账户数据!$B$7,"预警：超过账户风险上限",IF(COUNTIFS(加仓管理!$A$2:$A$1001,A143,加仓管理!$N$2:$N$1001,">0",加仓管理!$G$2:$G$1001,"")>0,"提示：存在待执行加仓计划","通过")))))
F144: =IF(OR(C144="",D144="",E144="",N144="",C144<=0,D144<=0,E144<=N144),"",ROUNDDOWN((C144*D144)/(E144-N144)/100,0)*100) | G144: =IF(A144="","",IF(H144<>"","已开仓",IF(账户数据!$B$23="已锁仓","禁止开仓：连续亏损达到上限",IF(账户数据!$B$23="解锁信息不完整","禁止开仓：请完整填写解锁信息",IF(OR(F144="",E144="",N144="",E144<=N144,账户数据!$B$7=""),"",IF(OR(AG144="",AH144="",AI144=""),"禁止开仓：交易预期未填写完整",IF(账户数据!$B$9+F144*(E144-N144)>=账户数据!$B$7,"禁止开仓：风险额度不足",IF(AJ144="周期与交易预期不匹配，请重新确认",IF(账户数据!$B$23="接近锁仓","允许开仓（接近锁仓；周期需复核）","允许开仓（周期需复核）"),IF(账户数据!$B$23="接近锁仓","允许开仓（接近锁仓）","允许开仓"))))))))) | L144: =IF(AP144="","",AP144) | U144: =IF(OR(AO144="",J144="",AO144<=0),"",(J144-AO144)/AO144) | V144: =IF(OR(AO144="",N144="",AO144<=0),"",(AO144-N144)/AO144) | W144: =IF(OR(U144="",V144="",V144<=0),"",U144/V144) | X144: =IF(OR(K144="",L144="",AO144="",AP144=""),"",(K144-AO144)*L144-IF(O144="",0,O144)-IF(P144="",0,P144)) | Y144: =IF(OR(X144="",AO144="",L144=""),"",IF(AO144*L144+IF(O144="",0,O144)<=0,"",X144/(AO144*L144+IF(O144="",0,O144)))) | Z144: =IF(OR(AE144="",多次统计数据!$B$8=""),"",AE144-多次统计数据!$B$8) | AA144: =IF(OR(I144="",M144="",M144<I144),"",M144-I144) | AB144: =IF(OR(A144="",多次统计数据!$B$8="",多次统计数据!$B$6<=0,多次统计数据!$B$6>=1),"",1-POWER(1+多次统计数据!$B$8,-多次统计数据!$B$6/(1-多次统计数据!$B$6))) | AC144: =IF(OR(AB144="",多次统计数据!$B$9=""),"",IF(多次统计数据!$B$9<AB144,"低于上限","达到或超过上限")) | AE144: =IF(OR(X144="",C144="",C144<=0),"",X144/C144) | AJ144: =IF(OR(AG144="",AH144=""),"",IF(OR(AND(AG144="短期博反弹",OR(AH144="1～3个交易日",AH144="4～10个交易日")),AND(AG144="突破冲新高",OR(AH144="4～10个交易日",AH144="11～20个交易日")),AND(AG144="趋势波段",OR(AH144="11～20个交易日",AH144="21～60个交易日",AH144="60个交易日以上"))),"匹配","周期与交易预期不匹配，请重新确认")) | AK144: =IF(A144="","",COUNTIFS(加仓管理!$A$2:$A$1001,A144,加仓管理!$G$2:$G$1001,">0")) | AL144: =IF(A144="","",SUMIFS(加仓管理!$G$2:$G$1001,加仓管理!$A$2:$A$1001,A144)) | AM144: =IF(AK144=0,"",IFERROR(LOOKUP(2,1/((加仓管理!$A$2:$A$1001=A144)*(加仓管理!$G$2:$G$1001>0)),加仓管理!$D$2:$D$1001),"")) | AN144: =IF(AK144=0,"",IFERROR(LOOKUP(2,1/((加仓管理!$A$2:$A$1001=A144)*(加仓管理!$G$2:$G$1001>0)),加仓管理!$E$2:$E$1001),"")) | AO144: =IF(OR(A144="",H144="",H144<=0),"",(E144*H144+SUMIFS(加仓管理!$H$2:$H$1001,加仓管理!$A$2:$A$1001,A144))/AP144) | AP144: =IF(OR(A144="",H144="",H144<=0),"",H144+AL144) | AQ144: =IF(A144="","",IF(M144<>"",0,IF(OR(H144="",N144=""),"",MAX((E144*H144+SUMIFS(加仓管理!$H$2:$H$1001,加仓管理!$A$2:$A$1001,A144))-MAX(N144,AN144)*AP144,0)))) | AR144: =IF(A144="","",IF(OR(E144="",H144=""),"违规：首次买入价格或股数缺失",IF(COUNTIFS(加仓管理!$A$2:$A$1001,A144,加仓管理!$R$2:$R$1001,"违规*")>0,"违规：请检查加仓管理表",IF(SUM($AQ$2:$AQ$201)>账户数据!$B$7,"预警：超过账户风险上限",IF(COUNTIFS(加仓管理!$A$2:$A$1001,A144,加仓管理!$N$2:$N$1001,">0",加仓管理!$G$2:$G$1001,"")>0,"提示：存在待执行加仓计划","通过")))))
